<?xml version="1.0" ?>
<robot name="RH5v2" version="1.0">
        <joint name="ALBase" type="fixed">
                <origin rpy="1.508093 0.25436 1.3265" xyz="0.29809 0.12609 0.025162"/>
                <parent link="Connector_Body/Torso_Link"/>
                <child link="ALBase_Link"/>
        </joint>
        <link name="ALBase_Link">
                <inertial>
                        <origin rpy="0.0 0.0 0.0" xyz="0.0079897 0.0 0.00019625"/>
                        <mass value="1.1943"/>
                        <inertia ixx="0.00089755" ixy="1.4484e-08" ixz="-2.6127e-07" iyy="0.00057565" iyz="-7.8027e-07" izz="0.00056347"/>
                </inertial>
                <visual name="ALBase_Link_Visual">
                        <origin rpy="0.0 0.0 0.0" xyz="0.0 0.0 0.0"/>
                        <geometry>
                                <mesh filename="../meshes/ALBase_Link.stl"/>
                        </geometry>
                        <material name="">
                                <color rgba="0.75294 0.75294 0.75294 1.0"/>
                        </material>
                </visual>
                <collision name="ALBase_Link_Collision">
                        <origin rpy="0.0 0.0 0.0" xyz="0.0 0.0 0.0"/>
                        <geometry>
                                <mesh filename="../meshes/ALBase_Link_convexhull.stl" scale="1.0 1.0 1.0"/>
                        </geometry>
                </collision>
        </link>
        <joint name="ALElbow" type="revolute">
                <origin rpy="0.0 0.0 0.0" xyz="0.0 0.001 0.3511"/>
                <axis xyz="1.0 0.0 0.0"/>
                <parent link="ALShoulder3_Link"/>
                <child link="ALElbow_Link"/>
                <limit effort="110.13" lower="-1.78" upper="0.01" velocity="7.075"/>
        </joint>
        <joint name="ALElbowAct" type="prismatic">
                <origin rpy="0.0 0.0 0.0" xyz="0.0 0.0 0.29542"/>
                <axis xyz="0.0 0.0 1.0"/>
                <parent link="ALElbowB11_Link"/>
                <child link="ALElbowAct_Link"/>
                <limit effort="2000.0" lower="-0.119" upper="-0.001" velocity="0.266"/>
        </joint>
        <link name="ALElbowAct_Link">
                <inertial>
                        <origin rpy="0.0 0.0 0.0" xyz="0.0 0.0 -0.085859"/>
                        <mass value="0.054652"/>
                        <inertia ixx="0.00010606969013629223" ixy="0.0" ixz="3.6185000000071752e-09" iyy="0.00010597469013629217" iyz="0.0" izz="1.0000000136292127e-05"/>
                </inertial>
                <visual name="ALElbowAct_Link_Visual">
                        <origin rpy="0.0 0.0 0.0" xyz="0.0 0.0 0.0"/>
                        <geometry>
                                <mesh filename="../meshes/ALElbow_Act_Link.stl"/>
                        </geometry>
                        <material name="">
                                <color rgba="0.75294 0.75294 0.75294 1.0"/>
                        </material>
                </visual>
                <collision name="ALElbowAct_Link_Collision">
                        <origin rpy="0.0 0.0 0.0" xyz="0.0 0.0 0.0"/>
                        <geometry>
                                <mesh filename="../meshes/ALElbow_Act_Link_convexhull.stl" scale="1.0 1.0 1.0"/>
                        </geometry>
                </collision>
        </link>
        <joint name="ALElbowB11" type="revolute">
                <origin rpy="-0.25319 0.0 0.0" xyz="0.0 -0.029 0.1391"/>
                <axis xyz="1.0 0.0 0.0"/>
                <parent link="ALShoulder3_Link"/>
                <child link="ALElbowB11_Link"/>
                <limit effort="400.0" lower="-1.57" upper="1.57" velocity="3.1415926"/>
        </joint>
        <link name="ALElbowB11_Link">
                <inertial>
                        <origin rpy="0.0 0.0 0.0" xyz="0.0 0.0 0.10704"/>
                        <mass value="0.32696"/>
                        <inertia ixx="0.00011102" ixy="-1.0985e-08" ixz="-6.6288e-08" iyy="0.00011251" iyz="1.4067e-07" izz="7.0733e-05"/>
                </inertial>
                <visual name="ALElbowB11_Link_Visual">
                        <origin rpy="0.0 0.0 0.0" xyz="0.0 0.0 0.0"/>
                        <geometry>
                                <mesh filename="../meshes/ALElbow_B11_Link.stl"/>
                        </geometry>
                        <material name="">
                                <color rgba="0.75294 0.75294 0.75294 1.0"/>
                        </material>
                </visual>
                <collision name="ALElbowB11_Link_Collision">
                        <origin rpy="0.0 0.0 0.0" xyz="0.0 0.0 0.0"/>
                        <geometry>
                                <mesh filename="../meshes/ALElbow_B11_Link_convexhull.stl" scale="1.0 1.0 1.0"/>
                        </geometry>
                </collision>
        </link>
        <link name="ALElbow_Link">
                <inertial>
                        <origin rpy="0.0 0.0 0.0" xyz="0.0 0.001127 0.080286"/>
                        <mass value="0.63578"/>
                        <inertia ixx="0.00050999" ixy="2.2297e-07" ixz="4.047e-07" iyy="0.00051633" iyz="-4.4233e-05" izz="0.00046537"/>
                </inertial>
                <visual name="ALElbow_Link_Visual">
                        <origin rpy="0.0 0.0 0.0" xyz="0.0 0.0 0.0"/>
                        <geometry>
                                <mesh filename="../meshes/ALElbow_Link.stl"/>
                        </geometry>
                        <material name="">
                                <color rgba="0.75294 0.75294 0.75294 1.0"/>
                        </material>
                </visual>
                <collision name="ALElbow_Link_Collision">
                        <origin rpy="0.0 0.0 0.0" xyz="0.0 0.0 0.0"/>
                        <geometry>
                                <mesh filename="../meshes/ALElbow_Link_convexhull.stl" scale="1.0 1.0 1.0"/>
                        </geometry>
                </collision>
        </link>
        <joint name="ALShoulder1" type="revolute">
                <origin rpy="3.1416 0.0 0.0" xyz="0.1076 0.0 0.0"/>
                <axis xyz="1.0 0.0 0.0"/>
                <parent link="ALBase_Link"/>
                <child link="ALShoulder1_Link"/>
                <limit effort="157.0" lower="-3.0543" upper="3.0543" velocity="3.6"/>
        </joint>
        <link name="ALShoulder1_Link">
                <inertial>
                        <origin rpy="0.0 0.0 0.0" xyz="-0.0091569 0.0036464 -0.00016872"/>
                        <mass value="1.602"/>
                        <inertia ixx="0.0012117" ixy="-8.0704e-05" ixz="-3.528e-06" iyy="0.0015561" iyz="-2.6511e-06" izz="0.0010024"/>
                </inertial>
                <visual name="ALShoulder1_Link_Visual">
                        <origin rpy="0.0 0.0 0.0" xyz="0.0 0.0 0.0"/>
                        <geometry>
                                <mesh filename="../meshes/ALShoulder1_Link.stl"/>
                        </geometry>
                        <material name="">
                                <color rgba="0.75294 0.75294 0.75294 1.0"/>
                        </material>
                </visual>
                <collision name="ALShoulder1_Link_Collision">
                        <origin rpy="0.0 0.0 0.0" xyz="0.0 0.0 0.0"/>
                        <geometry>
                                <mesh filename="../meshes/ALShoulder1_Link_convexhull.stl" scale="1.0 1.0 1.0"/>
                        </geometry>
                </collision>
        </link>
        <joint name="ALShoulder2" type="revolute">
                <origin rpy="0.0 0.0 0.0" xyz="0.0 0.0 0.0"/>
                <axis xyz="0.0 1.0 0.0"/>
                <parent link="ALShoulder1_Link"/>
                <child link="ALShoulder2_Link"/>
                <limit effort="157.0" lower="-0.248" upper="1.845" velocity="3.6"/>
        </joint>
        <link name="ALShoulder2_Link">
                <inertial>
                        <origin rpy="0.0 0.0 0.0" xyz="0.010763 0.020477 0.0278"/>
                        <mass value="0.50849"/>
                        <inertia ixx="0.0010465" ixy="0.00012061" ixz="5.4855e-05" iyy="0.00092568" iyz="0.00027501" izz="0.0010393"/>
                </inertial>
                <visual name="ALShoulder2_Link_Visual">
                        <origin rpy="0.0 0.0 0.0" xyz="0.0 0.0 0.0"/>
                        <geometry>
                                <mesh filename="../meshes/ALShoulder2_Link.stl"/>
                        </geometry>
                        <material name="">
                                <color rgba="0.75294 0.75294 0.75294 1.0"/>
                        </material>
                </visual>
                <collision name="ALShoulder2_Link_Collision">
                        <origin rpy="0.0 0.0 0.0" xyz="0.0 0.0 0.0"/>
                        <geometry>
                                <mesh filename="../meshes/ALShoulder2_Link_convexhull.stl" scale="1.0 1.0 1.0"/>
                        </geometry>
                </collision>
        </link>
        <joint name="ALShoulder3" type="revolute">
                <origin rpy="0.0 0.0 1.5707" xyz="0.0 0.0 0.0"/>
                <axis xyz="0.0 0.0 1.0"/>
                <parent link="ALShoulder2_Link"/>
                <child link="ALShoulder3_Link"/>
                <limit effort="28.0" lower="-3.0543" upper="3.0543" velocity="5.7"/>
        </joint>
        <link name="ALShoulder3_Link">
                <inertial>
                        <origin rpy="0.0 0.0 0.0" xyz="0.0 0.0033688 0.14648"/>
                        <mass value="0.85234"/>
                        <inertia ixx="0.0028013" ixy="5.1939e-07" ixz="-7.2591e-07" iyy="0.0027401" iyz="5.4672e-05" izz="0.00078629"/>
                </inertial>
                <visual name="ALShoulder3_Link_Visual">
                        <origin rpy="0.0 0.0 0.0" xyz="0.0 0.0 0.0"/>
                        <geometry>
                                <mesh filename="../meshes/ALShoulder3_Link.stl"/>
                        </geometry>
                        <material name="">
                                <color rgba="0.75294 0.75294 0.75294 1.0"/>
                        </material>
                </visual>
                <collision name="ALShoulder3_Link_Collision">
                        <origin rpy="0.0 0.0 0.0" xyz="0.0 0.0 0.0"/>
                        <geometry>
                                <mesh filename="../meshes/ALShoulder3_Link_convexhull.stl" scale="1.0 1.0 1.0"/>
                        </geometry>
                </collision>
        </link>
        <joint name="ALWristAL1" type="revolute">
                <origin rpy="1.5885 0.0 0.0" xyz="0.0155 -0.034 -0.178"/>
                <axis xyz="1.0 0.0 0.0"/>
                <parent link="ALWristRoot_Link"/>
                <child link="ALWristAL1_Link"/>
                <limit effort="400.0" lower="-1.57" upper="1.57" velocity="3.1415926"/>
        </joint>
        <link name="ALWristAL1_Link">
                <inertial>
                        <origin rpy="0.0 0.0 0.0" xyz="0.0 0.0605130022183077 0.0"/>
                        <mass value="0.110279568172128"/>
                        <inertia ixx="1.426060228931759e-05" ixy="-1.1829530729395678e-10" ixz="-1.5559842262297789e-09" iyy="1.0001497220685684e-05" iyz="-8.070848171024899e-08" izz="1.4350648635894694e-05"/>
                </inertial>
                <visual name="ALWristAL1_Link_Visual">
                        <origin rpy="0.0 0.0 0.0" xyz="0.0 0.0 0.0"/>
                        <geometry>
                                <mesh filename="../meshes/ALWrist_AL1_Link.stl"/>
                        </geometry>
                        <material name="">
                                <color rgba="0.898039215686275 0.917647058823529 0.929411764705882 1.0"/>
                        </material>
                </visual>
                <collision name="ALWristAL1_Link_Collision">
                        <origin rpy="0.0 0.0 0.0" xyz="0.0 0.0 0.0"/>
                        <geometry>
                                <mesh filename="../meshes/ALWrist_AL1_Link_convexhull.stl" scale="1.0 1.0 1.0"/>
                        </geometry>
                </collision>
        </link>
        <joint name="ALWristAR1" type="revolute">
                <origin rpy="1.5885 0.0 0.0" xyz="-0.0155 -0.034 -0.178"/>
                <axis xyz="1.0 0.0 0.0"/>
                <parent link="ALWristRoot_Link"/>
                <child link="ALWristAR1_Link"/>
                <limit effort="400.0" lower="-1.57" upper="1.57" velocity="3.1415926"/>
        </joint>
        <link name="ALWristAR1_Link">
                <inertial>
                        <origin rpy="0.0 0.0 0.0" xyz="0.0 0.058479 0.0"/>
                        <mass value="0.10113"/>
                        <inertia ixx="1.4212213742562422e-05" ixy="-1.1886000000000004e-10" ixz="-1.4829999999999594e-10" iyy="1.000151374256242e-05" iyz="-8.070899999999586e-08" izz="1.4303213742562425e-05"/>
                </inertial>
                <visual name="ALWristAR1_Link_Visual">
                        <origin rpy="0.0 0.0 0.0" xyz="0.0 0.0 0.0"/>
                        <geometry>
                                <mesh filename="../meshes/ALWrist_AR1_Link.stl"/>
                        </geometry>
                        <material name="">
                                <color rgba="0.89804 0.91765 0.92941 1.0"/>
                        </material>
                </visual>
                <collision name="ALWristAR1_Link_Collision">
                        <origin rpy="0.0 0.0 0.0" xyz="0.0 0.0 0.0"/>
                        <geometry>
                                <mesh filename="../meshes/ALWrist_AR1_Link_convexhull.stl" scale="1.0 1.0 1.0"/>
                        </geometry>
                </collision>
        </link>
        <joint name="ALWristActL" type="prismatic">
                <origin rpy="-1.5708 0.0 0.0" xyz="0.0 0.13346 0.0"/>
                <axis xyz="0.0 0.0 1.0"/>
                <parent link="ALWristAL1_Link"/>
                <child link="ALWristActL_Link"/>
                <limit effort="1094.0" lower="-0.018" upper="0.038" velocity="0.2"/>
        </joint>
        <link name="ALWristActL_Link">
                <inertial>
                        <origin rpy="0.0 0.0 0.0" xyz="0.0 0.0 -0.049176"/>
                        <mass value="0.022415"/>
                        <inertia ixx="2.2515570000000003e-05" ixy="0.0" ixz="0.0" iyy="2.2496570000000005e-05" iyz="0.0" izz="1e-05"/>
                </inertial>
                <visual name="ALWristActL_Link_Visual">
                        <origin rpy="0.0 0.0 0.0" xyz="0.0 0.0 0.0"/>
                        <geometry>
                                <mesh filename="../meshes/ALWrist_ActL_Link.stl"/>
                        </geometry>
                        <material name="">
                                <color rgba="0.77647 0.75686 0.73725 1.0"/>
                        </material>
                </visual>
                <collision name="ALWristActL_Link_Collision">
                        <origin rpy="0.0 0.0 0.0" xyz="0.0 0.0 0.0"/>
                        <geometry>
                                <mesh filename="../meshes/ALWrist_ActL_Link_convexhull.stl" scale="1.0 1.0 1.0"/>
                        </geometry>
                </collision>
        </link>
        <joint name="ALWristActR" type="prismatic">
                <origin rpy="-1.5708 0.0 0.0" xyz="0.0 0.13346 0.0"/>
                <axis xyz="0.0 0.0 1.0"/>
                <parent link="ALWristAR1_Link"/>
                <child link="ALWristActR_Link"/>
                <limit effort="1094.0" lower="-0.018" upper="0.038" velocity="0.2"/>
        </joint>
        <link name="ALWristActR_Link">
                <inertial>
                        <origin rpy="0.0 0.0 0.0" xyz="0.0 0.0 -0.0491763872735069"/>
                        <mass value="0.0224154782060298"/>
                        <inertia ixx="2.251577391703877e-05" ixy="0.0" ixz="0.0" iyy="2.249645939989927e-05" iyz="0.0" izz="1e-05"/>
                </inertial>
                <visual name="ALWristActR_Link_Visual">
                        <origin rpy="0.0 0.0 0.0" xyz="0.0 0.0 0.0"/>
                        <geometry>
                                <mesh filename="../meshes/ALWrist_ActR_Link.stl"/>
                        </geometry>
                        <material name="">
                                <color rgba="0.776470588235294 0.756862745098039 0.737254901960784 1.0"/>
                        </material>
                </visual>
                <collision name="ALWristActR_Link_Collision">
                        <origin rpy="0.0 0.0 0.0" xyz="0.0 0.0 0.0"/>
                        <geometry>
                                <mesh filename="../meshes/ALWrist_ActR_Link_convexhull.stl" scale="1.0 1.0 1.0"/>
                        </geometry>
                </collision>
        </link>
        <joint name="ALWristBL0" type="revolute">
                <origin rpy="0.0 0.0 0.0" xyz="0.0 0.0 0.045018"/>
                <axis xyz="1.0 0.0 0.0"/>
                <parent link="ALWristBL3_Link"/>
                <child link="ALWristBL0_Link"/>
                <limit effort="400.0" lower="-1.57" upper="1.57" velocity="3.1415926"/>
        </joint>
        <link name="ALWristBL0_Link">
                <inertial>
                        <origin rpy="0.0 0.0 0.0" xyz="0.0 0.0 0.0"/>
                        <mass value="0.0"/>
                        <inertia ixx="1e-05" ixy="0.0" ixz="0.0" iyy="1e-05" iyz="0.0" izz="1e-05"/>
                </inertial>
        </link>
        <joint name="ALWristBL1" type="revolute">
                <origin rpy="-2.8824 0.0 0.0" xyz="0.0155 0.011 -0.032"/>
                <axis xyz="1.0 0.0 0.0"/>
                <parent link="ALWristRoot_Link"/>
                <child link="ALWristBL1_Link"/>
                <limit effort="400.0" lower="-1.57" upper="1.57" velocity="3.1415926"/>
        </joint>
        <link name="ALWristBL1_Link">
                <inertial>
                        <origin rpy="0.0 0.0 0.0" xyz="0.0019151 0.02635 0.0010414"/>
                        <mass value="0.024008"/>
                        <inertia ixx="1.369030932629815e-05" ixy="0.0" ixz="0.0" iyy="1.004128932629815e-05" iyz="3.866799999999999e-07" izz="1.362130932629815e-05"/>
                </inertial>
                <visual name="ALWristBL1_Link_Visual">
                        <origin rpy="0.0 0.0 0.0" xyz="0.0 0.0 0.0"/>
                        <geometry>
                                <mesh filename="../meshes/ALWrist_BL1_Link.stl"/>
                        </geometry>
                        <material name="">
                                <color rgba="0.89804 0.91765 0.92941 1.0"/>
                        </material>
                </visual>
                <collision name="ALWristBL1_Link_Collision">
                        <origin rpy="0.0 0.0 0.0" xyz="0.0 0.0 0.0"/>
                        <geometry>
                                <mesh filename="../meshes/ALWrist_BL1_Link_convexhull.stl" scale="1.0 1.0 1.0"/>
                        </geometry>
                </collision>
        </link>
        <joint name="ALWristBL2" type="revolute">
                <origin rpy="0.0 0.0 0.0" xyz="0.0 0.0 0.0"/>
                <axis xyz="0.0 1.0 0.0"/>
                <parent link="ALWristBL0_Link"/>
                <child link="ALWristBL2_Link"/>
                <limit effort="400.0" lower="-1.57" upper="1.57" velocity="3.1415926"/>
        </joint>
        <link name="ALWristBL2_Link">
                <inertial>
                        <origin rpy="0.0 0.0 0.0" xyz="-0.00285895892979633 0.0 0.0"/>
                        <mass value="0.00373058333172257"/>
                        <inertia ixx="1.0000022086306678e-05" ixy="0.0" ixz="1.2800661535321242e-09" iyy="1.0074214747460805e-05" iyz="0.0" izz="1.0074189380048775e-05"/>
                </inertial>
                <visual name="ALWristBL2_Link_Visual">
                        <origin rpy="0.0 0.0 0.0" xyz="0.0 0.0 0.0"/>
                        <geometry>
                                <mesh filename="../meshes/ALWrist_BL2_Link.stl"/>
                        </geometry>
                        <material name="">
                                <color rgba="0.647058823529412 0.619607843137255 0.588235294117647 1.0"/>
                        </material>
                </visual>
                <collision name="ALWristBL2_Link_Collision">
                        <origin rpy="0.0 0.0 0.0" xyz="0.0 0.0 0.0"/>
                        <geometry>
                                <mesh filename="../meshes/ALWrist_BL2_Link_convexhull.stl" scale="1.0 1.0 1.0"/>
                        </geometry>
                </collision>
        </link>
        <joint name="ALWristBL3" type="revolute">
                <origin rpy="0.0 -0.017255 0.0" xyz="0.0 0.0 0.0"/>
                <axis xyz="0.0 1.0 0.0"/>
                <parent link="ALWristBL4_Link"/>
                <child link="ALWristBL3_Link"/>
                <limit effort="400.0" lower="-1.57" upper="1.57" velocity="3.1415926"/>
        </joint>
        <link name="ALWristBL3_Link">
                <inertial>
                        <origin rpy="0.0 0.0 0.0" xyz="0.0 0.0 0.0283017467527962"/>
                        <mass value="0.0163436688111198"/>
                        <inertia ixx="1.0588437589385662e-05" ixy="2.6491888917750254e-12" ixz="3.971418402991697e-10" iyy="1.0442298027473029e-05" iyz="-1.0478564692762442e-11" izz="1.0000000268282943e-05"/>
                </inertial>
                <visual name="ALWristBL3_Link_Visual">
                        <origin rpy="0.0 0.0 0.0" xyz="0.0 0.0 0.0"/>
                        <geometry>
                                <mesh filename="../meshes/ALWrist_BL3_Link.stl"/>
                        </geometry>
                        <material name="">
                                <color rgba="0.898039215686275 0.917647058823529 0.929411764705882 1.0"/>
                        </material>
                </visual>
                <collision name="ALWristBL3_Link_Collision">
                        <origin rpy="0.0 0.0 0.0" xyz="0.0 0.0 0.0"/>
                        <geometry>
                                <mesh filename="../meshes/ALWrist_BL3_Link_convexhull.stl" scale="1.0 1.0 1.0"/>
                        </geometry>
                </collision>
        </link>
        <joint name="ALWristBL4" type="revolute">
                <origin rpy="2.9998 0.0 0.0" xyz="0.027 -0.03 0.0"/>
                <axis xyz="1.0 0.0 0.0"/>
                <parent link="ALWristYaw_Link"/>
                <child link="ALWristBL4_Link"/>
                <limit effort="400.0" lower="-1.57" upper="1.57" velocity="3.1415926"/>
        </joint>
        <link name="ALWristBL4_Link">
                <inertial>
                        <origin rpy="0.0 0.0 0.0" xyz="-0.00221364330903131 0.0 0.0"/>
                        <mass value="0.0116530368127355"/>
                        <inertia ixx="1e-05" ixy="0.0" ixz="0.0" iyy="1.027752247888744e-05" iyz="0.0" izz="1.0188830976875939e-05"/>
                </inertial>
                <visual name="ALWristBL4_Link_Visual">
                        <origin rpy="0.0 0.0 0.0" xyz="0.0 0.0 0.0"/>
                        <geometry>
                                <mesh filename="../meshes/ALWrist_BL4_Link.stl"/>
                        </geometry>
                        <material name="">
                                <color rgba="0.776470588235294 0.756862745098039 0.737254901960784 1.0"/>
                        </material>
                </visual>
                <collision name="ALWristBL4_Link_Collision">
                        <origin rpy="0.0 0.0 0.0" xyz="0.0 0.0 0.0"/>
                        <geometry>
                                <mesh filename="../meshes/ALWrist_BL4_Link_convexhull.stl" scale="1.0 1.0 1.0"/>
                        </geometry>
                </collision>
        </link>
        <joint name="ALWristBR0" type="revolute">
                <origin rpy="0.0 0.0 0.0" xyz="0.0 0.0 0.045018"/>
                <axis xyz="1.0 0.0 0.0"/>
                <parent link="ALWristBR3_Link"/>
                <child link="ALWristBR0_Link"/>
                <limit effort="400.0" lower="-1.57" upper="1.57" velocity="3.1415926"/>
        </joint>
        <link name="ALWristBR0_Link">
                <inertial>
                        <origin rpy="0.0 0.0 0.0" xyz="0.0 0.0 0.0"/>
                        <mass value="0.0"/>
                        <inertia ixx="1e-05" ixy="0.0" ixz="0.0" iyy="1e-05" iyz="0.0" izz="1e-05"/>
                </inertial>
        </link>
        <joint name="ALWristBR1" type="revolute">
                <origin rpy="-2.8824 0.0 0.0" xyz="-0.0155 0.011 -0.032"/>
                <axis xyz="1.0 0.0 0.0"/>
                <parent link="ALWristRoot_Link"/>
                <child link="ALWristBR1_Link"/>
                <limit effort="400.0" lower="-1.57" upper="1.57" velocity="3.1415926"/>
        </joint>
        <link name="ALWristBR1_Link">
                <inertial>
                        <origin rpy="0.0 0.0 0.0" xyz="-0.0019151 0.02635 0.0010414"/>
                        <mass value="0.024008"/>
                        <inertia ixx="1.3690545308238603e-05" ixy="0.0" ixz="0.0" iyy="1.0041345308238603e-05" iyz="3.8696e-07" izz="1.3621645308238606e-05"/>
                </inertial>
                <visual name="ALWristBR1_Link_Visual">
                        <origin rpy="0.0 0.0 0.0" xyz="0.0 0.0 0.0"/>
                        <geometry>
                                <mesh filename="../meshes/ALWrist_BR1_Link.stl"/>
                        </geometry>
                        <material name="">
                                <color rgba="0.89804 0.91765 0.92941 1.0"/>
                        </material>
                </visual>
                <collision name="ALWristBR1_Link_Collision">
                        <origin rpy="0.0 0.0 0.0" xyz="0.0 0.0 0.0"/>
                        <geometry>
                                <mesh filename="../meshes/ALWrist_BR1_Link_convexhull.stl" scale="1.0 1.0 1.0"/>
                        </geometry>
                </collision>
        </link>
        <joint name="ALWristBR2" type="revolute">
                <origin rpy="0.0 0.0 0.0" xyz="0.0 0.0 0.0"/>
                <axis xyz="0.0 1.0 0.0"/>
                <parent link="ALWristBR0_Link"/>
                <child link="ALWristBR2_Link"/>
                <limit effort="400.0" lower="-1.57" upper="1.57" velocity="3.1415926"/>
        </joint>
        <link name="ALWristBR2_Link">
                <inertial>
                        <origin rpy="0.0 0.0 0.0" xyz="-0.00285890746146323 0.0 0.0"/>
                        <mass value="0.00373054475630146"/>
                        <inertia ixx="1.000002209364975e-05" ixy="0.0" ixz="1.2803063868888173e-09" iyy="1.0074212979026388e-05" iyz="-1.0109428273552697e-12" izz="1.0074192561095311e-05"/>
                </inertial>
                <visual name="ALWristBR2_Link_Visual">
                        <origin rpy="0.0 0.0 0.0" xyz="0.0 0.0 0.0"/>
                        <geometry>
                                <mesh filename="../meshes/ALWrist_BR2_Link.stl"/>
                        </geometry>
                        <material name="">
                                <color rgba="0.647058823529412 0.619607843137255 0.588235294117647 1.0"/>
                        </material>
                </visual>
                <collision name="ALWristBR2_Link_Collision">
                        <origin rpy="0.0 0.0 0.0" xyz="0.0 0.0 0.0"/>
                        <geometry>
                                <mesh filename="../meshes/ALWrist_BR2_Link_convexhull.stl" scale="1.0 1.0 1.0"/>
                        </geometry>
                </collision>
        </link>
        <joint name="ALWristBR3" type="revolute">
                <origin rpy="0.0 -0.017255 0.0" xyz="0.0 0.0 0.0"/>
                <axis xyz="0.0 1.0 0.0"/>
                <parent link="ALWristBR4_Link"/>
                <child link="ALWristBR3_Link"/>
                <limit effort="400.0" lower="-1.57" upper="1.57" velocity="3.1415926"/>
        </joint>
        <link name="ALWristBR3_Link">
                <inertial>
                        <origin rpy="0.0 0.0 0.0" xyz="0.0 0.0 0.0283017446065629"/>
                        <mass value="0.0163436663117003"/>
                        <inertia ixx="1.058843751107658e-05" ixy="3.883356249554021e-12" ixz="3.9714539909530543e-10" iyy="1.0442298557724912e-05" iyz="-9.93761778002401e-12" izz="1.0000000268262852e-05"/>
                </inertial>
                <visual name="ALWristBR3_Link_Visual">
                        <origin rpy="0.0 0.0 0.0" xyz="0.0 0.0 0.0"/>
                        <geometry>
                                <mesh filename="../meshes/ALWrist_BR3_Link.stl"/>
                        </geometry>
                        <material name="">
                                <color rgba="0.529411764705882 0.549019607843137 0.549019607843137 1.0"/>
                        </material>
                </visual>
                <collision name="ALWristBR3_Link_Collision">
                        <origin rpy="0.0 0.0 0.0" xyz="0.0 0.0 0.0"/>
                        <geometry>
                                <mesh filename="../meshes/ALWrist_BR3_Link_convexhull.stl" scale="1.0 1.0 1.0"/>
                        </geometry>
                </collision>
        </link>
        <joint name="ALWristBR4" type="revolute">
                <origin rpy="-2.9998 0.0 -3.1416" xyz="-0.027 -0.03 0.0"/>
                <axis xyz="1.0 0.0 0.0"/>
                <parent link="ALWristYaw_Link"/>
                <child link="ALWristBR4_Link"/>
                <limit effort="400.0" lower="-1.57" upper="1.57" velocity="3.1415926"/>
        </joint>
        <link name="ALWristBR4_Link">
                <inertial>
                        <origin rpy="0.0 0.0 0.0" xyz="-0.00221364330907749 0.0 0.0"/>
                        <mass value="0.0116530368127689"/>
                        <inertia ixx="1e-05" ixy="0.0" ixz="0.0" iyy="1.027752247888592e-05" iyz="0.0" izz="1.018883097687764e-05"/>
                </inertial>
                <visual name="ALWristBR4_Link_Visual">
                        <origin rpy="0.0 0.0 0.0" xyz="0.0 0.0 0.0"/>
                        <geometry>
                                <mesh filename="../meshes/ALWrist_BR4_Link.stl"/>
                        </geometry>
                        <material name="">
                                <color rgba="0.647058823529412 0.619607843137255 0.588235294117647 1.0"/>
                        </material>
                </visual>
                <collision name="ALWristBR4_Link_Collision">
                        <origin rpy="0.0 0.0 0.0" xyz="0.0 0.0 0.0"/>
                        <geometry>
                                <mesh filename="../meshes/ALWrist_BR4_Link_convexhull.stl" scale="1.0 1.0 1.0"/>
                        </geometry>
                </collision>
        </link>
        <joint name="ALWristBase" type="fixed">
                <origin rpy="0.0 -1.5708 0.0" xyz="0.0 0.0 -0.168"/>
                <parent link="ALWristRoot_Link"/>
                <child link="ALWristBase_Link"/>
        </joint>
        <link name="ALWristBase_Link">
                <inertial>
                        <origin rpy="0.0 0.0 0.0" xyz="0.0541597343830008 -0.00428968359174776 0.0"/>
                        <mass value="0.276021721766216"/>
                        <inertia ixx="0.000481869493582971" ixy="1.89399978244833e-05" ixz="-1.94485149438737e-08" iyy="0.00129886088799315" iyz="-3.56911305392632e-07" izz="0.00129140889559124"/>
                </inertial>
                <visual name="ALWristBase_Link_Visual">
                        <origin rpy="0.0 0.0 0.0" xyz="0.0 0.0 0.0"/>
                        <geometry>
                                <mesh filename="../meshes/ALWrist_Base_Link.stl"/>
                        </geometry>
                        <material name="">
                                <color rgba="0.898039215686275 0.917647058823529 0.929411764705882 1.0"/>
                        </material>
                </visual>
                <collision name="ALWristBase_Link_Collision">
                        <origin rpy="0.0 0.0 0.0" xyz="0.0 0.0 0.0"/>
                        <geometry>
                                <mesh filename="../meshes/ALWrist_Base_Link_convexhull.stl" scale="1.0 1.0 1.0"/>
                        </geometry>
                </collision>
        </link>
        <joint name="ALWristFT" type="fixed">
                <origin rpy="0.0 0.0 1.5708" xyz="0.0 0.0 0.042748"/>
                <parent link="ALWristYaw_Link"/>
                <child link="ALWristFT_Link"/>
        </joint>
        <link name="ALWristFT_Link">
                <inertial>
                        <origin rpy="0.0 0.0 0.0" xyz="0.0 0.0 -0.00791199218667672"/>
                        <mass value="0.0919909344510386"/>
                        <inertia ixx="1.39518131854906e-05" ixy="-3.05326757970196e-08" ixz="-1.47634493222953e-08" iyy="1.39070683493609e-05" iyz="-1.94813966896539e-08" izz="2.41202226678126e-05"/>
                </inertial>
                <visual name="ALWristFT_Link_Visual">
                        <origin rpy="0.0 0.0 0.0" xyz="0.0 0.0 0.0"/>
                        <geometry>
                                <mesh filename="../meshes/ALWristFT_Link.stl"/>
                        </geometry>
                        <material name="">
                                <color rgba="0.698039215686274 0.698039215686274 0.698039215686274 1.0"/>
                        </material>
                </visual>
                <collision name="ALWristFT_Link_Collision">
                        <origin rpy="0.0 0.0 0.0" xyz="0.0 0.0 0.0"/>
                        <geometry>
                                <mesh filename="../meshes/ALWristFT_Link_convexhull.stl" scale="1.0 1.0 1.0"/>
                        </geometry>
                </collision>
        </link>
        <joint name="ALWristPitch" type="revolute">
                <origin rpy="0.0 0.0 0.0" xyz="0.0 0.0 0.0"/>
                <axis xyz="1.0 0.0 0.0"/>
                <parent link="ALWristRoot_Link"/>
                <child link="ALWristPitch_Link"/>
                <limit effort="43.135" lower="-0.7" upper="1.57" velocity="9.255"/>
        </joint>
        <link name="ALWristPitch_Link">
                <inertial>
                        <origin rpy="0.0 0.0 0.0" xyz="0.0 0.0 0.0"/>
                        <mass value="0.0303458029555441"/>
                        <inertia ixx="1.0000000011242503e-05" ixy="0.0" ixz="1.3686128944734017e-10" iyy="1.0143779057796202e-05" iyz="1.3756897885334319e-10" izz="1.1666089364158581e-05"/>
                </inertial>
                <visual name="ALWristPitch_Link_Visual">
                        <origin rpy="0.0 0.0 0.0" xyz="0.0 0.0 0.0"/>
                        <geometry>
                                <mesh filename="../meshes/ALWristPitch_Link.stl"/>
                        </geometry>
                        <material name="">
                                <color rgba="0.647058823529412 0.619607843137255 0.588235294117647 1.0"/>
                        </material>
                </visual>
                <collision name="ALWristPitch_Link_Collision">
                        <origin rpy="0.0 0.0 0.0" xyz="0.0 0.0 0.0"/>
                        <geometry>
                                <mesh filename="../meshes/ALWristPitch_Link_convexhull.stl" scale="1.0 1.0 1.0"/>
                        </geometry>
                </collision>
        </link>
        <joint name="ALWristRoll" type="revolute">
                <origin rpy="3.1416 -1.5708 0.0" xyz="0.0 0.0 0.122"/>
                <axis xyz="1.0 0.0 0.0"/>
                <parent link="ALElbow_Link"/>
                <child link="ALWristRoll_Link"/>
                <limit effort="28.0" lower="-3.0543" upper="3.0543" velocity="5.7"/>
        </joint>
        <link name="ALWristRoll_Link">
                <inertial>
                        <origin rpy="0.0 0.0 0.0" xyz="0.0 0.0 0.0"/>
                        <mass value="0.0"/>
                        <inertia ixx="2e-05" ixy="0.0" ixz="0.0" iyy="2e-05" iyz="0.0" izz="2e-05"/>
                </inertial>
        </link>
        <joint name="ALWristRoot" type="fixed">
                <origin rpy="3.141593 -1.5707 0.0" xyz="0.173 0.0 0.0"/>
                <parent link="ALWristRoll_Link"/>
                <child link="ALWristRoot_Link"/>
        </joint>
        <link name="ALWristRoot_Link">
                <inertial>
                        <origin rpy="0.0 0.0 0.0" xyz="-0.00087527 0.015651 -0.10982"/>
                        <mass value="0.12307"/>
                        <inertia ixx="1.6915e-05" ixy="-1.069e-08" ixz="-1.5838e-08" iyy="2.9632e-05" iyz="5.8916e-07" izz="1.3864e-05"/>
                </inertial>
                <visual name="ALWristRoot_Link_Visual">
                        <origin rpy="0.0 0.0 0.0" xyz="0.0 0.0 0.0"/>
                        <geometry>
                                <mesh filename="../meshes/ALWrist_Root_Link.stl"/>
                        </geometry>
                        <material name="">
                                <color rgba="0.64706 0.61961 0.58824 1.0"/>
                        </material>
                </visual>
                <collision name="ALWristRoot_Link_Collision">
                        <origin rpy="0.0 0.0 0.0" xyz="0.0 0.0 0.0"/>
                        <geometry>
                                <mesh filename="../meshes/ALWrist_Root_Link_convexhull.stl" scale="1.0 1.0 1.0"/>
                        </geometry>
                </collision>
        </link>
        <joint name="ALWristYaw" type="revolute">
                <origin rpy="0.0 0.0 0.0" xyz="0.0 0.0 0.0"/>
                <axis xyz="0.0 1.0 0.0"/>
                <parent link="ALWristPitch_Link"/>
                <child link="ALWristYaw_Link"/>
                <limit effort="44.635" lower="-0.475" upper="0.585" velocity="7.725"/>
        </joint>
        <link name="ALWristYaw_Link">
                <inertial>
                        <origin rpy="0.0 0.0 0.0" xyz="0.0 -0.0112217565403197 0.0117774710310118"/>
                        <mass value="0.0440266507004541"/>
                        <inertia ixx="1.452337454289961e-05" ixy="3.52232240231331e-09" ixz="1.8324292440025615e-08" iyy="1.0332756954026827e-05" iyz="-1.4768212974215518e-06" izz="1.655459170101281e-05"/>
                </inertial>
                <visual name="ALWristYaw_Link_Visual">
                        <origin rpy="0.0 0.0 0.0" xyz="0.0 0.0 0.0"/>
                        <geometry>
                                <mesh filename="../meshes/ALWristYaw_Link.stl"/>
                        </geometry>
                        <material name="">
                                <color rgba="0.898039215686275 0.917647058823529 0.929411764705882 1.0"/>
                        </material>
                </visual>
                <collision name="ALWristYaw_Link_Collision">
                        <origin rpy="0.0 0.0 0.0" xyz="0.0 0.0 0.0"/>
                        <geometry>
                                <mesh filename="../meshes/ALWristYaw_Link_convexhull.stl" scale="1.0 1.0 1.0"/>
                        </geometry>
                </collision>
        </link>
        <joint name="ARBase" type="fixed">
                <origin rpy="-1.508093 0.25436 -1.3265" xyz="0.29809 -0.12609 0.025162"/>
                <parent link="Connector_Body/Torso_Link"/>
                <child link="ARBase_Link"/>
        </joint>
        <link name="ARBase_Link">
                <inertial>
                        <origin rpy="0.0 0.0 0.0" xyz="0.00799 0.0 0.000196"/>
                        <mass value="1.194300000000001"/>
                        <inertia ixx="0.00089755" ixy="-1.4484e-08" ixz="-2.6127e-07" iyy="0.00057565" iyz="7.8027e-07" izz="0.00056347"/>
                </inertial>
                <visual name="ARBase_Link_Visual">
                        <origin rpy="3.141593 0.0 0.0" xyz="0.0 0.0 0.0"/>
                        <geometry>
                                <mesh filename="../meshes/ARBase_Link.stl" scale="1.0 1.0 1.0"/>
                        </geometry>
                        <material name="">
                                <color rgba="0.75294 0.75294 0.75294 1.0"/>
                        </material>
                </visual>
                <collision name="ARBase_Link_Collision">
                        <origin rpy="0.0 0.0 0.0" xyz="0.0 0.0 0.0"/>
                        <geometry>
                                <mesh filename="../meshes/ARBase_Link_convexhull.stl" scale="1.0 1.0 1.0"/>
                        </geometry>
                </collision>
        </link>
        <joint name="ARElbow" type="revolute">
                <origin rpy="-3.141592 0.0 -3.141592" xyz="0.0 0.001 -0.3511"/>
                <axis xyz="1.0 0.0 0.0"/>
                <parent link="ARShoulder3_Link"/>
                <child link="ARElbow_Link"/>
                <limit effort="110.13" lower="-1.78" upper="0.01" velocity="7.075"/>
        </joint>
        <joint name="ARElbowAct" type="prismatic">
                <origin rpy="0.0 0.0 -3.141592" xyz="0.0 0.0 0.29542"/>
                <axis xyz="0.0 0.0 1.0"/>
                <parent link="ARElbowB11_Link"/>
                <child link="ARElbowAct_Link"/>
                <limit effort="2000.0" lower="-0.119" upper="0.001" velocity="0.266"/>
        </joint>
        <link name="ARElbowAct_Link">
                <inertial>
                        <origin rpy="0.0 0.0 0.0" xyz="0.0 0.0 -0.085859"/>
                        <mass value="0.05465199999999999"/>
                        <inertia ixx="0.00010606969013566318" ixy="0.0" ixz="3.626836028172578e-09" iyy="0.00010597469013629228" iyz="0.0" izz="1.0000000136920808e-05"/>
                </inertial>
                <visual name="ARElbowAct_Link_Visual">
                        <origin rpy="0.0 0.0 3.141593" xyz="0.0 0.0 0.0"/>
                        <geometry>
                                <mesh filename="../meshes/ARElbow_Act_Link.stl" scale="1.0 1.0 1.0"/>
                        </geometry>
                        <material name="">
                                <color rgba="0.75294 0.75294 0.75294 1.0"/>
                        </material>
                </visual>
                <collision name="ARElbowAct_Link_Collision">
                        <origin rpy="0.0 0.0 0.0" xyz="0.0 0.0 0.0"/>
                        <geometry>
                                <mesh filename="../meshes/ARElbow_Act_Link_convexhull.stl" scale="1.0 1.0 1.0"/>
                        </geometry>
                </collision>
        </link>
        <joint name="ARElbowB11" type="revolute">
                <origin rpy="2.888403 0.0 -3.141592" xyz="0.0 -0.029 -0.1391"/>
                <axis xyz="1.0 0.0 0.0"/>
                <parent link="ARShoulder3_Link"/>
                <child link="ARElbowB11_Link"/>
                <limit effort="400.0" lower="-1.57" upper="1.57" velocity="3.1415926"/>
        </joint>
        <link name="ARElbowB11_Link">
                <inertial>
                        <origin rpy="0.0 0.0 0.0" xyz="0.0 0.0 0.10704"/>
                        <mass value="0.32695999999999986"/>
                        <inertia ixx="0.00011101999998112811" ixy="1.0984488097443103e-08" ixz="6.629144855259e-08" iyy="0.00011251000000736784" iyz="1.406700231845442e-07" izz="7.073300001150397e-05"/>
                </inertial>
                <visual name="ARElbowB11_Link_Visual">
                        <origin rpy="0.0 0.0 0.0" xyz="0.0 0.0 0.0"/>
                        <geometry>
                                <mesh filename="../meshes/ARElbow_B11_Link.stl" scale="1.0 1.0 1.0"/>
                        </geometry>
                        <material name="">
                                <color rgba="0.75294 0.75294 0.75294 1.0"/>
                        </material>
                </visual>
                <collision name="ARElbowB11_Link_Collision">
                        <origin rpy="0.0 0.0 0.0" xyz="0.0 0.0 0.0"/>
                        <geometry>
                                <mesh filename="../meshes/ARElbow_B11_Link_convexhull.stl" scale="1.0 1.0 1.0"/>
                        </geometry>
                </collision>
        </link>
        <link name="ARElbow_Link">
                <inertial>
                        <origin rpy="0.0 0.0 0.0" xyz="0.0 0.001127 0.080286"/>
                        <mass value="0.6357799999999997"/>
                        <inertia ixx="0.0005099900001544764" ixy="-2.2297207206594354e-07" ixz="-4.0468474586715554e-07" iyy="0.0005163300270204655" iyz="-4.423298448630883e-05" izz="0.00046536997282505774"/>
                </inertial>
                <visual name="ARElbow_Link_Visual">
                        <origin rpy="0.0 0.0 3.141593" xyz="0.0 0.0 0.0"/>
                        <geometry>
                                <mesh filename="../meshes/ARElbow_Link.stl" scale="1.0 1.0 1.0"/>
                        </geometry>
                        <material name="">
                                <color rgba="0.75294 0.75294 0.75294 1.0"/>
                        </material>
                </visual>
                <collision name="ARElbow_Link_Collision">
                        <origin rpy="0.0 0.0 0.0" xyz="0.0 0.0 0.0"/>
                        <geometry>
                                <mesh filename="../meshes/ARElbow_Link_convexhull.stl" scale="1.0 1.0 1.0"/>
                        </geometry>
                </collision>
        </link>
        <joint name="ARShoulder1" type="revolute">
                <origin rpy="-3.141585 0.0 3.141593" xyz="0.1076 0.0 0.0"/>
                <axis xyz="1.0 0.0 0.0"/>
                <parent link="ARBase_Link"/>
                <child link="ARShoulder1_Link"/>
                <limit effort="157.0" lower="-3.0543" upper="3.0543" velocity="3.6"/>
        </joint>
        <link name="ARShoulder1_Link">
                <inertial>
                        <origin rpy="0.0 0.0 0.0" xyz="0.009157 0.003646 -0.000169"/>
                        <mass value="1.6019999999999996"/>
                        <inertia ixx="0.0012116999440866811" ixy="8.070387961256474e-05" ixz="3.5280257083975037e-06" iyy="0.001556100057542011" iyz="-2.650928692723903e-06" izz="0.0010023999983713062"/>
                </inertial>
                <visual name="ARShoulder1_Link_Visual">
                        <origin rpy="0.0 0.0 3.141593" xyz="0.0 0.0 0.0"/>
                        <geometry>
                                <mesh filename="../meshes/ARShoulder1_Link.stl" scale="1.0 1.0 1.0"/>
                        </geometry>
                        <material name="">
                                <color rgba="0.75294 0.75294 0.75294 1.0"/>
                        </material>
                </visual>
                <collision name="ARShoulder1_Link_Collision">
                        <origin rpy="0.0 0.0 0.0" xyz="0.0 0.0 0.0"/>
                        <geometry>
                                <mesh filename="../meshes/ARShoulder1_Link_convexhull.stl" scale="1.0 1.0 1.0"/>
                        </geometry>
                </collision>
        </link>
        <joint name="ARShoulder2" type="revolute">
                <origin rpy="0.0 0.0 -3.141592" xyz="0.0 0.0 0.0"/>
                <axis xyz="0.0 1.0 0.0"/>
                <parent link="ARShoulder1_Link"/>
                <child link="ARShoulder2_Link"/>
                <limit effort="157.0" lower="-0.248" upper="1.845" velocity="3.6"/>
        </joint>
        <link name="ARShoulder2_Link">
                <inertial>
                        <origin rpy="0.0 0.0 0.0" xyz="0.010763 -0.020477 0.0278"/>
                        <mass value="0.5084917431461261"/>
                        <inertia ixx="0.0010464999259024192" ixy="-0.00012061005396444852" ixz="5.485487847357631e-05" iyy="0.0009256802430528081" iyz="-0.0002750100517516733" izz="0.0010392998310447714"/>
                </inertial>
                <visual name="ARShoulder2_Link_Visual">
                        <origin rpy="0.0 0.0 0.0" xyz="0.0 0.0 0.0"/>
                        <geometry>
                                <mesh filename="../meshes/ARShoulder2_Link.stl" scale="1.0 1.0 1.0"/>
                        </geometry>
                        <material name="">
                                <color rgba="0.75294 0.75294 0.75294 1.0"/>
                        </material>
                </visual>
                <collision name="ARShoulder2_Link_Collision">
                        <origin rpy="0.0 0.0 0.0" xyz="0.0 0.0 0.0"/>
                        <geometry>
                                <mesh filename="../meshes/ARShoulder2_Link_convexhull.stl" scale="1.0 1.0 1.0"/>
                        </geometry>
                </collision>
        </link>
        <joint name="ARShoulder3" type="revolute">
                <origin rpy="-3.141593 1e-06 -1.5707" xyz="0.0 0.0 0.0"/>
                <axis xyz="0.0 0.0 1.0"/>
                <parent link="ARShoulder2_Link"/>
                <child link="ARShoulder3_Link"/>
                <limit effort="28.0" lower="-3.0543" upper="3.0543" velocity="5.7"/>
        </joint>
        <link name="ARShoulder3_Link">
                <inertial>
                        <origin rpy="0.0 0.0 0.0" xyz="0.0 0.003369 -0.14648"/>
                        <mass value="0.8525751706215601"/>
                        <inertia ixx="0.0028013000003190894" ixy="5.193714519100651e-07" ixz="7.258930202151745e-07" iyy="0.002740099961802801" iyz="-5.467267704269619e-05" izz="0.000786290037878108"/>
                </inertial>
                <visual name="ARShoulder3_Link_Visual">
                        <origin rpy="3.141593 0.0 0.0" xyz="0.0 0.0 0.0"/>
                        <geometry>
                                <mesh filename="../meshes/ARShoulder3_Link.stl" scale="1.0 1.0 1.0"/>
                        </geometry>
                        <material name="">
                                <color rgba="0.75294 0.75294 0.75294 1.0"/>
                        </material>
                </visual>
                <collision name="ARShoulder3_Link_Collision">
                        <origin rpy="0.0 0.0 0.0" xyz="0.0 0.0 0.0"/>
                        <geometry>
                                <mesh filename="../meshes/ARShoulder3_Link_convexhull.stl" scale="1.0 1.0 1.0"/>
                        </geometry>
                </collision>
        </link>
        <joint name="ARWristAL1" type="revolute">
                <origin rpy="1.5885 0.0 -3.141592" xyz="-0.0155 0.034 -0.178"/>
                <axis xyz="1.0 0.0 0.0"/>
                <parent link="ARWristRoot_Link"/>
                <child link="ARWristAL1_Link"/>
                <limit effort="400.0" lower="-1.57" upper="1.57" velocity="3.1415926"/>
        </joint>
        <link name="ARWristAL1_Link">
                <inertial>
                        <origin rpy="0.0 0.0 0.0" xyz="0.0 0.058479 0.0"/>
                        <mass value="0.10112999999999997"/>
                        <inertia ixx="1.4212213742458261e-05" ixy="1.1891377579045092e-10" ixz="1.482689765519501e-10" iyy="1.0001513742563879e-05" iyz="-8.07089999579205e-08" izz="1.4303213742665143e-05"/>
                </inertial>
                <visual name="ARWristAL1_Link_Visual">
                        <origin rpy="-3.141593 0.0 -3.141593" xyz="0.0 0.0 0.0"/>
                        <geometry>
                                <mesh filename="../meshes/ARWrist_AR1_Link.stl" scale="1.0 1.0 1.0"/>
                        </geometry>
                        <material name="">
                                <color rgba="0.89804 0.91765 0.92941 1.0"/>
                        </material>
                </visual>
                <collision name="ARWristAL1_Link_Collision">
                        <origin rpy="0.0 0.0 0.0" xyz="0.0 0.0 0.0"/>
                        <geometry>
                                <mesh filename="../meshes/ARWrist_AR1_Link_convexhull.stl" scale="1.0 1.0 1.0"/>
                        </geometry>
                </collision>
        </link>
        <joint name="ARWristAR1" type="revolute">
                <origin rpy="1.5885 0.0 -3.141592" xyz="0.0155 0.034 -0.178"/>
                <axis xyz="1.0 0.0 0.0"/>
                <parent link="ARWristRoot_Link"/>
                <child link="ARWristAR1_Link"/>
                <limit effort="400.0" lower="-1.57" upper="1.57" velocity="3.1415926"/>
        </joint>
        <link name="ARWristAR1_Link">
                <inertial>
                        <origin rpy="0.0 0.0 0.0" xyz="0.0 0.060513 0.0"/>
                        <mass value="0.11027956817212799"/>
                        <inertia ixx="1.42606022882383e-05" ixy="1.1834937974475046e-10" ixz="1.555953533081748e-09" iyy="1.0001497220687136e-05" iyz="-8.070848165972657e-08" izz="1.4350648636972524e-05"/>
                </inertial>
                <visual name="ARWristAR1_Link_Visual">
                        <origin rpy="-3.141593 0.0 -3.141593" xyz="0.0 0.0 0.0"/>
                        <geometry>
                                <mesh filename="../meshes/ARWrist_AL1_Link.stl" scale="1.0 1.0 1.0"/>
                        </geometry>
                        <material name="">
                                <color rgba="0.898039215686275 0.917647058823529 0.929411764705882 1.0"/>
                        </material>
                </visual>
                <collision name="ARWristAR1_Link_Collision">
                        <origin rpy="0.0 0.0 0.0" xyz="0.0 0.0 0.0"/>
                        <geometry>
                                <mesh filename="../meshes/ARWrist_AL1_Link_convexhull.stl" scale="1.0 1.0 1.0"/>
                        </geometry>
                </collision>
        </link>
        <joint name="ARWristActL" type="prismatic">
                <origin rpy="1.5708 0.0 -3.141593" xyz="0.0 0.13346 0.0"/>
                <axis xyz="0.0 0.0 1.0"/>
                <parent link="ARWristAL1_Link"/>
                <child link="ARWristActL_Link"/>
                <limit effort="1094.0" lower="-0.018" upper="0.038" velocity="0.2"/>
        </joint>
        <link name="ARWristActL_Link">
                <inertial>
                        <origin rpy="0.0 0.0 0.0" xyz="0.0 0.0 -0.049176"/>
                        <mass value="0.022415478206029786"/>
                        <inertia ixx="2.2515773917037203e-05" ixy="0.0" ixz="4.412407393697763e-12" iyy="2.2496459399899276e-05" iyz="0.0" izz="1.0000000000001556e-05"/>
                </inertial>
                <visual name="ARWristActL_Link_Visual">
                        <origin rpy="0.0 0.0 -3.141593" xyz="0.0 0.0 0.0"/>
                        <geometry>
                                <mesh filename="../meshes/ARWrist_ActR_Link.stl" scale="1.0 1.0 1.0"/>
                        </geometry>
                        <material name="">
                                <color rgba="0.776470588235294 0.756862745098039 0.737254901960784 1.0"/>
                        </material>
                </visual>
                <collision name="ARWristActL_Link_Collision">
                        <origin rpy="0.0 0.0 0.0" xyz="0.0 0.0 0.0"/>
                        <geometry>
                                <mesh filename="../meshes/ARWrist_ActR_Link_convexhull.stl" scale="1.0 1.0 1.0"/>
                        </geometry>
                </collision>
        </link>
        <joint name="ARWristActR" type="prismatic">
                <origin rpy="1.5708 0.0 -3.141593" xyz="0.0 0.13346 0.0"/>
                <axis xyz="0.0 0.0 1.0"/>
                <parent link="ARWristAR1_Link"/>
                <child link="ARWristActR_Link"/>
                <limit effort="1094.0" lower="-0.018" upper="0.038" velocity="0.2"/>
        </joint>
        <link name="ARWristActR_Link">
                <inertial>
                        <origin rpy="0.0 0.0 0.0" xyz="0.0 0.0 -0.049176"/>
                        <mass value="0.022414999999999987"/>
                        <inertia ixx="2.251556999999844e-05" ixy="0.0" ixz="4.412335509542261e-12" iyy="2.249657e-05" iyz="0.0" izz="1.0000000000001556e-05"/>
                </inertial>
                <visual name="ARWristActR_Link_Visual">
                        <origin rpy="0.0 0.0 -3.141593" xyz="0.0 0.0 0.0"/>
                        <geometry>
                                <mesh filename="../meshes/ARWrist_ActL_Link.stl" scale="1.0 1.0 1.0"/>
                        </geometry>
                        <material name="">
                                <color rgba="0.77647 0.75686 0.73725 1.0"/>
                        </material>
                </visual>
                <collision name="ARWristActR_Link_Collision">
                        <origin rpy="0.0 0.0 0.0" xyz="0.0 0.0 0.0"/>
                        <geometry>
                                <mesh filename="../meshes/ARWrist_ActL_Link_convexhull.stl" scale="1.0 1.0 1.0"/>
                        </geometry>
                </collision>
        </link>
        <joint name="ARWristBL0" type="revolute">
                <origin rpy="0.0 0.0 3.141592" xyz="0.0 0.0 0.045018"/>
                <axis xyz="1.0 0.0 0.0"/>
                <parent link="ARWristBL3_Link"/>
                <child link="ARWristBL0_Link"/>
                <limit effort="400.0" lower="-1.57" upper="1.57" velocity="3.1415926"/>
        </joint>
        <link name="ARWristBL0_Link">
                <inertial>
                        <origin rpy="0.0 0.0 0.0" xyz="0.0 0.0 0.0"/>
                        <mass value="0.0"/>
                        <inertia ixx="1e-05" ixy="0.0" ixz="0.0" iyy="1e-05" iyz="0.0" izz="1e-05"/>
                </inertial>
        </link>
        <joint name="ARWristBL1" type="revolute">
                <origin rpy="-2.8824 0.0 -3.141592" xyz="-0.0155 -0.011 -0.032"/>
                <axis xyz="1.0 0.0 0.0"/>
                <parent link="ARWristRoot_Link"/>
                <child link="ARWristBL1_Link"/>
                <limit effort="400.0" lower="-1.57" upper="1.57" velocity="3.1415926"/>
        </joint>
        <link name="ARWristBL1_Link">
                <inertial>
                        <origin rpy="0.0 0.0 0.0" xyz="0.001915 0.02635 0.001041"/>
                        <mass value="0.024008000000000012"/>
                        <inertia ixx="1.3690545308238087e-05" ixy="1.3711412479914173e-12" ixz="0.0" iyy="1.0041345308239099e-05" iyz="3.869599999998984e-07" izz="1.362164530823862e-05"/>
                </inertial>
                <visual name="ARWristBL1_Link_Visual">
                        <origin rpy="0.0 0.0 0.0" xyz="0.0 0.0 0.0"/>
                        <geometry>
                                <mesh filename="../meshes/ARWrist_BR1_Link.stl" scale="1.0 1.0 1.0"/>
                        </geometry>
                        <material name="">
                                <color rgba="0.89804 0.91765 0.92941 1.0"/>
                        </material>
                </visual>
                <collision name="ARWristBL1_Link_Collision">
                        <origin rpy="0.0 0.0 0.0" xyz="0.0 0.0 0.0"/>
                        <geometry>
                                <mesh filename="../meshes/ARWrist_BR1_Link_convexhull.stl" scale="1.0 1.0 1.0"/>
                        </geometry>
                </collision>
        </link>
        <joint name="ARWristBL2" type="revolute">
                <origin rpy="0.0 0.0 -3.141592" xyz="0.0 0.0 0.0"/>
                <axis xyz="0.0 1.0 0.0"/>
                <parent link="ARWristBL0_Link"/>
                <child link="ARWristBL2_Link"/>
                <limit effort="400.0" lower="-1.57" upper="1.57" velocity="3.1415926"/>
        </joint>
        <link name="ARWristBL2_Link">
                <inertial>
                        <origin rpy="0.0 0.0 0.0" xyz="-0.002859 0.0 0.0"/>
                        <mass value="0.0037305447563014613"/>
                        <inertia ixx="1.0000022093775196e-05" ixy="0.0" ixz="1.2803100181429313e-09" iyy="1.0074212979026307e-05" iyz="1.0105450352722507e-12" izz="1.0074192560969949e-05"/>
                </inertial>
                <visual name="ARWristBL2_Link_Visual">
                        <origin rpy="0.0 0.0 3.141593" xyz="0.0 0.0 0.0"/>
                        <geometry>
                                <mesh filename="../meshes/ARWrist_BR2_Link.stl" scale="1.0 1.0 1.0"/>
                        </geometry>
                        <material name="">
                                <color rgba="0.647058823529412 0.619607843137255 0.588235294117647 1.0"/>
                        </material>
                </visual>
                <collision name="ARWristBL2_Link_Collision">
                        <origin rpy="0.0 0.0 0.0" xyz="0.0 0.0 0.0"/>
                        <geometry>
                                <mesh filename="../meshes/ARWrist_BR2_Link_convexhull.stl" scale="1.0 1.0 1.0"/>
                        </geometry>
                </collision>
        </link>
        <joint name="ARWristBL3" type="revolute">
                <origin rpy="0.0 -0.017255 -3.141592" xyz="0.0 0.0 0.0"/>
                <axis xyz="0.0 1.0 0.0"/>
                <parent link="ARWristBL4_Link"/>
                <child link="ARWristBL3_Link"/>
                <limit effort="400.0" lower="-1.57" upper="1.57" velocity="3.1415926"/>
        </joint>
        <link name="ARWristBL3_Link">
                <inertial>
                        <origin rpy="0.0 0.0 0.0" xyz="0.0 0.0 0.028302"/>
                        <mass value="0.016343666311700304"/>
                        <inertia ixx="1.0588437511113046e-05" ixy="-3.928745829304398e-12" ixz="3.9711659584647646e-10" iyy="1.0442298557727444e-05" iyz="9.935123851420574e-12" izz="1.0000000268223861e-05"/>
                </inertial>
                <visual name="ARWristBL3_Link_Visual">
                        <origin rpy="0.0 0.0 3.141593" xyz="0.0 0.0 0.0"/>
                        <geometry>
                                <mesh filename="../meshes/ARWrist_BR3_Link.stl" scale="1.0 1.0 1.0"/>
                        </geometry>
                        <material name="">
                                <color rgba="0.529411764705882 0.549019607843137 0.549019607843137 1.0"/>
                        </material>
                </visual>
                <collision name="ARWristBL3_Link_Collision">
                        <origin rpy="0.0 0.0 0.0" xyz="0.0 0.0 0.0"/>
                        <geometry>
                                <mesh filename="../meshes/ARWrist_BR3_Link_convexhull.stl" scale="1.0 1.0 1.0"/>
                        </geometry>
                </collision>
        </link>
        <joint name="ARWristBL4" type="revolute">
                <origin rpy="-2.9998 0.0 8e-06" xyz="-0.027 0.03 0.0"/>
                <axis xyz="1.0 0.0 0.0"/>
                <parent link="ARWristYaw_Link"/>
                <child link="ARWristBL4_Link"/>
                <limit effort="400.0" lower="-1.57" upper="1.57" velocity="3.1415926"/>
        </joint>
        <link name="ARWristBL4_Link">
                <inertial>
                        <origin rpy="0.0 0.0 0.0" xyz="0.002214 0.0 0.0"/>
                        <mass value="0.011653036812768903"/>
                        <inertia ixx="1.0000000000000031e-05" ixy="0.0" ixz="0.0" iyy="1.0277522478885884e-05" iyz="0.0" izz="1.018883097687764e-05"/>
                </inertial>
                <visual name="ARWristBL4_Link_Visual">
                        <origin rpy="0.0 0.0 0.0" xyz="0.0 0.0 0.0"/>
                        <geometry>
                                <mesh filename="../meshes/ARWrist_BR4_Link.stl" scale="1.0 1.0 1.0"/>
                        </geometry>
                        <material name="">
                                <color rgba="0.647058823529412 0.619607843137255 0.588235294117647 1.0"/>
                        </material>
                </visual>
                <collision name="ARWristBL4_Link_Collision">
                        <origin rpy="0.0 0.0 0.0" xyz="0.0 0.0 0.0"/>
                        <geometry>
                                <mesh filename="../meshes/ARWrist_BR4_Link_convexhull.stl" scale="1.0 1.0 1.0"/>
                        </geometry>
                </collision>
        </link>
        <joint name="ARWristBR0" type="revolute">
                <origin rpy="0.0 0.0 3.141592" xyz="0.0 0.0 0.045018"/>
                <axis xyz="1.0 0.0 0.0"/>
                <parent link="ARWristBR3_Link"/>
                <child link="ARWristBR0_Link"/>
                <limit effort="400.0" lower="-1.57" upper="1.57" velocity="3.1415926"/>
        </joint>
        <link name="ARWristBR0_Link">
                <inertial>
                        <origin rpy="0.0 0.0 0.0" xyz="0.0 0.0 0.0"/>
                        <mass value="0.0"/>
                        <inertia ixx="1e-05" ixy="0.0" ixz="0.0" iyy="1e-05" iyz="0.0" izz="1e-05"/>
                </inertial>
        </link>
        <joint name="ARWristBR1" type="revolute">
                <origin rpy="-2.8824 0.0 -3.141592" xyz="0.0155 -0.011 -0.032"/>
                <axis xyz="1.0 0.0 0.0"/>
                <parent link="ARWristRoot_Link"/>
                <child link="ARWristBR1_Link"/>
                <limit effort="400.0" lower="-1.57" upper="1.57" velocity="3.1415926"/>
        </joint>
        <link name="ARWristBR1_Link">
                <inertial>
                        <origin rpy="0.0 0.0 0.0" xyz="-0.001915 0.02635 0.001041"/>
                        <mass value="0.024008000000000012"/>
                        <inertia ixx="1.3690309326297567e-05" ixy="1.5146961171299974e-12" ixz="0.0" iyy="1.0041289326298746e-05" iyz="3.866799999999256e-07" izz="1.3621309326298153e-05"/>
                </inertial>
                <visual name="ARWristBR1_Link_Visual">
                        <origin rpy="0.0 0.0 0.0" xyz="0.0 0.0 0.0"/>
                        <geometry>
                                <mesh filename="../meshes/ARWrist_BL1_Link.stl" scale="1.0 1.0 1.0"/>
                        </geometry>
                        <material name="">
                                <color rgba="0.89804 0.91765 0.92941 1.0"/>
                        </material>
                </visual>
                <collision name="ARWristBR1_Link_Collision">
                        <origin rpy="0.0 0.0 0.0" xyz="0.0 0.0 0.0"/>
                        <geometry>
                                <mesh filename="../meshes/ARWrist_BL1_Link_convexhull.stl" scale="1.0 1.0 1.0"/>
                        </geometry>
                </collision>
        </link>
        <joint name="ARWristBR2" type="revolute">
                <origin rpy="0.0 0.0 -3.141592" xyz="0.0 0.0 0.0"/>
                <axis xyz="0.0 1.0 0.0"/>
                <parent link="ARWristBR0_Link"/>
                <child link="ARWristBR2_Link"/>
                <limit effort="400.0" lower="-1.57" upper="1.57" velocity="3.1415926"/>
        </joint>
        <link name="ARWristBR2_Link">
                <inertial>
                        <origin rpy="0.0 0.0 0.0" xyz="-0.002859 0.0 0.0"/>
                        <mass value="0.003730583331722572"/>
                        <inertia ixx="1.0000022086181487e-05" ixy="0.0" ixz="1.2800625228418757e-09" iyy="1.007421474746067e-05" iyz="0.0" izz="1.00741893801741e-05"/>
                </inertial>
                <visual name="ARWristBR2_Link_Visual">
                        <origin rpy="0.0 0.0 -3.141593" xyz="0.0 0.0 0.0"/>
                        <geometry>
                                <mesh filename="../meshes/ARWrist_BL2_Link.stl" scale="1.0 1.0 1.0"/>
                        </geometry>
                        <material name="">
                                <color rgba="0.647058823529412 0.619607843137255 0.588235294117647 1.0"/>
                        </material>
                </visual>
                <collision name="ARWristBR2_Link_Collision">
                        <origin rpy="0.0 0.0 0.0" xyz="0.0 0.0 0.0"/>
                        <geometry>
                                <mesh filename="../meshes/ARWrist_BL2_Link_convexhull.stl" scale="1.0 1.0 1.0"/>
                        </geometry>
                </collision>
        </link>
        <joint name="ARWristBR3" type="revolute">
                <origin rpy="0.0 -0.017255 -3.141592" xyz="0.0 0.0 0.0"/>
                <axis xyz="0.0 1.0 0.0"/>
                <parent link="ARWristBR4_Link"/>
                <child link="ARWristBR3_Link"/>
                <limit effort="400.0" lower="-1.57" upper="1.57" velocity="3.1415926"/>
        </joint>
        <link name="ARWristBR3_Link">
                <inertial>
                        <origin rpy="0.0 0.0 0.0" xyz="0.0 0.0 0.028302"/>
                        <mass value="0.016343668811119795"/>
                        <inertia ixx="1.0588437589345121e-05" ixy="-2.694579659860282e-12" ixz="3.9717064992779286e-10" iyy="1.04422980274748e-05" iyz="1.0476070445409481e-11" izz="1.0000000268321719e-05"/>
                </inertial>
                <visual name="ARWristBR3_Link_Visual">
                        <origin rpy="0.0 0.0 -3.141593" xyz="0.0 0.0 0.0"/>
                        <geometry>
                                <mesh filename="../meshes/ARWrist_BL3_Link.stl" scale="1.0 1.0 1.0"/>
                        </geometry>
                        <material name="">
                                <color rgba="0.898039215686275 0.917647058823529 0.929411764705882 1.0"/>
                        </material>
                </visual>
                <collision name="ARWristBR3_Link_Collision">
                        <origin rpy="0.0 0.0 0.0" xyz="0.0 0.0 0.0"/>
                        <geometry>
                                <mesh filename="../meshes/ARWrist_BL3_Link_convexhull.stl" scale="1.0 1.0 1.0"/>
                        </geometry>
                </collision>
        </link>
        <joint name="ARWristBR4" type="revolute">
                <origin rpy="2.9998 0.0 -3.141592" xyz="0.027 0.03 0.0"/>
                <axis xyz="1.0 0.0 0.0"/>
                <parent link="ARWristYaw_Link"/>
                <child link="ARWristBR4_Link"/>
                <limit effort="400.0" lower="-1.57" upper="1.57" velocity="3.1415926"/>
        </joint>
        <link name="ARWristBR4_Link">
                <inertial>
                        <origin rpy="0.0 0.0 0.0" xyz="0.002214 0.0 0.0"/>
                        <mass value="0.0116530368127355"/>
                        <inertia ixx="1.0000000000000031e-05" ixy="0.0" ixz="0.0" iyy="1.0277522478887405e-05" iyz="0.0" izz="1.0188830976875939e-05"/>
                </inertial>
                <visual name="ARWristBR4_Link_Visual">
                        <origin rpy="0.0 0.0 0.0" xyz="0.0 0.0 0.0"/>
                        <geometry>
                                <mesh filename="../meshes/ARWrist_BL4_Link.stl" scale="1.0 1.0 1.0"/>
                        </geometry>
                        <material name="">
                                <color rgba="0.776470588235294 0.756862745098039 0.737254901960784 1.0"/>
                        </material>
                </visual>
                <collision name="ARWristBR4_Link_Collision">
                        <origin rpy="0.0 0.0 0.0" xyz="0.0 0.0 0.0"/>
                        <geometry>
                                <mesh filename="../meshes/ARWrist_BL4_Link_convexhull.stl" scale="1.0 1.0 1.0"/>
                        </geometry>
                </collision>
        </link>
        <joint name="ARWristBase" type="fixed">
                <origin rpy="-3.141592 -1.570793 -3.141592" xyz="0.0 0.0 -0.168"/>
                <parent link="ARWristRoot_Link"/>
                <child link="ARWristBase_Link"/>
        </joint>
        <link name="ARWristBase_Link">
                <inertial>
                        <origin rpy="0.0 0.0 0.0" xyz="0.05416 0.00429 0.0"/>
                        <mass value="0.27602181682106586"/>
                        <inertia ixx="0.0004818694935696462" ixy="-1.8939997715257535e-05" ixz="-1.915496021566553e-08" iyy="0.0012988608884876524" iyz="3.569127035083581e-07" izz="0.0012914088951100598"/>
                </inertial>
                <visual name="ARWristBase_Link_Visual">
                        <origin rpy="3.141593 0.0 0.0" xyz="0.0 0.0 0.0"/>
                        <geometry>
                                <mesh filename="../meshes/ARWrist_Base_Link.stl" scale="1.0 1.0 1.0"/>
                        </geometry>
                        <material name="">
                                <color rgba="0.898039215686275 0.917647058823529 0.929411764705882 1.0"/>
                        </material>
                </visual>
                <collision name="ARWristBase_Link_Collision">
                        <origin rpy="0.0 0.0 0.0" xyz="0.0 0.0 0.0"/>
                        <geometry>
                                <mesh filename="../meshes/ARWrist_Base_Link_convexhull.stl" scale="1.0 1.0 1.0"/>
                        </geometry>
                </collision>
        </link>
        <joint name="ARWristFT" type="fixed">
                <origin rpy="0.0 0.0 -1.5708" xyz="0.0 0.0 0.042748"/>
                <parent link="ARWristYaw_Link"/>
                <child link="ARWristFT_Link"/>
        </joint>
        <link name="ARWristFT_Link">
                <inertial>
                        <origin rpy="0.0 0.0 0.0" xyz="0.0 0.0 -0.007912"/>
                        <mass value="0.0919909344513703"/>
                        <inertia ixx="1.3951813166732569e-05" ixy="3.05326895417141e-08" ixz="-1.4763455306581984e-08" iyy="1.3907068368118933e-05" iyz="1.948139215462272e-08" izz="2.41202226678126e-05"/>
                </inertial>
                <visual name="ARWristFT_Link_Visual">
                        <origin rpy="0.0 0.0 3.141593" xyz="0.0 0.0 0.0"/>
                        <geometry>
                                <mesh filename="../meshes/ARWristFT_Link.stl" scale="1.0 1.0 1.0"/>
                        </geometry>
                        <material name="">
                                <color rgba="0.698039215686274 0.698039215686274 0.698039215686274 1.0"/>
                        </material>
                </visual>
                <collision name="ARWristFT_Link_Collision">
                        <origin rpy="0.0 0.0 0.0" xyz="0.0 0.0 0.0"/>
                        <geometry>
                                <mesh filename="../meshes/ARWristFT_Link_convexhull.stl" scale="1.0 1.0 1.0"/>
                        </geometry>
                </collision>
        </link>
        <joint name="ARWristPitch" type="revolute">
                <origin rpy="0.0 0.0 1e-06" xyz="0.0 0.0 0.0"/>
                <axis xyz="1.0 0.0 0.0"/>
                <parent link="ARWristRoot_Link"/>
                <child link="ARWristPitch_Link"/>
                <limit effort="43.135" lower="-0.7" upper="1.57" velocity="9.255"/>
        </joint>
        <link name="ARWristPitch_Link">
                <inertial>
                        <origin rpy="0.0 0.0 0.0" xyz="0.0 0.0 0.0"/>
                        <mass value="0.030345802955544107"/>
                        <inertia ixx="1.0000000011242505e-05" ixy="0.0" ixz="1.3686128944732079e-10" iyy="1.0143779057796206e-05" iyz="-1.3756897885220354e-10" izz="1.1666089364158585e-05"/>
                </inertial>
                <visual name="ARWristPitch_Link_Visual">
                        <origin rpy="0.0 0.0 0.0" xyz="0.0 0.0 0.0"/>
                        <geometry>
                                <mesh filename="../meshes/ARWristPitch_Link.stl" scale="1.0 1.0 1.0"/>
                        </geometry>
                        <material name="">
                                <color rgba="0.647058823529412 0.619607843137255 0.588235294117647 1.0"/>
                        </material>
                </visual>
                <collision name="ARWristPitch_Link_Collision">
                        <origin rpy="0.0 0.0 0.0" xyz="0.0 0.0 0.0"/>
                        <geometry>
                                <mesh filename="../meshes/ARWristPitch_Link_convexhull.stl" scale="1.0 1.0 1.0"/>
                        </geometry>
                </collision>
        </link>
        <joint name="ARWristRoll" type="revolute">
                <origin rpy="0.08344 1.570793 -3.058159" xyz="0.0 0.0 0.122"/>
                <axis xyz="1.0 0.0 0.0"/>
                <parent link="ARElbow_Link"/>
                <child link="ARWristRoll_Link"/>
                <limit effort="28.0" lower="-3.0543" upper="3.0543" velocity="5.7"/>
        </joint>
        <link name="ARWristRoll_Link">
                <inertial>
                        <origin rpy="0.0 0.0 0.0" xyz="0.0 0.0 0.0"/>
                        <mass value="0.0"/>
                        <inertia ixx="2.0000000000000005e-05" ixy="0.0" ixz="0.0" iyy="2.0000000000000005e-05" iyz="0.0" izz="2e-05"/>
                </inertial>
        </link>
        <joint name="ARWristRoot" type="fixed">
                <origin rpy="3.131212 -1.5707 -3.131212" xyz="-0.173 0.0 0.0"/>
                <parent link="ARWristRoll_Link"/>
                <child link="ARWristRoot_Link"/>
        </joint>
        <link name="ARWristRoot_Link">
                <inertial>
                        <origin rpy="0.0 0.0 0.0" xyz="-0.000875 -0.015651 -0.10982"/>
                        <mass value="0.12307001358415799"/>
                        <inertia ixx="1.6915e-05" ixy="1.069e-08" ixz="-1.5838e-08" iyy="2.9632e-05" iyz="-5.8916e-07" izz="1.3864e-05"/>
                </inertial>
                <visual name="ARWristRoot_Link_Visual">
                        <origin rpy="-3.141592 0.0 0.0" xyz="0.0 0.0 0.0"/>
                        <geometry>
                                <mesh filename="../meshes/ARWrist_Root_Link.stl" scale="1.0 1.0 1.0"/>
                        </geometry>
                        <material name="">
                                <color rgba="0.64706 0.61961 0.58824 1.0"/>
                        </material>
                </visual>
                <collision name="ARWristRoot_Link_Collision">
                        <origin rpy="0.0 0.0 0.0" xyz="0.0 0.0 0.0"/>
                        <geometry>
                                <mesh filename="../meshes/ARWrist_Root_Link_convexhull.stl" scale="1.0 1.0 1.0"/>
                        </geometry>
                </collision>
        </link>
        <joint name="ARWristYaw" type="revolute">
                <origin rpy="0.0 0.0 -1e-06" xyz="0.0 0.0 0.0"/>
                <axis xyz="0.0 1.0 0.0"/>
                <parent link="ARWristPitch_Link"/>
                <child link="ARWristYaw_Link"/>
                <limit effort="44.635" lower="-0.475" upper="0.585" velocity="7.725"/>
        </joint>
        <link name="ARWristYaw_Link">
                <inertial>
                        <origin rpy="0.0 0.0 0.0" xyz="0.0 0.011222 0.011777"/>
                        <mass value="0.04402665761680324"/>
                        <inertia ixx="1.4523374545063195e-05" ixy="-3.5210351301346614e-09" ixz="1.8323838790669446e-08" iyy="1.0332756951863251e-05" iyz="1.4768213030503297e-06" izz="1.6554591701012806e-05"/>
                </inertial>
                <visual name="ARWristYaw_Link_Visual">
                        <origin rpy="0.0 0.0 -3.141592" xyz="0.0 0.0 0.0"/>
                        <geometry>
                                <mesh filename="../meshes/ARWristYaw_Link.stl" scale="1.0 1.0 1.0"/>
                        </geometry>
                        <material name="">
                                <color rgba="0.898039215686275 0.917647058823529 0.929411764705882 1.0"/>
                        </material>
                </visual>
                <collision name="ARWristYaw_Link_Collision">
                        <origin rpy="0.0 0.0 0.0" xyz="0.0 0.0 0.0"/>
                        <geometry>
                                <mesh filename="../meshes/ARWristYaw_Link_convexhull.stl" scale="1.0 1.0 1.0"/>
                        </geometry>
                </collision>
        </link>
        <joint name="BodyActL" type="prismatic">
                <origin rpy="0.0 0.0 0.0" xyz="0.0 0.0 0.23999"/>
                <axis xyz="0.0 0.0 1.0"/>
                <parent link="BodyBL2_Link"/>
                <child link="BodyActL_Link"/>
                <limit effort="2716.0" lower="-0.0345" upper="0.0442" velocity="0.291"/>
        </joint>
        <link name="BodyActL_Link">
                <inertial>
                        <origin rpy="0.0 0.0 0.0" xyz="0.0 0.0 -0.077362"/>
                        <mass value="0.10190000000000002"/>
                        <inertia ixx="0.00013708249997353297" ixy="3.8201993071794706e-08" ixz="0.0" iyy="0.00013710250002646712" iyz="0.0" izz="1.0000000000000003e-05"/>
                </inertial>
                <visual name="BodyActL_Visual">
                        <origin rpy="0.0 0.0 -3.141593" xyz="0.0 0.0 0.0"/>
                        <geometry>
                                <mesh filename="../meshes/Body_ActL.stl"/>
                        </geometry>
                        <material name="">
                                <color rgba="0.69804 0.69804 0.69804 1.0"/>
                        </material>
                </visual>
                <collision name="BodyActL_Collision">
                        <origin rpy="0.0 0.0 0.0" xyz="0.0 0.0 0.0"/>
                        <geometry>
                                <mesh filename="../meshes/Body_ActL_convexhull.stl" scale="1.0 1.0 1.0"/>
                        </geometry>
                </collision>
        </link>
        <joint name="BodyActR" type="prismatic">
                <origin rpy="0.0 0.0 0.0" xyz="0.0 0.0 0.23999"/>
                <axis xyz="0.0 0.0 1.0"/>
                <parent link="BodyBR2_Link"/>
                <child link="BodyActR_Link"/>
                <limit effort="2716.0" lower="-0.0345" upper="0.0442" velocity="0.291"/>
        </joint>
        <link name="BodyActR_Link">
                <inertial>
                        <origin rpy="0.0 0.0 0.0" xyz="0.0 0.0 -0.077362"/>
                        <mass value="0.10190000000000002"/>
                        <inertia ixx="0.00013708250002646719" ixy="-3.820200692820298e-08" ixz="0.0" iyy="0.00013710249997353285" iyz="0.0" izz="1.0000000000000003e-05"/>
                </inertial>
                <visual name="BodyActR_Visual">
                        <origin rpy="0.0 0.0 -3.141593" xyz="0.0 0.0 0.0"/>
                        <geometry>
                                <mesh filename="../meshes/Body_ActR.stl"/>
                        </geometry>
                        <material name="">
                                <color rgba="0.69804 0.69804 0.69804 1.0"/>
                        </material>
                </visual>
                <collision name="BodyActR_Collision">
                        <origin rpy="0.0 0.0 0.0" xyz="0.0 0.0 0.0"/>
                        <geometry>
                                <mesh filename="../meshes/Body_ActR_convexhull.stl" scale="1.0 1.0 1.0"/>
                        </geometry>
                </collision>
        </link>
        <joint name="BodyBL1" type="revolute">
                <origin rpy="2.899823 0.0 1.5708" xyz="0.02 -0.089827 0.21"/>
                <axis xyz="1.0 0.0 0.0"/>
                <parent link="BodyRoot_Link"/>
                <child link="BodyBL1_Link"/>
                <limit effort="400.0" lower="-1.57" upper="1.57" velocity="3.1415926"/>
        </joint>
        <link name="BodyBL1_Link">
                <inertial>
                        <origin rpy="0.0 0.0 0.0" xyz="0.020399 0.0 0.0"/>
                        <mass value="0.042423"/>
                        <inertia ixx="1.0000000000001026e-05" ixy="-2.9574078259175723e-12" ixz="0.0" iyy="1.8537299999998983e-05" iyz="0.0" izz="2.0306299999999996e-05"/>
                </inertial>
                <visual name="BodyBL1_Visual">
                        <origin rpy="0.0 0.0 -3.141593" xyz="0.0 0.0 0.0"/>
                        <geometry>
                                <mesh filename="../meshes/Body_BL1.stl"/>
                        </geometry>
                        <material name="">
                                <color rgba="0.64706 0.61961 0.58824 1.0"/>
                        </material>
                </visual>
                <collision name="BodyBL1_Collision">
                        <origin rpy="0.0 0.0 0.0" xyz="0.0 0.0 0.0"/>
                        <geometry>
                                <mesh filename="../meshes/Body_BL1_convexhull.stl" scale="1.0 1.0 1.0"/>
                        </geometry>
                </collision>
        </link>
        <joint name="BodyBL2" type="revolute">
                <origin rpy="0.0 -0.010339 0.0" xyz="0.0 0.0 0.0"/>
                <axis xyz="0.0 1.0 0.0"/>
                <parent link="BodyBL1_Link"/>
                <child link="BodyBL2_Link"/>
                <limit effort="400.0" lower="-1.57" upper="1.57" velocity="3.1415926"/>
        </joint>
        <link name="BodyBL2_Link">
                <inertial>
                        <origin rpy="0.0 0.0 0.0" xyz="0.0 0.0 0.12216"/>
                        <mass value="0.8166400000000001"/>
                        <inertia ixx="0.0004187999999241573" ixy="1.0946911318984479e-07" ixz="4.637099902145767e-07" iyy="0.00042136000007584283" iyz="2.8248160633875217e-08" izz="0.00051891"/>
                </inertial>
                <visual name="BodyBL2_Visual">
                        <origin rpy="0.0 0.0 -3.141593" xyz="0.0 0.0 0.0"/>
                        <geometry>
                                <mesh filename="../meshes/Body_BL2.stl"/>
                        </geometry>
                        <material name="">
                                <color rgba="0.61961 0.40784 0.2 1.0"/>
                        </material>
                </visual>
                <collision name="BodyBL2_Collision">
                        <origin rpy="0.0 0.0 0.0" xyz="0.0 0.0 0.0"/>
                        <geometry>
                                <mesh filename="../meshes/Body_BL2_convexhull.stl" scale="1.0 1.0 1.0"/>
                        </geometry>
                </collision>
        </link>
        <joint name="BodyBR1" type="revolute">
                <origin rpy="-2.899823 0.0 1.5708" xyz="-0.02 -0.089827 0.21"/>
                <axis xyz="1.0 0.0 0.0"/>
                <parent link="BodyRoot_Link"/>
                <child link="BodyBR1_Link"/>
                <limit effort="400.0" lower="-1.57" upper="1.57" velocity="3.1415926"/>
        </joint>
        <link name="BodyBR1_Link">
                <inertial>
                        <origin rpy="0.0 0.0 0.0" xyz="0.020399 0.0 0.0"/>
                        <mass value="0.042423"/>
                        <inertia ixx="1.0000000000001026e-05" ixy="-2.9574078244755723e-12" ixz="0.0" iyy="1.8537299999998983e-05" iyz="0.0" izz="2.0306299999999996e-05"/>
                </inertial>
                <visual name="BodyBR1_Visual">
                        <origin rpy="0.0 0.0 -3.141593" xyz="0.0 0.0 0.0"/>
                        <geometry>
                                <mesh filename="../meshes/Body_BR1.stl"/>
                        </geometry>
                        <material name="">
                                <color rgba="0.64706 0.61961 0.58824 1.0"/>
                        </material>
                </visual>
                <collision name="BodyBR1_Collision">
                        <origin rpy="0.0 0.0 0.0" xyz="0.0 0.0 0.0"/>
                        <geometry>
                                <mesh filename="../meshes/Body_BR1_convexhull.stl" scale="1.0 1.0 1.0"/>
                        </geometry>
                </collision>
        </link>
        <joint name="BodyBR2" type="revolute">
                <origin rpy="0.0 -0.010339 0.0" xyz="0.0 0.0 0.0"/>
                <axis xyz="0.0 1.0 0.0"/>
                <parent link="BodyBR1_Link"/>
                <child link="BodyBR2_Link"/>
                <limit effort="400.0" lower="-1.57" upper="1.57" velocity="3.1415926"/>
        </joint>
        <link name="BodyBR2_Link">
                <inertial>
                        <origin rpy="0.0 0.0 0.0" xyz="0.0 0.0 0.12216"/>
                        <mass value="0.8166400000000001"/>
                        <inertia ixx="0.00041874999995572364" ixy="6.390708201293713e-08" ixz="4.4057001108232887e-07" iyy="0.0004214000000442765" iyz="-3.199184738205335e-08" izz="0.00051891"/>
                </inertial>
                <visual name="BodyBR2_Visual">
                        <origin rpy="0.0 0.0 -3.141593" xyz="0.0 0.0 0.0"/>
                        <geometry>
                                <mesh filename="../meshes/Body_BR2.stl"/>
                        </geometry>
                        <material name="">
                                <color rgba="0.64706 0.61961 0.58824 1.0"/>
                        </material>
                </visual>
                <collision name="BodyBR2_Collision">
                        <origin rpy="0.0 0.0 0.0" xyz="0.0 0.0 0.0"/>
                        <geometry>
                                <mesh filename="../meshes/Body_BR2_convexhull.stl" scale="1.0 1.0 1.0"/>
                        </geometry>
                </collision>
        </link>
        <joint name="BodyPitch" type="revolute">
                <origin rpy="3.141593 0.0 1.570797" xyz="0.0 0.0 0.0"/>
                <axis xyz="0.0 1.0 0.0"/>
                <parent link="BodyRoot_Link"/>
                <child link="BodyPitch_Link"/>
                <limit effort="400.0" lower="-0.34" upper="0.52" velocity="3.1415926"/>
        </joint>
        <link name="BodyPitch_Link">
                <inertial>
                        <origin rpy="0.0 0.0 0.0" xyz="0.0 0.0 0.0"/>
                        <mass value="0.076413"/>
                        <inertia ixx="1.3771000000001387e-05" ixy="2.1212999999995475e-12" ixz="2.1080999098829268e-12" iyy="1.3770999999998615e-05" iyz="0.0" izz="2.4637e-05"/>
                </inertial>
                <visual name="BodyPitch_Visual">
                        <origin rpy="0.0 0.0 -1.570796" xyz="0.0 0.0 0.0"/>
                        <geometry>
                                <mesh filename="../meshes/BodyPitch.stl"/>
                        </geometry>
                        <material name="">
                                <color rgba="0.89804 0.91765 0.92941 1.0"/>
                        </material>
                </visual>
                <collision name="BodyPitch_Collision">
                        <origin rpy="0.0 0.0 0.0" xyz="0.0 0.0 0.0"/>
                        <geometry>
                                <mesh filename="../meshes/BodyPitch_convexhull.stl" scale="1.0 1.0 1.0"/>
                        </geometry>
                </collision>
        </link>
        <joint name="BodyRoll" type="revolute">
                <origin rpy="0.0 0.0 0.0" xyz="0.0 0.0 0.0"/>
                <axis xyz="1.0 0.0 0.0"/>
                <parent link="BodyPitch_Link"/>
                <child link="BodyRoll_Link"/>
                <limit effort="400.0" lower="-0.44" upper="0.44" velocity="3.1415926"/>
        </joint>
        <link name="BodyRoll_Link">
                <inertial>
                        <origin rpy="0.0 0.0 0.0" xyz="-0.009734 0.0 0.052947"/>
                        <mass value="1.4553"/>
                        <inertia ixx="0.001065799999518147" ixy="-7.372513070271073e-07" ixz="-6.32019993920274e-06" iyy="0.001000600000481853" iyz="1.8604206540909618e-07" izz="0.0017602"/>
                </inertial>
                <visual name="BodyRoll_Visual">
                        <origin rpy="0.0 0.0 -1.570796" xyz="0.0 0.0 0.0"/>
                        <geometry>
                                <mesh filename="../meshes/BodyRoll.stl"/>
                        </geometry>
                        <material name="">
                                <color rgba="0.89804 0.91765 0.92941 1.0"/>
                        </material>
                </visual>
                <collision name="BodyRoll_Collision">
                        <origin rpy="0.0 0.0 0.0" xyz="0.0 0.0 0.0"/>
                        <geometry>
                                <mesh filename="../meshes/BodyRoll_convexhull.stl" scale="1.0 1.0 1.0"/>
                        </geometry>
                </collision>
        </link>
        <joint name="BodyRoot" type="fixed">
                <origin rpy="3.141593 0.0 1.570793" xyz="0.0 0.0 0.016"/>
                <parent link="RH5v2_Root_Link"/>
                <child link="BodyRoot_Link"/>
        </joint>
        <link name="BodyRoot_Link">
                <inertial>
                        <origin rpy="0.0 0.0 0.0" xyz="0.001001 0.011445 0.027995"/>
                        <mass value="0.1819"/>
                        <inertia ixx="0.00016560999999982624" ixy="2.4259007707886505e-10" ixz="1.6758933595730266e-08" iyy="0.00021346000013282973" iyz="1.9149442598622602e-07" izz="0.0003416899998673442"/>
                </inertial>
                <visual name="BodyRoot_Link_Visual">
                        <origin rpy="3.141593 0.0 3.141593" xyz="0.0 0.0 0.0"/>
                        <geometry>
                                <mesh filename="../meshes/Body_Root_Link.stl"/>
                        </geometry>
                        <material name="">
                                <color rgba="1.0 1.0 1.0 1.0"/>
                        </material>
                </visual>
                <collision name="BodyRoot_Link_Collision">
                        <origin rpy="0.0 0.0 0.0" xyz="0.0 0.0 0.0"/>
                        <geometry>
                                <mesh filename="../meshes/Body_Root_Link_convexhull.stl" scale="1.0 1.0 1.0"/>
                        </geometry>
                </collision>
        </link>
        <joint name="BodyYaw" type="revolute">
                <origin rpy="0.0 0.0 0.0" xyz="0.0 0.0 0.0"/>
                <axis xyz="0.0 0.0 1.0"/>
                <parent link="BodyRoll_Link"/>
                <child link="BodyYaw_Link"/>
                <limit effort="157.0" lower="-3.0543" upper="3.0543" velocity="3.6"/>
        </joint>
        <link name="BodyYaw_Link">
                <inertial>
                        <origin rpy="0.0 0.0 0.0" xyz="0.0 0.0 0.062225"/>
                        <mass value="0.25617"/>
                        <inertia ixx="0.00046732" ixy="0.0" ixz="-2.1180999999998868e-08" iyy="0.00046727000000000004" iyz="0.0" izz="0.00077487"/>
                </inertial>
                <visual name="BodyYaw_Visual">
                        <origin rpy="0.0 0.0 -1.570796" xyz="0.0 0.0 0.0"/>
                        <geometry>
                                <mesh filename="../meshes/BodyYaw.stl"/>
                        </geometry>
                        <material name="">
                                <color rgba="0.89804 0.91765 0.92941 1.0"/>
                        </material>
                </visual>
                <collision name="BodyYaw_Collision">
                        <origin rpy="0.0 0.0 0.0" xyz="0.0 0.0 0.0"/>
                        <geometry>
                                <mesh filename="../meshes/BodyYaw_convexhull.stl" scale="1.0 1.0 1.0"/>
                        </geometry>
                </collision>
        </link>
        <joint name="Connector_Body/Leg_left" type="fixed">
                <origin rpy="-1.570793 -1.309 7e-06" xyz="0.085744 0.025 0.11058"/>
                <parent link="BodyRoot_Link"/>
                <child link="Connector_Body/Leg_left_Link"/>
        </joint>
        <link name="Connector_Body/Leg_left_Link">
                <inertial>
                        <origin rpy="0.0 0.0 0.0" xyz="0.0 0.0 0.0"/>
                        <mass value="0.0"/>
                        <inertia ixx="1e-05" ixy="0.0" ixz="0.0" iyy="1e-05" iyz="0.0" izz="1e-05"/>
                </inertial>
        </link>
        <joint name="Connector_Body/Leg_right" type="fixed">
                <origin rpy="1.570793 -1.309 -3.141593" xyz="-0.085744 0.025 0.11058"/>
                <parent link="BodyRoot_Link"/>
                <child link="Connector_Body/Leg_right_Link"/>
        </joint>
        <link name="Connector_Body/Leg_right_Link">
                <inertial>
                        <origin rpy="0.0 0.0 0.0" xyz="0.0 0.0 0.0"/>
                        <mass value="0.0"/>
                        <inertia ixx="1.0000000000000003e-05" ixy="0.0" ixz="0.0" iyy="1.0000000000000004e-05" iyz="0.0" izz="1e-05"/>
                </inertial>
        </link>
        <joint name="Connector_Body/Torso" type="fixed">
                <origin rpy="-1.570793 -1.570793 1.570796" xyz="0.0 0.0 0.0525"/>
                <parent link="BodyYaw_Link"/>
                <child link="Connector_Body/Torso_Link"/>
        </joint>
        <link name="Connector_Body/Torso_Link">
                <inertial>
                        <origin rpy="0.0 0.0 0.0" xyz="0.18852258878884967 0.0 -0.006136751379971498"/>
                        <mass value="9.057654141048396"/>
                        <inertia ixx="0.13521096197328605" ixy="0.00020463773988279492" ixz="-0.005225465392652974" iyy="0.1581524298837754" iyz="-4.4239158097541136e-05" izz="0.22422604262450974"/>
                </inertial>
                <visual name="base_link_torso_Visual">
                        <origin rpy="3.141593 0.0 0.0" xyz="0.0 0.0 0.0"/>
                        <geometry>
                                <mesh filename="../meshes/base_link_torso.stl"/>
                        </geometry>
                        <material name="">
                                <color rgba="0.698039215686274 0.698039215686274 0.698039215686274 1.0"/>
                        </material>
                </visual>
                <visual name="Connector_Torso/Head_Visual">
                        <origin rpy="-3.141592 0.0 0.0" xyz="0.3485 0.0 0.0"/>
                        <geometry>
                                <mesh filename="../meshes/Connector_Torso_Head.stl"/>
                        </geometry>
                        <material name="">
                                <color rgba="0.69804 0.69804 0.69804 1.0"/>
                        </material>
                </visual>
                <visual name="Connector_Torso/ArmRight_Visual">
                        <origin rpy="-1.508093 0.25436 -1.3265" xyz="0.29809 -0.12609 0.025162"/>
                        <geometry>
                                <mesh filename="../meshes/Connector_Torso_ArmRight.stl"/>
                        </geometry>
                        <material name="">
                                <color rgba="0.69804 0.69804 0.69804 1.0"/>
                        </material>
                </visual>
                <visual name="Connector_Torso/ArmLeft_Visual">
                        <origin rpy="1.508093 0.25436 1.3265" xyz="0.29809 0.12609 0.025162"/>
                        <geometry>
                                <mesh filename="../meshes/Connector_Torso_ArmLeft.stl"/>
                        </geometry>
                        <material name="">
                                <color rgba="0.69804 0.69804 0.69804 1.0"/>
                        </material>
                </visual>
                <collision name="Connector_Body/Torso_Link_Collision">
                        <origin rpy="0.0 0.0 0.0" xyz="0.0 0.0 0.0"/>
                        <geometry>
                                <mesh filename="../meshes/base_link_torso.stl" scale="1.0 1.0 1.0"/>
                        </geometry>
                </collision>
        </link>
        <joint name="Connector_Torso/Backpack" type="fixed">
                <origin rpy="0.014588 -1.570793 3.127004" xyz="0.3015 0.135 0.139"/>
                <parent link="Connector_Body/Torso_Link"/>
                <child link="Connector_Torso/Backpack_Link"/>
        </joint>
        <link name="Connector_Torso/Backpack_Link">
                <inertial>
                        <origin rpy="0.0 0.0 0.0" xyz="0.0059236 0.13398 -0.12892"/>
                        <mass value="0.31044"/>
                        <inertia ixx="0.0062412" ixy="-3.547e-07" ixz="-0.00033605" iyy="0.0031219" iyz="2.3476e-05" izz="0.003565"/>
                </inertial>
                <visual name="Connector_Torso/Backpack_Visual">
                        <origin rpy="0.0 0.0 0.0" xyz="0.0 0.0 0.0"/>
                        <geometry>
                                <mesh filename="../meshes/Connector_Torso_Backpack.stl"/>
                        </geometry>
                        <material name="">
                                <color rgba="0.20784 0.30196 0.45098 1.0"/>
                        </material>
                </visual>
                <collision name="Connector_Torso/Backpack_Collision">
                        <origin rpy="0.0 0.0 0.0" xyz="0.0 0.0 0.0"/>
                        <geometry>
                                <mesh filename="../meshes/Connector_Torso_Backpack_convexhull.stl" scale="1.0 1.0 1.0"/>
                        </geometry>
                </collision>
        </link>
        <joint name="GLBase" type="fixed">
                <origin rpy="0.0 0.0 0.0" xyz="0.0 0.0 0.0"/>
                <parent link="ALWristFT_Link"/>
                <child link="GLBase_Link"/>
        </joint>
        <link name="GLBase_Link">
                <inertial>
                        <origin rpy="0.0 0.0 0.0" xyz="-0.0031425381417638943 0.0026602103582309524 0.01791402873528407"/>
                        <mass value="3.1111163372336628"/>
                        <inertia ixx="0.0022494755031819973" ixy="5.254231668369165e-05" ixz="1.792145016299537e-06" iyy="0.0014389611732038632" iyz="-5.247532023758915e-05" izz="0.0018127263007140547"/>
                </inertial>
                <visual name="GLBase_Visual">
                        <origin rpy="3.141593 0.0 0.0" xyz="0.0 0.0 0.0"/>
                        <geometry>
                                <mesh filename="../meshes/GripperLeft_BaseFrame.stl" scale="1.0 1.0 1.0"/>
                        </geometry>
                        <material name="">
                                <color rgba="0.94118 0.67451 0.11765 1.0"/>
                        </material>
                </visual>
                <visual name="GLF1Base_Visual">
                        <origin rpy="1.7921 0.1664 -1.533593" xyz="-0.013458 -0.038971 0.065211"/>
                        <geometry>
                                <mesh filename="../meshes/Finger_Base_Frame.stl"/>
                        </geometry>
                        <material name="">
                                <color rgba="0.79216 0.81961 0.93333 1.0"/>
                        </material>
                </visual>
                <visual name="GLF1ProximalBar_Visual">
                        <origin rpy="0.6783 0.1664 -1.533593" xyz="-0.053439 -0.029588 0.079319"/>
                        <geometry>
                                <mesh filename="../meshes/F_ProximalBar_Frame.stl"/>
                        </geometry>
                        <material name="">
                                <color rgba="0.94118 0.67451 0.11765 1.0"/>
                        </material>
                </visual>
                <visual name="GLF1ProximalSegment_Visual">
                        <origin rpy="0.6664 0.1664 -1.533593" xyz="-0.031453 -0.028781 0.079387"/>
                        <geometry>
                                <mesh filename="../meshes/F_ProximalSegment_Frame.stl"/>
                        </geometry>
                        <material name="">
                                <color rgba="0.94118 0.67451 0.11765 1.0"/>
                        </material>
                </visual>
                <visual name="GLF1Gear_Visual">
                        <origin rpy="1.9549 0.1664 -1.533593" xyz="-0.063936 -0.036895 0.120472"/>
                        <geometry>
                                <mesh filename="../meshes/F_Gear_Frame.stl"/>
                        </geometry>
                        <material name="">
                                <color rgba="0.94118 0.67451 0.11765 1.0"/>
                        </material>
                </visual>
                <visual name="GLF1TopSegment_Visual">
                        <origin rpy="1.9549 0.1664 -1.533593" xyz="-0.063936 -0.036895 0.120472"/>
                        <geometry>
                                <mesh filename="../meshes/F_TopSegment_Frame.stl"/>
                        </geometry>
                        <material name="">
                                <color rgba="0.94118 0.67451 0.11765 1.0"/>
                        </material>
                </visual>
                <visual name="GLF2Base_Visual">
                        <origin rpy="1.7907 -0.12478 -1.598593" xyz="-0.014454 0.012122 0.06971"/>
                        <geometry>
                                <mesh filename="../meshes/Finger_Base_Frame.stl"/>
                        </geometry>
                        <material name="">
                                <color rgba="0.79216 0.81961 0.93333 1.0"/>
                        </material>
                </visual>
                <visual name="GLF2ProximalBar_Visual">
                        <origin rpy="0.6769 -0.12478 -1.598593" xyz="-0.053624 0.02768 0.080161"/>
                        <geometry>
                                <mesh filename="../meshes/F_ProximalBar_Frame.stl"/>
                        </geometry>
                        <material name="">
                                <color rgba="0.94118 0.67451 0.11765 1.0"/>
                        </material>
                </visual>
                <visual name="GLF2ProximalSegment_Visual">
                        <origin rpy="0.665 -0.12478 -1.598593" xyz="-0.031632 0.027073 0.080199"/>
                        <geometry>
                                <mesh filename="../meshes/F_ProximalSegment_Frame.stl"/>
                        </geometry>
                        <material name="">
                                <color rgba="0.94118 0.67451 0.11765 1.0"/>
                        </material>
                </visual>
                <visual name="GLF2Gear_Visual">
                        <origin rpy="1.9535 -0.12478 -1.598593" xyz="-0.064179 0.033171 0.121581"/>
                        <geometry>
                                <mesh filename="../meshes/F_Gear_Frame.stl"/>
                        </geometry>
                        <material name="">
                                <color rgba="0.94118 0.67451 0.11765 1.0"/>
                        </material>
                </visual>
                <visual name="GLF2TopSegment_Visual">
                        <origin rpy="1.9535 -0.12478 -1.598593" xyz="-0.064179 0.033171 0.121581"/>
                        <geometry>
                                <mesh filename="../meshes/F_TopSegment_Frame.stl"/>
                        </geometry>
                        <material name="">
                                <color rgba="0.94118 0.67451 0.11765 1.0"/>
                        </material>
                </visual>
                <visual name="GLF3Base_Visual">
                        <origin rpy="1.7907 -0.124785 -1.598609" xyz="-0.013488 0.046837 0.065354"/>
                        <geometry>
                                <mesh filename="../meshes/Finger_Base_Frame.stl"/>
                        </geometry>
                        <material name="">
                                <color rgba="0.79216 0.81961 0.93333 1.0"/>
                        </material>
                </visual>
                <visual name="GLF3ProximalBar_Visual">
                        <origin rpy="0.6769 -0.124785 -1.598609" xyz="-0.052657 0.062395 0.075805"/>
                        <geometry>
                                <mesh filename="../meshes/F_ProximalBar_Frame.stl"/>
                        </geometry>
                        <material name="">
                                <color rgba="0.94118 0.67451 0.11765 1.0"/>
                        </material>
                </visual>
                <visual name="GLF3ProximalSegment_Visual">
                        <origin rpy="0.665 -0.124785 -1.598609" xyz="-0.030665 0.061788 0.075843"/>
                        <geometry>
                                <mesh filename="../meshes/F_ProximalSegment_Frame.stl"/>
                        </geometry>
                        <material name="">
                                <color rgba="0.94118 0.67451 0.11765 1.0"/>
                        </material>
                </visual>
                <visual name="GLF3Gear_Visual">
                        <origin rpy="1.9535 -0.124785 -1.598609" xyz="-0.063212 0.067886 0.117225"/>
                        <geometry>
                                <mesh filename="../meshes/F_Gear_Frame.stl"/>
                        </geometry>
                        <material name="">
                                <color rgba="0.94118 0.67451 0.11765 1.0"/>
                        </material>
                </visual>
                <visual name="GLF3TopSegment_Visual">
                        <origin rpy="1.9535 -0.124785 -1.598609" xyz="-0.063212 0.067886 0.117225"/>
                        <geometry>
                                <mesh filename="../meshes/F_TopSegment_Frame.stl"/>
                        </geometry>
                        <material name="">
                                <color rgba="0.94118 0.67451 0.11765 1.0"/>
                        </material>
                </visual>
                <visual name="GLThumb_Visual">
                        <origin rpy="0.0 0.0 1e-06" xyz="0.019161 -0.002327 0.042"/>
                        <geometry>
                                <mesh filename="../meshes/GL_Thumb.stl" scale="1.0 1.0 1.0"/>
                        </geometry>
                        <material name="">
                                <color rgba="0.94118 0.67451 0.11765 1.0"/>
                        </material>
                </visual>
                <visual name="GLF4Base_Visual">
                        <origin rpy="1.789 0.0 1.570792" xyz="0.031157 0.010673 0.070112"/>
                        <geometry>
                                <mesh filename="../meshes/Finger_Base_Frame.stl"/>
                        </geometry>
                        <material name="">
                                <color rgba="0.79216 0.81961 0.93333 1.0"/>
                        </material>
                </visual>
                <visual name="GLF4ProximalBar_Visual">
                        <origin rpy="0.6752 0.0 1.570792" xyz="0.070723 -0.002377 0.082349"/>
                        <geometry>
                                <mesh filename="../meshes/F_ProximalBar_Frame.stl"/>
                        </geometry>
                        <material name="">
                                <color rgba="0.94118 0.67451 0.11765 1.0"/>
                        </material>
                </visual>
                <visual name="GLF4ProximalSegment_Visual">
                        <origin rpy="0.6633 0.0 1.570792" xyz="0.048723 -0.002377 0.08235"/>
                        <geometry>
                                <mesh filename="../meshes/F_ProximalSegment_Frame.stl"/>
                        </geometry>
                        <material name="">
                                <color rgba="0.94118 0.67451 0.11765 1.0"/>
                        </material>
                </visual>
                <visual name="GLF4Gear_Visual">
                        <origin rpy="1.9518 0.0 1.570792" xyz="0.081356 -0.002377 0.124112"/>
                        <geometry>
                                <mesh filename="../meshes/F_Gear_Frame.stl"/>
                        </geometry>
                        <material name="">
                                <color rgba="0.94118 0.67451 0.11765 1.0"/>
                        </material>
                </visual>
                <visual name="GLF4TopSegment_Visual">
                        <origin rpy="1.9518 0.0 1.570792" xyz="0.081356 -0.002377 0.124112"/>
                        <geometry>
                                <mesh filename="../meshes/F_TopSegment_Frame.stl"/>
                        </geometry>
                        <material name="">
                                <color rgba="0.94118 0.67451 0.11765 1.0"/>
                        </material>
                </visual>
        </link>
        <joint name="GRBase" type="fixed">
                <origin rpy="0.0 0.0 3.1415926535" xyz="0.0 0.0 0.0"/>
                <parent link="ARWristFT_Link"/>
                <child link="GRBase_Link"/>
        </joint>
        <link name="GRBase_Link">
                <inertial>
                        <origin rpy="0.0 0.0 0.0" xyz="-0.0060597936052261695 -0.0031164978888453118 0.020768707306728605"/>
                        <mass value="0.8370142201706786"/>
                        <inertia ixx="0.0004374533977386897" ixy="-2.1912620618297095e-07" ixz="-6.71429187097938e-07" iyy="0.0005848849811336842" iyz="-1.5331163245339416e-05" izz="0.00046140360967758336"/>
                </inertial>
                <visual name="GRBase_Visual">
                        <origin rpy="0.0 0.0 0.0" xyz="0.0 0.0 0.0"/>
                        <geometry>
                                <mesh filename="../meshes/2FGripper_BaseFrame.stl"/>
                        </geometry>
                        <material name="">
                                <color rgba="0.77647 0.75686 0.73725 1.0"/>
                        </material>
                </visual>
                <visual name="GRF1Base_Visual">
                        <origin rpy="1.789 0.0 -1.5708" xyz="-0.021725 -0.013001 0.064903"/>
                        <geometry>
                                <mesh filename="../meshes/Finger_Base_Frame.stl"/>
                        </geometry>
                        <material name="">
                                <color rgba="0.79216 0.81961 0.93333 1.0"/>
                        </material>
                </visual>
                <visual name="GRF1ProximalBar_Visual">
                        <origin rpy="0.6752 0.0 -1.5708" xyz="-0.061291 0.0 0.07714"/>
                        <geometry>
                                <mesh filename="../meshes/F_ProximalBar_Frame.stl"/>
                        </geometry>
                        <material name="">
                                <color rgba="0.94118 0.67451 0.11765 1.0"/>
                        </material>
                </visual>
                <visual name="GRF1ProximalSegment_Visual">
                        <origin rpy="0.6633 0.0 -1.5708" xyz="-0.039291 0.0 0.077141"/>
                        <geometry>
                                <mesh filename="../meshes/F_ProximalSegment_Frame.stl"/>
                        </geometry>
                        <material name="">
                                <color rgba="0.94118 0.67451 0.11765 1.0"/>
                        </material>
                </visual>
                <visual name="GRF1Gear_Visual">
                        <origin rpy="1.9518 0.0 -1.5708" xyz="-0.071924 0.0 0.118903"/>
                        <geometry>
                                <mesh filename="../meshes/F_Gear_Frame.stl"/>
                        </geometry>
                        <material name="">
                                <color rgba="0.94118 0.67451 0.11765 1.0"/>
                        </material>
                </visual>
                <visual name="GRF1TopSegment_Visual">
                        <origin rpy="1.9518 0.0 -1.5708" xyz="-0.071924 0.0 0.118903"/>
                        <geometry>
                                <mesh filename="../meshes/F_TopSegment_Frame.stl"/>
                        </geometry>
                        <material name="">
                                <color rgba="0.94118 0.67451 0.11765 1.0"/>
                        </material>
                </visual>
                <visual name="GRF2Base_Visual">
                        <origin rpy="1.789 0.0 1.5708" xyz="0.02175 0.012996 0.064903"/>
                        <geometry>
                                <mesh filename="../meshes/Finger_Base_Frame.stl"/>
                        </geometry>
                        <material name="">
                                <color rgba="0.79216 0.81961 0.93333 1.0"/>
                        </material>
                </visual>
                <visual name="GRF2ProximalBar_Visual">
                        <origin rpy="0.6752 0.0 1.5708" xyz="0.061316 0.0 0.07714"/>
                        <geometry>
                                <mesh filename="../meshes/F_ProximalBar_Frame.stl"/>
                        </geometry>
                        <material name="">
                                <color rgba="0.94118 0.67451 0.11765 1.0"/>
                        </material>
                </visual>
                <visual name="GRF2ProximalSegment_Visual">
                        <origin rpy="0.6633 0.0 1.5708" xyz="0.039316 0.0 0.077141"/>
                        <geometry>
                                <mesh filename="../meshes/F_ProximalSegment_Frame.stl"/>
                        </geometry>
                        <material name="">
                                <color rgba="0.94118 0.67451 0.11765 1.0"/>
                        </material>
                </visual>
                <visual name="GRF2Gear_Visual">
                        <origin rpy="1.9518 0.0 1.5708" xyz="0.071949 0.0 0.118903"/>
                        <geometry>
                                <mesh filename="../meshes/F_Gear_Frame.stl"/>
                        </geometry>
                        <material name="">
                                <color rgba="0.94118 0.67451 0.11765 1.0"/>
                        </material>
                </visual>
                <visual name="GRF2TopSegment_Visual">
                        <origin rpy="1.9518 0.0 1.5708" xyz="0.071949 0.0 0.118903"/>
                        <geometry>
                                <mesh filename="../meshes/F_TopSegment_Frame.stl"/>
                        </geometry>
                        <material name="">
                                <color rgba="0.94118 0.67451 0.11765 1.0"/>
                        </material>
                </visual>
        </link>
        <joint name="HeadActC" type="revolute">
                <origin rpy="-1.5708 0.0 0.0" xyz="0.15925 0.0 0.0"/>
                <axis xyz="1.0 0.0 0.0"/>
                <parent link="HeadBase_Link"/>
                <child link="HeadActC_Link"/>
                <limit effort="400.0" lower="-3.1415926" upper="3.1415926" velocity="3.1415926"/>
        </joint>
        <link name="HeadActC_Link">
                <inertial>
                        <origin rpy="0.0 0.0 0.0" xyz="-0.017674 0.0 0.0"/>
                        <mass value="0.0046686"/>
                        <inertia ixx="1e-05" ixy="0.0" ixz="0.0" iyy="1.003789e-05" iyz="-4.798999999999274e-09" izz="1.004626e-05"/>
                </inertial>
                <visual name="HeadActC_Visual">
                        <origin rpy="0.0 0.0 0.0" xyz="0.0 0.0 0.0"/>
                        <geometry>
                                <mesh filename="../meshes/Head_ActC.stl"/>
                        </geometry>
                        <material name="">
                                <color rgba="0.89804 0.91765 0.92941 1.0"/>
                        </material>
                </visual>
                <collision name="HeadActC_Collision">
                        <origin rpy="0.0 0.0 0.0" xyz="0.0 0.0 0.0"/>
                        <geometry>
                                <mesh filename="../meshes/Head_ActC_convexhull.stl" scale="1.0 1.0 1.0"/>
                        </geometry>
                </collision>
        </link>
        <joint name="HeadActL" type="revolute">
                <origin rpy="3.1416 0.0 1.5708" xyz="0.15925 0.0 0.0"/>
                <axis xyz="1.0 0.0 0.0"/>
                <parent link="HeadBase_Link"/>
                <child link="HeadActL_Link"/>
                <limit effort="400.0" lower="-3.1415926" upper="3.1415926" velocity="3.1415926"/>
        </joint>
        <link name="HeadActL_Link">
                <inertial>
                        <origin rpy="0.0 0.0 0.0" xyz="-0.018628 0.0 0.0"/>
                        <mass value="0.049162"/>
                        <inertia ixx="1.50716e-05" ixy="0.0" ixz="0.0" iyy="1.0000000000000003e-05" iyz="0.0" izz="1.0000000000000003e-05"/>
                </inertial>
                <visual name="HeadActL_Visual">
                        <origin rpy="0.0 0.0 0.0" xyz="0.0 0.0 0.0"/>
                        <geometry>
                                <mesh filename="../meshes/Head_ActL.stl"/>
                        </geometry>
                        <material name="">
                                <color rgba="0.69804 0.69804 0.69804 1.0"/>
                        </material>
                </visual>
                <collision name="HeadActL_Collision">
                        <origin rpy="0.0 0.0 0.0" xyz="0.0 0.0 0.0"/>
                        <geometry>
                                <mesh filename="../meshes/Head_ActL_convexhull.stl" scale="1.0 1.0 1.0"/>
                        </geometry>
                </collision>
        </link>
        <joint name="HeadActR" type="revolute">
                <origin rpy="0.0 0.0 -1.5708" xyz="0.15925 0.0 0.0"/>
                <axis xyz="1.0 0.0 0.0"/>
                <parent link="HeadBase_Link"/>
                <child link="HeadActR_Link"/>
                <limit effort="400.0" lower="-3.1415926" upper="3.1415926" velocity="3.1415926"/>
        </joint>
        <link name="HeadActR_Link">
                <inertial>
                        <origin rpy="0.0 0.0 0.0" xyz="-0.018628 0.0 0.0"/>
                        <mass value="0.049162"/>
                        <inertia ixx="1.50716e-05" ixy="0.0" ixz="0.0" iyy="1e-05" iyz="0.0" izz="1e-05"/>
                </inertial>
                <visual name="HeadActR_Visual">
                        <origin rpy="0.0 0.0 0.0" xyz="0.0 0.0 0.0"/>
                        <geometry>
                                <mesh filename="../meshes/Head_ActR.stl"/>
                        </geometry>
                        <material name="">
                                <color rgba="0.69804 0.69804 0.69804 1.0"/>
                        </material>
                </visual>
                <collision name="HeadActR_Collision">
                        <origin rpy="0.0 0.0 0.0" xyz="0.0 0.0 0.0"/>
                        <geometry>
                                <mesh filename="../meshes/Head_ActR_convexhull.stl" scale="1.0 1.0 1.0"/>
                        </geometry>
                </collision>
        </link>
        <joint name="HeadBase" type="fixed">
                <origin rpy="-3.141592 0.0 0.0" xyz="0.3485 0.0 0.0"/>
                <parent link="Connector_Body/Torso_Link"/>
                <child link="HeadBase_Link"/>
        </joint>
        <link name="HeadBase_Link">
                <inertial>
                        <origin rpy="0.0 0.0 0.0" xyz="0.074228 0.0 -0.00062034"/>
                        <mass value="1.339"/>
                        <inertia ixx="0.0017089" ixy="4.2668e-08" ixz="5.2598e-08" iyy="0.0014476" iyz="7.0143e-07" izz="0.0013396"/>
                </inertial>
                <visual name="HeadBase_Visual">
                        <origin rpy="0.0 0.0 0.0" xyz="0.0 0.0 0.0"/>
                        <geometry>
                                <mesh filename="../meshes/Head_Base.stl"/>
                        </geometry>
                        <material name="">
                                <color rgba="0.69804 0.69804 0.69804 1.0"/>
                        </material>
                </visual>
                <collision name="HeadBase_Collision">
                        <origin rpy="0.0 0.0 0.0" xyz="0.0 0.0 0.0"/>
                        <geometry>
                                <mesh filename="../meshes/Head_Base_convexhull.stl" scale="1.0 1.0 1.0"/>
                        </geometry>
                </collision>
        </link>
        <joint name="HeadPitch" type="revolute">
                <origin rpy="0.0 0.0 -1.5708" xyz="0.15925 0.0 0.0"/>
                <axis xyz="1.0 0.0 0.0"/>
                <parent link="HeadBase_Link"/>
                <child link="HeadPitch_Link"/>
                <limit effort="8.2" lower="-0.3" upper="0.35" velocity="4.8"/>
        </joint>
        <link name="HeadPitch_Link">
                <inertial>
                        <origin rpy="0.0 0.0 0.0" xyz="0.0 0.0 0.00296950883117566"/>
                        <mass value="0.0135306815484183"/>
                        <inertia ixx="1.0900469792997046e-05" ixy="-1.983276674419689e-12" ixz="2.9229038977620623e-12" iyy="1.1777940400612256e-05" iyz="0.0" izz="1.0000000000009494e-05"/>
                </inertial>
                <visual name="HeadPitch_Visual">
                        <origin rpy="0.0 0.0 0.0" xyz="0.0 0.0 0.0"/>
                        <geometry>
                                <mesh filename="../meshes/HeadPitch.stl"/>
                        </geometry>
                        <material name="">
                                <color rgba="0.898039215686275 0.917647058823529 0.929411764705882 1.0"/>
                        </material>
                </visual>
                <collision name="HeadPitch_Collision">
                        <origin rpy="0.0 0.0 0.0" xyz="0.0 0.0 0.0"/>
                        <geometry>
                                <mesh filename="../meshes/HeadPitch_convexhull.stl" scale="1.0 1.0 1.0"/>
                        </geometry>
                </collision>
        </link>
        <joint name="HeadRoll" type="revolute">
                <origin rpy="-1.5708 -1.5708 0.0" xyz="0.0 0.0 0.0"/>
                <axis xyz="-1.0 0.0 0.0"/>
                <parent link="HeadPitch_Link"/>
                <child link="HeadRoll_Link"/>
                <limit effort="8.2" lower="-0.45" upper="0.45" velocity="4.8"/>
        </joint>
        <link name="HeadRoll_Link">
                <inertial>
                        <origin rpy="0.0 0.0 0.0" xyz="-0.00844253878850604 0.0 0.00884603238325907"/>
                        <mass value="0.109788715391496"/>
                        <inertia ixx="1.83994177455821e-05" ixy="5.13405597754959e-11" ixz="-1.07875589146075e-08" iyy="1.359548687449e-05" iyz="-9.3011670884998e-10" izz="1.39946184243742e-05"/>
                </inertial>
                <visual name="HeadRoll_Visual">
                        <origin rpy="0.0 0.0 0.0" xyz="0.0 0.0 0.0"/>
                        <geometry>
                                <mesh filename="../meshes/HeadRoll.stl"/>
                        </geometry>
                        <material name="">
                                <color rgba="0.898039215686275 0.917647058823529 0.929411764705882 1.0"/>
                        </material>
                </visual>
                <collision name="HeadRoll_Collision">
                        <origin rpy="0.0 0.0 0.0" xyz="0.0 0.0 0.0"/>
                        <geometry>
                                <mesh filename="../meshes/HeadRoll_convexhull.stl" scale="1.0 1.0 1.0"/>
                        </geometry>
                </collision>
        </link>
        <joint name="HeadYaw" type="revolute">
                <origin rpy="1.5708 -1.5708 0.0" xyz="0.0 0.0 0.0"/>
                <axis xyz="1.0 0.0 0.0"/>
                <parent link="HeadRoll_Link"/>
                <child link="HeadYaw_Link"/>
                <limit effort="4.1" lower="-2.1" upper="2.1" velocity="4.8"/>
        </joint>
        <link name="HeadYaw_Link">
                <inertial>
                        <origin rpy="0.0 0.0 0.0" xyz="0.0865202750448954 -0.0440420348532486 -0.00282280741895916"/>
                        <mass value="1.46451930762968"/>
                        <inertia ixx="0.00400957562211491" ixy="-0.000773636855316844" ixz="-8.24762860917018e-06" iyy="0.00399135489001388" iyz="-9.04346097850664e-06" izz="0.00411109150468807"/>
                </inertial>
                <visual name="HeadYaw_Visual">
                        <origin rpy="0.0 0.0 0.0" xyz="0.0 0.0 0.0"/>
                        <geometry>
                                <mesh filename="../meshes/HeadYaw.stl"/>
                        </geometry>
                        <material name="">
                                <color rgba="0.498039215686275 0.498039215686275 0.498039215686275 1.0"/>
                        </material>
                </visual>
                <collision name="HeadYaw_Collision">
                        <origin rpy="0.0 0.0 0.0" xyz="0.0 0.0 0.0"/>
                        <geometry>
                                <mesh filename="../meshes/HeadYaw_convexhull.stl" scale="1.0 1.0 1.0"/>
                        </geometry>
                </collision>
        </link>
        <joint name="IMU_Body" type="fixed">
                <origin rpy="-3.141593 0.0 1.570793" xyz="-0.01745 -0.005 0.10795"/>
                <parent link="BodyRoot_Link"/>
                <child link="IMU_Body_Link"/>
        </joint>
        <link name="IMU_Body_Link">
                <inertial>
                        <origin rpy="0.0 0.0 0.0" xyz="0.020181 0.018941 0.0015699"/>
                        <mass value="0.093167"/>
                        <inertia ixx="1.4618e-05" ixy="-6.5521e-08" ixz="-5.6588e-08" iyy="2.4402e-05" iyz="6.4435e-09" izz="3.4276e-05"/>
                </inertial>
                <visual name="IMU_Body_Visual">
                        <origin rpy="0.0 0.0 0.0" xyz="0.0 0.0 0.0"/>
                        <geometry>
                                <mesh filename="../meshes/IMU_Body.stl"/>
                        </geometry>
                        <material name="">
                                <color rgba="0.69804 0.69804 0.69804 1.0"/>
                        </material>
                </visual>
                <collision name="IMU_Body_Collision">
                        <origin rpy="0.0 0.0 0.0" xyz="0.0 0.0 0.0"/>
                        <geometry>
                                <mesh filename="../meshes/IMU_Body_convexhull.stl" scale="1.0 1.0 1.0"/>
                        </geometry>
                </collision>
        </link>
        <joint name="IMU_Torso" type="fixed">
                <origin rpy="0.014588 -1.570793 3.127004" xyz="0.14735 -0.10255 0.0075"/>
                <parent link="Connector_Body/Torso_Link"/>
                <child link="IMU_Torso_Link"/>
        </joint>
        <link name="IMU_Torso_Link">
                <inertial>
                        <origin rpy="0.0 0.0 0.0" xyz="0.020181 0.018941 0.0015699"/>
                        <mass value="0.093167"/>
                        <inertia ixx="1.4618e-05" ixy="-6.5519e-08" ixz="-5.6587e-08" iyy="2.4402e-05" iyz="6.4433e-09" izz="3.4276e-05"/>
                </inertial>
                <visual name="IMU_Torso_Visual">
                        <origin rpy="0.0 0.0 0.0" xyz="0.0 0.0 0.0"/>
                        <geometry>
                                <mesh filename="../meshes/IMU_Torso.stl"/>
                        </geometry>
                        <material name="">
                                <color rgba="0.69804 0.69804 0.69804 1.0"/>
                        </material>
                </visual>
                <collision name="IMU_Torso_Collision">
                        <origin rpy="0.0 0.0 0.0" xyz="0.0 0.0 0.0"/>
                        <geometry>
                                <mesh filename="../meshes/IMU_Torso_convexhull.stl" scale="1.0 1.0 1.0"/>
                        </geometry>
                </collision>
        </link>
        <link name="RH5v2_Root_Link">
                <inertial>
                        <origin rpy="0.0 0.0 0.0" xyz="0.004352 0.0 -0.079131"/>
                        <mass value="1.7255"/>
                        <inertia ixx="0.016198" ixy="-6.064e-07" ixz="-0.0013383" iyy="0.010542" iyz="-5.0064e-07" izz="0.016367"/>
                </inertial>
                <visual name="RH5v2_Root_Link_Visual">
                        <origin rpy="0.0 0.0 0.0" xyz="0.0 0.0 0.0"/>
                        <geometry>
                                <mesh filename="../meshes/RH5v2_Root_Link.stl"/>
                        </geometry>
                        <material name="">
                                <color rgba="0.89804 0.91765 0.92941 1.0"/>
                        </material>
                </visual>
                <collision name="RH5v2_Root_Link_Collision">
                        <origin rpy="0.0 0.0 0.0" xyz="0.0 0.0 0.0"/>
                        <geometry>
                                <mesh filename="../meshes/RH5v2_Root_Link_convexhull.stl" scale="1.0 1.0 1.0"/>
                        </geometry>
                </collision>
        </link>
        <joint name="Stereo_Camera_Head" type="fixed">
                <origin rpy="-3.141496 -1.5707 -1.570796" xyz="0.069 -0.1035 -0.031499"/>
                <parent link="HeadYaw_Link"/>
                <child link="Stereo_Camera_Head_Link"/>
        </joint>
        <link name="Stereo_Camera_Head_Link">
                <inertial>
                        <origin rpy="0.0 0.0 0.0" xyz="0.02429 0.0 0.009299"/>
                        <mass value="0.16394274956965307"/>
                        <inertia ixx="0.00021315559509522546" ixy="8.028068239105281e-10" ixz="1.8189970232574128e-08" iyy="0.00021456968378314532" iyz="2.481963350513344e-06" izz="1.5494393629639505e-05"/>
                </inertial>
                <visual name="Stereo_Camera_Head_Visual">
                        <origin rpy="0.785398 -1.57066 0.785398" xyz="0.0 0.0 0.0"/>
                        <geometry>
                                <mesh filename="../meshes/Stereo_Camera_Head.stl"/>
                        </geometry>
                        <material name="">
                                <color rgba="0.698039215686274 0.698039215686274 0.698039215686274 1.0"/>
                        </material>
                </visual>
                <collision name="Stereo_Camera_Head_Collision">
                        <origin rpy="0.0 0.0 0.0" xyz="0.0 0.0 0.0"/>
                        <geometry>
                                <mesh filename="../meshes/Stereo_Camera_Head_convexhull.stl" scale="1.0 1.0 1.0"/>
                        </geometry>
                </collision>
        </link>
        <joint name="Structure_Sensor" type="fixed">
                <origin rpy="2.792523 -4e-05 -1.570892" xyz="0.31589 0.03825 -0.120411"/>
                <parent link="Connector_Body/Torso_Link"/>
                <child link="Structure_Sensor_Link"/>
        </joint>
        <link name="Structure_Sensor_Link">
                <inertial>
                        <origin rpy="0.0 0.0 0.0" xyz="0.038622 0.0 -0.005631"/>
                        <mass value="0.35771000000000003"/>
                        <inertia ixx="3.9054002146696363e-05" ixy="2.7546331115970395e-08" ixz="6.539800799468631e-07" iyy="0.0003796399978528181" iyz="7.024737852269282e-10" izz="0.0003707500000004858"/>
                </inertial>
                <visual name="Structure_Sensor_Visual">
                        <origin rpy="-3.141593 0.0 1.5707" xyz="0.0765 0.0 0.0"/>
                        <geometry>
                                <mesh filename="../meshes/Structure_Sensor_Torso.stl"/>
                        </geometry>
                        <material name="">
                                <color rgba="0.69804 0.69804 0.69804 1.0"/>
                        </material>
                </visual>
                <collision name="Structure_Sensor_Collision">
                        <origin rpy="0.0 0.0 0.0" xyz="0.0 0.0 0.0"/>
                        <geometry>
                                <mesh filename="../meshes/Structure_Sensor_Torso_convexhull.stl" scale="1.0 1.0 1.0"/>
                        </geometry>
                </collision>
        </link>
        <joint name="platform" type="fixed">
                <origin rpy="0.0 0.0 0.0" xyz="0.0 0.0 0.0"/>
                <parent link="Connector_Body/Leg_right_Link"/>
                <child link="platform_Link"/>
        </joint>
        <link name="platform_Link">
                <inertial>
                        <origin rpy="0.0 0.0 0.0" xyz="0.60163 0.24997 -0.2825"/>
                        <mass value="98.726"/>
                        <inertia ixx="1.4402" ixy="0.1287" ixz="0.044177" iyy="0.99436" iyz="0.011837" izz="0.83359"/>
                </inertial>
                <visual name="platform_Visual">
                        <origin rpy="0.0 0.0 0.0" xyz="0.0 0.0 0.0"/>
                        <geometry>
                                <mesh filename="../meshes/base_link.stl"/>
                        </geometry>
                        <material name="">
                                <color rgba="0.75294 0.75294 0.75294 1.0"/>
                        </material>
                </visual>
                <collision name="platform_Collision">
                        <origin rpy="0.0 0.0 0.0" xyz="0.0 0.0 0.0"/>
                        <geometry>
                                <mesh filename="../meshes/base_link_convexhull.stl" scale="1.0 1.0 1.0"/>
                        </geometry>
                </collision>
        </link>
</robot>
