<robot name="RH5v2">
  <joint name="ALBase" type="fixed">
    <origin xyz="0.29809 0.12609 0.025162" rpy="1.508093 0.25436 1.3265"/>
    <parent link="Connector_Body/Torso_Link"/>
    <child link="ALBase_Link"/>
  </joint>
  <link name="ALBase_Link">
    <inertial>
      <origin xyz="0.0079897 -7.1316e-07 0.00019625" rpy="0.0 0.0 0.0"/>
      <mass value="1.1943"/>
      <inertia ixx="0.00089755" ixy="1.4484e-08" ixz="-2.6127e-07" iyy="0.00057565" iyz="-7.8027e-07" izz="0.00056347"/>
    </inertial>
    <visual name="ALBase_Link_Visual">
      <origin xyz="0.0 0.0 0.0" rpy="0.0 0.0 0.0"/>
      <geometry>
        <mesh filename="../meshes/ALBase_Link.stl"/>
      </geometry>
      <material name="">
        <color rgba="0.75294 0.75294 0.75294 1.0"/>
      </material>
    </visual>
    <collision name="ALBase_Link_Collision">
      <origin xyz="0.0 0.0 0.0" rpy="0.0 0.0 0.0"/>
      <geometry>
        <mesh filename="../meshes/ALBase_Link_convexhull.stl" scale="1.0 1.0 1.0"/>
      </geometry>
    </collision>
  </link>
  <joint name="ALElbow" type="revolute">
    <origin xyz="0.0 0.001 0.3511" rpy="0.0 0.0 0.0"/>
    <axis xyz="1.0 0.0 0.0"/>
    <parent link="ALShoulder3_Link"/>
    <child link="ALElbow_Link"/>
    <limit effort="400.0" lower="-1.832" upper="0.0" velocity="3.1415926"/>
  </joint>
  <joint name="ALElbowAct" type="prismatic">
    <origin xyz="0.0 0.0 0.29542" rpy="0.0 0.0 0.0"/>
    <axis xyz="0.0 0.0 1.0"/>
    <parent link="ALElbowB11_Link"/>
    <child link="ALElbowAct_Link"/>
    <limit effort="400.0" lower="-1.57" upper="1.57" velocity="3.1415926"/>
  </joint>
  <link name="ALElbowAct_Link">
    <inertial>
      <origin xyz="-6.1594e-06 1.459e-10 -0.085859" rpy="0.0 0.0 0.0"/>
      <mass value="0.054652"/>
      <inertia ixx="0.00010606969013629223" ixy="3.492500000065374e-13" ixz="3.6185000000071752e-09" iyy="0.00010597469013629217" iyz="-4.3476005705310174e-14" izz="1.0000000136292127e-05"/>
    </inertial>
    <visual name="ALElbowAct_Link_Visual">
      <origin xyz="0.0 0.0 0.0" rpy="0.0 0.0 0.0"/>
      <geometry>
        <mesh filename="../meshes/ALElbow_Act_Link.stl"/>
      </geometry>
      <material name="">
        <color rgba="0.75294 0.75294 0.75294 1.0"/>
      </material>
    </visual>
    <collision name="ALElbowAct_Link_Collision">
      <origin xyz="0.0 0.0 0.0" rpy="0.0 0.0 0.0"/>
      <geometry>
        <mesh filename="../meshes/ALElbow_Act_Link_convexhull.stl" scale="1.0 1.0 1.0"/>
      </geometry>
    </collision>
  </link>
  <joint name="ALElbowB11" type="revolute">
    <origin xyz="0.0 -0.029 0.1391" rpy="-0.25319 0.0 0.0"/>
    <axis xyz="1.0 0.0 0.0"/>
    <parent link="ALShoulder3_Link"/>
    <child link="ALElbowB11_Link"/>
    <limit effort="400.0" lower="-1.57" upper="1.57" velocity="3.1415926"/>
  </joint>
  <link name="ALElbowB11_Link">
    <inertial>
      <origin xyz="2.5944e-05 1.8924e-05 0.10704" rpy="0.0 0.0 0.0"/>
      <mass value="0.32696"/>
      <inertia ixx="0.00011102" ixy="-1.0985e-08" ixz="-6.6288e-08" iyy="0.00011251" iyz="1.4067e-07" izz="7.0733e-05"/>
    </inertial>
    <visual name="ALElbowB11_Link_Visual">
      <origin xyz="0.0 0.0 0.0" rpy="0.0 0.0 0.0"/>
      <geometry>
        <mesh filename="../meshes/ALElbow_B11_Link.stl"/>
      </geometry>
      <material name="">
        <color rgba="0.75294 0.75294 0.75294 1.0"/>
      </material>
    </visual>
    <collision name="ALElbowB11_Link_Collision">
      <origin xyz="0.0 0.0 0.0" rpy="0.0 0.0 0.0"/>
      <geometry>
        <mesh filename="../meshes/ALElbow_B11_Link_convexhull.stl" scale="1.0 1.0 1.0"/>
      </geometry>
    </collision>
  </link>
  <link name="ALElbow_Link">
    <inertial>
      <origin xyz="-7.016e-05 0.001127 0.080286" rpy="0.0 0.0 0.0"/>
      <mass value="0.63578"/>
      <inertia ixx="0.00050999" ixy="2.2297e-07" ixz="4.047e-07" iyy="0.00051633" iyz="-4.4233e-05" izz="0.00046537"/>
    </inertial>
    <visual name="ALElbow_Link_Visual">
      <origin xyz="0.0 0.0 0.0" rpy="0.0 0.0 0.0"/>
      <geometry>
        <mesh filename="../meshes/ALElbow_Link.stl"/>
      </geometry>
      <material name="">
        <color rgba="0.75294 0.75294 0.75294 1.0"/>
      </material>
    </visual>
    <collision name="ALElbow_Link_Collision">
      <origin xyz="0.0 0.0 0.0" rpy="0.0 0.0 0.0"/>
      <geometry>
        <mesh filename="../meshes/ALElbow_Link_convexhull.stl" scale="1.0 1.0 1.0"/>
      </geometry>
    </collision>
  </link>
  <joint name="ALShoulder1" type="revolute">
    <origin xyz="0.1076 0.0 0.0" rpy="3.1416 0.0 0.0"/>
    <axis xyz="1.0 0.0 0.0"/>
    <parent link="ALBase_Link"/>
    <child link="ALShoulder1_Link"/>
    <limit effort="400.0" lower="-3.141" upper="3.141" velocity="3.1415926"/>
  </joint>
  <link name="ALShoulder1_Link">
    <inertial>
      <origin xyz="-0.0091569 0.0036464 -0.00016872" rpy="0.0 0.0 0.0"/>
      <mass value="1.602"/>
      <inertia ixx="0.0012117" ixy="-8.0704e-05" ixz="-3.528e-06" iyy="0.0015561" iyz="-2.6511e-06" izz="0.0010024"/>
    </inertial>
    <visual name="ALShoulder1_Link_Visual">
      <origin xyz="0.0 0.0 0.0" rpy="0.0 0.0 0.0"/>
      <geometry>
        <mesh filename="../meshes/ALShoulder1_Link.stl"/>
      </geometry>
      <material name="">
        <color rgba="0.75294 0.75294 0.75294 1.0"/>
      </material>
    </visual>
    <collision name="ALShoulder1_Link_Collision">
      <origin xyz="0.0 0.0 0.0" rpy="0.0 0.0 0.0"/>
      <geometry>
        <mesh filename="../meshes/ALShoulder1_Link_convexhull.stl" scale="1.0 1.0 1.0"/>
      </geometry>
    </collision>
  </link>
  <joint name="ALShoulder2" type="revolute">
    <origin xyz="0.0 0.0 0.0" rpy="0.0 0.0 0.0"/>
    <axis xyz="0.0 1.0 0.0"/>
    <parent link="ALShoulder1_Link"/>
    <child link="ALShoulder2_Link"/>
    <limit effort="400.0" lower="-0.253" upper="1.85" velocity="3.1415926"/>
  </joint>
  <link name="ALShoulder2_Link">
    <inertial>
      <origin xyz="0.010763 0.020477 0.0278" rpy="0.0 0.0 0.0"/>
      <mass value="0.50849"/>
      <inertia ixx="0.0010465" ixy="0.00012061" ixz="5.4855e-05" iyy="0.00092568" iyz="0.00027501" izz="0.0010393"/>
    </inertial>
    <visual name="ALShoulder2_Link_Visual">
      <origin xyz="0.0 0.0 0.0" rpy="0.0 0.0 0.0"/>
      <geometry>
        <mesh filename="../meshes/ALShoulder2_Link.stl"/>
      </geometry>
      <material name="">
        <color rgba="0.75294 0.75294 0.75294 1.0"/>
      </material>
    </visual>
    <collision name="ALShoulder2_Link_Collision">
      <origin xyz="0.0 0.0 0.0" rpy="0.0 0.0 0.0"/>
      <geometry>
        <mesh filename="../meshes/ALShoulder2_Link_convexhull.stl" scale="1.0 1.0 1.0"/>
      </geometry>
    </collision>
  </link>
  <joint name="ALShoulder3" type="revolute">
    <origin xyz="0.0 0.0 0.0" rpy="0.0 0.0 1.5707"/>
    <axis xyz="0.0 0.0 1.0"/>
    <parent link="ALShoulder2_Link"/>
    <child link="ALShoulder3_Link"/>
    <limit effort="400.0" lower="-3.141" upper="3.141" velocity="3.1415926"/>
  </joint>
  <link name="ALShoulder3_Link">
    <inertial>
      <origin xyz="-3.2703e-05 0.0033688 0.14648" rpy="0.0 0.0 0.0"/>
      <mass value="0.85234"/>
      <inertia ixx="0.0028013" ixy="5.1939e-07" ixz="-7.2591e-07" iyy="0.0027401" iyz="5.4672e-05" izz="0.00078629"/>
    </inertial>
    <visual name="ALShoulder3_Link_Visual">
      <origin xyz="0.0 0.0 0.0" rpy="0.0 0.0 0.0"/>
      <geometry>
        <mesh filename="../meshes/ALShoulder3_Link.stl"/>
      </geometry>
      <material name="">
        <color rgba="0.75294 0.75294 0.75294 1.0"/>
      </material>
    </visual>
    <collision name="ALShoulder3_Link_Collision">
      <origin xyz="0.0 0.0 0.0" rpy="0.0 0.0 0.0"/>
      <geometry>
        <mesh filename="../meshes/ALShoulder3_Link_convexhull.stl" scale="1.0 1.0 1.0"/>
      </geometry>
    </collision>
  </link>
  <joint name="ALWristAL1" type="revolute">
    <origin xyz="0.0155 -0.034 -0.178" rpy="1.5885 0.0 0.0"/>
    <axis xyz="1.0 0.0 0.0"/>
    <parent link="ALWristRoot_Link"/>
    <child link="ALWristAL1_Link"/>
    <limit effort="400.0" lower="-1.57" upper="1.57" velocity="3.1415926"/>
  </joint>
  <link name="ALWristAL1_Link">
    <inertial>
      <origin xyz="4.69848839836778e-06 0.0605130022183077 8.23954439692215e-05" rpy="0.0 0.0 0.0"/>
      <mass value="0.110279568172128"/>
      <inertia ixx="1.426060228931759e-05" ixy="-1.1829530729395678e-10" ixz="-1.5559842262297789e-09" iyy="1.0001497220685684e-05" iyz="-8.070848171024899e-08" izz="1.4350648635894694e-05"/>
    </inertial>
    <visual name="ALWristAL1_Link_Visual">
      <origin xyz="0.0 0.0 0.0" rpy="0.0 0.0 0.0"/>
      <geometry>
        <mesh filename="../meshes/ALWrist_AL1_Link.stl"/>
      </geometry>
      <material name="">
        <color rgba="0.898039215686275 0.917647058823529 0.929411764705882 1.0"/>
      </material>
    </visual>
    <collision name="ALWristAL1_Link_Collision">
      <origin xyz="0.0 0.0 0.0" rpy="0.0 0.0 0.0"/>
      <geometry>
        <mesh filename="../meshes/ALWrist_AL1_Link_convexhull.stl" scale="1.0 1.0 1.0"/>
      </geometry>
    </collision>
  </link>
  <joint name="ALWristAR1" type="revolute">
    <origin xyz="-0.0155 -0.034 -0.178" rpy="1.5885 0.0 0.0"/>
    <axis xyz="1.0 0.0 0.0"/>
    <parent link="ALWristRoot_Link"/>
    <child link="ALWristAR1_Link"/>
    <limit effort="400.0" lower="-1.57" upper="1.57" velocity="3.1415926"/>
  </joint>
  <link name="ALWristAR1_Link">
    <inertial>
      <origin xyz="1.0632e-07 0.058479 9.3561e-05" rpy="0.0 0.0 0.0"/>
      <mass value="0.10113"/>
      <inertia ixx="1.4212213742562422e-05" ixy="-1.1886000000000004e-10" ixz="-1.4829999999999594e-10" iyy="1.000151374256242e-05" iyz="-8.070899999999586e-08" izz="1.4303213742562425e-05"/>
    </inertial>
    <visual name="ALWristAR1_Link_Visual">
      <origin xyz="0.0 0.0 0.0" rpy="0.0 0.0 0.0"/>
      <geometry>
        <mesh filename="../meshes/ALWrist_AR1_Link.stl"/>
      </geometry>
      <material name="">
        <color rgba="0.89804 0.91765 0.92941 1.0"/>
      </material>
    </visual>
    <collision name="ALWristAR1_Link_Collision">
      <origin xyz="0.0 0.0 0.0" rpy="0.0 0.0 0.0"/>
      <geometry>
        <mesh filename="../meshes/ALWrist_AR1_Link_convexhull.stl" scale="1.0 1.0 1.0"/>
      </geometry>
    </collision>
  </link>
  <joint name="ALWristActL" type="prismatic">
    <origin xyz="0.0 0.13346 0.0" rpy="-1.5708 0.0 0.0"/>
    <axis xyz="0.0 0.0 1.0"/>
    <parent link="ALWristAL1_Link"/>
    <child link="ALWristActL_Link"/>
    <limit effort="400.0" lower="-1.57" upper="1.57" velocity="3.1415926"/>
  </joint>
  <link name="ALWristActL_Link">
    <inertial>
      <origin xyz="1.6961e-10 -3.3309e-11 -0.049176" rpy="0.0 0.0 0.0"/>
      <mass value="0.022415"/>
      <inertia ixx="2.2515570000000003e-05" ixy="-8.666700000001066e-16" ixz="7.960299999999999e-17" iyy="2.2496570000000005e-05" iyz="2.9215000273952845e-15" izz="1e-05"/>
    </inertial>
    <visual name="ALWristActL_Link_Visual">
      <origin xyz="0.0 0.0 0.0" rpy="0.0 0.0 0.0"/>
      <geometry>
        <mesh filename="../meshes/ALWrist_ActL_Link.stl"/>
      </geometry>
      <material name="">
        <color rgba="0.77647 0.75686 0.73725 1.0"/>
      </material>
    </visual>
    <collision name="ALWristActL_Link_Collision">
      <origin xyz="0.0 0.0 0.0" rpy="0.0 0.0 0.0"/>
      <geometry>
        <mesh filename="../meshes/ALWrist_ActL_Link_convexhull.stl" scale="1.0 1.0 1.0"/>
      </geometry>
    </collision>
  </link>
  <joint name="ALWristActR" type="prismatic">
    <origin xyz="0.0 0.13346 0.0" rpy="-1.5708 0.0 0.0"/>
    <axis xyz="0.0 0.0 1.0"/>
    <parent link="ALWristAR1_Link"/>
    <child link="ALWristActR_Link"/>
    <limit effort="400.0" lower="-1.57" upper="1.57" velocity="3.1415926"/>
  </joint>
  <link name="ALWristActR_Link">
    <inertial>
      <origin xyz="-2.50423902101171e-10 -5.99230387532401e-12 -0.0491763872735069" rpy="0.0 0.0 0.0"/>
      <mass value="0.0224154782060298"/>
      <inertia ixx="2.251577391703877e-05" ixy="-8.666685437716609e-16" ixz="7.959775514672119e-17" iyy="2.249645939989927e-05" iyz="2.9215994791528672e-15" izz="1e-05"/>
    </inertial>
    <visual name="ALWristActR_Link_Visual">
      <origin xyz="0.0 0.0 0.0" rpy="0.0 0.0 0.0"/>
      <geometry>
        <mesh filename="../meshes/ALWrist_ActR_Link.stl"/>
      </geometry>
      <material name="">
        <color rgba="0.776470588235294 0.756862745098039 0.737254901960784 1.0"/>
      </material>
    </visual>
    <collision name="ALWristActR_Link_Collision">
      <origin xyz="0.0 0.0 0.0" rpy="0.0 0.0 0.0"/>
      <geometry>
        <mesh filename="../meshes/ALWrist_ActR_Link_convexhull.stl" scale="1.0 1.0 1.0"/>
      </geometry>
    </collision>
  </link>
  <joint name="ALWristBL0" type="revolute">
    <origin xyz="0.0 0.0 0.045018" rpy="0.0 0.0 0.0"/>
    <axis xyz="1.0 0.0 0.0"/>
    <parent link="ALWristBL3_Link"/>
    <child link="ALWristBL0_Link"/>
    <limit effort="400.0" lower="-1.57" upper="1.57" velocity="3.1415926"/>
  </joint>
  <link name="ALWristBL0_Link">
    <inertial>
      <origin xyz="0.0 0.0 0.0" rpy="0.0 0.0 0.0"/>
      <mass value="1e-05"/>
      <inertia ixx="1e-05" ixy="0.0" ixz="0.0" iyy="1e-05" iyz="0.0" izz="1e-05"/>
    </inertial>
  </link>
  <joint name="ALWristBL1" type="revolute">
    <origin xyz="0.0155 0.011 -0.032" rpy="-2.8824 0.0 0.0"/>
    <axis xyz="1.0 0.0 0.0"/>
    <parent link="ALWristRoot_Link"/>
    <child link="ALWristBL1_Link"/>
    <limit effort="400.0" lower="-1.57" upper="1.57" velocity="3.1415926"/>
  </joint>
  <link name="ALWristBL1_Link">
    <inertial>
      <origin xyz="0.0019151 0.02635 0.0010414" rpy="0.0 0.0 0.0"/>
      <mass value="0.024008"/>
      <inertia ixx="1.3690309326298155e-05" ixy="-2.58529999998267e-13" ixz="-8.119499999914014e-14" iyy="1.0041289326298152e-05" iyz="3.8667999999999843e-07" izz="1.3621309326298154e-05"/>
    </inertial>
    <visual name="ALWristBL1_Link_Visual">
      <origin xyz="0.0 0.0 0.0" rpy="0.0 0.0 0.0"/>
      <geometry>
        <mesh filename="../meshes/ALWrist_BL1_Link.stl"/>
      </geometry>
      <material name="">
        <color rgba="0.89804 0.91765 0.92941 1.0"/>
      </material>
    </visual>
    <collision name="ALWristBL1_Link_Collision">
      <origin xyz="0.0 0.0 0.0" rpy="0.0 0.0 0.0"/>
      <geometry>
        <mesh filename="../meshes/ALWrist_BL1_Link_convexhull.stl" scale="1.0 1.0 1.0"/>
      </geometry>
    </collision>
  </link>
  <joint name="ALWristBL2" type="revolute">
    <origin xyz="0.0 0.0 0.0" rpy="0.0 0.0 0.0"/>
    <axis xyz="0.0 1.0 0.0"/>
    <parent link="ALWristBL0_Link"/>
    <child link="ALWristBL2_Link"/>
    <limit effort="400.0" lower="-1.57" upper="1.57" velocity="3.1415926"/>
  </joint>
  <link name="ALWristBL2_Link">
    <inertial>
      <origin xyz="-0.00285895892979633 1.59419756701196e-08 4.93600032917541e-05" rpy="0.0 0.0 0.0"/>
      <mass value="0.00373058333172257"/>
      <inertia ixx="1.0000022086306678e-05" ixy="-2.1170777449156144e-13" ixz="1.2800661535321242e-09" iyy="1.0074214747460805e-05" iyz="-3.1071812995088624e-13" izz="1.0074189380048775e-05"/>
    </inertial>
    <visual name="ALWristBL2_Link_Visual">
      <origin xyz="0.0 0.0 0.0" rpy="0.0 0.0 0.0"/>
      <geometry>
        <mesh filename="../meshes/ALWrist_BL2_Link.stl"/>
      </geometry>
      <material name="">
        <color rgba="0.647058823529412 0.619607843137255 0.588235294117647 1.0"/>
      </material>
    </visual>
    <collision name="ALWristBL2_Link_Collision">
      <origin xyz="0.0 0.0 0.0" rpy="0.0 0.0 0.0"/>
      <geometry>
        <mesh filename="../meshes/ALWrist_BL2_Link_convexhull.stl" scale="1.0 1.0 1.0"/>
      </geometry>
    </collision>
  </link>
  <joint name="ALWristBL3" type="revolute">
    <origin xyz="0.0 0.0 0.0" rpy="0.0 -0.017255 0.0"/>
    <axis xyz="0.0 1.0 0.0"/>
    <parent link="ALWristBL4_Link"/>
    <child link="ALWristBL3_Link"/>
    <limit effort="400.0" lower="-1.57" upper="1.57" velocity="3.1415926"/>
  </joint>
  <link name="ALWristBL3_Link">
    <inertial>
      <origin xyz="2.38502552360881e-05 4.66313256272666e-08 0.0283017467527962" rpy="0.0 0.0 0.0"/>
      <mass value="0.0163436688111198"/>
      <inertia ixx="1.0588437589385662e-05" ixy="2.6491888917750254e-12" ixz="3.971418402991697e-10" iyy="1.0442298027473029e-05" iyz="-1.0478564692762442e-11" izz="1.0000000268282943e-05"/>
    </inertial>
    <visual name="ALWristBL3_Link_Visual">
      <origin xyz="0.0 0.0 0.0" rpy="0.0 0.0 0.0"/>
      <geometry>
        <mesh filename="../meshes/ALWrist_BL3_Link.stl"/>
      </geometry>
      <material name="">
        <color rgba="0.898039215686275 0.917647058823529 0.929411764705882 1.0"/>
      </material>
    </visual>
    <collision name="ALWristBL3_Link_Collision">
      <origin xyz="0.0 0.0 0.0" rpy="0.0 0.0 0.0"/>
      <geometry>
        <mesh filename="../meshes/ALWrist_BL3_Link_convexhull.stl" scale="1.0 1.0 1.0"/>
      </geometry>
    </collision>
  </link>
  <joint name="ALWristBL4" type="revolute">
    <origin xyz="0.027 -0.03 0.0" rpy="2.9998 0.0 0.0"/>
    <axis xyz="1.0 0.0 0.0"/>
    <parent link="ALWristYaw_Link"/>
    <child link="ALWristBL4_Link"/>
    <limit effort="400.0" lower="-1.57" upper="1.57" velocity="3.1415926"/>
  </joint>
  <link name="ALWristBL4_Link">
    <inertial>
      <origin xyz="-0.00221364330903131 4.35096403350599e-12 -8.57685450439405e-13" rpy="0.0 0.0 0.0"/>
      <mass value="0.0116530368127355"/>
      <inertia ixx="1e-05" ixy="1.5953378838595036e-20" ixz="3.4058691933577745e-19" iyy="1.027752247888744e-05" iyz="-9.076929593055545e-16" izz="1.0188830976875939e-05"/>
    </inertial>
    <visual name="ALWristBL4_Link_Visual">
      <origin xyz="0.0 0.0 0.0" rpy="0.0 0.0 0.0"/>
      <geometry>
        <mesh filename="../meshes/ALWrist_BL4_Link.stl"/>
      </geometry>
      <material name="">
        <color rgba="0.776470588235294 0.756862745098039 0.737254901960784 1.0"/>
      </material>
    </visual>
    <collision name="ALWristBL4_Link_Collision">
      <origin xyz="0.0 0.0 0.0" rpy="0.0 0.0 0.0"/>
      <geometry>
        <mesh filename="../meshes/ALWrist_BL4_Link_convexhull.stl" scale="1.0 1.0 1.0"/>
      </geometry>
    </collision>
  </link>
  <joint name="ALWristBR0" type="revolute">
    <origin xyz="0.0 0.0 0.045018" rpy="0.0 0.0 0.0"/>
    <axis xyz="1.0 0.0 0.0"/>
    <parent link="ALWristBR3_Link"/>
    <child link="ALWristBR0_Link"/>
    <limit effort="400.0" lower="-1.57" upper="1.57" velocity="3.1415926"/>
  </joint>
  <link name="ALWristBR0_Link">
    <inertial>
      <origin xyz="0.0 0.0 0.0" rpy="0.0 0.0 0.0"/>
      <mass value="1e-05"/>
      <inertia ixx="1e-05" ixy="0.0" ixz="0.0" iyy="1e-05" iyz="0.0" izz="1e-05"/>
    </inertial>
  </link>
  <joint name="ALWristBR1" type="revolute">
    <origin xyz="-0.0155 0.011 -0.032" rpy="-2.8824 0.0 0.0"/>
    <axis xyz="1.0 0.0 0.0"/>
    <parent link="ALWristRoot_Link"/>
    <child link="ALWristBR1_Link"/>
    <limit effort="400.0" lower="-1.57" upper="1.57" velocity="3.1415926"/>
  </joint>
  <link name="ALWristBR1_Link">
    <inertial>
      <origin xyz="-0.0019151 0.02635 0.0010414" rpy="0.0 0.0 0.0"/>
      <mass value="0.024008"/>
      <inertia ixx="1.3690545308238603e-05" ixy="-1.148899999986299e-13" ixz="3.822099999976209e-14" iyy="1.0041345308238603e-05" iyz="3.8696e-07" izz="1.3621645308238606e-05"/>
    </inertial>
    <visual name="ALWristBR1_Link_Visual">
      <origin xyz="0.0 0.0 0.0" rpy="0.0 0.0 0.0"/>
      <geometry>
        <mesh filename="../meshes/ALWrist_BR1_Link.stl"/>
      </geometry>
      <material name="">
        <color rgba="0.89804 0.91765 0.92941 1.0"/>
      </material>
    </visual>
    <collision name="ALWristBR1_Link_Collision">
      <origin xyz="0.0 0.0 0.0" rpy="0.0 0.0 0.0"/>
      <geometry>
        <mesh filename="../meshes/ALWrist_BR1_Link_convexhull.stl" scale="1.0 1.0 1.0"/>
      </geometry>
    </collision>
  </link>
  <joint name="ALWristBR2" type="revolute">
    <origin xyz="0.0 0.0 0.0" rpy="0.0 0.0 0.0"/>
    <axis xyz="0.0 1.0 0.0"/>
    <parent link="ALWristBR0_Link"/>
    <child link="ALWristBR2_Link"/>
    <limit effort="400.0" lower="-1.57" upper="1.57" velocity="3.1415926"/>
  </joint>
  <link name="ALWristBR2_Link">
    <inertial>
      <origin xyz="-0.00285890746146323 2.16333476826813e-09 4.93604190743499e-05" rpy="0.0 0.0 0.0"/>
      <mass value="0.00373054475630146"/>
      <inertia ixx="1.000002209364975e-05" ixy="-1.3816128592343518e-13" ixz="1.2803063868888173e-09" iyy="1.0074212979026388e-05" iyz="-1.0109428273552697e-12" izz="1.0074192561095311e-05"/>
    </inertial>
    <visual name="ALWristBR2_Link_Visual">
      <origin xyz="0.0 0.0 0.0" rpy="0.0 0.0 0.0"/>
      <geometry>
        <mesh filename="../meshes/ALWrist_BR2_Link.stl"/>
      </geometry>
      <material name="">
        <color rgba="0.647058823529412 0.619607843137255 0.588235294117647 1.0"/>
      </material>
    </visual>
    <collision name="ALWristBR2_Link_Collision">
      <origin xyz="0.0 0.0 0.0" rpy="0.0 0.0 0.0"/>
      <geometry>
        <mesh filename="../meshes/ALWrist_BR2_Link_convexhull.stl" scale="1.0 1.0 1.0"/>
      </geometry>
    </collision>
  </link>
  <joint name="ALWristBR3" type="revolute">
    <origin xyz="0.0 0.0 0.0" rpy="0.0 -0.017255 0.0"/>
    <axis xyz="0.0 1.0 0.0"/>
    <parent link="ALWristBR4_Link"/>
    <child link="ALWristBR3_Link"/>
    <limit effort="400.0" lower="-1.57" upper="1.57" velocity="3.1415926"/>
  </joint>
  <link name="ALWristBR3_Link">
    <inertial>
      <origin xyz="2.38500712359466e-05 4.68942149695062e-08 0.0283017446065629" rpy="0.0 0.0 0.0"/>
      <mass value="0.0163436663117003"/>
      <inertia ixx="1.058843751107658e-05" ixy="3.883356249554021e-12" ixz="3.9714539909530543e-10" iyy="1.0442298557724912e-05" iyz="-9.93761778002401e-12" izz="1.0000000268262852e-05"/>
    </inertial>
    <visual name="ALWristBR3_Link_Visual">
      <origin xyz="0.0 0.0 0.0" rpy="0.0 0.0 0.0"/>
      <geometry>
        <mesh filename="../meshes/ALWrist_BR3_Link.stl"/>
      </geometry>
      <material name="">
        <color rgba="0.529411764705882 0.549019607843137 0.549019607843137 1.0"/>
      </material>
    </visual>
    <collision name="ALWristBR3_Link_Collision">
      <origin xyz="0.0 0.0 0.0" rpy="0.0 0.0 0.0"/>
      <geometry>
        <mesh filename="../meshes/ALWrist_BR3_Link_convexhull.stl" scale="1.0 1.0 1.0"/>
      </geometry>
    </collision>
  </link>
  <joint name="ALWristBR4" type="revolute">
    <origin xyz="-0.027 -0.03 0.0" rpy="-2.9998 0.0 -3.1416"/>
    <axis xyz="1.0 0.0 0.0"/>
    <parent link="ALWristYaw_Link"/>
    <child link="ALWristBR4_Link"/>
    <limit effort="400.0" lower="-1.57" upper="1.57" velocity="3.1415926"/>
  </joint>
  <link name="ALWristBR4_Link">
    <inertial>
      <origin xyz="-0.00221364330907749 -4.11274486689095e-12 8.10143618856785e-13" rpy="0.0 0.0 0.0"/>
      <mass value="0.0116530368127689"/>
      <inertia ixx="1e-05" ixy="-7.714431638365371e-20" ixz="-3.728723958847608e-19" iyy="1.027752247888592e-05" iyz="-9.04953782288128e-16" izz="1.018883097687764e-05"/>
    </inertial>
    <visual name="ALWristBR4_Link_Visual">
      <origin xyz="0.0 0.0 0.0" rpy="0.0 0.0 0.0"/>
      <geometry>
        <mesh filename="../meshes/ALWrist_BR4_Link.stl"/>
      </geometry>
      <material name="">
        <color rgba="0.647058823529412 0.619607843137255 0.588235294117647 1.0"/>
      </material>
    </visual>
    <collision name="ALWristBR4_Link_Collision">
      <origin xyz="0.0 0.0 0.0" rpy="0.0 0.0 0.0"/>
      <geometry>
        <mesh filename="../meshes/ALWrist_BR4_Link_convexhull.stl" scale="1.0 1.0 1.0"/>
      </geometry>
    </collision>
  </link>
  <joint name="ALWristBase" type="fixed">
    <origin xyz="0.0 0.0 -0.168" rpy="0.0 -1.5708 0.0"/>
    <parent link="ALWristRoot_Link"/>
    <child link="ALWristBase_Link"/>
  </joint>
  <link name="ALWristBase_Link">
    <inertial>
      <origin xyz="0.0541597343830008 -0.00428968359174776 -5.49036455757147e-05" rpy="0.0 0.0 0.0"/>
      <mass value="0.276021721766216"/>
      <inertia ixx="0.000481869493582971" ixy="1.89399978244833e-05" ixz="-1.94485149438737e-08" iyy="0.00129886088799315" iyz="-3.56911305392632e-07" izz="0.00129140889559124"/>
    </inertial>
    <visual name="ALWristBase_Link_Visual">
      <origin xyz="0.0 0.0 0.0" rpy="0.0 0.0 0.0"/>
      <geometry>
        <mesh filename="../meshes/ALWrist_Base_Link.stl"/>
      </geometry>
      <material name="">
        <color rgba="0.898039215686275 0.917647058823529 0.929411764705882 1.0"/>
      </material>
    </visual>
    <collision name="ALWristBase_Link_Collision">
      <origin xyz="0.0 0.0 0.0" rpy="0.0 0.0 0.0"/>
      <geometry>
        <mesh filename="../meshes/ALWrist_Base_Link_convexhull.stl" scale="1.0 1.0 1.0"/>
      </geometry>
    </collision>
  </link>
  <joint name="ALWristFT" type="fixed">
    <origin xyz="-1.2399e-05 0.0 0.042748" rpy="0.0 0.0 1.5708"/>
    <parent link="ALWristYaw_Link"/>
    <child link="ALWristFT_Link"/>
  </joint>
  <link name="ALWristFT_Link">
    <inertial>
      <origin xyz="-3.68488827482899e-05 -5.88316189521624e-05 -0.00791199218667672" rpy="0.0 0.0 0.0"/>
      <mass value="0.0919909344510386"/>
      <inertia ixx="1.39518131854906e-05" ixy="-3.05326757970196e-08" ixz="-1.47634493222953e-08" iyy="1.39070683493609e-05" iyz="-1.94813966896539e-08" izz="2.41202226678126e-05"/>
    </inertial>
    <visual name="ALWristFT_Link_Visual">
      <origin xyz="0.0 0.0 0.0" rpy="0.0 0.0 0.0"/>
      <geometry>
        <mesh filename="../meshes/ALWristFT_Link.stl"/>
      </geometry>
      <material name="">
        <color rgba="0.698039215686274 0.698039215686274 0.698039215686274 1.0"/>
      </material>
    </visual>
    <collision name="ALWristFT_Link_Collision">
      <origin xyz="0.0 0.0 0.0" rpy="0.0 0.0 0.0"/>
      <geometry>
        <mesh filename="../meshes/ALWristFT_Link_convexhull.stl" scale="1.0 1.0 1.0"/>
      </geometry>
    </collision>
  </link>
  <joint name="ALWristPitch" type="revolute">
    <origin xyz="0.0 0.0 0.0" rpy="0.0 0.0 0.0"/>
    <axis xyz="1.0 0.0 0.0"/>
    <parent link="ALWristRoot_Link"/>
    <child link="ALWristPitch_Link"/>
    <limit effort="400.0" lower="-0.741" upper="1.75" velocity="3.1415926"/>
  </joint>
  <link name="ALWristPitch_Link">
    <inertial>
      <origin xyz="7.46248686255566e-19 -1.12543960307545e-16 -1.73472347597681e-18" rpy="0.0 0.0 0.0"/>
      <mass value="0.0303458029555441"/>
      <inertia ixx="1.0000000011242503e-05" ixy="-1.991593733750814e-21" ixz="1.3686128944734017e-10" iyy="1.0143779057796202e-05" iyz="1.3756897885334319e-10" izz="1.1666089364158581e-05"/>
    </inertial>
    <visual name="ALWristPitch_Link_Visual">
      <origin xyz="0.0 0.0 0.0" rpy="0.0 0.0 0.0"/>
      <geometry>
        <mesh filename="../meshes/ALWristPitch_Link.stl"/>
      </geometry>
      <material name="">
        <color rgba="0.647058823529412 0.619607843137255 0.588235294117647 1.0"/>
      </material>
    </visual>
    <collision name="ALWristPitch_Link_Collision">
      <origin xyz="0.0 0.0 0.0" rpy="0.0 0.0 0.0"/>
      <geometry>
        <mesh filename="../meshes/ALWristPitch_Link_convexhull.stl" scale="1.0 1.0 1.0"/>
      </geometry>
    </collision>
  </link>
  <joint name="ALWristRoll" type="revolute">
    <origin xyz="0.0 0.0 0.122" rpy="3.1416 -1.5708 0.0"/>
    <axis xyz="1.0 0.0 0.0"/>
    <parent link="ALElbow_Link"/>
    <child link="ALWristRoll_Link"/>
    <limit effort="400.0" lower="-3.141" upper="3.141" velocity="3.1415926"/>
  </joint>
  <link name="ALWristRoll_Link">
    <inertial>
      <origin xyz="-1.6653e-16 -1.9082e-17 -1.3878e-17" rpy="0.0 0.0 0.0"/>
      <mass value="2e-05"/>
      <inertia ixx="2.0000000000000005e-05" ixy="3.3881317890172014e-21" ixz="0.0" iyy="2.0000000000000005e-05" iyz="0.0" izz="2.0000000000000005e-05"/>
    </inertial>
  </link>
  <joint name="ALWristRoot" type="fixed">
    <origin xyz="0.173 0.0 0.0" rpy="3.141593 -1.5707 0.0"/>
    <parent link="ALWristRoll_Link"/>
    <child link="ALWristRoot_Link"/>
  </joint>
  <link name="ALWristRoot_Link">
    <inertial>
      <origin xyz="-0.00087527 0.015651 -0.10982" rpy="0.0 0.0 0.0"/>
      <mass value="0.12307"/>
      <inertia ixx="1.6915e-05" ixy="-1.069e-08" ixz="-1.5838e-08" iyy="2.9632e-05" iyz="5.8916e-07" izz="1.3864e-05"/>
    </inertial>
    <visual name="ALWristRoot_Link_Visual">
      <origin xyz="0.0 0.0 0.0" rpy="0.0 0.0 0.0"/>
      <geometry>
        <mesh filename="../meshes/ALWrist_Root_Link.stl"/>
      </geometry>
      <material name="">
        <color rgba="0.64706 0.61961 0.58824 1.0"/>
      </material>
    </visual>
    <collision name="ALWristRoot_Link_Collision">
      <origin xyz="0.0 0.0 0.0" rpy="0.0 0.0 0.0"/>
      <geometry>
        <mesh filename="../meshes/ALWrist_Root_Link_convexhull.stl" scale="1.0 1.0 1.0"/>
      </geometry>
    </collision>
  </link>
  <joint name="ALWristYaw" type="revolute">
    <origin xyz="0.0 0.0 0.0" rpy="0.0 0.0 0.0"/>
    <axis xyz="0.0 1.0 0.0"/>
    <parent link="ALWristPitch_Link"/>
    <child link="ALWristYaw_Link"/>
    <limit effort="400.0" lower="-0.558" upper="0.593" velocity="3.1415926"/>
  </joint>
  <link name="ALWristYaw_Link">
    <inertial>
      <origin xyz="-5.96363888886987e-05 -0.0112217565403197 0.0117774710310118" rpy="0.0 0.0 0.0"/>
      <mass value="0.0440266507004541"/>
      <inertia ixx="1.452337454289961e-05" ixy="3.52232240231331e-09" ixz="1.8324292440025615e-08" iyy="1.0332756954026827e-05" iyz="-1.4768212974215518e-06" izz="1.655459170101281e-05"/>
    </inertial>
    <visual name="ALWristYaw_Link_Visual">
      <origin xyz="0.0 0.0 0.0" rpy="0.0 0.0 0.0"/>
      <geometry>
        <mesh filename="../meshes/ALWristYaw_Link.stl"/>
      </geometry>
      <material name="">
        <color rgba="0.898039215686275 0.917647058823529 0.929411764705882 1.0"/>
      </material>
    </visual>
    <collision name="ALWristYaw_Link_Collision">
      <origin xyz="0.0 0.0 0.0" rpy="0.0 0.0 0.0"/>
      <geometry>
        <mesh filename="../meshes/ALWristYaw_Link_convexhull.stl" scale="1.0 1.0 1.0"/>
      </geometry>
    </collision>
  </link>
  <joint name="ARBase" type="fixed">
    <origin xyz="0.29809 -0.12609 0.025162" rpy="-1.508093 0.25436 -1.3265"/>
    <parent link="Connector_Body/Torso_Link"/>
    <child link="ARBase_Link"/>
  </joint>
  <link name="ARBase_Link">
    <inertial>
      <origin xyz="0.00799 1e-06 0.000196" rpy="0.0 0.0 0.0"/>
      <mass value="1.194300000000001"/>
      <inertia ixx="0.00089755" ixy="-1.4484e-08" ixz="-2.6127e-07" iyy="0.00057565" iyz="7.8027e-07" izz="0.00056347"/>
    </inertial>
    <visual name="ARBase_Link_Visual">
      <origin xyz="0.0 0.0 0.0" rpy="3.141593 0.0 0.0"/>
      <geometry>
        <mesh filename="../meshes/ARBase_Link.stl" scale="1.0 1.0 1.0"/>
      </geometry>
      <material name="">
        <color rgba="0.75294 0.75294 0.75294 1.0"/>
      </material>
    </visual>
    <collision name="ARBase_Link_Collision">
      <origin xyz="0.0 0.0 0.0" rpy="0.0 0.0 0.0"/>
      <geometry>
        <mesh filename="../meshes/ARBase_Link_convexhull.stl" scale="1.0 1.0 1.0"/>
      </geometry>
    </collision>
  </link>
  <joint name="ARElbow" type="revolute">
    <origin xyz="0.0 0.001 -0.3511" rpy="-3.141592 0.0 -3.141592"/>
    <axis xyz="1.0 0.0 0.0"/>
    <parent link="ARShoulder3_Link"/>
    <child link="ARElbow_Link"/>
    <limit effort="400.0" lower="-1.832" upper="0.0" velocity="3.1415926"/>
  </joint>
  <joint name="ARElbowAct" type="prismatic">
    <origin xyz="0.0 0.0 0.29542" rpy="0.0 0.0 -3.141592"/>
    <axis xyz="0.0 0.0 1.0"/>
    <parent link="ARElbowB11_Link"/>
    <child link="ARElbowAct_Link"/>
    <limit effort="400.0" lower="-1.57" upper="1.57" velocity="3.1415926"/>
  </joint>
  <link name="ARElbowAct_Link">
    <inertial>
      <origin xyz="-6e-06 0.0 -0.085859" rpy="0.0 0.0 0.0"/>
      <mass value="0.05465199999999999"/>
      <inertia ixx="0.00010606969013566325" ixy="-3.794811884488628e-13" ixz="3.6268360281805788e-09" iyy="0.0001059746901362923" iyz="4.232588795943544e-14" izz="1.0000000136920807e-05"/>
    </inertial>
    <visual name="ARElbowAct_Link_Visual">
      <origin xyz="0.0 0.0 0.0" rpy="0.0 0.0 3.141593"/>
      <geometry>
        <mesh filename="../meshes/ARElbow_Act_Link.stl" scale="1.0 1.0 1.0"/>
      </geometry>
      <material name="">
        <color rgba="0.75294 0.75294 0.75294 1.0"/>
      </material>
    </visual>
    <collision name="ARElbowAct_Link_Collision">
      <origin xyz="0.0 0.0 0.0" rpy="0.0 0.0 0.0"/>
      <geometry>
        <mesh filename="../meshes/ARElbow_Act_Link_convexhull.stl" scale="1.0 1.0 1.0"/>
      </geometry>
    </collision>
  </link>
  <joint name="ARElbowB11" type="revolute">
    <origin xyz="0.0 -0.029 -0.1391" rpy="2.888403 0.0 -3.141592"/>
    <axis xyz="1.0 0.0 0.0"/>
    <parent link="ARShoulder3_Link"/>
    <child link="ARElbowB11_Link"/>
    <limit effort="400.0" lower="-1.57" upper="1.57" velocity="3.1415926"/>
  </joint>
  <link name="ARElbowB11_Link">
    <inertial>
      <origin xyz="-2.6e-05 1.9e-05 0.10704" rpy="0.0 0.0 0.0"/>
      <mass value="0.32695999999999986"/>
      <inertia ixx="0.00011101999998112811" ixy="1.0984488097443103e-08" ixz="6.629144855259e-08" iyy="0.00011251000000736784" iyz="1.406700231845442e-07" izz="7.073300001150397e-05"/>
    </inertial>
    <visual name="ARElbowB11_Link_Visual">
      <origin xyz="0.0 0.0 0.0" rpy="0.0 0.0 0.0"/>
      <geometry>
        <mesh filename="../meshes/ARElbow_B11_Link.stl" scale="1.0 1.0 1.0"/>
      </geometry>
      <material name="">
        <color rgba="0.75294 0.75294 0.75294 1.0"/>
      </material>
    </visual>
    <collision name="ARElbowB11_Link_Collision">
      <origin xyz="0.0 0.0 0.0" rpy="0.0 0.0 0.0"/>
      <geometry>
        <mesh filename="../meshes/ARElbow_B11_Link_convexhull.stl" scale="1.0 1.0 1.0"/>
      </geometry>
    </collision>
  </link>
  <link name="ARElbow_Link">
    <inertial>
      <origin xyz="7e-05 0.001127 0.080286" rpy="0.0 0.0 0.0"/>
      <mass value="0.6357799999999997"/>
      <inertia ixx="0.0005099900001544764" ixy="-2.2297207206594354e-07" ixz="-4.0468474586715554e-07" iyy="0.0005163300270204655" iyz="-4.423298448630883e-05" izz="0.00046536997282505774"/>
    </inertial>
    <visual name="ARElbow_Link_Visual">
      <origin xyz="0.0 -0.0 0.0" rpy="0.0 0.0 3.141593"/>
      <geometry>
        <mesh filename="../meshes/ARElbow_Link.stl" scale="1.0 1.0 1.0"/>
      </geometry>
      <material name="">
        <color rgba="0.75294 0.75294 0.75294 1.0"/>
      </material>
    </visual>
    <collision name="ARElbow_Link_Collision">
      <origin xyz="0.0 0.0 0.0" rpy="0.0 0.0 0.0"/>
      <geometry>
        <mesh filename="../meshes/ARElbow_Link_convexhull.stl" scale="1.0 1.0 1.0"/>
      </geometry>
    </collision>
  </link>
  <joint name="ARShoulder1" type="revolute">
    <origin xyz="0.1076 0.0 0.0" rpy="-3.141585 0.0 3.141593"/>
    <axis xyz="1.0 0.0 0.0"/>
    <parent link="ARBase_Link"/>
    <child link="ARShoulder1_Link"/>
    <limit effort="400.0" lower="-3.141" upper="3.141" velocity="3.1415926"/>
  </joint>
  <link name="ARShoulder1_Link">
    <inertial>
      <origin xyz="0.009157 0.003646 -0.000169" rpy="0.0 0.0 0.0"/>
      <mass value="1.6019999999999996"/>
      <inertia ixx="0.0012116999440866811" ixy="8.070387961256474e-05" ixz="3.5280257083975037e-06" iyy="0.001556100057542011" iyz="-2.650928692723903e-06" izz="0.0010023999983713062"/>
    </inertial>
    <visual name="ARShoulder1_Link_Visual">
      <origin xyz="0.0 0.0 0.0" rpy="0.0 0.0 3.141593"/>
      <geometry>
        <mesh filename="../meshes/ARShoulder1_Link.stl" scale="1.0 1.0 1.0"/>
      </geometry>
      <material name="">
        <color rgba="0.75294 0.75294 0.75294 1.0"/>
      </material>
    </visual>
    <collision name="ARShoulder1_Link_Collision">
      <origin xyz="0.0 0.0 0.0" rpy="0.0 0.0 0.0"/>
      <geometry>
        <mesh filename="../meshes/ARShoulder1_Link_convexhull.stl" scale="1.0 1.0 1.0"/>
      </geometry>
    </collision>
  </link>
  <joint name="ARShoulder2" type="revolute">
    <origin xyz="0.0 0.0 0.0" rpy="0.0 0.0 -3.141592"/>
    <axis xyz="0.0 1.0 0.0"/>
    <parent link="ARShoulder1_Link"/>
    <child link="ARShoulder2_Link"/>
    <limit effort="400.0" lower="-0.253" upper="1.85" velocity="3.1415926"/>
  </joint>
  <link name="ARShoulder2_Link">
    <inertial>
      <origin xyz="0.010763 -0.020477 0.0278" rpy="0.0 0.0 0.0"/>
      <mass value="0.5084917431461261"/>
      <inertia ixx="0.0010464999259024192" ixy="-0.00012061005396444852" ixz="5.485487847357631e-05" iyy="0.0009256802430528081" iyz="-0.0002750100517516733" izz="0.0010392998310447714"/>
    </inertial>
    <visual name="ARShoulder2_Link_Visual">
      <origin xyz="0.0 0.0 0.0" rpy="0.0 0.0 0.0"/>
      <geometry>
        <mesh filename="../meshes/ARShoulder2_Link.stl" scale="1.0 1.0 1.0"/>
      </geometry>
      <material name="">
        <color rgba="0.75294 0.75294 0.75294 1.0"/>
      </material>
    </visual>
    <collision name="ARShoulder2_Link_Collision">
      <origin xyz="0.0 0.0 0.0" rpy="0.0 0.0 0.0"/>
      <geometry>
        <mesh filename="../meshes/ARShoulder2_Link_convexhull.stl" scale="1.0 1.0 1.0"/>
      </geometry>
    </collision>
  </link>
  <joint name="ARShoulder3" type="revolute">
    <origin xyz="0.0 0.0 0.0" rpy="-3.141593 1e-06 -1.5707"/>
    <axis xyz="0.0 0.0 1.0"/>
    <parent link="ARShoulder2_Link"/>
    <child link="ARShoulder3_Link"/>
    <limit effort="400.0" lower="-3.141" upper="3.141" velocity="3.1415926"/>
  </joint>
  <link name="ARShoulder3_Link">
    <inertial>
      <origin xyz="-3.3e-05 0.003369 -0.14648" rpy="0.0 0.0 0.0"/>
      <mass value="0.8525751706215601"/>
      <inertia ixx="0.0028013000003190894" ixy="5.193714519100651e-07" ixz="7.258930202151745e-07" iyy="0.002740099961802801" iyz="-5.467267704269619e-05" izz="0.000786290037878108"/>
    </inertial>
    <visual name="ARShoulder3_Link_Visual">
      <origin xyz="0.0 0.0 0.0" rpy="3.141593 0.0 0.0"/>
      <geometry>
        <mesh filename="../meshes/ARShoulder3_Link.stl" scale="1.0 1.0 1.0"/>
      </geometry>
      <material name="">
        <color rgba="0.75294 0.75294 0.75294 1.0"/>
      </material>
    </visual>
    <collision name="ARShoulder3_Link_Collision">
      <origin xyz="0.0 0.0 0.0" rpy="0.0 0.0 0.0"/>
      <geometry>
        <mesh filename="../meshes/ARShoulder3_Link_convexhull.stl" scale="1.0 1.0 1.0"/>
      </geometry>
    </collision>
  </link>
  <joint name="ARWristAL1" type="revolute">
    <origin xyz="0.0155 -0.034 0.178" rpy="-1.553093 0.0 3.141592"/>
    <axis xyz="1.0 0.0 0.0"/>
    <parent link="ARWristRoot_Link"/>
    <child link="ARWristAL1_Link"/>
    <limit effort="400.0" lower="-1.57" upper="1.57" velocity="3.1415926"/>
  </joint>
  <link name="ARWristAL1_Link">
    <inertial>
      <origin xyz="-5e-06 0.060513 8.2e-05" rpy="0.0 0.0 0.0"/>
      <mass value="0.11027956817212799"/>
      <inertia ixx="1.42606022882383e-05" ixy="1.1834937974475046e-10" ixz="1.555953533081748e-09" iyy="1.0001497220687136e-05" iyz="-8.070848165972657e-08" izz="1.4350648636972524e-05"/>
    </inertial>
    <visual name="ARWristAL1_Link_Visual">
      <origin xyz="0.0 0.0 0.0" rpy="-3.141593 0.0 -3.141593"/>
      <geometry>
        <mesh filename="../meshes/ARWrist_AL1_Link.stl" scale="1.0 1.0 1.0"/>
      </geometry>
      <material name="">
        <color rgba="0.898039215686275 0.917647058823529 0.929411764705882 1.0"/>
      </material>
    </visual>
    <collision name="ARWristAL1_Link_Collision">
      <origin xyz="0.0 0.0 0.0" rpy="0.0 0.0 0.0"/>
      <geometry>
        <mesh filename="../meshes/ARWrist_AL1_Link_convexhull.stl" scale="1.0 1.0 1.0"/>
      </geometry>
    </collision>
  </link>
  <joint name="ARWristAR1" type="revolute">
    <origin xyz="-0.0155 -0.034 0.178" rpy="-1.553093 0.0 3.141592"/>
    <axis xyz="1.0 0.0 0.0"/>
    <parent link="ARWristRoot_Link"/>
    <child link="ARWristAR1_Link"/>
    <limit effort="400.0" lower="-1.57" upper="1.57" velocity="3.1415926"/>
  </joint>
  <link name="ARWristAR1_Link">
    <inertial>
      <origin xyz="-0.0 0.058479 9.4e-05" rpy="0.0 0.0 0.0"/>
      <mass value="0.10112999999999997"/>
      <inertia ixx="1.4212213742458261e-05" ixy="1.1891377579045092e-10" ixz="1.482689765519501e-10" iyy="1.0001513742563879e-05" iyz="-8.07089999579205e-08" izz="1.4303213742665143e-05"/>
    </inertial>
    <visual name="ARWristAR1_Link_Visual">
      <origin xyz="0.0 0.0 0.0" rpy="-3.141593 0.0 -3.141593"/>
      <geometry>
        <mesh filename="../meshes/ARWrist_AR1_Link.stl" scale="1.0 1.0 1.0"/>
      </geometry>
      <material name="">
        <color rgba="0.89804 0.91765 0.92941 1.0"/>
      </material>
    </visual>
    <collision name="ARWristAR1_Link_Collision">
      <origin xyz="0.0 0.0 0.0" rpy="0.0 0.0 0.0"/>
      <geometry>
        <mesh filename="../meshes/ARWrist_AR1_Link_convexhull.stl" scale="1.0 1.0 1.0"/>
      </geometry>
    </collision>
  </link>
  <joint name="ARWristActL" type="prismatic">
    <origin xyz="0.0 0.13346 0.0" rpy="1.5708 0.0 -3.141593"/>
    <axis xyz="0.0 0.0 1.0"/>
    <parent link="ARWristAL1_Link"/>
    <child link="ARWristActL_Link"/>
    <limit effort="400.0" lower="-1.57" upper="1.57" velocity="3.1415926"/>
  </joint>
  <link name="ARWristActL_Link">
    <inertial>
      <origin xyz="0.0 0.0 -0.049176" rpy="0.0 0.0 0.0"/>
      <mass value="0.022414999999999987"/>
      <inertia ixx="2.2515569999998444e-05" ixy="-5.7141160926537444e-15" ixz="4.4123355091187445e-12" iyy="2.2496570000000005e-05" iyz="-2.923012745974418e-15" izz="1.0000000000001556e-05"/>
    </inertial>
    <visual name="ARWristActL_Link_Visual">
      <origin xyz="0.0 0.0 0.0" rpy="0.0 0.0 -3.141593"/>
      <geometry>
        <mesh filename="../meshes/ARWrist_ActL_Link.stl" scale="1.0 1.0 1.0"/>
      </geometry>
      <material name="">
        <color rgba="0.77647 0.75686 0.73725 1.0"/>
      </material>
    </visual>
    <collision name="ARWristActL_Link_Collision">
      <origin xyz="0.0 0.0 0.0" rpy="0.0 0.0 0.0"/>
      <geometry>
        <mesh filename="../meshes/ARWrist_ActL_Link_convexhull.stl" scale="1.0 1.0 1.0"/>
      </geometry>
    </collision>
  </link>
  <joint name="ARWristActR" type="prismatic">
    <origin xyz="0.0 0.13346 0.0" rpy="1.5708 0.0 -3.141593"/>
    <axis xyz="0.0 0.0 1.0"/>
    <parent link="ARWristAR1_Link"/>
    <child link="ARWristActR_Link"/>
    <limit effort="400.0" lower="-1.57" upper="1.57" velocity="3.1415926"/>
  </joint>
  <link name="ARWristActR_Link">
    <inertial>
      <origin xyz="0.0 0.0 -0.049176" rpy="0.0 0.0 0.0"/>
      <mass value="0.022415478206029786"/>
      <inertia ixx="2.2515773917037203e-05" ixy="-5.823052830156676e-15" ixz="4.412407393697763e-12" iyy="2.2496459399899276e-05" iyz="-2.923111850980787e-15" izz="1.0000000000001556e-05"/>
    </inertial>
    <visual name="ARWristActR_Link_Visual">
      <origin xyz="0.0 0.0 0.0" rpy="0.0 0.0 -3.141593"/>
      <geometry>
        <mesh filename="../meshes/ARWrist_ActR_Link.stl" scale="1.0 1.0 1.0"/>
      </geometry>
      <material name="">
        <color rgba="0.776470588235294 0.756862745098039 0.737254901960784 1.0"/>
      </material>
    </visual>
    <collision name="ARWristActR_Link_Collision">
      <origin xyz="0.0 0.0 0.0" rpy="0.0 0.0 0.0"/>
      <geometry>
        <mesh filename="../meshes/ARWrist_ActR_Link_convexhull.stl" scale="1.0 1.0 1.0"/>
      </geometry>
    </collision>
  </link>
  <joint name="ARWristBL0" type="revolute">
    <origin xyz="0.0 0.0 0.045018" rpy="0.0 0.0 3.141592"/>
    <axis xyz="1.0 0.0 0.0"/>
    <parent link="ARWristBL3_Link"/>
    <child link="ARWristBL0_Link"/>
    <limit effort="400.0" lower="-1.57" upper="1.57" velocity="3.1415926"/>
  </joint>
  <link name="ARWristBL0_Link">
    <inertial>
      <origin xyz="0.0 0.0 0.0" rpy="0.0 0.0 0.0"/>
      <mass value="1e-05"/>
      <inertia ixx="1e-05" ixy="0.0" ixz="0.0" iyy="1e-05" iyz="0.0" izz="1e-05"/>
    </inertial>
  </link>
  <joint name="ARWristBL1" type="revolute">
    <origin xyz="0.0155 0.011 0.032" rpy="0.259193 0.0 3.141592"/>
    <axis xyz="1.0 0.0 0.0"/>
    <parent link="ARWristRoot_Link"/>
    <child link="ARWristBL1_Link"/>
    <limit effort="400.0" lower="-1.57" upper="1.57" velocity="3.1415926"/>
  </joint>
  <link name="ARWristBL1_Link">
    <inertial>
      <origin xyz="-0.001915 0.02635 0.001041" rpy="0.0 0.0 0.0"/>
      <mass value="0.024008000000000012"/>
      <inertia ixx="1.3690309326297567e-05" ixy="1.5146961171299974e-12" ixz="-5.440676590840389e-14" iyy="1.0041289326298746e-05" iyz="3.866799999999256e-07" izz="1.3621309326298153e-05"/>
    </inertial>
    <visual name="ARWristBL1_Link_Visual">
      <origin xyz="0.0 0.0 0.0" rpy="0.0 0.0 0.0"/>
      <geometry>
        <mesh filename="../meshes/ARWrist_BL1_Link.stl" scale="1.0 1.0 1.0"/>
      </geometry>
      <material name="">
        <color rgba="0.89804 0.91765 0.92941 1.0"/>
      </material>
    </visual>
    <collision name="ARWristBL1_Link_Collision">
      <origin xyz="0.0 0.0 0.0" rpy="0.0 0.0 0.0"/>
      <geometry>
        <mesh filename="../meshes/ARWrist_BL1_Link_convexhull.stl" scale="1.0 1.0 1.0"/>
      </geometry>
    </collision>
  </link>
  <joint name="ARWristBL2" type="revolute">
    <origin xyz="0.0 0.0 0.0" rpy="0.0 0.0 -3.141592"/>
    <axis xyz="0.0 1.0 0.0"/>
    <parent link="ARWristBL0_Link"/>
    <child link="ARWristBL2_Link"/>
    <limit effort="400.0" lower="-1.57" upper="1.57" velocity="3.1415926"/>
  </joint>
  <link name="ARWristBL2_Link">
    <inertial>
      <origin xyz="-0.002859 0.0 4.9e-05" rpy="0.0 0.0 0.0"/>
      <mass value="0.003730583331722572"/>
      <inertia ixx="1.0000022086181487e-05" ixy="2.3475959017441574e-13" ixz="1.2800625228418757e-09" iyy="1.007421474746067e-05" iyz="3.1032040435995356e-13" izz="1.00741893801741e-05"/>
    </inertial>
    <visual name="ARWristBL2_Link_Visual">
      <origin xyz="0.0 0.0 0.0" rpy="0.0 0.0 -3.141593"/>
      <geometry>
        <mesh filename="../meshes/ARWrist_BL2_Link.stl" scale="1.0 1.0 1.0"/>
      </geometry>
      <material name="">
        <color rgba="0.647058823529412 0.619607843137255 0.588235294117647 1.0"/>
      </material>
    </visual>
    <collision name="ARWristBL2_Link_Collision">
      <origin xyz="0.0 0.0 0.0" rpy="0.0 0.0 0.0"/>
      <geometry>
        <mesh filename="../meshes/ARWrist_BL2_Link_convexhull.stl" scale="1.0 1.0 1.0"/>
      </geometry>
    </collision>
  </link>
  <joint name="ARWristBL3" type="revolute">
    <origin xyz="0.0 0.0 0.0" rpy="0.0 -0.017255 -3.141592"/>
    <axis xyz="0.0 1.0 0.0"/>
    <parent link="ARWristBL4_Link"/>
    <child link="ARWristBL3_Link"/>
    <limit effort="400.0" lower="-1.57" upper="1.57" velocity="3.1415926"/>
  </joint>
  <link name="ARWristBL3_Link">
    <inertial>
      <origin xyz="2.4e-05 0.0 0.028302" rpy="0.0 0.0 0.0"/>
      <mass value="0.016343668811119795"/>
      <inertia ixx="1.0588437589345121e-05" ixy="-2.694579659860282e-12" ixz="3.9717064992779286e-10" iyy="1.04422980274748e-05" iyz="1.0476070445409481e-11" izz="1.0000000268321719e-05"/>
    </inertial>
    <visual name="ARWristBL3_Link_Visual">
      <origin xyz="0.0 0.0 0.0" rpy="0.0 0.0 -3.141593"/>
      <geometry>
        <mesh filename="../meshes/ARWrist_BL3_Link.stl" scale="1.0 1.0 1.0"/>
      </geometry>
      <material name="">
        <color rgba="0.898039215686275 0.917647058823529 0.929411764705882 1.0"/>
      </material>
    </visual>
    <collision name="ARWristBL3_Link_Collision">
      <origin xyz="0.0 0.0 0.0" rpy="0.0 0.0 0.0"/>
      <geometry>
        <mesh filename="../meshes/ARWrist_BL3_Link_convexhull.stl" scale="1.0 1.0 1.0"/>
      </geometry>
    </collision>
  </link>
  <joint name="ARWristBL4" type="revolute">
    <origin xyz="0.027 -0.03 0.0" rpy="-0.141793 0.0 3.141592"/>
    <axis xyz="1.0 0.0 0.0"/>
    <parent link="ARWristYaw_Link"/>
    <child link="ARWristBL4_Link"/>
    <limit effort="400.0" lower="-1.57" upper="1.57" velocity="3.1415926"/>
  </joint>
  <link name="ARWristBL4_Link">
    <inertial>
      <origin xyz="0.002214 0.0 0.0" rpy="0.0 0.0 0.0"/>
      <mass value="0.0116530368127355"/>
      <inertia ixx="1.0000000000000031e-05" ixy="-9.517183235429624e-14" ixz="-9.24437170482028e-15" iyy="1.02775224788874e-05" iyz="-9.076970388458057e-16" izz="1.0188830976875944e-05"/>
    </inertial>
    <visual name="ARWristBL4_Link_Visual">
      <origin xyz="0.0 0.0 0.0" rpy="0.0 0.0 0.0"/>
      <geometry>
        <mesh filename="../meshes/ARWrist_BL4_Link.stl" scale="1.0 1.0 1.0"/>
      </geometry>
      <material name="">
        <color rgba="0.776470588235294 0.756862745098039 0.737254901960784 1.0"/>
      </material>
    </visual>
    <collision name="ARWristBL4_Link_Collision">
      <origin xyz="0.0 0.0 0.0" rpy="0.0 0.0 0.0"/>
      <geometry>
        <mesh filename="../meshes/ARWrist_BL4_Link_convexhull.stl" scale="1.0 1.0 1.0"/>
      </geometry>
    </collision>
  </link>
  <joint name="ARWristBR0" type="revolute">
    <origin xyz="0.0 0.0 0.045018" rpy="0.0 0.0 3.141592"/>
    <axis xyz="1.0 0.0 0.0"/>
    <parent link="ARWristBR3_Link"/>
    <child link="ARWristBR0_Link"/>
    <limit effort="400.0" lower="-1.57" upper="1.57" velocity="3.1415926"/>
  </joint>
  <link name="ARWristBR0_Link">
    <inertial>
      <origin xyz="0.0 0.0 0.0" rpy="0.0 0.0 0.0"/>
      <mass value="1e-05"/>
      <inertia ixx="1e-05" ixy="0.0" ixz="0.0" iyy="1e-05" iyz="0.0" izz="1e-05"/>
    </inertial>
  </link>
  <joint name="ARWristBR1" type="revolute">
    <origin xyz="-0.0155 0.011 0.032" rpy="0.259193 0.0 3.141592"/>
    <axis xyz="1.0 0.0 0.0"/>
    <parent link="ARWristRoot_Link"/>
    <child link="ARWristBR1_Link"/>
    <limit effort="400.0" lower="-1.57" upper="1.57" velocity="3.1415926"/>
  </joint>
  <link name="ARWristBR1_Link">
    <inertial>
      <origin xyz="0.001915 0.02635 0.001041" rpy="0.0 0.0 0.0"/>
      <mass value="0.024008000000000012"/>
      <inertia ixx="1.3690545308238087e-05" ixy="1.3711412479914173e-12" ixz="-1.7390764236681272e-13" iyy="1.0041345308239099e-05" iyz="3.869599999998984e-07" izz="1.362164530823862e-05"/>
    </inertial>
    <visual name="ARWristBR1_Link_Visual">
      <origin xyz="0.0 0.0 0.0" rpy="0.0 0.0 0.0"/>
      <geometry>
        <mesh filename="../meshes/ARWrist_BR1_Link.stl" scale="1.0 1.0 1.0"/>
      </geometry>
      <material name="">
        <color rgba="0.89804 0.91765 0.92941 1.0"/>
      </material>
    </visual>
    <collision name="ARWristBR1_Link_Collision">
      <origin xyz="0.0 0.0 0.0" rpy="0.0 0.0 0.0"/>
      <geometry>
        <mesh filename="../meshes/ARWrist_BR1_Link_convexhull.stl" scale="1.0 1.0 1.0"/>
      </geometry>
    </collision>
  </link>
  <joint name="ARWristBR2" type="revolute">
    <origin xyz="0.0 0.0 0.0" rpy="0.0 0.0 -3.141592"/>
    <axis xyz="0.0 1.0 0.0"/>
    <parent link="ARWristBR0_Link"/>
    <child link="ARWristBR2_Link"/>
    <limit effort="400.0" lower="-1.57" upper="1.57" velocity="3.1415926"/>
  </joint>
  <link name="ARWristBR2_Link">
    <inertial>
      <origin xyz="-0.002859 0.0 4.9e-05" rpy="0.0 0.0 0.0"/>
      <mass value="0.0037305447563014613"/>
      <inertia ixx="1.0000022093775196e-05" ixy="1.6121261596524313e-13" ixz="1.280310018142885e-09" iyy="1.0074212979026307e-05" iyz="1.0105450335781848e-12" izz="1.0074192560969954e-05"/>
    </inertial>
    <visual name="ARWristBR2_Link_Visual">
      <origin xyz="0.0 0.0 0.0" rpy="0.0 0.0 3.141593"/>
      <geometry>
        <mesh filename="../meshes/ARWrist_BR2_Link.stl" scale="1.0 1.0 1.0"/>
      </geometry>
      <material name="">
        <color rgba="0.647058823529412 0.619607843137255 0.588235294117647 1.0"/>
      </material>
    </visual>
    <collision name="ARWristBR2_Link_Collision">
      <origin xyz="0.0 0.0 0.0" rpy="0.0 0.0 0.0"/>
      <geometry>
        <mesh filename="../meshes/ARWrist_BR2_Link_convexhull.stl" scale="1.0 1.0 1.0"/>
      </geometry>
    </collision>
  </link>
  <joint name="ARWristBR3" type="revolute">
    <origin xyz="0.0 0.0 0.0" rpy="0.0 -0.017255 -3.141592"/>
    <axis xyz="0.0 1.0 0.0"/>
    <parent link="ARWristBR4_Link"/>
    <child link="ARWristBR3_Link"/>
    <limit effort="400.0" lower="-1.57" upper="1.57" velocity="3.1415926"/>
  </joint>
  <link name="ARWristBR3_Link">
    <inertial>
      <origin xyz="2.4e-05 0.0 0.028302" rpy="0.0 0.0 0.0"/>
      <mass value="0.016343666311700304"/>
      <inertia ixx="1.0588437511113046e-05" ixy="-3.928745829304398e-12" ixz="3.9711659584647646e-10" iyy="1.0442298557727444e-05" iyz="9.935123851420574e-12" izz="1.0000000268223861e-05"/>
    </inertial>
    <visual name="ARWristBR3_Link_Visual">
      <origin xyz="0.0 0.0 0.0" rpy="0.0 0.0 3.141593"/>
      <geometry>
        <mesh filename="../meshes/ARWrist_BR3_Link.stl" scale="1.0 1.0 1.0"/>
      </geometry>
      <material name="">
        <color rgba="0.529411764705882 0.549019607843137 0.549019607843137 1.0"/>
      </material>
    </visual>
    <collision name="ARWristBR3_Link_Collision">
      <origin xyz="0.0 0.0 0.0" rpy="0.0 0.0 0.0"/>
      <geometry>
        <mesh filename="../meshes/ARWrist_BR3_Link_convexhull.stl" scale="1.0 1.0 1.0"/>
      </geometry>
    </collision>
  </link>
  <joint name="ARWristBR4" type="revolute">
    <origin xyz="-0.027 -0.03 0.0" rpy="0.141793 0.0 -8e-06"/>
    <axis xyz="1.0 0.0 0.0"/>
    <parent link="ARWristYaw_Link"/>
    <child link="ARWristBR4_Link"/>
    <limit effort="400.0" lower="-1.57" upper="1.57" velocity="3.1415926"/>
  </joint>
  <link name="ARWristBR4_Link">
    <inertial>
      <origin xyz="0.002214 0.0 0.0" rpy="0.0 0.0 0.0"/>
      <mass value="0.011653036812768903"/>
      <inertia ixx="1.0000000000000031e-05" ixy="-9.5171739403622e-14" ixz="9.244404617709602e-15" iyy="1.0277522478885879e-05" iyz="-9.049494430282981e-16" izz="1.0188830976877643e-05"/>
    </inertial>
    <visual name="ARWristBR4_Link_Visual">
      <origin xyz="0.0 0.0 0.0" rpy="0.0 0.0 0.0"/>
      <geometry>
        <mesh filename="../meshes/ARWrist_BR4_Link.stl" scale="1.0 1.0 1.0"/>
      </geometry>
      <material name="">
        <color rgba="0.647058823529412 0.619607843137255 0.588235294117647 1.0"/>
      </material>
    </visual>
    <collision name="ARWristBR4_Link_Collision">
      <origin xyz="0.0 0.0 0.0" rpy="0.0 0.0 0.0"/>
      <geometry>
        <mesh filename="../meshes/ARWrist_BR4_Link_convexhull.stl" scale="1.0 1.0 1.0"/>
      </geometry>
    </collision>
  </link>
  <joint name="ARWristBase" type="fixed">
    <origin xyz="0.0 0.0 0.168" rpy="-0.016107 1.570793 3.125485"/>
    <parent link="ARWristRoot_Link"/>
    <child link="ARWristBase_Link"/>
  </joint>
  <link name="ARWristBase_Link">
    <inertial>
      <origin xyz="0.05416 0.00429 -5.5e-05" rpy="0.0 0.0 0.0"/>
      <mass value="0.27602181682106586"/>
      <inertia ixx="0.0004818694935696462" ixy="-1.8939997715257535e-05" ixz="-1.915496021566553e-08" iyy="0.0012988608884876524" iyz="3.569127035083581e-07" izz="0.0012914088951100598"/>
    </inertial>
    <visual name="ARWristBase_Link_Visual">
      <origin xyz="0.0 0.0 0.0" rpy="3.141593 0.0 0.0"/>
      <geometry>
        <mesh filename="../meshes/ARWrist_Base_Link.stl" scale="1.0 1.0 1.0"/>
      </geometry>
      <material name="">
        <color rgba="0.898039215686275 0.917647058823529 0.929411764705882 1.0"/>
      </material>
    </visual>
    <collision name="ARWristBase_Link_Collision">
      <origin xyz="0.0 0.0 0.0" rpy="0.0 0.0 0.0"/>
      <geometry>
        <mesh filename="../meshes/ARWrist_Base_Link_convexhull.stl" scale="1.0 1.0 1.0"/>
      </geometry>
    </collision>
  </link>
  <joint name="ARWristFT" type="fixed">
    <origin xyz="-1.2e-05 0.0 -0.042748" rpy="3.141593 0.0 1.5708"/>
    <parent link="ARWristYaw_Link"/>
    <child link="ARWristFT_Link"/>
  </joint>
  <link name="ARWristFT_Link">
    <inertial>
      <origin xyz="-3.7e-05 5.8e-05 -0.007912" rpy="0.0 0.0 0.0"/>
      <mass value="0.0919909344513703"/>
      <inertia ixx="1.3951813166732569e-05" ixy="3.05326895417141e-08" ixz="-1.4763455306581984e-08" iyy="1.3907068368118933e-05" iyz="1.948139215462272e-08" izz="2.41202226678126e-05"/>
    </inertial>
    <visual name="ARWristFT_Link_Visual">
      <origin xyz="0.0 -0.0 0.0" rpy="0.0 0.0 3.141593"/>
      <geometry>
        <mesh filename="../meshes/ARWristFT_Link.stl" scale="1.0 1.0 1.0"/>
      </geometry>
      <material name="">
        <color rgba="0.698039215686274 0.698039215686274 0.698039215686274 1.0"/>
      </material>
    </visual>
    <collision name="ARWristFT_Link_Collision">
      <origin xyz="0.0 0.0 0.0" rpy="0.0 0.0 0.0"/>
      <geometry>
        <mesh filename="../meshes/ARWristFT_Link_convexhull.stl" scale="1.0 1.0 1.0"/>
      </geometry>
    </collision>
  </link>
  <joint name="ARWristPitch" type="revolute">
    <origin xyz="0.0 0.0 0.0" rpy="-0.0 0.0 -1e-06"/>
    <axis xyz="1.0 0.0 0.0"/>
    <parent link="ARWristRoot_Link"/>
    <child link="ARWristPitch_Link"/>
    <limit effort="400.0" lower="-0.741" upper="1.75" velocity="3.1415926"/>
  </joint>
  <link name="ARWristPitch_Link">
    <inertial>
      <origin xyz="0.0 0.0 0.0" rpy="0.0 0.0 0.0"/>
      <mass value="0.030345802955544107"/>
      <inertia ixx="1.0000000011242574e-05" ixy="-9.966047055450726e-14" ixz="-1.3686119410217597e-10" iyy="1.014377905770101e-05" iyz="-1.3704172984466683e-10" izz="1.1666089364253713e-05"/>
    </inertial>
    <visual name="ARWristPitch_Link_Visual">
      <origin xyz="0.0 0.0 0.0" rpy="3.141593 0.0 -0.0"/>
      <geometry>
        <mesh filename="../meshes/ARWristPitch_Link.stl" scale="1.0 1.0 1.0"/>
      </geometry>
      <material name="">
        <color rgba="0.647058823529412 0.619607843137255 0.588235294117647 1.0"/>
      </material>
    </visual>
    <collision name="ARWristPitch_Link_Collision">
      <origin xyz="0.0 0.0 0.0" rpy="0.0 0.0 0.0"/>
      <geometry>
        <mesh filename="../meshes/ARWristPitch_Link_convexhull.stl" scale="1.0 1.0 1.0"/>
      </geometry>
    </collision>
  </link>
  <joint name="ARWristRoll" type="revolute">
    <origin xyz="0.0 0.0 0.122" rpy="0.08344 1.570793 -3.058159"/>
    <axis xyz="1.0 0.0 0.0"/>
    <parent link="ARElbow_Link"/>
    <child link="ARWristRoll_Link"/>
    <limit effort="400.0" lower="-3.141" upper="3.141" velocity="3.1415926"/>
  </joint>
  <link name="ARWristRoll_Link">
    <inertial>
      <origin xyz="0.0 0.0 0.0" rpy="0.0 0.0 0.0"/>
      <mass value="2e-05"/>
      <inertia ixx="2.0000000000000005e-05" ixy="1.6461063629699659e-22" ixz="1.778282480377345e-23" iyy="2.0000000000000005e-05" iyz="-8.470324889451552e-22" izz="2e-05"/>
    </inertial>
  </link>
  <joint name="ARWristRoot" type="fixed">
    <origin xyz="-0.173 0.0 0.0" rpy="-0.010381 -1.5707 -3.131212"/>
    <parent link="ARWristRoll_Link"/>
    <child link="ARWristRoot_Link"/>
  </joint>
  <link name="ARWristRoot_Link">
    <inertial>
      <origin xyz="-0.000875 0.015651 0.10982" rpy="0.0 0.0 0.0"/>
      <mass value="0.12307001358415799"/>
      <inertia ixx="1.6915e-05" ixy="-1.0690005486444212e-08" ixz="1.5837996296873942e-08" iyy="2.9632000408180187e-05" iyz="-5.891545378037206e-07" izz="1.3863999591819818e-05"/>
    </inertial>
    <visual name="ARWristRoot_Link_Visual">
      <origin xyz="0.0 0.0 0.0" rpy="0.0 0.0 0.0"/>
      <geometry>
        <mesh filename="../meshes/ARWrist_Root_Link.stl" scale="1.0 1.0 1.0"/>
      </geometry>
      <material name="">
        <color rgba="0.64706 0.61961 0.58824 1.0"/>
      </material>
    </visual>
    <collision name="ARWristRoot_Link_Collision">
      <origin xyz="0.0 0.0 0.0" rpy="0.0 0.0 0.0"/>
      <geometry>
        <mesh filename="../meshes/ARWrist_Root_Link_convexhull.stl" scale="1.0 1.0 1.0"/>
      </geometry>
    </collision>
  </link>
  <joint name="ARWristYaw" type="revolute">
    <origin xyz="0.0 0.0 0.0" rpy="0.0 0.0 1e-06"/>
    <axis xyz="0.0 1.0 0.0"/>
    <parent link="ARWristPitch_Link"/>
    <child link="ARWristYaw_Link"/>
    <limit effort="400.0" lower="-0.558" upper="0.593" velocity="3.1415926"/>
  </joint>
  <link name="ARWristYaw_Link">
    <inertial>
      <origin xyz="-6e-05 -0.011222 -0.011777" rpy="0.0 0.0 0.0"/>
      <mass value="0.04402665761680324"/>
      <inertia ixx="1.4523374545063202e-05" ixy="3.5210414776992013e-09" ixz="-1.8323837570945907e-08" iyy="1.0332755928692055e-05" iyz="1.476819147742914e-06" izz="1.6554592724183995e-05"/>
    </inertial>
    <visual name="ARWristYaw_Link_Visual">
      <origin xyz="0.0 0.0 0.0" rpy="3.141593 0.0 3.141592"/>
      <geometry>
        <mesh filename="../meshes/ARWristYaw_Link.stl" scale="1.0 1.0 1.0"/>
      </geometry>
      <material name="">
        <color rgba="0.898039215686275 0.917647058823529 0.929411764705882 1.0"/>
      </material>
    </visual>
    <collision name="ARWristYaw_Link_Collision">
      <origin xyz="0.0 0.0 0.0" rpy="0.0 0.0 0.0"/>
      <geometry>
        <mesh filename="../meshes/ARWristYaw_Link_convexhull.stl" scale="1.0 1.0 1.0"/>
      </geometry>
    </collision>
  </link>
  <joint name="BodyActL" type="prismatic">
    <origin xyz="0.0 0.0 0.23999" rpy="0.0 0.0 -0.0"/>
    <axis xyz="0.0 0.0 1.0"/>
    <parent link="BodyBL2_Link"/>
    <child link="BodyActL_Link"/>
    <limit effort="400.0" lower="-1.57" upper="1.57" velocity="3.1415926"/>
  </joint>
  <link name="BodyActL_Link">
    <inertial>
      <origin xyz="0.0 0.0 -0.077362" rpy="0.0 0.0 0.0"/>
      <mass value="0.10190000000000002"/>
      <inertia ixx="0.00013708249997353297" ixy="3.8201993071794706e-08" ixz="1.1083966073276513e-22" iyy="0.00013710250002646712" iyz="9.793800383959562e-22" izz="1.0000000000000003e-05"/>
    </inertial>
    <visual name="BodyActL_Visual">
      <origin xyz="0.0 0.0 0.0" rpy="0.0 0.0 -3.141593"/>
      <geometry>
        <mesh filename="../meshes/Body_ActL.stl"/>
      </geometry>
      <material name="">
        <color rgba="0.69804 0.69804 0.69804 1.0"/>
      </material>
    </visual>
    <collision name="BodyActL_Collision">
      <origin xyz="0.0 0.0 0.0" rpy="0.0 0.0 0.0"/>
      <geometry>
        <mesh filename="../meshes/Body_ActL_convexhull.stl" scale="1.0 1.0 1.0"/>
      </geometry>
    </collision>
  </link>
  <joint name="BodyActR" type="prismatic">
    <origin xyz="0.0 0.0 0.23999" rpy="0.0 0.0 -0.0"/>
    <axis xyz="0.0 0.0 1.0"/>
    <parent link="BodyBR2_Link"/>
    <child link="BodyActR_Link"/>
    <limit effort="400.0" lower="-1.57" upper="1.57" velocity="3.1415926"/>
  </joint>
  <link name="BodyActR_Link">
    <inertial>
      <origin xyz="0.0 0.0 -0.077362" rpy="0.0 0.0 0.0"/>
      <mass value="0.10190000000000002"/>
      <inertia ixx="0.00013708250002646719" ixy="-3.820200692820298e-08" ixz="2.0798008804014167e-17" iyy="0.00013710249997353285" iyz="-2.5414992795339697e-17" izz="1.0000000000000003e-05"/>
    </inertial>
    <visual name="BodyActR_Visual">
      <origin xyz="0.0 0.0 0.0" rpy="0.0 0.0 -3.141593"/>
      <geometry>
        <mesh filename="../meshes/Body_ActR.stl"/>
      </geometry>
      <material name="">
        <color rgba="0.69804 0.69804 0.69804 1.0"/>
      </material>
    </visual>
    <collision name="BodyActR_Collision">
      <origin xyz="0.0 0.0 0.0" rpy="0.0 0.0 0.0"/>
      <geometry>
        <mesh filename="../meshes/Body_ActR_convexhull.stl" scale="1.0 1.0 1.0"/>
      </geometry>
    </collision>
  </link>
  <joint name="BodyBL1" type="revolute">
    <origin xyz="0.02 -0.089827 0.21" rpy="2.899823 0.0 1.5708"/>
    <axis xyz="1.0 0.0 0.0"/>
    <parent link="BodyRoot_Link"/>
    <child link="BodyBL1_Link"/>
    <limit effort="400.0" lower="-1.57" upper="1.57" velocity="3.1415926"/>
  </joint>
  <link name="BodyBL1_Link">
    <inertial>
      <origin xyz="0.020399 0.0 0.0" rpy="0.0 0.0 0.0"/>
      <mass value="0.042423"/>
      <inertia ixx="1.0000000000001026e-05" ixy="-2.9574078259175723e-12" ixz="-6.764500061230576e-20" iyy="1.8537299999998983e-05" iyz="1.767562644587376e-21" izz="2.0306299999999996e-05"/>
    </inertial>
    <visual name="BodyBL1_Visual">
      <origin xyz="0.0 0.0 0.0" rpy="0.0 0.0 -3.141593"/>
      <geometry>
        <mesh filename="../meshes/Body_BL1.stl"/>
      </geometry>
      <material name="">
        <color rgba="0.64706 0.61961 0.58824 1.0"/>
      </material>
    </visual>
    <collision name="BodyBL1_Collision">
      <origin xyz="0.0 0.0 0.0" rpy="0.0 0.0 0.0"/>
      <geometry>
        <mesh filename="../meshes/Body_BL1_convexhull.stl" scale="1.0 1.0 1.0"/>
      </geometry>
    </collision>
  </link>
  <joint name="BodyBL2" type="revolute">
    <origin xyz="0.0 0.0 0.0" rpy="0.0 -0.010339 -0.0"/>
    <axis xyz="0.0 1.0 0.0"/>
    <parent link="BodyBL1_Link"/>
    <child link="BodyBL2_Link"/>
    <limit effort="400.0" lower="-1.57" upper="1.57" velocity="3.1415926"/>
  </joint>
  <link name="BodyBL2_Link">
    <inertial>
      <origin xyz="-5.3e-05 1.1e-05 0.12216" rpy="0.0 0.0 0.0"/>
      <mass value="0.8166400000000001"/>
      <inertia ixx="0.0004187999999241573" ixy="1.0946911318984479e-07" ixz="4.637099902145767e-07" iyy="0.00042136000007584283" iyz="2.8248160633875217e-08" izz="0.00051891"/>
    </inertial>
    <visual name="BodyBL2_Visual">
      <origin xyz="0.0 0.0 0.0" rpy="0.0 0.0 -3.141593"/>
      <geometry>
        <mesh filename="../meshes/Body_BL2.stl"/>
      </geometry>
      <material name="">
        <color rgba="0.61961 0.40784 0.2 1.0"/>
      </material>
    </visual>
    <collision name="BodyBL2_Collision">
      <origin xyz="0.0 0.0 0.0" rpy="0.0 0.0 0.0"/>
      <geometry>
        <mesh filename="../meshes/Body_BL2_convexhull.stl" scale="1.0 1.0 1.0"/>
      </geometry>
    </collision>
  </link>
  <joint name="BodyBR1" type="revolute">
    <origin xyz="-0.02 -0.089827 0.21" rpy="-2.899823 0.0 1.5708"/>
    <axis xyz="1.0 0.0 0.0"/>
    <parent link="BodyRoot_Link"/>
    <child link="BodyBR1_Link"/>
    <limit effort="400.0" lower="-1.57" upper="1.57" velocity="3.1415926"/>
  </joint>
  <link name="BodyBR1_Link">
    <inertial>
      <origin xyz="0.020399 0.0 0.0" rpy="0.0 0.0 0.0"/>
      <mass value="0.042423"/>
      <inertia ixx="1.0000000000001026e-05" ixy="-2.9574078244755723e-12" ixz="-6.968000025102942e-20" iyy="1.8537299999998983e-05" iyz="7.246474869280696e-22" izz="2.0306299999999996e-05"/>
    </inertial>
    <visual name="BodyBR1_Visual">
      <origin xyz="0.0 0.0 0.0" rpy="0.0 0.0 -3.141593"/>
      <geometry>
        <mesh filename="../meshes/Body_BR1.stl"/>
      </geometry>
      <material name="">
        <color rgba="0.64706 0.61961 0.58824 1.0"/>
      </material>
    </visual>
    <collision name="BodyBR1_Collision">
      <origin xyz="0.0 0.0 0.0" rpy="0.0 0.0 0.0"/>
      <geometry>
        <mesh filename="../meshes/Body_BR1_convexhull.stl" scale="1.0 1.0 1.0"/>
      </geometry>
    </collision>
  </link>
  <joint name="BodyBR2" type="revolute">
    <origin xyz="0.0 0.0 0.0" rpy="0.0 -0.010339 -0.0"/>
    <axis xyz="0.0 1.0 0.0"/>
    <parent link="BodyBR1_Link"/>
    <child link="BodyBR2_Link"/>
    <limit effort="400.0" lower="-1.57" upper="1.57" velocity="3.1415926"/>
  </joint>
  <link name="BodyBR2_Link">
    <inertial>
      <origin xyz="-6.2e-05 -1.2e-05 0.12216" rpy="0.0 0.0 0.0"/>
      <mass value="0.8166400000000001"/>
      <inertia ixx="0.00041874999995572364" ixy="6.390708201293713e-08" ixz="4.4057001108232887e-07" iyy="0.0004214000000442765" iyz="-3.199184738205335e-08" izz="0.00051891"/>
    </inertial>
    <visual name="BodyBR2_Visual">
      <origin xyz="0.0 0.0 0.0" rpy="0.0 0.0 -3.141593"/>
      <geometry>
        <mesh filename="../meshes/Body_BR2.stl"/>
      </geometry>
      <material name="">
        <color rgba="0.64706 0.61961 0.58824 1.0"/>
      </material>
    </visual>
    <collision name="BodyBR2_Collision">
      <origin xyz="0.0 0.0 0.0" rpy="0.0 0.0 0.0"/>
      <geometry>
        <mesh filename="../meshes/Body_BR2_convexhull.stl" scale="1.0 1.0 1.0"/>
      </geometry>
    </collision>
  </link>
  <joint name="BodyPitch" type="revolute">
    <origin xyz="0.0 0.0 0.0" rpy="3.141593 0.0 1.570797"/>
    <axis xyz="0.0 1.0 0.0"/>
    <parent link="BodyRoot_Link"/>
    <child link="BodyPitch_Link"/>
    <limit effort="400.0" lower="-0.349" upper="0.527" velocity="3.1415926"/>
  </joint>
  <link name="BodyPitch_Link">
    <inertial>
      <origin xyz="0.0 0.0 0.0" rpy="0.0 0.0 0.0"/>
      <mass value="0.076413"/>
      <inertia ixx="1.3771000000001387e-05" ixy="2.1212999999995475e-12" ixz="2.1080999098829268e-12" iyy="1.3770999999998615e-05" iyz="-2.7576068891630696e-13" izz="2.4637e-05"/>
    </inertial>
    <visual name="BodyPitch_Visual">
      <origin xyz="0.0 0.0 0.0" rpy="0.0 0.0 -1.570796"/>
      <geometry>
        <mesh filename="../meshes/BodyPitch.stl"/>
      </geometry>
      <material name="">
        <color rgba="0.89804 0.91765 0.92941 1.0"/>
      </material>
    </visual>
    <collision name="BodyPitch_Collision">
      <origin xyz="0.0 0.0 0.0" rpy="0.0 0.0 0.0"/>
      <geometry>
        <mesh filename="../meshes/BodyPitch_convexhull.stl" scale="1.0 1.0 1.0"/>
      </geometry>
    </collision>
  </link>
  <joint name="BodyRoll" type="revolute">
    <origin xyz="0.0 0.0 0.0" rpy="0.0 0.0 -0.0"/>
    <axis xyz="1.0 0.0 0.0"/>
    <parent link="BodyPitch_Link"/>
    <child link="BodyRoll_Link"/>
    <limit effort="400.0" lower="-0.448" upper="0.448" velocity="3.1415926"/>
  </joint>
  <link name="BodyRoll_Link">
    <inertial>
      <origin xyz="-0.009734 1.6e-05 0.052947" rpy="0.0 0.0 0.0"/>
      <mass value="1.4553"/>
      <inertia ixx="0.001065799999518147" ixy="-7.372513070271073e-07" ixz="-6.32019993920274e-06" iyy="0.001000600000481853" iyz="1.8604206540909618e-07" izz="0.0017602"/>
    </inertial>
    <visual name="BodyRoll_Visual">
      <origin xyz="0.0 0.0 0.0" rpy="0.0 0.0 -1.570796"/>
      <geometry>
        <mesh filename="../meshes/BodyRoll.stl"/>
      </geometry>
      <material name="">
        <color rgba="0.89804 0.91765 0.92941 1.0"/>
      </material>
    </visual>
    <collision name="BodyRoll_Collision">
      <origin xyz="0.0 0.0 0.0" rpy="0.0 0.0 0.0"/>
      <geometry>
        <mesh filename="../meshes/BodyRoll_convexhull.stl" scale="1.0 1.0 1.0"/>
      </geometry>
    </collision>
  </link>
  <joint name="BodyRoot" type="fixed">
    <origin xyz="0.0 0.0 0.016" rpy="3.141593 0.0 1.570793"/>
    <parent link="RH5v2_Root_Link"/>
    <child link="BodyRoot_Link"/>
  </joint>
  <link name="BodyRoot_Link">
    <inertial>
      <origin xyz="0.001001 0.011445 0.027995" rpy="0.0 0.0 0.0"/>
      <mass value="0.1819"/>
      <inertia ixx="0.00016560999999982624" ixy="2.4259007707886505e-10" ixz="1.6758933595730266e-08" iyy="0.00021346000013282973" iyz="1.9149442598622602e-07" izz="0.0003416899998673442"/>
    </inertial>
    <visual name="BodyRoot_Link_Visual">
      <origin xyz="0.0 0.0 0.0" rpy="3.141593 0.0 3.141593"/>
      <geometry>
        <mesh filename="../meshes/Body_Root_Link.stl"/>
      </geometry>
      <material name="">
        <color rgba="1.0 1.0 1.0 1.0"/>
      </material>
    </visual>
    <collision name="BodyRoot_Link_Collision">
      <origin xyz="0.0 0.0 0.0" rpy="0.0 0.0 0.0"/>
      <geometry>
        <mesh filename="../meshes/Body_Root_Link_convexhull.stl" scale="1.0 1.0 1.0"/>
      </geometry>
    </collision>
  </link>
  <joint name="BodyYaw" type="revolute">
    <origin xyz="0.0 0.0 0.0" rpy="0.0 0.0 -0.0"/>
    <axis xyz="0.0 0.0 1.0"/>
    <parent link="BodyRoll_Link"/>
    <child link="BodyYaw_Link"/>
    <limit effort="400.0" lower="-3.141" upper="3.141" velocity="3.1415926"/>
  </joint>
  <link name="BodyYaw_Link">
    <inertial>
      <origin xyz="5e-06 0.0 0.062225" rpy="0.0 0.0 0.0"/>
      <mass value="0.25617"/>
      <inertia ixx="0.00046732" ixy="-1.6340031834935254e-14" ixz="-2.1180999999998868e-08" iyy="0.00046727000000000004" iyz="6.921897699980597e-15" izz="0.00077487"/>
    </inertial>
    <visual name="BodyYaw_Visual">
      <origin xyz="0.0 0.0 0.0" rpy="0.0 0.0 -1.570796"/>
      <geometry>
        <mesh filename="../meshes/BodyYaw.stl"/>
      </geometry>
      <material name="">
        <color rgba="0.89804 0.91765 0.92941 1.0"/>
      </material>
    </visual>
    <collision name="BodyYaw_Collision">
      <origin xyz="0.0 0.0 0.0" rpy="0.0 0.0 0.0"/>
      <geometry>
        <mesh filename="../meshes/BodyYaw_convexhull.stl" scale="1.0 1.0 1.0"/>
      </geometry>
    </collision>
  </link>
  <joint name="Connector_Body/Leg_left" type="fixed">
    <origin xyz="0.085744 0.025 0.11058" rpy="-1.570793 -1.309 7e-06"/>
    <parent link="BodyRoot_Link"/>
    <child link="Connector_Body/Leg_left_Link"/>
  </joint>
  <link name="Connector_Body/Leg_left_Link">
    <inertial>
      <origin xyz="0.0 -1.3878e-17 0.0" rpy="0.0 0.0 0.0"/>
      <mass value="1e-05"/>
      <inertia ixx="1e-05" ixy="0.0" ixz="0.0" iyy="1e-05" iyz="0.0" izz="1e-05"/>
    </inertial>
  </link>
  <joint name="Connector_Body/Leg_right" type="fixed">
    <origin xyz="-0.085744 0.025 0.11058" rpy="1.570793 -1.309 -3.141593"/>
    <parent link="BodyRoot_Link"/>
    <child link="Connector_Body/Leg_right_Link"/>
  </joint>
  <link name="Connector_Body/Leg_right_Link">
    <inertial>
      <origin xyz="0.0 1.3878e-17 0.0" rpy="0.0 0.0 0.0"/>
      <mass value="1e-05"/>
      <inertia ixx="1.0000000000000003e-05" ixy="0.0" ixz="0.0" iyy="1.0000000000000004e-05" iyz="0.0" izz="1e-05"/>
    </inertial>
  </link>
  <joint name="Connector_Body/Torso" type="fixed">
    <origin xyz="0.0 0.0 0.0525" rpy="-1.570793 -1.570793 1.570796"/>
    <parent link="BodyYaw_Link"/>
    <child link="Connector_Body/Torso_Link"/>
  </joint>
  <link name="Connector_Body/Torso_Link">
    <inertial>
      <origin xyz="0.0 -4.7606e-18 6.1827e-22" rpy="0.0 0.0 0.0"/>
      <mass value="9.057619513349467"/>
      <inertia ixx="0.13521096197328605" ixy="0.00020463773988279492" ixz="-0.005225465392652974" iyy="0.1581524298837754" iyz="-4.4239158097541136e-05" izz="0.22422604262450974"/>
    </inertial>
    <visual name="base_link_torso_Visual">
      <origin xyz="0.0 0.0 0.0" rpy="3.141593 0.0 0.0"/>
      <geometry>
        <mesh filename="../meshes/base_link_torso.stl"/>
      </geometry>
      <material name="">
        <color rgba="0.698039215686274 0.698039215686274 0.698039215686274 1.0"/>
      </material>
    </visual>
    <visual name="Connector_Torso/Head_Visual">
      <origin xyz="0.3485 0.0 0.0" rpy="-3.141592 0.0 0.0"/>
      <geometry>
        <mesh filename="../meshes/Connector_Torso_Head.stl"/>
      </geometry>
      <material name="">
        <color rgba="0.69804 0.69804 0.69804 1.0"/>
      </material>
    </visual>
    <visual name="Connector_Torso/ArmRight_Visual">
      <origin xyz="0.29809 -0.12609 0.025162" rpy="-1.508093 0.25436 -1.3265"/>
      <geometry>
        <mesh filename="../meshes/Connector_Torso_ArmRight.stl"/>
      </geometry>
      <material name="">
        <color rgba="0.69804 0.69804 0.69804 1.0"/>
      </material>
    </visual>
    <visual name="Connector_Torso/ArmLeft_Visual">
      <origin xyz="0.29809 0.12609 0.025162" rpy="1.508093 0.25436 1.3265"/>
      <geometry>
        <mesh filename="../meshes/Connector_Torso_ArmLeft.stl"/>
      </geometry>
      <material name="">
        <color rgba="0.69804 0.69804 0.69804 1.0"/>
      </material>
    </visual>
    <collision name="Connector_Body/Torso_Link_Collision">
      <origin xyz="0.0 0.0 0.0" rpy="0.0 0.0 0.0"/>
      <geometry>
        <mesh filename="../meshes/Connector_BodyTorso_Link_full-urdf_joined_convexhull.stl" scale="1.0 1.0 1.0"/>
      </geometry>
    </collision>
  </link>
  <joint name="Connector_Torso/Backpack" type="fixed">
    <origin xyz="0.3015 0.135 0.139" rpy="0.014588 -1.570793 3.127004"/>
    <parent link="Connector_Body/Torso_Link"/>
    <child link="Connector_Torso/Backpack_Link"/>
  </joint>
  <link name="Connector_Torso/Backpack_Link">
    <inertial>
      <origin xyz="0.0059236 0.13398 -0.12892" rpy="0.0 0.0 0.0"/>
      <mass value="0.31044"/>
      <inertia ixx="0.0062412" ixy="-3.547e-07" ixz="-0.00033605" iyy="0.0031219" iyz="2.3476e-05" izz="0.003565"/>
    </inertial>
    <visual name="Connector_Torso/Backpack_Visual">
      <origin xyz="0.0 0.0 0.0" rpy="0.0 0.0 0.0"/>
      <geometry>
        <mesh filename="../meshes/Connector_Torso_Backpack.stl"/>
      </geometry>
      <material name="">
        <color rgba="0.20784 0.30196 0.45098 1.0"/>
      </material>
    </visual>
    <collision name="Connector_Torso/Backpack_Collision">
      <origin xyz="0.0 0.0 0.0" rpy="0.0 0.0 0.0"/>
      <geometry>
        <mesh filename="../meshes/Connector_Torso_Backpack_convexhull.stl" scale="1.0 1.0 1.0"/>
      </geometry>
    </collision>
  </link>
  <joint name="GLBase" type="fixed">
    <origin xyz="0.0 0.0 0.0" rpy="0.0 0.0 0.0"/>
    <parent link="ALWristFT_Link"/>
    <child link="GLBase_Link"/>
  </joint>
  <link name="GLBase_Link">
    <inertial>
      <origin xyz="0.003469 0.020574 0.047268" rpy="0.0 0.0 0.0"/>
      <mass value="1.6158618735699422"/>
      <inertia ixx="0.0015309000000000002" ixy="5.5487e-05" ixz="4.3401e-06" iyy="0.0007222700000000001" iyz="-2.1644e-05" izz="0.0011271"/>
    </inertial>
    <visual name="GLBase_Visual">
      <origin xyz="0.0 0.0 0.0" rpy="3.141593 0.0 0.0"/>
      <geometry>
        <mesh filename="../meshes/GripperLeft_BaseFrame.stl" scale="1.0 1.0 1.0"/>
      </geometry>
      <material name="">
        <color rgba="0.94118 0.67451 0.11765 1.0"/>
      </material>
    </visual>
    <collision name="GLBase_Collision">
      <origin xyz="0.0 0.0 0.0" rpy="0.0 0.0 0.0"/>
      <geometry>
        <mesh filename="../meshes/GripperLeft_BaseFrame_convexhull.stl" scale="1.0 1.0 1.0"/>
      </geometry>
    </collision>
  </link>
  <joint name="GLDistanceSensor1" type="fixed">
    <origin xyz="-0.000863 0.037716 0.083475" rpy="3.141593 -1.570793 3.141593"/>
    <parent link="GLBase_Link"/>
    <child link="GLDistanceSensor1_Link"/>
  </joint>
  <link name="GLDistanceSensor1_Link">
    <inertial>
      <origin xyz="0.0 0.0 0.0" rpy="0.0 0.0 0.0"/>
      <mass value="1e-05"/>
      <inertia ixx="1e-05" ixy="0.0" ixz="0.0" iyy="1e-05" iyz="0.0" izz="1e-05"/>
    </inertial>
  </link>
  <joint name="GLDistanceSensor2" type="fixed">
    <origin xyz="-0.000709 -0.002977 0.083475" rpy="3.141593 -1.570793 3.141593"/>
    <parent link="GLBase_Link"/>
    <child link="GLDistanceSensor2_Link"/>
  </joint>
  <link name="GLDistanceSensor2_Link">
    <inertial>
      <origin xyz="0.0 -0.0 0.0" rpy="0.0 0.0 0.0"/>
      <mass value="1e-05"/>
      <inertia ixx="1e-05" ixy="0.0" ixz="0.0" iyy="1e-05" iyz="0.0" izz="1e-05"/>
    </inertial>
  </link>
  <joint name="GLF1Base" type="fixed">
    <origin xyz="-0.013458 -0.038971 0.065211" rpy="1.7921 0.1664 -1.533593"/>
    <parent link="GLBase_Link"/>
    <child link="GLF1Base_Link"/>
  </joint>
  <link name="GLF1Base_Link">
    <inertial>
      <origin xyz="-0.013075 -0.015412 0.022007" rpy="0.0 0.0 0.0"/>
      <mass value="0.19184"/>
      <inertia ixx="3.9359e-05" ixy="-1.1994e-07" ixz="-1.876e-07" iyy="3.2122e-05" iyz="-2.0609e-07" izz="4.6536e-05"/>
    </inertial>
    <visual name="GLF1Base_Visual">
      <origin xyz="0.0 0.0 0.0" rpy="0.0 0.0 0.0"/>
      <geometry>
        <mesh filename="../meshes/Finger_Base_Frame.stl"/>
      </geometry>
      <material name="">
        <color rgba="0.79216 0.81961 0.93333 1.0"/>
      </material>
    </visual>
    <collision name="GLF1Base_Collision">
      <origin xyz="0.0 0.0 0.0" rpy="0.0 0.0 0.0"/>
      <geometry>
        <mesh filename="../meshes/Finger_Base_Frame_convexhull.stl" scale="1.0 1.0 1.0"/>
      </geometry>
    </collision>
  </link>
  <joint name="GLF1DistanceSensorDistal1" type="fixed">
    <origin xyz="0.000299999833291532 -0.0247775082611843 -0.0163492159542979" rpy="0.0 1.13794911843156 1.5707963267949"/>
    <parent link="GLF1TopSegment_Link"/>
    <child link="GLF1DistanceSensorDistal1_Link"/>
  </joint>
  <link name="GLF1DistanceSensorDistal1_Link">
    <inertial>
      <origin xyz="0.0 0.0 0.0" rpy="0.0 0.0 0.0"/>
      <mass value="1e-05"/>
      <inertia ixx="1e-05" ixy="0.0" ixz="0.0" iyy="1e-05" iyz="0.0" izz="1e-05"/>
    </inertial>
  </link>
  <joint name="GLF1DistanceSensorDistal2" type="fixed">
    <origin xyz="0.000199995310425429 0.0507125844075086 -0.0195804953991652" rpy="3.14159265358977 -0.751361283639969 1.57079632679489"/>
    <parent link="GLF1TopSegment_Link"/>
    <child link="GLF1DistanceSensorDistal2_Link"/>
  </joint>
  <link name="GLF1DistanceSensorDistal2_Link">
    <inertial>
      <origin xyz="0.0 0.0 0.0" rpy="0.0 0.0 0.0"/>
      <mass value="1e-05"/>
      <inertia ixx="1e-05" ixy="0.0" ixz="0.0" iyy="1e-05" iyz="0.0" izz="1e-05"/>
    </inertial>
  </link>
  <joint name="GLF1Gear" type="revolute">
    <origin xyz="0.0 0.0 0.053" rpy="1.2885 0.0 0.0"/>
    <axis xyz="1.0 0.0 0.0"/>
    <parent link="GLF1ProximalSegment_Link"/>
    <child link="GLF1Gear_Link"/>
    <limit effort="400.0" lower="-3.1415926" upper="3.1415926" velocity="3.1415926"/>
    <mimic joint="GLF1ProximalSegment" multiplier="-1.0" offset="0.0"/>
  </joint>
  <link name="GLF1Gear_Link">
    <inertial>
      <origin xyz="0.00042134 0.00032509 0.0086803" rpy="0.0 0.0 0.0"/>
      <mass value="0.024785"/>
      <inertia ixx="1.1031768852531896e-05" ixy="-3.314199999999995e-09" ixz="-1.3220000000000009e-08" iyy="1.04518688525319e-05" iyz="-1.0513000000000047e-07" izz="1.0024648852531899e-05"/>
    </inertial>
    <visual name="GLF1Gear_Visual">
      <origin xyz="0.0 0.0 0.0" rpy="0.0 0.0 0.0"/>
      <geometry>
        <mesh filename="../meshes/F_Gear_Frame.stl"/>
      </geometry>
      <material name="">
        <color rgba="0.94118 0.67451 0.11765 1.0"/>
      </material>
    </visual>
    <collision name="GLF1Gear_Collision">
      <origin xyz="0.0 0.0 0.0" rpy="0.0 0.0 0.0"/>
      <geometry>
        <mesh filename="../meshes/F_Gear_Frame_convexhull.stl" scale="1.0 1.0 1.0"/>
      </geometry>
    </collision>
  </link>
  <joint name="GLF1ProximalBar" type="revolute">
    <origin xyz="-0.01305 0.020512 0.035979" rpy="-1.1138 0.0 0.0"/>
    <axis xyz="-1.0 0.0 0.0"/>
    <parent link="GLF1Base_Link"/>
    <child link="GLF1ProximalBar_Link"/>
    <limit effort="400.0" lower="-3.1415926" upper="3.1415926" velocity="3.1415926"/>
    <mimic joint="GLF1ProximalSegment" multiplier="-1.0" offset="0.0"/>
  </joint>
  <link name="GLF1ProximalBar_Link">
    <inertial>
      <origin xyz="0.0021195 9.8516e-05 0.017626" rpy="0.0 0.0 0.0"/>
      <mass value="0.013406"/>
      <inertia ixx="1.3148561531334552e-05" ixy="-2.4433999999999384e-08" ixz="2.606700000000039e-07" iyy="1.3680961531334562e-05" iyz="7.3035999999996e-08" izz="1.0023111531334548e-05"/>
    </inertial>
    <visual name="GLF1ProximalBar_Visual">
      <origin xyz="0.0 0.0 0.0" rpy="0.0 0.0 0.0"/>
      <geometry>
        <mesh filename="../meshes/F_ProximalBar_Frame.stl"/>
      </geometry>
      <material name="">
        <color rgba="0.94118 0.67451 0.11765 1.0"/>
      </material>
    </visual>
    <collision name="GLF1ProximalBar_Collision">
      <origin xyz="0.0 0.0 0.0" rpy="0.0 0.0 0.0"/>
      <geometry>
        <mesh filename="../meshes/F_ProximalBar_Frame_convexhull.stl" scale="1.0 1.0 1.0"/>
      </geometry>
    </collision>
  </link>
  <joint name="GLF1ProximalSegment" type="revolute">
    <origin xyz="-0.01305 0.01575 0.0145" rpy="-1.1257 0.0 0.0"/>
    <axis xyz="1.0 0.0 0.0"/>
    <parent link="GLF1Base_Link"/>
    <child link="GLF1ProximalSegment_Link"/>
    <limit effort="400.0" lower="-0.62" upper="0.75" velocity="3.1415926"/>
  </joint>
  <link name="GLF1ProximalSegment_Link">
    <inertial>
      <origin xyz="-0.0020803 0.000387 0.0216" rpy="0.0 0.0 0.0"/>
      <mass value="0.054293"/>
      <inertia ixx="2.0885480277942027e-05" ixy="-1.4302000000000018e-08" ixz="-2.6832000000000287e-07" iyy="2.3749480277942032e-05" iyz="6.182299999999969e-07" izz="1.0034380277942036e-05"/>
    </inertial>
    <visual name="GLF1ProximalSegment_Visual">
      <origin xyz="0.0 0.0 0.0" rpy="0.0 0.0 0.0"/>
      <geometry>
        <mesh filename="../meshes/F_ProximalSegment_Frame.stl"/>
      </geometry>
      <material name="">
        <color rgba="0.94118 0.67451 0.11765 1.0"/>
      </material>
    </visual>
    <collision name="GLF1ProximalSegment_Collision">
      <origin xyz="0.0 0.0 0.0" rpy="0.0 0.0 0.0"/>
      <geometry>
        <mesh filename="../meshes/F_ProximalSegment_Frame_convexhull.stl" scale="1.0 1.0 1.0"/>
      </geometry>
    </collision>
  </link>
  <joint name="GLF1TopSegment" type="revolute">
    <origin xyz="0.0 0.0 0.0" rpy="0.0 0.0 0.0"/>
    <axis xyz="1.0 0.0 0.0"/>
    <parent link="GLF1Gear_Link"/>
    <child link="GLF1TopSegment_Link"/>
    <limit effort="400.0" lower="0.0" upper="2.1" velocity="3.1415926"/>
  </joint>
  <link name="GLF1TopSegment_Link">
    <inertial>
      <origin xyz="0.00093543 0.026024 -0.013282" rpy="0.0 0.0 0.0"/>
      <mass value="0.049549"/>
      <inertia ixx="1.1651277429850969e-05" ixy="4.429600000000007e-07" ixz="-6.034000000000013e-08" iyy="1.0300577429850967e-05" iyz="7.458100000000004e-07" izz="1.319687742985097e-05"/>
    </inertial>
    <visual name="GLF1TopSegment_Visual">
      <origin xyz="0.0 0.0 0.0" rpy="0.0 0.0 0.0"/>
      <geometry>
        <mesh filename="../meshes/F_TopSegment_Frame.stl"/>
      </geometry>
      <material name="">
        <color rgba="0.94118 0.67451 0.11765 1.0"/>
      </material>
    </visual>
    <collision name="GLF1TopSegment_Collision">
      <origin xyz="0.0 0.0 0.0" rpy="0.0 0.0 0.0"/>
      <geometry>
        <mesh filename="../meshes/F_TopSegment_Frame_convexhull.stl" scale="1.0 1.0 1.0"/>
      </geometry>
    </collision>
  </link>
  <joint name="GLF1TouchSensorDistal" type="fixed">
    <origin xyz="0.000200002939819318 0.0407117537406957 -0.0292563156876496" rpy="-3.14159265358978 1.17417004512815 -1.57079632679488"/>
    <parent link="GLF1TopSegment_Link"/>
    <child link="GLF1TouchSensorDistal_Link"/>
  </joint>
  <link name="GLF1TouchSensorDistal_Link">
    <inertial>
      <origin xyz="0.0 0.0 0.0" rpy="0.0 0.0 0.0"/>
      <mass value="1e-05"/>
      <inertia ixx="1e-05" ixy="0.0" ixz="0.0" iyy="1e-05" iyz="0.0" izz="1e-05"/>
    </inertial>
  </link>
  <joint name="GLF1TouchSensorIntermedial" type="fixed">
    <origin xyz="0.000200000530702645 0.0123371368999994 -0.01766647971245" rpy="-3.14159265358978 1.18769356276747 -1.57079632679488"/>
    <parent link="GLF1TopSegment_Link"/>
    <child link="GLF1TouchSensorIntermedial_Link"/>
  </joint>
  <link name="GLF1TouchSensorIntermedial_Link">
    <inertial>
      <origin xyz="0.0 0.0 0.0" rpy="0.0 0.0 0.0"/>
      <mass value="1e-05"/>
      <inertia ixx="1e-05" ixy="0.0" ixz="0.0" iyy="1e-05" iyz="0.0" izz="1e-05"/>
    </inertial>
  </link>
  <joint name="GLF1TouchSensor_FingerProximal" type="fixed">
    <origin xyz="0.0003 0.0088011 0.024649" rpy="0.0 -0.15059 1.5708"/>
    <parent link="GLF1ProximalSegment_Link"/>
    <child link="GLF1TouchSensor_FingerProximal_Link"/>
  </joint>
  <link name="GLF1TouchSensor_FingerProximal_Link">
    <inertial>
      <origin xyz="0.0 0.0 0.0" rpy="0.0 0.0 0.0"/>
      <mass value="1e-05"/>
      <inertia ixx="1e-05" ixy="0.0" ixz="0.0" iyy="1e-05" iyz="0.0" izz="1e-05"/>
    </inertial>
  </link>
  <joint name="GLF2Base" type="fixed">
    <origin xyz="-0.014454 0.012122 0.06971" rpy="1.7907 -0.12478 -1.598593"/>
    <parent link="GLBase_Link"/>
    <child link="GLF2Base_Link"/>
  </joint>
  <link name="GLF2Base_Link">
    <inertial>
      <origin xyz="-0.013075 -0.015412 0.022007" rpy="0.0 0.0 0.0"/>
      <mass value="0.19184"/>
      <inertia ixx="3.9359e-05" ixy="-1.1994e-07" ixz="-1.876e-07" iyy="3.2122e-05" iyz="-2.0609e-07" izz="4.6536e-05"/>
    </inertial>
    <visual name="GLF2Base_Visual">
      <origin xyz="0.0 0.0 0.0" rpy="0.0 0.0 0.0"/>
      <geometry>
        <mesh filename="../meshes/Finger_Base_Frame.stl"/>
      </geometry>
      <material name="">
        <color rgba="0.79216 0.81961 0.93333 1.0"/>
      </material>
    </visual>
    <collision name="GLF2Base_Collision">
      <origin xyz="0.0 0.0 0.0" rpy="0.0 0.0 0.0"/>
      <geometry>
        <mesh filename="../meshes/Finger_Base_Frame_convexhull.stl" scale="1.0 1.0 1.0"/>
      </geometry>
    </collision>
  </link>
  <joint name="GLF2DistanceSensorDistal1" type="fixed">
    <origin xyz="0.000299999833291532 -0.0247775082611843 -0.0163492159542979" rpy="0.0 1.13794911843156 1.5707963267949"/>
    <parent link="GLF2TopSegment_Link"/>
    <child link="GLF2DistanceSensorDistal1_Link"/>
  </joint>
  <link name="GLF2DistanceSensorDistal1_Link">
    <inertial>
      <origin xyz="0.0 0.0 0.0" rpy="0.0 0.0 0.0"/>
      <mass value="1e-05"/>
      <inertia ixx="1e-05" ixy="0.0" ixz="0.0" iyy="1e-05" iyz="0.0" izz="1e-05"/>
    </inertial>
  </link>
  <joint name="GLF2DistanceSensorDistal2" type="fixed">
    <origin xyz="0.000199995310425429 0.0507125844075086 -0.0195804953991652" rpy="3.14159265358977 -0.751361283639969 1.57079632679489"/>
    <parent link="GLF2TopSegment_Link"/>
    <child link="GLF2DistanceSensorDistal2_Link"/>
  </joint>
  <link name="GLF2DistanceSensorDistal2_Link">
    <inertial>
      <origin xyz="0.0 0.0 0.0" rpy="0.0 0.0 0.0"/>
      <mass value="1e-05"/>
      <inertia ixx="1e-05" ixy="0.0" ixz="0.0" iyy="1e-05" iyz="0.0" izz="1e-05"/>
    </inertial>
  </link>
  <joint name="GLF2Gear" type="revolute">
    <origin xyz="0.0 0.0 0.053" rpy="1.2885 0.0 0.0"/>
    <axis xyz="1.0 0.0 0.0"/>
    <parent link="GLF2ProximalSegment_Link"/>
    <child link="GLF2Gear_Link"/>
    <limit effort="400.0" lower="-3.1415926" upper="3.1415926" velocity="3.1415926"/>
    <mimic joint="GLF2ProximalSegment" multiplier="-1.0" offset="0.0"/>
  </joint>
  <link name="GLF2Gear_Link">
    <inertial>
      <origin xyz="0.00042134 0.00032509 0.0086803" rpy="0.0 0.0 0.0"/>
      <mass value="0.024785"/>
      <inertia ixx="1.1031768852531896e-05" ixy="-3.314199999999995e-09" ixz="-1.3220000000000009e-08" iyy="1.04518688525319e-05" iyz="-1.0513000000000047e-07" izz="1.0024648852531899e-05"/>
    </inertial>
    <visual name="GLF2Gear_Visual">
      <origin xyz="0.0 0.0 0.0" rpy="0.0 0.0 0.0"/>
      <geometry>
        <mesh filename="../meshes/F_Gear_Frame.stl"/>
      </geometry>
      <material name="">
        <color rgba="0.94118 0.67451 0.11765 1.0"/>
      </material>
    </visual>
    <collision name="GLF2Gear_Collision">
      <origin xyz="0.0 0.0 0.0" rpy="0.0 0.0 0.0"/>
      <geometry>
        <mesh filename="../meshes/F_Gear_Frame_convexhull.stl" scale="1.0 1.0 1.0"/>
      </geometry>
    </collision>
  </link>
  <joint name="GLF2ProximalBar" type="revolute">
    <origin xyz="-0.01305 0.020512 0.035979" rpy="-1.1138 0.0 0.0"/>
    <axis xyz="-1.0 0.0 0.0"/>
    <parent link="GLF2Base_Link"/>
    <child link="GLF2ProximalBar_Link"/>
    <limit effort="400.0" lower="-3.1415926" upper="3.1415926" velocity="3.1415926"/>
    <mimic joint="GLF2ProximalSegment" multiplier="-1.0" offset="0.0"/>
  </joint>
  <link name="GLF2ProximalBar_Link">
    <inertial>
      <origin xyz="0.0021195 9.8516e-05 0.017626" rpy="0.0 0.0 0.0"/>
      <mass value="0.013406"/>
      <inertia ixx="1.3148561531334552e-05" ixy="-2.4433999999999384e-08" ixz="2.606700000000039e-07" iyy="1.3680961531334562e-05" iyz="7.3035999999996e-08" izz="1.0023111531334548e-05"/>
    </inertial>
    <visual name="GLF2ProximalBar_Visual">
      <origin xyz="0.0 0.0 0.0" rpy="0.0 0.0 0.0"/>
      <geometry>
        <mesh filename="../meshes/F_ProximalBar_Frame.stl"/>
      </geometry>
      <material name="">
        <color rgba="0.94118 0.67451 0.11765 1.0"/>
      </material>
    </visual>
    <collision name="GLF2ProximalBar_Collision">
      <origin xyz="0.0 0.0 0.0" rpy="0.0 0.0 0.0"/>
      <geometry>
        <mesh filename="../meshes/F_ProximalBar_Frame_convexhull.stl" scale="1.0 1.0 1.0"/>
      </geometry>
    </collision>
  </link>
  <joint name="GLF2ProximalSegment" type="revolute">
    <origin xyz="-0.01305 0.01575 0.0145" rpy="-1.1257 0.0 0.0"/>
    <axis xyz="1.0 0.0 0.0"/>
    <parent link="GLF2Base_Link"/>
    <child link="GLF2ProximalSegment_Link"/>
    <limit effort="400.0" lower="-0.62" upper="0.75" velocity="3.1415926"/>
  </joint>
  <link name="GLF2ProximalSegment_Link">
    <inertial>
      <origin xyz="-0.0020803 0.000387 0.0216" rpy="0.0 0.0 0.0"/>
      <mass value="0.054293"/>
      <inertia ixx="2.0885480277942027e-05" ixy="-1.4302000000000018e-08" ixz="-2.6832000000000287e-07" iyy="2.3749480277942032e-05" iyz="6.182299999999969e-07" izz="1.0034380277942036e-05"/>
    </inertial>
    <visual name="GLF2ProximalSegment_Visual">
      <origin xyz="0.0 0.0 0.0" rpy="0.0 0.0 0.0"/>
      <geometry>
        <mesh filename="../meshes/F_ProximalSegment_Frame.stl"/>
      </geometry>
      <material name="">
        <color rgba="0.94118 0.67451 0.11765 1.0"/>
      </material>
    </visual>
    <collision name="GLF2ProximalSegment_Collision">
      <origin xyz="0.0 0.0 0.0" rpy="0.0 0.0 0.0"/>
      <geometry>
        <mesh filename="../meshes/F_ProximalSegment_Frame_convexhull.stl" scale="1.0 1.0 1.0"/>
      </geometry>
    </collision>
  </link>
  <joint name="GLF2TopSegment" type="revolute">
    <origin xyz="0.0 0.0 0.0" rpy="0.0 0.0 0.0"/>
    <axis xyz="1.0 0.0 0.0"/>
    <parent link="GLF2Gear_Link"/>
    <child link="GLF2TopSegment_Link"/>
    <limit effort="400.0" lower="0.0" upper="2.1" velocity="3.1415926"/>
  </joint>
  <link name="GLF2TopSegment_Link">
    <inertial>
      <origin xyz="0.00093543 0.026024 -0.013282" rpy="0.0 0.0 0.0"/>
      <mass value="0.049549"/>
      <inertia ixx="1.1651277429850969e-05" ixy="4.429600000000007e-07" ixz="-6.034000000000013e-08" iyy="1.0300577429850967e-05" iyz="7.458100000000004e-07" izz="1.319687742985097e-05"/>
    </inertial>
    <visual name="GLF2TopSegment_Visual">
      <origin xyz="0.0 0.0 0.0" rpy="0.0 0.0 0.0"/>
      <geometry>
        <mesh filename="../meshes/F_TopSegment_Frame.stl"/>
      </geometry>
      <material name="">
        <color rgba="0.94118 0.67451 0.11765 1.0"/>
      </material>
    </visual>
    <collision name="GLF2TopSegment_Collision">
      <origin xyz="0.0 0.0 0.0" rpy="0.0 0.0 0.0"/>
      <geometry>
        <mesh filename="../meshes/F_TopSegment_Frame_convexhull.stl" scale="1.0 1.0 1.0"/>
      </geometry>
    </collision>
  </link>
  <joint name="GLF2TouchSensorDistal" type="fixed">
    <origin xyz="0.000200002939819318 0.0407117537406957 -0.0292563156876496" rpy="-3.14159265358978 1.17417004512815 -1.57079632679488"/>
    <parent link="GLF2TopSegment_Link"/>
    <child link="GLF2TouchSensorDistal_Link"/>
  </joint>
  <link name="GLF2TouchSensorDistal_Link">
    <inertial>
      <origin xyz="0.0 0.0 0.0" rpy="0.0 0.0 0.0"/>
      <mass value="1e-05"/>
      <inertia ixx="1e-05" ixy="0.0" ixz="0.0" iyy="1e-05" iyz="0.0" izz="1e-05"/>
    </inertial>
  </link>
  <joint name="GLF2TouchSensorIntermedial" type="fixed">
    <origin xyz="0.000200000530702645 0.0123371368999994 -0.01766647971245" rpy="-3.14159265358978 1.18769356276747 -1.57079632679488"/>
    <parent link="GLF2TopSegment_Link"/>
    <child link="GLF2TouchSensorIntermedial_Link"/>
  </joint>
  <link name="GLF2TouchSensorIntermedial_Link">
    <inertial>
      <origin xyz="0.0 0.0 0.0" rpy="0.0 0.0 0.0"/>
      <mass value="1e-05"/>
      <inertia ixx="1e-05" ixy="0.0" ixz="0.0" iyy="1e-05" iyz="0.0" izz="1e-05"/>
    </inertial>
  </link>
  <joint name="GLF2TouchSensor_FingerProximal" type="fixed">
    <origin xyz="0.0003 0.0088011 0.024649" rpy="0.0 -0.15059 1.5708"/>
    <parent link="GLF2ProximalSegment_Link"/>
    <child link="GLF2TouchSensor_FingerProximal_Link"/>
  </joint>
  <link name="GLF2TouchSensor_FingerProximal_Link">
    <inertial>
      <origin xyz="0.0 0.0 0.0" rpy="0.0 0.0 0.0"/>
      <mass value="1e-05"/>
      <inertia ixx="1e-05" ixy="0.0" ixz="0.0" iyy="1e-05" iyz="0.0" izz="1e-05"/>
    </inertial>
  </link>
  <joint name="GLF3Base" type="fixed">
    <origin xyz="-0.013488 0.046837 0.065354" rpy="1.7907 -0.124785 -1.598609"/>
    <parent link="GLBase_Link"/>
    <child link="GLF3Base_Link"/>
  </joint>
  <link name="GLF3Base_Link">
    <inertial>
      <origin xyz="-0.013075 -0.015412 0.022007" rpy="0.0 0.0 0.0"/>
      <mass value="0.19184"/>
      <inertia ixx="3.9359e-05" ixy="-1.1994e-07" ixz="-1.876e-07" iyy="3.2122e-05" iyz="-2.0609e-07" izz="4.6536e-05"/>
    </inertial>
    <visual name="GLF3Base_Visual">
      <origin xyz="0.0 0.0 0.0" rpy="0.0 0.0 0.0"/>
      <geometry>
        <mesh filename="../meshes/Finger_Base_Frame.stl"/>
      </geometry>
      <material name="">
        <color rgba="0.79216 0.81961 0.93333 1.0"/>
      </material>
    </visual>
    <collision name="GLF3Base_Collision">
      <origin xyz="0.0 0.0 0.0" rpy="0.0 0.0 0.0"/>
      <geometry>
        <mesh filename="../meshes/Finger_Base_Frame_convexhull.stl" scale="1.0 1.0 1.0"/>
      </geometry>
    </collision>
  </link>
  <joint name="GLF3DistanceSensorDistal1" type="fixed">
    <origin xyz="0.000299999833291532 -0.0247775082611843 -0.0163492159542979" rpy="0.0 1.13794911843156 1.5707963267949"/>
    <parent link="GLF3TopSegment_Link"/>
    <child link="GLF3DistanceSensorDistal1_Link"/>
  </joint>
  <link name="GLF3DistanceSensorDistal1_Link">
    <inertial>
      <origin xyz="0.0 0.0 0.0" rpy="0.0 0.0 0.0"/>
      <mass value="1e-05"/>
      <inertia ixx="1e-05" ixy="0.0" ixz="0.0" iyy="1e-05" iyz="0.0" izz="1e-05"/>
    </inertial>
  </link>
  <joint name="GLF3DistanceSensorDistal2" type="fixed">
    <origin xyz="0.000199995310425429 0.0507125844075086 -0.0195804953991652" rpy="3.14159265358977 -0.751361283639969 1.57079632679489"/>
    <parent link="GLF3TopSegment_Link"/>
    <child link="GLF3DistanceSensorDistal2_Link"/>
  </joint>
  <link name="GLF3DistanceSensorDistal2_Link">
    <inertial>
      <origin xyz="0.0 0.0 0.0" rpy="0.0 0.0 0.0"/>
      <mass value="1e-05"/>
      <inertia ixx="1e-05" ixy="0.0" ixz="0.0" iyy="1e-05" iyz="0.0" izz="1e-05"/>
    </inertial>
  </link>
  <joint name="GLF3Gear" type="revolute">
    <origin xyz="0.0 0.0 0.053" rpy="1.2885 0.0 0.0"/>
    <axis xyz="1.0 0.0 0.0"/>
    <parent link="GLF3ProximalSegment_Link"/>
    <child link="GLF3Gear_Link"/>
    <limit effort="400.0" lower="-3.1415926" upper="3.1415926" velocity="3.1415926"/>
    <mimic joint="GLF3ProximalSegment" multiplier="-1.0" offset="0.0"/>
  </joint>
  <link name="GLF3Gear_Link">
    <inertial>
      <origin xyz="0.00042134 0.00032509 0.0086803" rpy="0.0 0.0 0.0"/>
      <mass value="0.024785"/>
      <inertia ixx="1.1031768852531896e-05" ixy="-3.314199999999995e-09" ixz="-1.3220000000000009e-08" iyy="1.04518688525319e-05" iyz="-1.0513000000000047e-07" izz="1.0024648852531899e-05"/>
    </inertial>
    <visual name="GLF3Gear_Visual">
      <origin xyz="0.0 0.0 0.0" rpy="0.0 0.0 0.0"/>
      <geometry>
        <mesh filename="../meshes/F_Gear_Frame.stl"/>
      </geometry>
      <material name="">
        <color rgba="0.94118 0.67451 0.11765 1.0"/>
      </material>
    </visual>
    <collision name="GLF3Gear_Collision">
      <origin xyz="0.0 0.0 0.0" rpy="0.0 0.0 0.0"/>
      <geometry>
        <mesh filename="../meshes/F_Gear_Frame_convexhull.stl" scale="1.0 1.0 1.0"/>
      </geometry>
    </collision>
  </link>
  <joint name="GLF3ProximalBar" type="revolute">
    <origin xyz="-0.01305 0.020512 0.035979" rpy="-1.1138 0.0 0.0"/>
    <axis xyz="-1.0 0.0 0.0"/>
    <parent link="GLF3Base_Link"/>
    <child link="GLF3ProximalBar_Link"/>
    <limit effort="400.0" lower="-3.1415926" upper="3.1415926" velocity="3.1415926"/>
    <mimic joint="GLF3ProximalSegment" multiplier="-1.0" offset="0.0"/>
  </joint>
  <link name="GLF3ProximalBar_Link">
    <inertial>
      <origin xyz="0.0021195 9.8516e-05 0.017626" rpy="0.0 0.0 0.0"/>
      <mass value="0.013406"/>
      <inertia ixx="1.3148561531334552e-05" ixy="-2.4433999999999384e-08" ixz="2.606700000000039e-07" iyy="1.3680961531334562e-05" iyz="7.3035999999996e-08" izz="1.0023111531334548e-05"/>
    </inertial>
    <visual name="GLF3ProximalBar_Visual">
      <origin xyz="0.0 0.0 0.0" rpy="0.0 0.0 0.0"/>
      <geometry>
        <mesh filename="../meshes/F_ProximalBar_Frame.stl"/>
      </geometry>
      <material name="">
        <color rgba="0.94118 0.67451 0.11765 1.0"/>
      </material>
    </visual>
    <collision name="GLF3ProximalBar_Collision">
      <origin xyz="0.0 0.0 0.0" rpy="0.0 0.0 0.0"/>
      <geometry>
        <mesh filename="../meshes/F_ProximalBar_Frame_convexhull.stl" scale="1.0 1.0 1.0"/>
      </geometry>
    </collision>
  </link>
  <joint name="GLF3ProximalSegment" type="revolute">
    <origin xyz="-0.01305 0.01575 0.0145" rpy="-1.1257 0.0 0.0"/>
    <axis xyz="1.0 0.0 0.0"/>
    <parent link="GLF3Base_Link"/>
    <child link="GLF3ProximalSegment_Link"/>
    <limit effort="400.0" lower="-0.62" upper="0.75" velocity="3.1415926"/>
  </joint>
  <link name="GLF3ProximalSegment_Link">
    <inertial>
      <origin xyz="-0.0020803 0.000387 0.0216" rpy="0.0 0.0 0.0"/>
      <mass value="0.054293"/>
      <inertia ixx="2.0885480277942027e-05" ixy="-1.4302000000000018e-08" ixz="-2.6832000000000287e-07" iyy="2.3749480277942032e-05" iyz="6.182299999999969e-07" izz="1.0034380277942036e-05"/>
    </inertial>
    <visual name="GLF3ProximalSegment_Visual">
      <origin xyz="0.0 0.0 0.0" rpy="0.0 0.0 0.0"/>
      <geometry>
        <mesh filename="../meshes/F_ProximalSegment_Frame.stl"/>
      </geometry>
      <material name="">
        <color rgba="0.94118 0.67451 0.11765 1.0"/>
      </material>
    </visual>
    <collision name="GLF3ProximalSegment_Collision">
      <origin xyz="0.0 0.0 0.0" rpy="0.0 0.0 0.0"/>
      <geometry>
        <mesh filename="../meshes/F_ProximalSegment_Frame_convexhull.stl" scale="1.0 1.0 1.0"/>
      </geometry>
    </collision>
  </link>
  <joint name="GLF3TopSegment" type="revolute">
    <origin xyz="0.0 0.0 0.0" rpy="0.0 0.0 0.0"/>
    <axis xyz="1.0 0.0 0.0"/>
    <parent link="GLF3Gear_Link"/>
    <child link="GLF3TopSegment_Link"/>
    <limit effort="400.0" lower="0.0" upper="2.1" velocity="3.1415926"/>
  </joint>
  <link name="GLF3TopSegment_Link">
    <inertial>
      <origin xyz="0.00093543 0.026024 -0.013282" rpy="0.0 0.0 0.0"/>
      <mass value="0.049549"/>
      <inertia ixx="1.1651277429850969e-05" ixy="4.429600000000007e-07" ixz="-6.034000000000013e-08" iyy="1.0300577429850967e-05" iyz="7.458100000000004e-07" izz="1.319687742985097e-05"/>
    </inertial>
    <visual name="GLF3TopSegment_Visual">
      <origin xyz="0.0 0.0 0.0" rpy="0.0 0.0 0.0"/>
      <geometry>
        <mesh filename="../meshes/F_TopSegment_Frame.stl"/>
      </geometry>
      <material name="">
        <color rgba="0.94118 0.67451 0.11765 1.0"/>
      </material>
    </visual>
    <collision name="GLF3TopSegment_Collision">
      <origin xyz="0.0 0.0 0.0" rpy="0.0 0.0 0.0"/>
      <geometry>
        <mesh filename="../meshes/F_TopSegment_Frame_convexhull.stl" scale="1.0 1.0 1.0"/>
      </geometry>
    </collision>
  </link>
  <joint name="GLF3TouchSensorDistal" type="fixed">
    <origin xyz="0.000200002939819318 0.0407117537406957 -0.0292563156876496" rpy="-3.14159265358978 1.17417004512815 -1.57079632679488"/>
    <parent link="GLF3TopSegment_Link"/>
    <child link="GLF3TouchSensorDistal_Link"/>
  </joint>
  <link name="GLF3TouchSensorDistal_Link">
    <inertial>
      <origin xyz="0.0 0.0 0.0" rpy="0.0 0.0 0.0"/>
      <mass value="1e-05"/>
      <inertia ixx="1e-05" ixy="0.0" ixz="0.0" iyy="1e-05" iyz="0.0" izz="1e-05"/>
    </inertial>
  </link>
  <joint name="GLF3TouchSensorIntermedial" type="fixed">
    <origin xyz="0.000200000530702645 0.0123371368999994 -0.01766647971245" rpy="-3.14159265358978 1.18769356276747 -1.57079632679488"/>
    <parent link="GLF3TopSegment_Link"/>
    <child link="GLF3TouchSensorIntermedial_Link"/>
  </joint>
  <link name="GLF3TouchSensorIntermedial_Link">
    <inertial>
      <origin xyz="0.0 0.0 0.0" rpy="0.0 0.0 0.0"/>
      <mass value="1e-05"/>
      <inertia ixx="1e-05" ixy="0.0" ixz="0.0" iyy="1e-05" iyz="0.0" izz="1e-05"/>
    </inertial>
  </link>
  <joint name="GLF3TouchSensor_FingerProximal" type="fixed">
    <origin xyz="0.0003 0.0088011 0.024649" rpy="0.0 -0.15059 1.5708"/>
    <parent link="GLF3ProximalSegment_Link"/>
    <child link="GLF3TouchSensor_FingerProximal_Link"/>
  </joint>
  <link name="GLF3TouchSensor_FingerProximal_Link">
    <inertial>
      <origin xyz="0.0 0.0 0.0" rpy="0.0 0.0 0.0"/>
      <mass value="1e-05"/>
      <inertia ixx="1e-05" ixy="0.0" ixz="0.0" iyy="1e-05" iyz="0.0" izz="1e-05"/>
    </inertial>
  </link>
  <joint name="GLF4Base" type="fixed">
    <origin xyz="-0.011996 -0.013 0.028112" rpy="1.789 0.0 -1.570801"/>
    <parent link="GLThumb_Link"/>
    <child link="GLF4Base_Link"/>
  </joint>
  <link name="GLF4Base_Link">
    <inertial>
      <origin xyz="-0.013075 -0.015412 0.022007" rpy="0.0 0.0 0.0"/>
      <mass value="0.19184"/>
      <inertia ixx="3.9359e-05" ixy="-1.1994e-07" ixz="-1.876e-07" iyy="3.2122e-05" iyz="-2.0609e-07" izz="4.6536e-05"/>
    </inertial>
    <visual name="GLF4Base_Visual">
      <origin xyz="0.0 0.0 0.0" rpy="0.0 0.0 0.0"/>
      <geometry>
        <mesh filename="../meshes/Finger_Base_Frame.stl"/>
      </geometry>
      <material name="">
        <color rgba="0.79216 0.81961 0.93333 1.0"/>
      </material>
    </visual>
    <collision name="GLF4Base_Collision">
      <origin xyz="0.0 0.0 0.0" rpy="0.0 0.0 0.0"/>
      <geometry>
        <mesh filename="../meshes/Finger_Base_Frame_convexhull.stl" scale="1.0 1.0 1.0"/>
      </geometry>
    </collision>
  </link>
  <joint name="GLF4DistanceSensorDistal1" type="fixed">
    <origin xyz="0.000299999833291532 -0.0247775082611843 -0.0163492159542979" rpy="0.0 1.13794911843156 1.5707963267949"/>
    <parent link="GLF4TopSegment_Link"/>
    <child link="GLF4DistanceSensorDistal1_Link"/>
  </joint>
  <link name="GLF4DistanceSensorDistal1_Link">
    <inertial>
      <origin xyz="0.0 0.0 0.0" rpy="0.0 0.0 0.0"/>
      <mass value="1e-05"/>
      <inertia ixx="1e-05" ixy="0.0" ixz="0.0" iyy="1e-05" iyz="0.0" izz="1e-05"/>
    </inertial>
  </link>
  <joint name="GLF4DistanceSensorDistal2" type="fixed">
    <origin xyz="0.000199995310425429 0.0507125844075086 -0.0195804953991652" rpy="3.14159265358977 -0.751361283639969 1.57079632679489"/>
    <parent link="GLF4TopSegment_Link"/>
    <child link="GLF4DistanceSensorDistal2_Link"/>
  </joint>
  <link name="GLF4DistanceSensorDistal2_Link">
    <inertial>
      <origin xyz="0.0 0.0 0.0" rpy="0.0 0.0 0.0"/>
      <mass value="1e-05"/>
      <inertia ixx="1e-05" ixy="0.0" ixz="0.0" iyy="1e-05" iyz="0.0" izz="1e-05"/>
    </inertial>
  </link>
  <joint name="GLF4Gear" type="revolute">
    <origin xyz="0.0 0.0 0.053" rpy="1.2885 0.0 0.0"/>
    <axis xyz="1.0 0.0 0.0"/>
    <parent link="GLF4ProximalSegment_Link"/>
    <child link="GLF4Gear_Link"/>
    <limit effort="400.0" lower="-3.1415926" upper="3.1415926" velocity="3.1415926"/>
    <mimic joint="GLF4ProximalSegment" multiplier="-1.0" offset="0.0"/>
  </joint>
  <link name="GLF4Gear_Link">
    <inertial>
      <origin xyz="0.00042134 0.00032509 0.0086803" rpy="0.0 0.0 0.0"/>
      <mass value="0.024785"/>
      <inertia ixx="1.1031768852531896e-05" ixy="-3.314199999999995e-09" ixz="-1.3220000000000009e-08" iyy="1.04518688525319e-05" iyz="-1.0513000000000047e-07" izz="1.0024648852531899e-05"/>
    </inertial>
    <visual name="GLF4Gear_Visual">
      <origin xyz="0.0 0.0 0.0" rpy="0.0 0.0 0.0"/>
      <geometry>
        <mesh filename="../meshes/F_Gear_Frame.stl"/>
      </geometry>
      <material name="">
        <color rgba="0.94118 0.67451 0.11765 1.0"/>
      </material>
    </visual>
    <collision name="GLF4Gear_Collision">
      <origin xyz="0.0 0.0 0.0" rpy="0.0 0.0 0.0"/>
      <geometry>
        <mesh filename="../meshes/F_Gear_Frame_convexhull.stl" scale="1.0 1.0 1.0"/>
      </geometry>
    </collision>
  </link>
  <joint name="GLF4ProximalBar" type="revolute">
    <origin xyz="-0.01305 0.020512 0.035979" rpy="-1.1138 0.0 0.0"/>
    <axis xyz="-1.0 0.0 0.0"/>
    <parent link="GLF4Base_Link"/>
    <child link="GLF4ProximalBar_Link"/>
    <limit effort="400.0" lower="-3.1415926" upper="3.1415926" velocity="3.1415926"/>
    <mimic joint="GLF4ProximalSegment" multiplier="-1.0" offset="0.0"/>
  </joint>
  <link name="GLF4ProximalBar_Link">
    <inertial>
      <origin xyz="0.0021195 9.8516e-05 0.017626" rpy="0.0 0.0 0.0"/>
      <mass value="0.013406"/>
      <inertia ixx="1.3148561531334552e-05" ixy="-2.4433999999999384e-08" ixz="2.606700000000039e-07" iyy="1.3680961531334562e-05" iyz="7.3035999999996e-08" izz="1.0023111531334548e-05"/>
    </inertial>
    <visual name="GLF4ProximalBar_Visual">
      <origin xyz="0.0 0.0 0.0" rpy="0.0 0.0 0.0"/>
      <geometry>
        <mesh filename="../meshes/F_ProximalBar_Frame.stl"/>
      </geometry>
      <material name="">
        <color rgba="0.94118 0.67451 0.11765 1.0"/>
      </material>
    </visual>
    <collision name="GLF4ProximalBar_Collision">
      <origin xyz="0.0 0.0 0.0" rpy="0.0 0.0 0.0"/>
      <geometry>
        <mesh filename="../meshes/F_ProximalBar_Frame_convexhull.stl" scale="1.0 1.0 1.0"/>
      </geometry>
    </collision>
  </link>
  <joint name="GLF4ProximalSegment" type="revolute">
    <origin xyz="-0.01305 0.01575 0.0145" rpy="-1.1257 0.0 0.0"/>
    <axis xyz="1.0 0.0 0.0"/>
    <parent link="GLF4Base_Link"/>
    <child link="GLF4ProximalSegment_Link"/>
    <limit effort="400.0" lower="-0.62" upper="0.75" velocity="3.1415926"/>
  </joint>
  <link name="GLF4ProximalSegment_Link">
    <inertial>
      <origin xyz="-0.0020803 0.000387 0.0216" rpy="0.0 0.0 0.0"/>
      <mass value="0.054293"/>
      <inertia ixx="2.0885480277942027e-05" ixy="-1.4302000000000018e-08" ixz="-2.6832000000000287e-07" iyy="2.3749480277942032e-05" iyz="6.182299999999969e-07" izz="1.0034380277942036e-05"/>
    </inertial>
    <visual name="GLF4ProximalSegment_Visual">
      <origin xyz="0.0 0.0 0.0" rpy="0.0 0.0 0.0"/>
      <geometry>
        <mesh filename="../meshes/F_ProximalSegment_Frame.stl"/>
      </geometry>
      <material name="">
        <color rgba="0.94118 0.67451 0.11765 1.0"/>
      </material>
    </visual>
    <collision name="GLF4ProximalSegment_Collision">
      <origin xyz="0.0 0.0 0.0" rpy="0.0 0.0 0.0"/>
      <geometry>
        <mesh filename="../meshes/F_ProximalSegment_Frame_convexhull.stl" scale="1.0 1.0 1.0"/>
      </geometry>
    </collision>
  </link>
  <joint name="GLF4TopSegment" type="revolute">
    <origin xyz="0.0 0.0 0.0" rpy="0.0 0.0 0.0"/>
    <axis xyz="1.0 0.0 0.0"/>
    <parent link="GLF4Gear_Link"/>
    <child link="GLF4TopSegment_Link"/>
    <limit effort="400.0" lower="0.0" upper="2.1" velocity="3.1415926"/>
  </joint>
  <link name="GLF4TopSegment_Link">
    <inertial>
      <origin xyz="0.00093543 0.026024 -0.013282" rpy="0.0 0.0 0.0"/>
      <mass value="0.049549"/>
      <inertia ixx="1.1651277429850969e-05" ixy="4.429600000000007e-07" ixz="-6.034000000000013e-08" iyy="1.0300577429850967e-05" iyz="7.458100000000004e-07" izz="1.319687742985097e-05"/>
    </inertial>
    <visual name="GLF4TopSegment_Visual">
      <origin xyz="0.0 0.0 0.0" rpy="0.0 0.0 0.0"/>
      <geometry>
        <mesh filename="../meshes/F_TopSegment_Frame.stl"/>
      </geometry>
      <material name="">
        <color rgba="0.94118 0.67451 0.11765 1.0"/>
      </material>
    </visual>
    <collision name="GLF4TopSegment_Collision">
      <origin xyz="0.0 0.0 0.0" rpy="0.0 0.0 0.0"/>
      <geometry>
        <mesh filename="../meshes/F_TopSegment_Frame_convexhull.stl" scale="1.0 1.0 1.0"/>
      </geometry>
    </collision>
  </link>
  <joint name="GLF4TouchSensorDistal" type="fixed">
    <origin xyz="0.000200002939819318 0.0407117537406957 -0.0292563156876496" rpy="-3.14159265358978 1.17417004512815 -1.57079632679488"/>
    <parent link="GLF4TopSegment_Link"/>
    <child link="GLF4TouchSensorDistal_Link"/>
  </joint>
  <link name="GLF4TouchSensorDistal_Link">
    <inertial>
      <origin xyz="0.0 0.0 0.0" rpy="0.0 0.0 0.0"/>
      <mass value="1e-05"/>
      <inertia ixx="1e-05" ixy="0.0" ixz="0.0" iyy="1e-05" iyz="0.0" izz="1e-05"/>
    </inertial>
  </link>
  <joint name="GLF4TouchSensorIntermedial" type="fixed">
    <origin xyz="0.000200000530702645 0.0123371368999994 -0.01766647971245" rpy="-3.14159265358978 1.18769356276747 -1.57079632679488"/>
    <parent link="GLF4TopSegment_Link"/>
    <child link="GLF4TouchSensorIntermedial_Link"/>
  </joint>
  <link name="GLF4TouchSensorIntermedial_Link">
    <inertial>
      <origin xyz="0.0 0.0 0.0" rpy="0.0 0.0 0.0"/>
      <mass value="1e-05"/>
      <inertia ixx="1e-05" ixy="0.0" ixz="0.0" iyy="1e-05" iyz="0.0" izz="1e-05"/>
    </inertial>
  </link>
  <joint name="GLF4TouchSensor_FingerProximal" type="fixed">
    <origin xyz="0.0003 0.0088011 0.024649" rpy="0.0 -0.15059 1.5708"/>
    <parent link="GLF4ProximalSegment_Link"/>
    <child link="GLF4TouchSensor_FingerProximal_Link"/>
  </joint>
  <link name="GLF4TouchSensor_FingerProximal_Link">
    <inertial>
      <origin xyz="0.0 0.0 0.0" rpy="0.0 0.0 0.0"/>
      <mass value="1e-05"/>
      <inertia ixx="1e-05" ixy="0.0" ixz="0.0" iyy="1e-05" iyz="0.0" izz="1e-05"/>
    </inertial>
  </link>
  <joint name="GLIMU" type="fixed">
    <origin xyz="-0.003256 0.00202 0.053849" rpy="0.0 1.3526 0.0"/>
    <parent link="GLBase_Link"/>
    <child link="GLIMU_Link"/>
  </joint>
  <link name="GLIMU_Link">
    <inertial>
      <origin xyz="0.0 -0.0 0.0" rpy="0.0 0.0 0.0"/>
      <mass value="1e-05"/>
      <inertia ixx="1e-05" ixy="0.0" ixz="0.0" iyy="1e-05" iyz="0.0" izz="1e-05"/>
    </inertial>
  </link>
  <joint name="GLThumb" type="revolute">
    <origin xyz="0.019161 -0.002327 0.042" rpy="0.0 0.0 3.141593"/>
    <axis xyz="1.0 0.0 0.0"/>
    <parent link="GLBase_Link"/>
    <child link="GLThumb_Link"/>
    <limit effort="400.0" lower="-0.261" upper="1.309" velocity="3.1415926"/>
  </joint>
  <link name="GLThumb_Link">
    <inertial>
      <origin xyz="-0.013372 -1.5e-05 0.005722" rpy="0.0 0.0 0.0"/>
      <mass value="0.15951000503205323"/>
      <inertia ixx="0.00012916999997455712" ixy="-3.672917796453883e-08" ixz="-5.48909950442523e-07" iyy="9.690200002544285e-05" iyz="1.4306019014801817e-07" izz="0.000100037"/>
    </inertial>
    <visual name="GLThumb_Visual">
      <origin xyz="0.0 -0.0 0.0" rpy="0.0 0.0 3.141593"/>
      <geometry>
        <mesh filename="../meshes/GL_Thumb.stl" scale="1.0 1.0 1.0"/>
      </geometry>
      <material name="">
        <color rgba="0.94118 0.67451 0.11765 1.0"/>
      </material>
    </visual>
    <collision name="GLThumb_Collision">
      <origin xyz="0.0 0.0 0.0" rpy="0.0 0.0 0.0"/>
      <geometry>
        <mesh filename="../meshes/GL_Thumb_convexhull.stl" scale="1.0 1.0 1.0"/>
      </geometry>
    </collision>
  </link>
  <joint name="GRBase" type="fixed">
    <origin xyz="0.0 0.0 0.0" rpy="0.0 0.0 3.1415926535"/>
    <parent link="ARWristFT_Link"/>
    <child link="GRBase_Link"/>
  </joint>
  <link name="GRBase_Link">
    <inertial>
      <origin xyz="-7.9877e-05 0.0039477 0.041434" rpy="0.0 0.0 0.0"/>
      <mass value="0.16915002046641558"/>
      <inertia ixx="0.00014761" ixy="-2.1314e-09" ixz="-5.6431e-09" iyy="0.00027908999999999996" iyz="2.001199999999992e-07" izz="0.00017465"/>
    </inertial>
    <visual name="GRBase_Visual">
      <origin xyz="0.0 0.0 0.0" rpy="0.0 0.0 0.0"/>
      <geometry>
        <mesh filename="../meshes/2FGripper_BaseFrame.stl"/>
      </geometry>
      <material name="">
        <color rgba="0.77647 0.75686 0.73725 1.0"/>
      </material>
    </visual>
    <collision name="GRBase_Collision">
      <origin xyz="0.0 0.0 0.0" rpy="0.0 0.0 0.0"/>
      <geometry>
        <mesh filename="../meshes/2FGripper_BaseFrame_convexhull.stl" scale="1.0 1.0 1.0"/>
      </geometry>
    </collision>
  </link>
  <joint name="GRF1Base" type="fixed">
    <origin xyz="-0.021725 -0.013001 0.064903" rpy="1.789 0.0 -1.5708"/>
    <parent link="GRBase_Link"/>
    <child link="GRF1Base_Link"/>
  </joint>
  <link name="GRF1Base_Link">
    <inertial>
      <origin xyz="-0.013075 -0.015412 0.022007" rpy="0.0 0.0 0.0"/>
      <mass value="0.19184"/>
      <inertia ixx="3.9359e-05" ixy="-1.1994e-07" ixz="-1.876e-07" iyy="3.2122e-05" iyz="-2.0609e-07" izz="4.6536e-05"/>
    </inertial>
    <visual name="GRF1Base_Visual">
      <origin xyz="0.0 0.0 0.0" rpy="0.0 0.0 0.0"/>
      <geometry>
        <mesh filename="../meshes/Finger_Base_Frame.stl"/>
      </geometry>
      <material name="">
        <color rgba="0.79216 0.81961 0.93333 1.0"/>
      </material>
    </visual>
    <collision name="GRF1Base_Collision">
      <origin xyz="0.0 0.0 0.0" rpy="0.0 0.0 0.0"/>
      <geometry>
        <mesh filename="../meshes/Finger_Base_Frame_convexhull.stl" scale="1.0 1.0 1.0"/>
      </geometry>
    </collision>
  </link>
  <joint name="GRF1DistanceSensorDistal1" type="fixed">
    <origin xyz="0.000299999833291532 -0.0247775082611843 -0.0163492159542979" rpy="0.0 1.13794911843156 1.5707963267949"/>
    <parent link="GRF1TopSegment_Link"/>
    <child link="GRF1DistanceSensorDistal1_Link"/>
  </joint>
  <link name="GRF1DistanceSensorDistal1_Link">
    <inertial>
      <origin xyz="0.0 0.0 0.0" rpy="0.0 0.0 0.0"/>
      <mass value="1e-05"/>
      <inertia ixx="1e-05" ixy="0.0" ixz="0.0" iyy="1e-05" iyz="0.0" izz="1e-05"/>
    </inertial>
  </link>
  <joint name="GRF1DistanceSensorDistal2" type="fixed">
    <origin xyz="0.000199995310425429 0.0507125844075086 -0.0195804953991652" rpy="3.14159265358977 -0.751361283639969 1.57079632679489"/>
    <parent link="GRF1TopSegment_Link"/>
    <child link="GRF1DistanceSensorDistal2_Link"/>
  </joint>
  <link name="GRF1DistanceSensorDistal2_Link">
    <inertial>
      <origin xyz="0.0 0.0 0.0" rpy="0.0 0.0 0.0"/>
      <mass value="1e-05"/>
      <inertia ixx="1e-05" ixy="0.0" ixz="0.0" iyy="1e-05" iyz="0.0" izz="1e-05"/>
    </inertial>
  </link>
  <joint name="GRF1Gear" type="revolute">
    <origin xyz="0.0 0.0 0.053" rpy="1.2885 0.0 0.0"/>
    <axis xyz="1.0 0.0 0.0"/>
    <parent link="GRF1ProximalSegment_Link"/>
    <child link="GRF1Gear_Link"/>
    <limit effort="400.0" lower="-3.1415926" upper="3.1415926" velocity="3.1415926"/>
    <mimic joint="GRF1ProximalSegment" multiplier="-1.0" offset="0.0"/>
  </joint>
  <link name="GRF1Gear_Link">
    <inertial>
      <origin xyz="0.00042134 0.00032509 0.0086803" rpy="0.0 0.0 0.0"/>
      <mass value="0.024785"/>
      <inertia ixx="1.1031768852531896e-05" ixy="-3.314199999999995e-09" ixz="-1.3220000000000009e-08" iyy="1.04518688525319e-05" iyz="-1.0513000000000047e-07" izz="1.0024648852531899e-05"/>
    </inertial>
    <visual name="GRF1Gear_Visual">
      <origin xyz="0.0 0.0 0.0" rpy="0.0 0.0 0.0"/>
      <geometry>
        <mesh filename="../meshes/F_Gear_Frame.stl"/>
      </geometry>
      <material name="">
        <color rgba="0.94118 0.67451 0.11765 1.0"/>
      </material>
    </visual>
    <collision name="GRF1Gear_Collision">
      <origin xyz="0.0 0.0 0.0" rpy="0.0 0.0 0.0"/>
      <geometry>
        <mesh filename="../meshes/F_Gear_Frame_convexhull.stl" scale="1.0 1.0 1.0"/>
      </geometry>
    </collision>
  </link>
  <joint name="GRF1ProximalBar" type="revolute">
    <origin xyz="-0.01305 0.020512 0.035979" rpy="-1.1138 0.0 0.0"/>
    <axis xyz="-1.0 0.0 0.0"/>
    <parent link="GRF1Base_Link"/>
    <child link="GRF1ProximalBar_Link"/>
    <limit effort="400.0" lower="-3.1415926" upper="3.1415926" velocity="3.1415926"/>
    <mimic joint="GRF1ProximalSegment" multiplier="-1.0" offset="0.0"/>
  </joint>
  <link name="GRF1ProximalBar_Link">
    <inertial>
      <origin xyz="0.0021195 9.8516e-05 0.017626" rpy="0.0 0.0 0.0"/>
      <mass value="0.013406"/>
      <inertia ixx="1.3148561531334552e-05" ixy="-2.4433999999999384e-08" ixz="2.606700000000039e-07" iyy="1.3680961531334562e-05" iyz="7.3035999999996e-08" izz="1.0023111531334548e-05"/>
    </inertial>
    <visual name="GRF1ProximalBar_Visual">
      <origin xyz="0.0 0.0 0.0" rpy="0.0 0.0 0.0"/>
      <geometry>
        <mesh filename="../meshes/F_ProximalBar_Frame.stl"/>
      </geometry>
      <material name="">
        <color rgba="0.94118 0.67451 0.11765 1.0"/>
      </material>
    </visual>
    <collision name="GRF1ProximalBar_Collision">
      <origin xyz="0.0 0.0 0.0" rpy="0.0 0.0 0.0"/>
      <geometry>
        <mesh filename="../meshes/F_ProximalBar_Frame_convexhull.stl" scale="1.0 1.0 1.0"/>
      </geometry>
    </collision>
  </link>
  <joint name="GRF1ProximalSegment" type="revolute">
    <origin xyz="-0.01305 0.01575 0.0145" rpy="-1.1257 0.0 0.0"/>
    <axis xyz="1.0 0.0 0.0"/>
    <parent link="GRF1Base_Link"/>
    <child link="GRF1ProximalSegment_Link"/>
    <limit effort="400.0" lower="-0.62" upper="0.75" velocity="3.1415926"/>
  </joint>
  <link name="GRF1ProximalSegment_Link">
    <inertial>
      <origin xyz="-0.0020803 0.000387 0.0216" rpy="0.0 0.0 0.0"/>
      <mass value="0.054293"/>
      <inertia ixx="2.0885480277942027e-05" ixy="-1.4302000000000018e-08" ixz="-2.6832000000000287e-07" iyy="2.3749480277942032e-05" iyz="6.182299999999969e-07" izz="1.0034380277942036e-05"/>
    </inertial>
    <visual name="GRF1ProximalSegment_Visual">
      <origin xyz="0.0 0.0 0.0" rpy="0.0 0.0 0.0"/>
      <geometry>
        <mesh filename="../meshes/F_ProximalSegment_Frame.stl"/>
      </geometry>
      <material name="">
        <color rgba="0.94118 0.67451 0.11765 1.0"/>
      </material>
    </visual>
    <collision name="GRF1ProximalSegment_Collision">
      <origin xyz="0.0 0.0 0.0" rpy="0.0 0.0 0.0"/>
      <geometry>
        <mesh filename="../meshes/F_ProximalSegment_Frame_convexhull.stl" scale="1.0 1.0 1.0"/>
      </geometry>
    </collision>
  </link>
  <joint name="GRF1TopSegment" type="revolute">
    <origin xyz="0.0 0.0 0.0" rpy="0.0 0.0 0.0"/>
    <axis xyz="1.0 0.0 0.0"/>
    <parent link="GRF1Gear_Link"/>
    <child link="GRF1TopSegment_Link"/>
    <limit effort="400.0" lower="0.0" upper="2.1" velocity="3.1415926"/>
  </joint>
  <link name="GRF1TopSegment_Link">
    <inertial>
      <origin xyz="0.00093543 0.026024 -0.013282" rpy="0.0 0.0 0.0"/>
      <mass value="0.049549"/>
      <inertia ixx="1.1651277429850969e-05" ixy="4.429600000000007e-07" ixz="-6.034000000000013e-08" iyy="1.0300577429850967e-05" iyz="7.458100000000004e-07" izz="1.319687742985097e-05"/>
    </inertial>
    <visual name="GRF1TopSegment_Visual">
      <origin xyz="0.0 0.0 0.0" rpy="0.0 0.0 0.0"/>
      <geometry>
        <mesh filename="../meshes/F_TopSegment_Frame.stl"/>
      </geometry>
      <material name="">
        <color rgba="0.94118 0.67451 0.11765 1.0"/>
      </material>
    </visual>
    <collision name="GRF1TopSegment_Collision">
      <origin xyz="0.0 0.0 0.0" rpy="0.0 0.0 0.0"/>
      <geometry>
        <mesh filename="../meshes/F_TopSegment_Frame_convexhull.stl" scale="1.0 1.0 1.0"/>
      </geometry>
    </collision>
  </link>
  <joint name="GRF1TouchSensorDistal" type="fixed">
    <origin xyz="0.000200002939819318 0.0407117537406957 -0.0292563156876496" rpy="-3.14159265358978 1.17417004512815 -1.57079632679488"/>
    <parent link="GRF1TopSegment_Link"/>
    <child link="GRF1TouchSensorDistal_Link"/>
  </joint>
  <link name="GRF1TouchSensorDistal_Link">
    <inertial>
      <origin xyz="0.0 0.0 0.0" rpy="0.0 0.0 0.0"/>
      <mass value="1e-05"/>
      <inertia ixx="1e-05" ixy="0.0" ixz="0.0" iyy="1e-05" iyz="0.0" izz="1e-05"/>
    </inertial>
  </link>
  <joint name="GRF1TouchSensorIntermedial" type="fixed">
    <origin xyz="0.000200000530702645 0.0123371368999994 -0.01766647971245" rpy="-3.14159265358978 1.18769356276747 -1.57079632679488"/>
    <parent link="GRF1TopSegment_Link"/>
    <child link="GRF1TouchSensorIntermedial_Link"/>
  </joint>
  <link name="GRF1TouchSensorIntermedial_Link">
    <inertial>
      <origin xyz="0.0 0.0 0.0" rpy="0.0 0.0 0.0"/>
      <mass value="1e-05"/>
      <inertia ixx="1e-05" ixy="0.0" ixz="0.0" iyy="1e-05" iyz="0.0" izz="1e-05"/>
    </inertial>
  </link>
  <joint name="GRF1TouchSensor_FingerProximal" type="fixed">
    <origin xyz="0.0003 0.0088011 0.024649" rpy="0.0 -0.15059 1.5708"/>
    <parent link="GRF1ProximalSegment_Link"/>
    <child link="GRF1TouchSensor_FingerProximal_Link"/>
  </joint>
  <link name="GRF1TouchSensor_FingerProximal_Link">
    <inertial>
      <origin xyz="0.0 0.0 0.0" rpy="0.0 0.0 0.0"/>
      <mass value="1e-05"/>
      <inertia ixx="1e-05" ixy="0.0" ixz="0.0" iyy="1e-05" iyz="0.0" izz="1e-05"/>
    </inertial>
  </link>
  <joint name="GRF2Base" type="fixed">
    <origin xyz="0.02175 0.012996 0.064903" rpy="1.789 0.0 1.5708"/>
    <parent link="GRBase_Link"/>
    <child link="GRF2Base_Link"/>
  </joint>
  <link name="GRF2Base_Link">
    <inertial>
      <origin xyz="-0.013075 -0.015412 0.022007" rpy="0.0 0.0 0.0"/>
      <mass value="0.19184"/>
      <inertia ixx="3.9359e-05" ixy="-1.1994e-07" ixz="-1.876e-07" iyy="3.2122e-05" iyz="-2.0609e-07" izz="4.6536e-05"/>
    </inertial>
    <visual name="GRF2Base_Visual">
      <origin xyz="0.0 0.0 0.0" rpy="0.0 0.0 0.0"/>
      <geometry>
        <mesh filename="../meshes/Finger_Base_Frame.stl"/>
      </geometry>
      <material name="">
        <color rgba="0.79216 0.81961 0.93333 1.0"/>
      </material>
    </visual>
    <collision name="GRF2Base_Collision">
      <origin xyz="0.0 0.0 0.0" rpy="0.0 0.0 0.0"/>
      <geometry>
        <mesh filename="../meshes/Finger_Base_Frame_convexhull.stl" scale="1.0 1.0 1.0"/>
      </geometry>
    </collision>
  </link>
  <joint name="GRF2DistanceSensorDistal1" type="fixed">
    <origin xyz="0.000299999833291532 -0.0247775082611843 -0.0163492159542979" rpy="0.0 1.13794911843156 1.5707963267949"/>
    <parent link="GRF2TopSegment_Link"/>
    <child link="GRF2DistanceSensorDistal1_Link"/>
  </joint>
  <link name="GRF2DistanceSensorDistal1_Link">
    <inertial>
      <origin xyz="0.0 0.0 0.0" rpy="0.0 0.0 0.0"/>
      <mass value="1e-05"/>
      <inertia ixx="1e-05" ixy="0.0" ixz="0.0" iyy="1e-05" iyz="0.0" izz="1e-05"/>
    </inertial>
  </link>
  <joint name="GRF2DistanceSensorDistal2" type="fixed">
    <origin xyz="0.000199995310425429 0.0507125844075086 -0.0195804953991652" rpy="3.14159265358977 -0.751361283639969 1.57079632679489"/>
    <parent link="GRF2TopSegment_Link"/>
    <child link="GRF2DistanceSensorDistal2_Link"/>
  </joint>
  <link name="GRF2DistanceSensorDistal2_Link">
    <inertial>
      <origin xyz="0.0 0.0 0.0" rpy="0.0 0.0 0.0"/>
      <mass value="1e-05"/>
      <inertia ixx="1e-05" ixy="0.0" ixz="0.0" iyy="1e-05" iyz="0.0" izz="1e-05"/>
    </inertial>
  </link>
  <joint name="GRF2Gear" type="revolute">
    <origin xyz="0.0 0.0 0.053" rpy="1.2885 0.0 0.0"/>
    <axis xyz="1.0 0.0 0.0"/>
    <parent link="GRF2ProximalSegment_Link"/>
    <child link="GRF2Gear_Link"/>
    <limit effort="400.0" lower="-3.1415926" upper="3.1415926" velocity="3.1415926"/>
    <mimic joint="GRF2ProximalSegment" multiplier="-1.0" offset="0.0"/>
  </joint>
  <link name="GRF2Gear_Link">
    <inertial>
      <origin xyz="0.00042134 0.00032509 0.0086803" rpy="0.0 0.0 0.0"/>
      <mass value="0.024785"/>
      <inertia ixx="1.1031768852531896e-05" ixy="-3.314199999999995e-09" ixz="-1.3220000000000009e-08" iyy="1.04518688525319e-05" iyz="-1.0513000000000047e-07" izz="1.0024648852531899e-05"/>
    </inertial>
    <visual name="GRF2Gear_Visual">
      <origin xyz="0.0 0.0 0.0" rpy="0.0 0.0 0.0"/>
      <geometry>
        <mesh filename="../meshes/F_Gear_Frame.stl"/>
      </geometry>
      <material name="">
        <color rgba="0.94118 0.67451 0.11765 1.0"/>
      </material>
    </visual>
    <collision name="GRF2Gear_Collision">
      <origin xyz="0.0 0.0 0.0" rpy="0.0 0.0 0.0"/>
      <geometry>
        <mesh filename="../meshes/F_Gear_Frame_convexhull.stl" scale="1.0 1.0 1.0"/>
      </geometry>
    </collision>
  </link>
  <joint name="GRF2ProximalBar" type="revolute">
    <origin xyz="-0.01305 0.020512 0.035979" rpy="-1.1138 0.0 0.0"/>
    <axis xyz="-1.0 0.0 0.0"/>
    <parent link="GRF2Base_Link"/>
    <child link="GRF2ProximalBar_Link"/>
    <limit effort="400.0" lower="-3.1415926" upper="3.1415926" velocity="3.1415926"/>
    <mimic joint="GRF2ProximalSegment" multiplier="-1.0" offset="0.0"/>
  </joint>
  <link name="GRF2ProximalBar_Link">
    <inertial>
      <origin xyz="0.0021195 9.8516e-05 0.017626" rpy="0.0 0.0 0.0"/>
      <mass value="0.013406"/>
      <inertia ixx="1.3148561531334552e-05" ixy="-2.4433999999999384e-08" ixz="2.606700000000039e-07" iyy="1.3680961531334562e-05" iyz="7.3035999999996e-08" izz="1.0023111531334548e-05"/>
    </inertial>
    <visual name="GRF2ProximalBar_Visual">
      <origin xyz="0.0 0.0 0.0" rpy="0.0 0.0 0.0"/>
      <geometry>
        <mesh filename="../meshes/F_ProximalBar_Frame.stl"/>
      </geometry>
      <material name="">
        <color rgba="0.94118 0.67451 0.11765 1.0"/>
      </material>
    </visual>
    <collision name="GRF2ProximalBar_Collision">
      <origin xyz="0.0 0.0 0.0" rpy="0.0 0.0 0.0"/>
      <geometry>
        <mesh filename="../meshes/F_ProximalBar_Frame_convexhull.stl" scale="1.0 1.0 1.0"/>
      </geometry>
    </collision>
  </link>
  <joint name="GRF2ProximalSegment" type="revolute">
    <origin xyz="-0.01305 0.01575 0.0145" rpy="-1.1257 0.0 0.0"/>
    <axis xyz="1.0 0.0 0.0"/>
    <parent link="GRF2Base_Link"/>
    <child link="GRF2ProximalSegment_Link"/>
    <limit effort="400.0" lower="-0.62" upper="0.75" velocity="3.1415926"/>
  </joint>
  <link name="GRF2ProximalSegment_Link">
    <inertial>
      <origin xyz="-0.0020803 0.000387 0.0216" rpy="0.0 0.0 0.0"/>
      <mass value="0.054293"/>
      <inertia ixx="2.0885480277942027e-05" ixy="-1.4302000000000018e-08" ixz="-2.6832000000000287e-07" iyy="2.3749480277942032e-05" iyz="6.182299999999969e-07" izz="1.0034380277942036e-05"/>
    </inertial>
    <visual name="GRF2ProximalSegment_Visual">
      <origin xyz="0.0 0.0 0.0" rpy="0.0 0.0 0.0"/>
      <geometry>
        <mesh filename="../meshes/F_ProximalSegment_Frame.stl"/>
      </geometry>
      <material name="">
        <color rgba="0.94118 0.67451 0.11765 1.0"/>
      </material>
    </visual>
    <collision name="GRF2ProximalSegment_Collision">
      <origin xyz="0.0 0.0 0.0" rpy="0.0 0.0 0.0"/>
      <geometry>
        <mesh filename="../meshes/F_ProximalSegment_Frame_convexhull.stl" scale="1.0 1.0 1.0"/>
      </geometry>
    </collision>
  </link>
  <joint name="GRF2TopSegment" type="revolute">
    <origin xyz="0.0 0.0 0.0" rpy="0.0 0.0 0.0"/>
    <axis xyz="1.0 0.0 0.0"/>
    <parent link="GRF2Gear_Link"/>
    <child link="GRF2TopSegment_Link"/>
    <limit effort="400.0" lower="0.0" upper="2.1" velocity="3.1415926"/>
  </joint>
  <link name="GRF2TopSegment_Link">
    <inertial>
      <origin xyz="0.00093543 0.026024 -0.013282" rpy="0.0 0.0 0.0"/>
      <mass value="0.049549"/>
      <inertia ixx="1.1651277429850969e-05" ixy="4.429600000000007e-07" ixz="-6.034000000000013e-08" iyy="1.0300577429850967e-05" iyz="7.458100000000004e-07" izz="1.319687742985097e-05"/>
    </inertial>
    <visual name="GRF2TopSegment_Visual">
      <origin xyz="0.0 0.0 0.0" rpy="0.0 0.0 0.0"/>
      <geometry>
        <mesh filename="../meshes/F_TopSegment_Frame.stl"/>
      </geometry>
      <material name="">
        <color rgba="0.94118 0.67451 0.11765 1.0"/>
      </material>
    </visual>
    <collision name="GRF2TopSegment_Collision">
      <origin xyz="0.0 0.0 0.0" rpy="0.0 0.0 0.0"/>
      <geometry>
        <mesh filename="../meshes/F_TopSegment_Frame_convexhull.stl" scale="1.0 1.0 1.0"/>
      </geometry>
    </collision>
  </link>
  <joint name="GRF2TouchSensorDistal" type="fixed">
    <origin xyz="0.000200002939819318 0.0407117537406957 -0.0292563156876496" rpy="-3.14159265358978 1.17417004512815 -1.57079632679488"/>
    <parent link="GRF2TopSegment_Link"/>
    <child link="GRF2TouchSensorDistal_Link"/>
  </joint>
  <link name="GRF2TouchSensorDistal_Link">
    <inertial>
      <origin xyz="0.0 0.0 0.0" rpy="0.0 0.0 0.0"/>
      <mass value="1e-05"/>
      <inertia ixx="1e-05" ixy="0.0" ixz="0.0" iyy="1e-05" iyz="0.0" izz="1e-05"/>
    </inertial>
  </link>
  <joint name="GRF2TouchSensorIntermedial" type="fixed">
    <origin xyz="0.000200000530702645 0.0123371368999994 -0.01766647971245" rpy="-3.14159265358978 1.18769356276747 -1.57079632679488"/>
    <parent link="GRF2TopSegment_Link"/>
    <child link="GRF2TouchSensorIntermedial_Link"/>
  </joint>
  <link name="GRF2TouchSensorIntermedial_Link">
    <inertial>
      <origin xyz="0.0 0.0 0.0" rpy="0.0 0.0 0.0"/>
      <mass value="1e-05"/>
      <inertia ixx="1e-05" ixy="0.0" ixz="0.0" iyy="1e-05" iyz="0.0" izz="1e-05"/>
    </inertial>
  </link>
  <joint name="GRF2TouchSensor_FingerProximal" type="fixed">
    <origin xyz="0.0003 0.0088011 0.024649" rpy="0.0 -0.15059 1.5708"/>
    <parent link="GRF2ProximalSegment_Link"/>
    <child link="GRF2TouchSensor_FingerProximal_Link"/>
  </joint>
  <link name="GRF2TouchSensor_FingerProximal_Link">
    <inertial>
      <origin xyz="0.0 0.0 0.0" rpy="0.0 0.0 0.0"/>
      <mass value="1e-05"/>
      <inertia ixx="1e-05" ixy="0.0" ixz="0.0" iyy="1e-05" iyz="0.0" izz="1e-05"/>
    </inertial>
  </link>
  <joint name="GRIMU" type="fixed">
    <origin xyz="-0.0018624 0.026119 0.056625" rpy="-1.5708 -0.0097081 0.0"/>
    <parent link="GRBase_Link"/>
    <child link="GRIMU_Link"/>
  </joint>
  <link name="GRIMU_Link">
    <inertial>
      <origin xyz="0.0 0.0 0.0" rpy="0.0 0.0 0.0"/>
      <mass value="1e-05"/>
      <inertia ixx="1e-05" ixy="0.0" ixz="0.0" iyy="1e-05" iyz="0.0" izz="1e-05"/>
    </inertial>
  </link>
  <joint name="HeadActC" type="revolute">
    <origin xyz="0.15925 0.0 0.0" rpy="-1.5708 0.0 0.0"/>
    <axis xyz="1.0 0.0 0.0"/>
    <parent link="HeadBase_Link"/>
    <child link="HeadActC_Link"/>
    <limit effort="400.0" lower="-3.1415926" upper="3.1415926" velocity="3.1415926"/>
  </joint>
  <link name="HeadActC_Link">
    <inertial>
      <origin xyz="-0.017674 7.2495e-17 5.4996e-17" rpy="0.0 0.0 0.0"/>
      <mass value="0.0046686"/>
      <inertia ixx="1e-05" ixy="4.873599999999988e-23" ixz="5.031600000000013e-23" iyy="1.003789e-05" iyz="-4.798999999999274e-09" izz="1.004626e-05"/>
    </inertial>
    <visual name="HeadActC_Visual">
      <origin xyz="0.0 0.0 0.0" rpy="0.0 0.0 0.0"/>
      <geometry>
        <mesh filename="../meshes/Head_ActC.stl"/>
      </geometry>
      <material name="">
        <color rgba="0.89804 0.91765 0.92941 1.0"/>
      </material>
    </visual>
    <collision name="HeadActC_Collision">
      <origin xyz="0.0 0.0 0.0" rpy="0.0 0.0 0.0"/>
      <geometry>
        <mesh filename="../meshes/Head_ActC_convexhull.stl" scale="1.0 1.0 1.0"/>
      </geometry>
    </collision>
  </link>
  <joint name="HeadActL" type="revolute">
    <origin xyz="0.15925 0.0 0.0" rpy="3.1416 0.0 1.5708"/>
    <axis xyz="1.0 0.0 0.0"/>
    <parent link="HeadBase_Link"/>
    <child link="HeadActL_Link"/>
    <limit effort="400.0" lower="-3.1415926" upper="3.1415926" velocity="3.1415926"/>
  </joint>
  <link name="HeadActL_Link">
    <inertial>
      <origin xyz="-0.018628 0.0 1.3747e-17" rpy="0.0 0.0 0.0"/>
      <mass value="0.049162"/>
      <inertia ixx="1.50716e-05" ixy="3.3203e-22" ixz="-3.6271000000000003e-22" iyy="1.0000000000000003e-05" iyz="-8.470329472543003e-22" izz="1.0000000000000003e-05"/>
    </inertial>
    <visual name="HeadActL_Visual">
      <origin xyz="0.0 0.0 0.0" rpy="0.0 0.0 0.0"/>
      <geometry>
        <mesh filename="../meshes/Head_ActL.stl"/>
      </geometry>
      <material name="">
        <color rgba="0.69804 0.69804 0.69804 1.0"/>
      </material>
    </visual>
    <collision name="HeadActL_Collision">
      <origin xyz="0.0 0.0 0.0" rpy="0.0 0.0 0.0"/>
      <geometry>
        <mesh filename="../meshes/Head_ActL_convexhull.stl" scale="1.0 1.0 1.0"/>
      </geometry>
    </collision>
  </link>
  <joint name="HeadActR" type="revolute">
    <origin xyz="0.15925 0.0 0.0" rpy="0.0 0.0 -1.5708"/>
    <axis xyz="1.0 0.0 0.0"/>
    <parent link="HeadBase_Link"/>
    <child link="HeadActR_Link"/>
    <limit effort="400.0" lower="-3.1415926" upper="3.1415926" velocity="3.1415926"/>
  </joint>
  <link name="HeadActR_Link">
    <inertial>
      <origin xyz="-0.018628 -1.3878e-17 9.5749e-18" rpy="0.0 0.0 0.0"/>
      <mass value="0.049162"/>
      <inertia ixx="1.5071600000000002e-05" ixy="2.9254000000000035e-22" ixz="-3.611699999999999e-22" iyy="1.0000000000000008e-05" iyz="-2.541098841762901e-21" izz="1e-05"/>
    </inertial>
    <visual name="HeadActR_Visual">
      <origin xyz="0.0 0.0 0.0" rpy="0.0 0.0 0.0"/>
      <geometry>
        <mesh filename="../meshes/Head_ActR.stl"/>
      </geometry>
      <material name="">
        <color rgba="0.69804 0.69804 0.69804 1.0"/>
      </material>
    </visual>
    <collision name="HeadActR_Collision">
      <origin xyz="0.0 0.0 0.0" rpy="0.0 0.0 0.0"/>
      <geometry>
        <mesh filename="../meshes/Head_ActR_convexhull.stl" scale="1.0 1.0 1.0"/>
      </geometry>
    </collision>
  </link>
  <joint name="HeadBase" type="fixed">
    <origin xyz="0.3485 0.0 0.0" rpy="-3.141592 0.0 0.0"/>
    <parent link="Connector_Body/Torso_Link"/>
    <child link="HeadBase_Link"/>
  </joint>
  <link name="HeadBase_Link">
    <inertial>
      <origin xyz="0.074228 -3.6471e-05 -0.00062034" rpy="0.0 0.0 0.0"/>
      <mass value="1.339"/>
      <inertia ixx="0.0017089" ixy="4.2668e-08" ixz="5.2598e-08" iyy="0.0014476" iyz="7.0143e-07" izz="0.0013396"/>
    </inertial>
    <visual name="HeadBase_Visual">
      <origin xyz="0.0 0.0 0.0" rpy="0.0 0.0 0.0"/>
      <geometry>
        <mesh filename="../meshes/Head_Base.stl"/>
      </geometry>
      <material name="">
        <color rgba="0.69804 0.69804 0.69804 1.0"/>
      </material>
    </visual>
    <collision name="HeadBase_Collision">
      <origin xyz="0.0 0.0 0.0" rpy="0.0 0.0 0.0"/>
      <geometry>
        <mesh filename="../meshes/Head_Base_convexhull.stl" scale="1.0 1.0 1.0"/>
      </geometry>
    </collision>
  </link>
  <joint name="HeadPitch" type="revolute">
    <origin xyz="0.15925 0.0 0.0" rpy="0.0 0.0 -1.5708"/>
    <axis xyz="1.0 0.0 0.0"/>
    <parent link="HeadBase_Link"/>
    <child link="HeadPitch_Link"/>
    <limit effort="400.0" lower="-0.3" upper="0.35" velocity="3.1415926"/>
  </joint>
  <link name="HeadPitch_Link">
    <inertial>
      <origin xyz="3.73800046473431e-08 -4.45791975556276e-09 0.00296950883117566" rpy="0.0 0.0 0.0"/>
      <mass value="0.0135306815484183"/>
      <inertia ixx="1.0900469792997046e-05" ixy="-1.983276674419689e-12" ixz="2.9229038977620623e-12" iyy="1.1777940400612256e-05" iyz="-1.006944634337718e-13" izz="1.0000000000009494e-05"/>
    </inertial>
    <visual name="HeadPitch_Visual">
      <origin xyz="0.0 0.0 0.0" rpy="0.0 0.0 0.0"/>
      <geometry>
        <mesh filename="../meshes/HeadPitch.stl"/>
      </geometry>
      <material name="">
        <color rgba="0.898039215686275 0.917647058823529 0.929411764705882 1.0"/>
      </material>
    </visual>
    <collision name="HeadPitch_Collision">
      <origin xyz="0.0 0.0 0.0" rpy="0.0 0.0 0.0"/>
      <geometry>
        <mesh filename="../meshes/HeadPitch_convexhull.stl" scale="1.0 1.0 1.0"/>
      </geometry>
    </collision>
  </link>
  <joint name="HeadRoll" type="revolute">
    <origin xyz="0.0 0.0 0.0" rpy="-1.5708 -1.5708 0.0"/>
    <axis xyz="-1.0 0.0 0.0"/>
    <parent link="HeadPitch_Link"/>
    <child link="HeadRoll_Link"/>
    <limit effort="400.0" lower="-0.45" upper="0.007853981633974483" velocity="3.1415926"/>
  </joint>
  <link name="HeadRoll_Link">
    <inertial>
      <origin xyz="-0.00844253878850604 -4.18737776903302e-08 0.00884603238325907" rpy="0.0 0.0 0.0"/>
      <mass value="0.109788715391496"/>
      <inertia ixx="1.83994177455821e-05" ixy="5.13405597754959e-11" ixz="-1.07875589146075e-08" iyy="1.359548687449e-05" iyz="-9.3011670884998e-10" izz="1.39946184243742e-05"/>
    </inertial>
    <visual name="HeadRoll_Visual">
      <origin xyz="0.0 0.0 0.0" rpy="0.0 0.0 0.0"/>
      <geometry>
        <mesh filename="../meshes/HeadRoll.stl"/>
      </geometry>
      <material name="">
        <color rgba="0.898039215686275 0.917647058823529 0.929411764705882 1.0"/>
      </material>
    </visual>
    <collision name="HeadRoll_Collision">
      <origin xyz="0.0 0.0 0.0" rpy="0.0 0.0 0.0"/>
      <geometry>
        <mesh filename="../meshes/HeadRoll_convexhull.stl" scale="1.0 1.0 1.0"/>
      </geometry>
    </collision>
  </link>
  <joint name="HeadYaw" type="revolute">
    <origin xyz="0.0 0.0 0.0" rpy="1.5708 -1.5708 0.0"/>
    <axis xyz="1.0 0.0 0.0"/>
    <parent link="HeadRoll_Link"/>
    <child link="HeadYaw_Link"/>
    <limit effort="400.0" lower="-2.1" upper="2.1" velocity="3.1415926"/>
  </joint>
  <link name="HeadYaw_Link">
    <inertial>
      <origin xyz="0.0865202750448954 -0.0440420348532486 -0.00282280741895916" rpy="0.0 0.0 0.0"/>
      <mass value="1.46451930762968"/>
      <inertia ixx="0.00400957562211491" ixy="-0.000773636855316844" ixz="-8.24762860917018e-06" iyy="0.00399135489001388" iyz="-9.04346097850664e-06" izz="0.00411109150468807"/>
    </inertial>
    <visual name="HeadYaw_Visual">
      <origin xyz="0.0 0.0 0.0" rpy="0.0 0.0 0.0"/>
      <geometry>
        <mesh filename="../meshes/HeadYaw.stl"/>
      </geometry>
      <material name="">
        <color rgba="0.498039215686275 0.498039215686275 0.498039215686275 1.0"/>
      </material>
    </visual>
    <collision name="HeadYaw_Collision">
      <origin xyz="0.0 0.0 0.0" rpy="0.0 0.0 0.0"/>
      <geometry>
        <mesh filename="../meshes/HeadYaw_convexhull.stl" scale="1.0 1.0 1.0"/>
      </geometry>
    </collision>
  </link>
  <joint name="IMU_Body" type="fixed">
    <origin xyz="-0.01745 -0.005 0.10795" rpy="-3.141593 0.0 1.570793"/>
    <parent link="BodyRoot_Link"/>
    <child link="IMU_Body_Link"/>
  </joint>
  <link name="IMU_Body_Link">
    <inertial>
      <origin xyz="0.020181 0.018941 0.0015699" rpy="0.0 0.0 0.0"/>
      <mass value="0.093167"/>
      <inertia ixx="1.4618e-05" ixy="-6.5521e-08" ixz="-5.6588e-08" iyy="2.4402e-05" iyz="6.4435e-09" izz="3.4276e-05"/>
    </inertial>
    <visual name="IMU_Body_Visual">
      <origin xyz="0.0 0.0 0.0" rpy="0.0 0.0 0.0"/>
      <geometry>
        <mesh filename="../meshes/IMU_Body.stl"/>
      </geometry>
      <material name="">
        <color rgba="0.69804 0.69804 0.69804 1.0"/>
      </material>
    </visual>
    <collision name="IMU_Body_Collision">
      <origin xyz="0.0 0.0 0.0" rpy="0.0 0.0 0.0"/>
      <geometry>
        <mesh filename="../meshes/IMU_Body_convexhull.stl" scale="1.0 1.0 1.0"/>
      </geometry>
    </collision>
  </link>
  <joint name="IMU_Torso" type="fixed">
    <origin xyz="0.14735 -0.10255 0.0075" rpy="0.014588 -1.570793 3.127004"/>
    <parent link="Connector_Body/Torso_Link"/>
    <child link="IMU_Torso_Link"/>
  </joint>
  <link name="IMU_Torso_Link">
    <inertial>
      <origin xyz="0.020181 0.018941 0.0015699" rpy="0.0 0.0 0.0"/>
      <mass value="0.093167"/>
      <inertia ixx="1.4618e-05" ixy="-6.5519e-08" ixz="-5.6587e-08" iyy="2.4402e-05" iyz="6.4433e-09" izz="3.4276e-05"/>
    </inertial>
    <visual name="IMU_Torso_Visual">
      <origin xyz="0.0 0.0 0.0" rpy="0.0 0.0 0.0"/>
      <geometry>
        <mesh filename="../meshes/IMU_Torso.stl"/>
      </geometry>
      <material name="">
        <color rgba="0.69804 0.69804 0.69804 1.0"/>
      </material>
    </visual>
    <collision name="IMU_Torso_Collision">
      <origin xyz="0.0 0.0 0.0" rpy="0.0 0.0 0.0"/>
      <geometry>
        <mesh filename="../meshes/IMU_Torso_convexhull.stl" scale="1.0 1.0 1.0"/>
      </geometry>
    </collision>
  </link>
  <link name="RH5v2_Root_Link">
    <inertial>
      <origin xyz="0.004352 -2.1674e-05 -0.079131" rpy="0.0 0.0 0.0"/>
      <mass value="1.7255"/>
      <inertia ixx="0.016198" ixy="-6.064e-07" ixz="-0.0013383" iyy="0.010542" iyz="-5.0064e-07" izz="0.016367"/>
    </inertial>
    <visual name="RH5v2_Root_Link_Visual">
      <origin xyz="0.0 0.0 0.0" rpy="0.0 0.0 0.0"/>
      <geometry>
        <mesh filename="../meshes/RH5v2_Root_Link.stl"/>
      </geometry>
      <material name="">
        <color rgba="0.89804 0.91765 0.92941 1.0"/>
      </material>
    </visual>
    <collision name="RH5v2_Root_Link_Collision">
      <origin xyz="0.0 0.0 0.0" rpy="0.0 0.0 0.0"/>
      <geometry>
        <mesh filename="../meshes/RH5v2_Root_Link_convexhull.stl" scale="1.0 1.0 1.0"/>
      </geometry>
    </collision>
  </link>
  <joint name="Stereo_Camera_Head" type="fixed">
    <origin xyz="0.0689999999999992 -0.103499999999999 -0.0314985000000005" rpy="-1.5707963267949 0.0 -1.5707963267949"/>
    <parent link="HeadYaw_Link"/>
    <child link="Stereo_Camera_Head_Link"/>
  </joint>
  <link name="Stereo_Camera_Head_Link">
    <inertial>
      <origin xyz="0.0093017380297578 -0.0242892236376383 -2.56629836528632e-06" rpy="0.0 0.0 0.0"/>
      <mass value="0.163942749569653"/>
      <inertia ixx="0.000214569685214328" ixy="2.48189735161484e-06" ixz="-1.1783765192218e-09" iyy="1.54943903142391e-05" iyz="6.24843939247585e-10" izz="0.000213155596979443"/>
    </inertial>
    <visual name="Stereo_Camera_Head_Visual">
      <origin xyz="0.0 0.0 0.0" rpy="0.0 0.0 0.0"/>
      <geometry>
        <mesh filename="../meshes/Stereo_Camera_Head.stl"/>
      </geometry>
      <material name="">
        <color rgba="0.698039215686274 0.698039215686274 0.698039215686274 1.0"/>
      </material>
    </visual>
    <collision name="Stereo_Camera_Head_Collision">
      <origin xyz="0.0 0.0 0.0" rpy="0.0 0.0 0.0"/>
      <geometry>
        <mesh filename="../meshes/Stereo_Camera_Head_convexhull.stl" scale="1.0 1.0 1.0"/>
      </geometry>
    </collision>
  </link>
  <joint name="Structure_Sensor" type="fixed">
    <origin xyz="0.31589 -0.03825 -0.12041" rpy="7e-06 -0.34907 3.141585"/>
    <parent link="Connector_Body/Torso_Link"/>
    <child link="Structure_Sensor_Link"/>
  </joint>
  <link name="Structure_Sensor_Link">
    <inertial>
      <origin xyz="2.2259e-06 -0.037878 0.0056313" rpy="0.0 0.0 0.0"/>
      <mass value="0.35771"/>
      <inertia ixx="0.00037964" ixy="-5.261e-09" ixz="-7.6239e-10" iyy="3.9054e-05" iyz="-6.5398e-07" izz="0.00037075"/>
    </inertial>
    <visual name="Structure_Sensor_Visual">
      <origin xyz="0.0 0.0 0.0" rpy="0.0 0.0 0.0"/>
      <geometry>
        <mesh filename="../meshes/Structure_Sensor_Torso.stl"/>
      </geometry>
      <material name="">
        <color rgba="0.69804 0.69804 0.69804 1.0"/>
      </material>
    </visual>
    <collision name="Structure_Sensor_Collision">
      <origin xyz="0.0 0.0 0.0" rpy="0.0 0.0 0.0"/>
      <geometry>
        <mesh filename="../meshes/Structure_Sensor_Torso_convexhull.stl" scale="1.0 1.0 1.0"/>
      </geometry>
    </collision>
  </link>
</robot>
