<robot name="RH5">
  <joint name="FLC_FrontLeft" type="fixed">
    <origin xyz="0.13 -0.04 0.0274" rpy="3.1416 0.0 0.0"/>
    <axis xyz="0.0 0.0 0.0"/>
    <parent link="LLAnkle_FT"/>
    <child link="FLC_FrontLeft_Link"/>
  </joint>
  <link name="FLC_FrontLeft_Link">
    <collision name="FLC_FrontLeft_Collision">
      <origin xyz="0.0 0.0 0.0" rpy="0.0 0.0 0.0"/>
      <geometry>
        <sphere radius="0.017"/>
      </geometry>
    </collision>
  </link>
  <joint name="FLC_FrontRight" type="fixed">
    <origin xyz="0.13 0.04 0.0274" rpy="3.1416 0.0 0.0"/>
    <axis xyz="0.0 0.0 0.0"/>
    <parent link="LLAnkle_FT"/>
    <child link="FLC_FrontRight_Link"/>
  </joint>
  <link name="FLC_FrontRight_Link">
    <collision name="FLC_FrontRight_Collision">
      <origin xyz="0.0 0.0 0.0" rpy="0.0 0.0 0.0"/>
      <geometry>
        <sphere radius="0.017"/>
      </geometry>
    </collision>
  </link>
  <joint name="FLC_RearLeft" type="fixed">
    <origin xyz="-0.07 -0.04 0.0274" rpy="3.1416 0.0 0.0"/>
    <axis xyz="0.0 0.0 0.0"/>
    <parent link="LLAnkle_FT"/>
    <child link="FLC_RearLeft_Link"/>
  </joint>
  <link name="FLC_RearLeft_Link">
    <collision name="FLC_RearLeft_Collision">
      <origin xyz="0.0 0.0 0.0" rpy="0.0 0.0 0.0"/>
      <geometry>
        <sphere radius="0.017"/>
      </geometry>
    </collision>
  </link>
  <joint name="FLC_RearRight" type="fixed">
    <origin xyz="-0.07 0.04 0.0274" rpy="3.1416 0.0 0.0"/>
    <axis xyz="0.0 0.0 0.0"/>
    <parent link="LLAnkle_FT"/>
    <child link="FLC_RearRight_Link"/>
  </joint>
  <link name="FLC_RearRight_Link">
    <collision name="FLC_RearRight_Collision">
      <origin xyz="0.0 0.0 0.0" rpy="0.0 0.0 0.0"/>
      <geometry>
        <sphere radius="0.017"/>
      </geometry>
    </collision>
  </link>
  <link name="FL_SupportCenter"/>
  <joint name="FL_SupportCenter" type="fixed">
    <origin xyz="0.03 0.0 0.0444" rpy="3.1416 0.0 0.0"/>
    <axis xyz="0.0 0.0 0.0"/>
    <parent link="LLAnkle_FT"/>
    <child link="FL_SupportCenter"/>
  </joint>
  <!--joint name="FRC_FrontLeft" type="fixed">
    <origin xyz="0.13 -0.04 0.0274" rpy="3.1416 0.0 0.0"/>
    <axis xyz="0.0 0.0 0.0"/>
    <parent link="LRAnkle_FT"/>
    <child link="FRC_FrontLeft_Link"/>
  </joint>
  <link name="FRC_FrontLeft_Link">
    <collision name="FRC_FrontLeft_Collision">
      <origin xyz="0.0 0.0 0.0" rpy="0.0 0.0 0.0"/>
      <geometry>
        <sphere radius="0.017"/>
      </geometry>
    </collision>
  </link>
  <joint name="FRC_FrontRight" type="fixed">
    <origin xyz="0.13 0.04 0.0274" rpy="3.1416 0.0 0.0"/>
    <axis xyz="0.0 0.0 0.0"/>
    <parent link="LRAnkle_FT"/>
    <child link="FRC_FrontRight_Link"/>
  </joint>
  <link name="FRC_FrontRight_Link">
    <collision name="FRC_FrontRight_Collision">
      <origin xyz="0.0 0.0 0.0" rpy="0.0 0.0 0.0"/>
      <geometry>
        <sphere radius="0.017"/>
      </geometry>
    </collision>
  </link>
  <joint name="FRC_RearLeft" type="fixed">
    <origin xyz="-0.07 -0.04 0.0274" rpy="3.1416 0.0 0.0"/>
    <axis xyz="0.0 0.0 0.0"/>
    <parent link="LRAnkle_FT"/>
    <child link="FRC_RearLeft_Link"/>
  </joint>
  <link name="FRC_RearLeft_Link">
    <collision name="FRC_RearLeft_Collision">
      <origin xyz="0.0 0.0 0.0" rpy="0.0 0.0 0.0"/>
      <geometry>
        <sphere radius="0.017"/>
      </geometry>
    </collision>
  </link>
  <joint name="FRC_RearRight" type="fixed">
    <origin xyz="-0.07 0.04 0.0274" rpy="3.1416 0.0 0.0"/>
    <axis xyz="0.0 0.0 0.0"/>
    <parent link="LRAnkle_FT"/>
    <child link="FRC_RearRight_Link"/>
  </joint>
  <link name="FRC_RearRight_Link">
    <collision name="FRC_RearRight_Collision">
      <origin xyz="0.0 0.0 0.0" rpy="0.0 0.0 0.0"/>
      <geometry>
        <sphere radius="0.017"/>
      </geometry>
    </collision>
  </link>
  <link name="FR_SupportCenter"/>
  <joint name="FR_SupportCenter" type="fixed">
    <origin xyz="0.03 0.0 0.0444" rpy="3.1416 0.0 0.0"/>
    <axis xyz="0.0 0.0 0.0"/>
    <parent link="LRAnkle_FT"/>
    <child link="FR_SupportCenter"/>
  </joint-->
  <joint name="IMU" type="fixed">
    <origin xyz="0 0.0 0" rpy="0.0 0 0"/>
    <axis xyz="0.0 0.0 0.0"/>
    <parent link="RH5_Root_Link"/>
    <child link="IMU_Link"/>
  </joint>
  <link name="IMU_Link"/>
  <joint name="LLAnklePitch" type="revolute">
    <origin xyz="0.0 0.0 0.0" rpy="0.0 0.0 0.0"/>
    <axis xyz="0.0 1.0 0.0"/>
    <parent link="LLAnkleRoll_Link"/>
    <child link="LLAnklePitch_Link"/>
    <limit effort="200.0" lower="-0.8988445648" upper="0.7853981634" velocity="6.0"/>
  </joint>
  <link name="LLAnklePitch_Link">
    <inertial>
      <origin xyz="2.8493e-18 -1.3878e-16 0.0" rpy="0.0 0.0 0.0"/>
      <mass value="0.05002825763253648"/>
      <inertia ixx="1.1393245912e-05" ixy="1.7670484276950664e-28" ixz="-1.2474451909533485e-12" iyy="1.0892263576532345e-05" iyz="0.0" izz="2.9520429504676554e-06"/>
    </inertial>
    <visual name="LLAnklePitch_Link_visual">
      <origin xyz="0.0 0.0 0.0" rpy="0.0 0.0 0.0"/>
      <geometry>
        <mesh filename="../meshes/stl/AnklePitch_Link.STL"/>
      </geometry>
      <material name="">
        <color rgba="0.79216 0.81961 0.93333 1.0"/>
      </material>
    </visual>
    <visual name="LLAnkle_E21_Link_visual">
      <origin xyz="-0.07 -0.04 0.0" rpy="-0.05066 -0.0 0.0"/>
      <geometry>
        <mesh filename="../meshes/stl/Ankle_E21_Link.STL"/>
      </geometry>
      <material name="">
        <color rgba="0.69804 0.69804 0.69804 1.0"/>
      </material>
    </visual>
    <visual name="LLAnkle_E11_Link_visual">
      <origin xyz="-0.07 0.04 0.0" rpy="0.05066 -0.0 0.0"/>
      <geometry>
        <mesh filename="../meshes/stl/Ankle_E11_Link.STL"/>
      </geometry>
      <material name="">
        <color rgba="0.69804 0.69804 0.69804 1.0"/>
      </material>
    </visual>
  </link>
  <joint name="LLAnkleRoll" type="revolute">
    <origin xyz="0.42 0.0 0.0015" rpy="1.5708 5.551115123125783e-17 -1.5708"/>
    <axis xyz="1.0 0.0 0.0"/>
    <parent link="LLKnee_Link"/>
    <child link="LLAnkleRoll_Link"/>
    <limit effort="200.0" lower="-0.9948376736" upper="0.9948376736" velocity="6.0"/>
  </joint>
  <link name="LLAnkleRoll_Link">
    <inertial>
      <origin xyz="-4.1608e-08 7.2923e-08 -5.2997e-09" rpy="0.0 0.0 0.0"/>
      <mass value="0.02493"/>
      <inertia ixx="2.9269e-06" ixy="-7.8377e-12" ixz="-1.0382e-12" iyy="1.1591e-06" iyz="1.5876e-12" izz="3.5758e-06"/>
    </inertial>
    <visual name="LLAnkleRoll_Link_visual">
      <origin xyz="0.0 0.0 0.0" rpy="0.0 0.0 0.0"/>
      <geometry>
        <mesh filename="../meshes/stl/AnkleRoll_Link.STL"/>
      </geometry>
      <material name="">
        <color rgba="0.64706 0.61961 0.58824 1.0"/>
      </material>
    </visual>
  </link>
  <link name="LLAnkle_FT">
    <inertial>
      <origin xyz="0.016102 4.5932e-05 0.0078533" rpy="0.0 0.0 0.0"/>
      <mass value="1.2348"/>
      <inertia ixx="0.0018722" ixy="1.7891e-07" ixz="-0.00077672" iyy="0.0072567" iyz="3.8393e-06" izz="0.007267"/>
    </inertial>
    <visual name="LLAnkle_FT_visual">
      <origin xyz="0.0 0.0 0.0" rpy="0.0 0.0 0.0"/>
      <geometry>
        <mesh filename="../meshes/stl/FL_FT_Link.STL"/>
      </geometry>
      <material name="">
        <color rgba="0.69804 0.69804 0.69804 1.0"/>
      </material>
    </visual>
  </link>
  <joint name="LLAnkle_FT" type="fixed">
    <origin xyz="0.0 0.0 -0.058972" rpy="-3.1416 0.0 -1.2151e-16"/>
    <axis xyz="0.0 0.0 0.0"/>
    <parent link="LLAnklePitch_Link"/>
    <child link="LLAnkle_FT"/>
  </joint>
  <joint name="LLHip1" type="revolute">
    <!--origin xyz="0.0735 0.11044 0.014269" rpy="8.0247e-16 0.2618 -1.5708"/-->
    <origin xyz="0.0 0.0 0.0" rpy="8.0247e-16 0.2618 -1.5708"/>
    <axis xyz="0.0 0.0 1.0"/>
    <parent link="RH5_Root_Link"/>
    <child link="LLHip1_Link"/>
    <limit effort="135.0" lower="-0.7854" upper="0.7854" velocity="1.8326"/>
  </joint>
  <link name="LLHip1_Link">
    <inertial>
      <origin xyz="-4.7812e-08 -0.0016168 0.04962" rpy="0.0 0.0 0.0"/>
      <mass value="0.5"/>
      <inertia ixx="0.0020247" ixy="7.2405e-09" ixz="3.8164e-09" iyy="0.00095765" iyz="-0.00012913" izz="0.0015078"/>
    </inertial>
    <visual name="LLHip1_Link_visual">
      <origin xyz="0.0 0.0 0.0" rpy="0.0 0.0 0.0"/>
      <geometry>
        <mesh filename="../meshes/stl/LLHip1_Link.STL"/>
      </geometry>
      <material name="">
        <color rgba="0.69804 0.69804 0.69804 1.0"/>
      </material>
    </visual>
  </link>
  <joint name="LLHip2" type="revolute">
    <origin xyz="0.0 0.0 0.0" rpy="9.8608e-32 2.7756e-17 -4.9304e-32"/>
    <axis xyz="0.0 1.0 0.0"/>
    <parent link="LLHip1_Link"/>
    <child link="LLHip2_Link"/>
    <limit effort="135.0" lower="-0.4363" upper="0.8727" velocity="1.8326"/>
  </joint>
  <link name="LLHip2_Link">
    <inertial>
      <origin xyz="0.0013954 0.0024309 -0.0053241" rpy="0.0 0.0 0.0"/>
      <mass value="2.3580361324518035"/>
      <inertia ixx="0.008083434004413779" ixy="2.6244834705305358e-05" ixz="0.0015310237705679207" iyy="0.007915769158281745" iyz="-9.344933737144451e-05" izz="0.0027252481373044738"/>
    </inertial>
    <visual name="LLHip2_Link_visual">
      <origin xyz="0.0 0.0 0.0" rpy="0.0 0.0 0.0"/>
      <geometry>
        <mesh filename="../meshes/stl/LLHip2_Link.STL"/>
      </geometry>
      <material name="">
        <color rgba="0.69804 0.69804 0.69804 1.0"/>
      </material>
    </visual>
    <visual name="LLHip3_B11_Link_visual">
      <origin xyz="0.018117 -0.09 -0.067615" rpy="-2.5686 1.2576999999999998 0.5958800000000001"/>
      <geometry>
        <mesh filename="../meshes/stl/Hip3_B11_Link.STL"/>
      </geometry>
      <material name="">
        <color rgba="0.69804 0.69804 0.69804 1.0"/>
      </material>
    </visual>
    <visual name="LLHip3_Act1_Link_visual">
      <origin xyz="0.09393098308289657 -0.038590125898753366 -0.3505567339559511" rpy="0.5729999999999998 1.2576999999999994 0.5958800000000001"/>
      <geometry>
        <mesh filename="../meshes/stl/LLHip3_Act1_Link.STL"/>
      </geometry>
      <material name="">
        <color rgba="0.69804 0.69804 0.69804 1.0"/>
      </material>
    </visual>
  </link>
  <joint name="LLHip3" type="revolute">
    <origin xyz="0.0 0.0 0.0" rpy="9.8608e-32 2.7756e-17 -4.9304e-32"/>
    <axis xyz="-0.96593 0.0 -0.25882"/>
    <parent link="LLHip2_Link"/>
    <child link="LLHip3_Link"/>
    <limit effort="378.0" lower="-1.16" upper="0.28" velocity="2.321"/>
  </joint>
  <link name="LLHip3_Link">
    <inertial>
      <origin xyz="0.051263 0.0072511 -0.19232" rpy="0.0 0.0 0.0"/>
      <mass value="2.4377337930824305"/>
      <inertia ixx="0.0267577627146784" ixy="3.2673817728971014e-05" ixz="0.0032268691746643605" iyy="0.029394554214711634" iyz="-0.0001498356765101371" izz="0.005399934370609966"/>
    </inertial>
    <visual name="LLHip3_Link_visual">
      <origin xyz="0.0 0.0 0.0" rpy="0.0 0.0 0.0"/>
      <geometry>
        <mesh filename="../meshes/stl/Hip3_Link.STL"/>
      </geometry>
      <material name="">
        <color rgba="0.69804 0.69804 0.69804 1.0"/>
      </material>
    </visual>
    <collision name="LLHip3_Link_collision">
      <origin xyz="0.05410637838284813 0.005196313895957175 -0.20155622029885475" rpy="2.8786935033165375 0.09046667825579376 1.5464941877752887"/>
      <geometry>
        <box size="0.12200059773407665 0.15002443346404168 0.474515434996993"/>
      </geometry>
    </collision>
    <visual name="LLKnee_B11_Link_visual">
      <origin xyz="0.020175 0.070737 -0.075294" rpy="-0.15080999999999992 1.3059000000000005 -0.15616999999999992"/>
      <geometry>
        <mesh filename="../meshes/stl/Knee_B11_Link.STL"/>
      </geometry>
      <material name="">
        <color rgba="0.69804 0.69804 0.69804 1.0"/>
      </material>
    </visual>
    <visual name="LLKnee_Act1_Link_visual">
      <origin xyz="0.09088512935033356 0.059603540016275505 -0.3391673631423413" rpy="-0.15080999999999994 1.3059000000000005 -0.15616999999999995"/>
      <geometry>
        <mesh filename="../meshes/stl/Knee_Act1_Link.STL"/>
      </geometry>
      <material name="">
        <color rgba="0.69804 0.69804 0.69804 1.0"/>
      </material>
    </visual>
  </link>
  <joint name="LLKnee" type="revolute">
    <origin xyz="0.10788 -0.0005 -0.39684" rpy="3.1416 1.309 -2.9949e-15"/>
    <axis xyz="0.0 0.0 1.0"/>
    <parent link="LLHip3_Link"/>
    <child link="LLKnee_Link"/>
    <limit effort="325.0" lower="-0.026" upper="1.43" velocity="2.321"/>
  </joint>
  <link name="LLKnee_Link">
    <inertial>
      <origin xyz="0.11911 -0.001888 0.00058411" rpy="0.0 0.0 0.0"/>
      <mass value="2.3690392835599923"/>
      <inertia ixx="0.007186070874806159" ixy="-5.408981012900345e-05" ixz="-0.00010460818246783018" iyy="0.015334532906158908" iyz="-0.0009184931600015315" izz="0.019875099619034924"/>
    </inertial>
    <visual name="LLKnee_Link_visual">
      <origin xyz="0.0 0.0 0.0" rpy="0.0 0.0 0.0"/>
      <geometry>
        <mesh filename="../meshes/stl/Knee_Link.STL"/>
      </geometry>
      <material name="">
        <color rgba="0.69804 0.69804 0.69804 1.0"/>
      </material>
    </visual>
    <collision name="LLKnee_Link_collision">
      <origin xyz="0.18142876774072647 -0.003944786265492439 0.0014998912811279297" rpy="0.0 -0.0 0.0"/>
      <geometry>
        <box size="0.5021360367536545 0.12789290770888329 0.11989995092153549"/>
      </geometry>
    </collision>
    <visual name="LLAnkle_B11_Link_visual">
      <origin xyz="0.12872999008627622 0.022301069894637288 0.02649893010538089" rpy="1.5201995950723244 -1.9755524692725744e-06 1.7452956535986952"/>
      <geometry>
        <mesh filename="../meshes/stl/Ankle_B11_Link.STL"/>
      </geometry>
      <material name="">
        <color rgba="0.69804 0.69804 0.69804 1.0"/>
      </material>
    </visual>
    <visual name="LLAnkle_B12_Link_visual">
      <origin xyz="0.12872999008627622 0.022301069894637288 0.02649893010538089" rpy="1.6213921335695103 0.0003060746390916892 -1.4023021588708646"/>
      <geometry>
        <mesh filename="../meshes/stl/Ankle_B12_Link.STL"/>
      </geometry>
      <material name="">
        <color rgba="0.69804 0.69804 0.69804 1.0"/>
      </material>
    </visual>
    <visual name="LLAnkle_Act1_Link_visual">
      <origin xyz="0.39059846357402106 0.06684327487261481 0.03995015565913803" rpy="-3.135543074958524 1.5202022485750566 0.17453865585220907"/>
      <geometry>
        <mesh filename="../meshes/stl/Ankle_Act1_Link.STL"/>
      </geometry>
      <material name="">
        <color rgba="0.69804 0.69804 0.69804 1.0"/>
      </material>
    </visual>
    <visual name="LLAnkle_B21_Link_visual">
      <origin xyz="0.1287301737465314 0.022301069893962668 -0.023501069894281797" rpy="1.6214049022519106 -1.9755524692725744e-06 1.7452956535986952"/>
      <geometry>
        <mesh filename="../meshes/stl/Ankle_B21_Link.STL"/>
      </geometry>
      <material name="">
        <color rgba="0.69804 0.69804 0.69804 1.0"/>
      </material>
    </visual>
    <visual name="LLAnkle_B22_Link_visual">
      <origin xyz="0.1287301737465314 0.022301069893962668 -0.023501069894281797" rpy="1.520188652771982 -0.00030219472845357864 -1.4023021552616228"/>
      <geometry>
        <mesh filename="../meshes/stl/Ankle_B22_Link.STL"/>
      </geometry>
      <material name="">
        <color rgba="0.69804 0.69804 0.69804 1.0"/>
      </material>
    </visual>
    <visual name="LLAnkle_Act2_Link_visual">
      <origin xyz="0.39059848109430023 0.06684329955582428 -0.03695544775297088" rpy="1.520188652771982 -0.00030219472845357864 -1.4023021552616228"/>
      <geometry>
        <mesh filename="../meshes/stl/Ankle_Act2_Link.STL"/>
      </geometry>
      <material name="">
        <color rgba="0.69804 0.69804 0.69804 1.0"/>
      </material>
    </visual>
  </link>
  <!--joint name="LRAnklePitch" type="revolute">
    <origin xyz="0.0 0.0 0.0" rpy="0.0 0.0 0.0"/>
    <axis xyz="0.0 1.0 0.0"/>
    <parent link="LRAnkleRoll_Link"/>
    <child link="LRAnklePitch_Link"/>
    <limit effort="200.0" lower="-0.8988445648" upper="0.7853981634" velocity="6.0"/>
  </joint>
  <link name="LRAnklePitch_Link">
    <inertial>
      <origin xyz="2.8493e-18 -1.3878e-16 0.0" rpy="0.0 0.0 0.0"/>
      <mass value="0.05002825763253648"/>
      <inertia ixx="1.1393245912e-05" ixy="1.7670484276950664e-28" ixz="-1.2474451909533485e-12" iyy="1.0892263576532345e-05" iyz="0.0" izz="2.9520429504676554e-06"/>
    </inertial>
    <visual name="LRAnklePitch_Link_visual">
      <origin xyz="0.0 0.0 0.0" rpy="0.0 0.0 0.0"/>
      <geometry>
        <mesh filename="../meshes/stl/AnklePitch_Link.STL"/>
      </geometry>
      <material name="">
        <color rgba="0.79216 0.81961 0.93333 1.0"/>
      </material>
    </visual>
    <visual name="LRAnkle_E21_Link_visual">
      <origin xyz="-0.07 -0.04 0.0" rpy="-0.05066 -0.0 0.0"/>
      <geometry>
        <mesh filename="../meshes/stl/Ankle_E21_Link.STL"/>
      </geometry>
      <material name="">
        <color rgba="0.69804 0.69804 0.69804 1.0"/>
      </material>
    </visual>
    <visual name="LRAnkle_E11_Link_visual">
      <origin xyz="-0.07 0.04 0.0" rpy="0.05066 -0.0 0.0"/>
      <geometry>
        <mesh filename="../meshes/stl/Ankle_E11_Link.STL"/>
      </geometry>
      <material name="">
        <color rgba="0.69804 0.69804 0.69804 1.0"/>
      </material>
    </visual>
  </link>
  <joint name="LRAnkleRoll" type="revolute">
    <origin xyz="0.42 0.0 0.0015" rpy="1.5708 5.551115123125783e-17 -1.5708"/>
    <axis xyz="1.0 0.0 0.0"/>
    <parent link="LRKnee_Link"/>
    <child link="LRAnkleRoll_Link"/>
    <limit effort="200.0" lower="-0.9948376736" upper="0.9948376736" velocity="6.0"/>
  </joint>
  <link name="LRAnkleRoll_Link">
    <inertial>
      <origin xyz="-4.1608e-08 7.2923e-08 -5.2997e-09" rpy="0.0 0.0 0.0"/>
      <mass value="0.02493"/>
      <inertia ixx="2.9269e-06" ixy="-7.8377e-12" ixz="-1.0382e-12" iyy="1.1591e-06" iyz="1.5876e-12" izz="3.5758e-06"/>
    </inertial>
    <visual name="LRAnkleRoll_Link_visual">
      <origin xyz="0.0 0.0 0.0" rpy="0.0 0.0 0.0"/>
      <geometry>
        <mesh filename="../meshes/stl/AnkleRoll_Link.STL"/>
      </geometry>
      <material name="">
        <color rgba="0.64706 0.61961 0.58824 1.0"/>
      </material>
    </visual>
  </link>
  <link name="LRAnkle_FT">
    <inertial>
      <origin xyz="0.016102 4.5932e-05 0.0078533" rpy="0.0 0.0 0.0"/>
      <mass value="1.2348"/>
      <inertia ixx="0.0018722" ixy="1.7891e-07" ixz="-0.00077672" iyy="0.0072567" iyz="3.8393e-06" izz="0.007267"/>
    </inertial>
    <visual name="LRAnkle_FT_visual">
      <origin xyz="0.0 0.0 0.0" rpy="0.0 0.0 0.0"/>
      <geometry>
        <mesh filename="../meshes/stl/FL_FT_Link.STL"/>
      </geometry>
      <material name="">
        <color rgba="0.69804 0.69804 0.69804 1.0"/>
      </material>
    </visual>
  </link>
  <joint name="LRAnkle_FT" type="fixed">
    <origin xyz="0.0 0.0 -0.058972" rpy="-3.1416 0.0 -1.2151e-16"/>
    <axis xyz="0.0 0.0 0.0"/>
    <parent link="LRAnklePitch_Link"/>
    <child link="LRAnkle_FT"/>
  </joint>
  <joint name="LRHip1" type="revolute">
    <origin xyz="0.0735 -0.11044 0.014269" rpy="3.4781e-17 -0.2618 -1.5708"/>
    <axis xyz="0.0 0.0 1.0"/>
    <parent link="RH5_Root_Link"/>
    <child link="LRHip1_Link"/>
    <limit effort="135.0" lower="-0.7854" upper="0.7854" velocity="1.8326"/>
  </joint>
  <link name="LRHip1_Link">
    <inertial>
      <origin xyz="-4.5821e-08 -0.0016166 0.04962" rpy="0.0 0.0 0.0"/>
      <mass value="0.5"/>
      <inertia ixx="0.0020247" ixy="8.3227e-09" ixz="3.6838e-09" iyy="0.00095763" iyz="-0.00012913" izz="0.0015078"/>
    </inertial>
    <visual name="LRHip1_Link_visual">
      <origin xyz="0.0 0.0 0.0" rpy="0.0 0.0 0.0"/>
      <geometry>
        <mesh filename="../meshes/stl/LRHip1_Link.STL"/>
      </geometry>
      <material name="">
        <color rgba="0.69804 0.69804 0.69804 1.0"/>
      </material>
    </visual>
  </link>
  <joint name="LRHip2" type="revolute">
    <origin xyz="0.0 0.0 0.0" rpy="-4.0161e-17 0.5236 -2.0081e-17"/>
    <axis xyz="0.0 1.0 0.0"/>
    <parent link="LRHip1_Link"/>
    <child link="LRHip2_Link"/>
    <limit effort="135.0" lower="-0.8727" upper="0.4363" velocity="1.8326"/>
  </joint>
  <link name="LRHip2_Link">
    <inertial>
      <origin xyz="0.0013954 0.0024309 -0.0053241" rpy="0.0 0.0 0.0"/>
      <mass value="2.3580361324518035"/>
      <inertia ixx="0.008083434004413779" ixy="2.6244834705305358e-05" ixz="0.0015310237705679207" iyy="0.007915769158281745" iyz="-9.344933737144451e-05" izz="0.0027252481373044738"/>
    </inertial>
    <visual name="LRHip2_Link_visual">
      <origin xyz="0.0 0.0 0.0" rpy="0.0 0.0 0.0"/>
      <geometry>
        <mesh filename="../meshes/stl/LRHip2_Link.STL"/>
      </geometry>
      <material name="">
        <color rgba="0.69804 0.69804 0.69804 1.0"/>
      </material>
    </visual>
    <visual name="LRHip3_B11_Link_visual">
      <origin xyz="0.018117 -0.09 -0.067615" rpy="-2.5686 1.2576999999999998 0.5958800000000001"/>
      <geometry>
        <mesh filename="../meshes/stl/Hip3_B11_Link.STL"/>
      </geometry>
      <material name="">
        <color rgba="0.69804 0.69804 0.69804 1.0"/>
      </material>
    </visual>
    <visual name="LRHip3_Act1_Link_visual">
      <origin xyz="0.09393098308289657 -0.038590125898753366 -0.3505567339559511" rpy="0.5729999999999998 1.2576999999999994 0.5958800000000001"/>
      <geometry>
        <mesh filename="../meshes/stl/LLHip3_Act1_Link.STL"/>
      </geometry>
      <material name="">
        <color rgba="0.69804 0.69804 0.69804 1.0"/>
      </material>
    </visual>
  </link>
  <joint name="LRHip3" type="revolute">
    <origin xyz="0.0 0.0 0.0" rpy="9.8608e-32 2.7756e-17 -4.9304e-32"/>
    <axis xyz="-0.96593 0.0 -0.25882"/>
    <parent link="LRHip2_Link"/>
    <child link="LRHip3_Link"/>
    <limit effort="378.0" lower="-1.16" upper="0.28" velocity="2.321"/>
  </joint>
  <link name="LRHip3_Link">
    <inertial>
      <origin xyz="0.051263 0.0072511 -0.19232" rpy="0.0 0.0 0.0"/>
      <mass value="2.4377337930824305"/>
      <inertia ixx="0.0267577627146784" ixy="3.2673817728971014e-05" ixz="0.0032268691746643605" iyy="0.029394554214711634" iyz="-0.0001498356765101371" izz="0.005399934370609966"/>
    </inertial>
    <visual name="LRHip3_Link_visual">
      <origin xyz="0.0 0.0 0.0" rpy="0.0 0.0 0.0"/>
      <geometry>
        <mesh filename="../meshes/stl/Hip3_Link.STL"/>
      </geometry>
      <material name="">
        <color rgba="0.69804 0.69804 0.69804 1.0"/>
      </material>
    </visual>
    <collision name="LRHip3_Link_collision">
      <origin xyz="0.05410637838284813 0.005196313895957175 -0.20155622029885475" rpy="2.8786935033165375 0.09046667825579376 1.5464941877752887"/>
      <geometry>
        <box size="0.12200059773407665 0.15002443346404168 0.474515434996993"/>
      </geometry>
    </collision>
    <visual name="LRKnee_B11_Link_visual">
      <origin xyz="0.020175 0.070737 -0.075294" rpy="-0.15080999999999992 1.3059000000000005 -0.15616999999999992"/>
      <geometry>
        <mesh filename="../meshes/stl/Knee_B11_Link.STL"/>
      </geometry>
      <material name="">
        <color rgba="0.69804 0.69804 0.69804 1.0"/>
      </material>
    </visual>
    <visual name="LRKnee_Act1_Link_visual">
      <origin xyz="0.09088512935033356 0.059603540016275505 -0.3391673631423413" rpy="-0.15080999999999994 1.3059000000000005 -0.15616999999999995"/>
      <geometry>
        <mesh filename="../meshes/stl/Knee_Act1_Link.STL"/>
      </geometry>
      <material name="">
        <color rgba="0.69804 0.69804 0.69804 1.0"/>
      </material>
    </visual>
  </link>
  <joint name="LRKnee" type="revolute">
    <origin xyz="0.10788 -0.0005 -0.39684" rpy="3.1416 1.309 -2.9949e-15"/>
    <axis xyz="0.0 0.0 1.0"/>
    <parent link="LRHip3_Link"/>
    <child link="LRKnee_Link"/>
    <limit effort="325.0" lower="-0.026" upper="1.43" velocity="2.321"/>
  </joint>
  <link name="LRKnee_Link">
    <inertial>
      <origin xyz="0.11911 -0.001888 0.00058411" rpy="0.0 0.0 0.0"/>
      <mass value="2.369041606483567"/>
      <inertia ixx="0.00718607087481035" ixy="-5.4089810208980605e-05" ixz="-0.00010460818216963791" iyy="0.015334532907684004" iyz="-0.0009184931643303047" izz="0.01987509961750564"/>
    </inertial>
    <visual name="LRKnee_Link_visual">
      <origin xyz="0.0 0.0 0.0" rpy="0.0 0.0 0.0"/>
      <geometry>
        <mesh filename="../meshes/stl/Knee_Link.STL"/>
      </geometry>
      <material name="">
        <color rgba="0.69804 0.69804 0.69804 1.0"/>
      </material>
    </visual>
    <collision name="LRKnee_Link_collision">
      <origin xyz="0.18142876774072647 -0.003944786265492439 0.0014998912811279297" rpy="0.0 -0.0 0.0"/>
      <geometry>
        <box size="0.5021360367536545 0.12789290770888329 0.11989995092153549"/>
      </geometry>
    </collision>
    <visual name="LRAnkle_B11_Link_visual">
      <origin xyz="0.12872999008627622 0.022301069894637288 0.02649893010538089" rpy="1.5201995950723244 -1.9755524692725744e-06 1.7452956535986952"/>
      <geometry>
        <mesh filename="../meshes/stl/Ankle_B11_Link.STL"/>
      </geometry>
      <material name="">
        <color rgba="0.69804 0.69804 0.69804 1.0"/>
      </material>
    </visual>
    <visual name="LRAnkle_B12_Link_visual">
      <origin xyz="0.12872999008627622 0.022301069894637288 0.02649893010538089" rpy="1.6213921335695103 0.0003060746390916892 -1.4023021588708646"/>
      <geometry>
        <mesh filename="../meshes/stl/Ankle_B12_Link.STL"/>
      </geometry>
      <material name="">
        <color rgba="0.69804 0.69804 0.69804 1.0"/>
      </material>
    </visual>
    <visual name="LRAnkle_Act1_Link_visual">
      <origin xyz="0.39059846357402106 0.06684327487261481 0.03995015565913803" rpy="-3.135543074958524 1.5202022485750566 0.17453865585220907"/>
      <geometry>
        <mesh filename="../meshes/stl/Ankle_Act1_Link.STL"/>
      </geometry>
      <material name="">
        <color rgba="0.69804 0.69804 0.69804 1.0"/>
      </material>
    </visual>
    <visual name="LRAnkle_B21_Link_visual">
      <origin xyz="0.1287301737465314 0.022301069893962668 -0.023501069894281797" rpy="1.5201877513328248 1.8413153890626716e-06 -1.3962996501833926"/>
      <geometry>
        <mesh filename="../meshes/stl/Ankle_B21_Link.STL"/>
      </geometry>
      <material name="">
        <color rgba="0.69804 0.69804 0.69804 1.0"/>
      </material>
    </visual>
    <visual name="LRAnkle_B22_Link_visual">
      <origin xyz="0.1287301737465314 0.022301069893962668 -0.023501069894281797" rpy="1.520188652771982 -0.00030219472845357864 -1.4023021552616228"/>
      <geometry>
        <mesh filename="../meshes/stl/Ankle_B22_Link.STL"/>
      </geometry>
      <material name="">
        <color rgba="0.69804 0.69804 0.69804 1.0"/>
      </material>
    </visual>
    <visual name="LRAnkle_Act2_Link_visual">
      <origin xyz="0.39059848109430023 0.06684329955582428 -0.03695544775297088" rpy="1.520188652771982 -0.00030219472845357864 -1.4023021552616228"/>
      <geometry>
        <mesh filename="../meshes/stl/Ankle_Act2_Link.STL"/>
      </geometry>
      <material name="">
        <color rgba="0.69804 0.69804 0.69804 1.0"/>
      </material>
    </visual>
  </link>
  <link name="RH5_Root_Link">
    <inertial>
      <origin xyz="0.057726 2.1253e-05 0.13284" rpy="0.0 0.0 0.0"/>
      <mass value="4.80289768335972"/>
      <inertia ixx="0.03304656577513494" ixy="-3.6100616894227637e-06" ixz="-0.0020457081602203537" iyy="0.021956704" iyz="-5.465636509300982e-06" izz="0.03752923602486506"/>
    </inertial>
    <visual name="RH5_Root_Link_visual">
      <origin xyz="0.0 0.0 0.0" rpy="0.0 0.0 0.0"/>
      <geometry>
        <mesh filename="../meshes/stl/RH5_Root_Link.STL"/>
      </geometry>
      <material name="">
        <color rgba="0.69804 0.69804 0.69804 1.0"/>
      </material>
    </visual>
    <collision name="RH5_Root_Link_collision">
      <origin xyz="0.04128999263048172 0.0 0.1133179023017874" rpy="0.0 -0.0 0.0"/>
      <geometry>
        <box size="0.2746039479970932 0.3261495530605316 0.22715241627884097"/>
      </geometry>
    </collision>
  </link-->
  <link name="RH5_Root_Link">
    <inertial>
      <origin xyz="0 0 0" rpy="0.0 0.0 0.0"/>
      <mass value="0"/>
      <inertia ixx="0" ixy="0" ixz="0" iyy="0" iyz="-0" izz="0"/>
    </inertial>
  </link>
</robot>
