<?xml version='1.0' ?>
<robot name='kuka_iiwa'>

  <material name='LightGrey'>
    <color rgba='0.6 0.6 0.6 1.0'/>
  </material>
  <material name='Orange'>
    <color rgba='1.0 0.423529411765 0.0392156862745 1.0'/>
  </material>

<link name='world'>
<inertial>
  <origin rpy='0 0 0' xyz='0 -0.03 0.12'/>
  <mass value='4'/>
  <inertia ixx='0.1' ixy='0' ixz='0' iyy='0.09' iyz='0' izz='0.02'/>
</inertial>
</link>
<link name='link_floating_base_trans_x'>
<inertial>
  <origin rpy='0 0 0' xyz='0 -0.03 0.12'/>
  <mass value='4'/>
  <inertia ixx='0.1' ixy='0' ixz='0' iyy='0.09' iyz='0' izz='0.02'/>
</inertial>
</link>
<link name='link_floating_base_trans_y'>
<inertial>
  <origin rpy='0 0 0' xyz='0 -0.03 0.12'/>
  <mass value='4'/>
  <inertia ixx='0.1' ixy='0' ixz='0' iyy='0.09' iyz='0' izz='0.02'/>
</inertial>
</link>
<link name='link_floating_base_trans_z'>
<inertial>
  <origin rpy='0 0 0' xyz='0 -0.03 0.12'/>
  <mass value='4'/>
  <inertia ixx='0.1' ixy='0' ixz='0' iyy='0.09' iyz='0' izz='0.02'/>
</inertial>
</link>
<link name='link_floating_base_rot_x'>
<inertial>
  <origin rpy='0 0 0' xyz='0 -0.03 0.12'/>
  <mass value='4'/>
  <inertia ixx='0.1' ixy='0' ixz='0' iyy='0.09' iyz='0' izz='0.02'/>
</inertial>
</link>
<link name='link_floating_base_rot_y'>
<inertial>
  <origin rpy='0 0 0' xyz='0 -0.03 0.12'/>
  <mass value='4'/>
  <inertia ixx='0.1' ixy='0' ixz='0' iyy='0.09' iyz='0' izz='0.02'/>
</inertial>
</link>

  <joint name='floating_base_trans_x' type='prismatic'>
    <parent link='world'/>
    <child link='link_floating_base_trans_x'/>
    <origin rpy='0 0 0' xyz='0 0 0'/>
    <axis xyz='1 0 0'/>
    <limit effort='1000' lower='-1000' upper='1000' velocity='1000'/>
  </joint>

  <joint name='floating_base_trans_y' type='prismatic'>
    <parent link='link_floating_base_trans_x'/>
    <child link='link_floating_base_trans_y'/>
    <origin rpy='0 0 0' xyz='0 0 0'/>
    <axis xyz='0 1 0'/>
    <limit effort='1000' lower='-1000' upper='1000' velocity='1000'/>
  </joint>

  <joint name='floating_base_trans_z' type='prismatic'>
    <parent link='link_floating_base_trans_y'/>
    <child link='link_floating_base_trans_z'/>
    <origin rpy='0 0 0' xyz='0 0 0'/>
    <axis xyz='0 0 1'/>
    <limit effort='1000' lower='-1000' upper='1000' velocity='1000'/>
  </joint>

  <joint name='floating_base_rot_x' type='revolute'>
    <parent link='link_floating_base_trans_z'/>
    <child link='link_floating_base_rot_x'/>
    <origin rpy='0 0 0' xyz='0 0 0'/>
    <axis xyz='1 0 0'/>
    <limit effort='1000' lower='-1000' upper='1000' velocity='1000'/>
  </joint>

  <joint name='floating_base_rot_y' type='revolute'>
    <parent link='link_floating_base_rot_x'/>
    <child link='link_floating_base_rot_y'/>
    <origin rpy='0 0 0' xyz='0 0 0'/>
    <axis xyz='0 1 0'/>
    <limit effort='1000' lower='-1000' upper='1000' velocity='1000'/>
  </joint>

  <joint name='floating_base_rot_z' type='revolute'>
    <parent link='link_floating_base_rot_y'/>
    <child link='kuka_lbr_l_link_0'/>
    <origin rpy='0 0 0' xyz='0 0 0'/>
    <axis xyz='0 0 1'/>
    <limit effort='1000' lower='-1000' upper='1000' velocity='1000'/>
  </joint>

  <link name='kuka_lbr_l_link_0'>
    <inertial>
      <origin rpy='0 0 0' xyz='-0.1 0 0.07'/>
      <mass value='5'/>
      <inertia ixx='0.05' ixy='0' ixz='0' iyy='0.06' iyz='0' izz='0.03'/>
    </inertial>
    <visual name='visual_kuka_lbr_l_link_0'>
      <origin rpy='0 0 0' xyz='0 0 0'/>
      <geometry>
        <mesh filename='../meshes/link_0.stl'/>
      </geometry>
      <material name='LightGrey'/>
    </visual>
    <collision name='collision_kuka_lbr_l_link_0'>
      <origin xyz='0 0 0' rpy='0 0 0'/>
      <geometry>
        <mesh filename='../meshes/link_0.stl' scale='1.0 1.0 1.0'/>
      </geometry>
    </collision>
  </link>

  <joint name='kuka_lbr_l_joint_1' type='revolute'>
    <parent link='kuka_lbr_l_link_0'/>
    <child link='kuka_lbr_l_link_1'/>
    <origin rpy='0 0 0' xyz='0 0 0.1575'/>
    <axis xyz='0 0 1'/>
    <limit effort='300' lower='-2.94' upper='2.94' velocity='1.48352986419'/>
    <dynamics damping='0.5'/>
  </joint>

  <link name='kuka_lbr_l_link_1'>
    <inertial>
      <origin rpy='0 0 0' xyz='0 -0.03 0.12'/>
      <mass value='4'/>
      <inertia ixx='0.1' ixy='0' ixz='0' iyy='0.09' iyz='0' izz='0.02'/>
    </inertial>
    <visual name='visual_kuka_lbr_l_link_1'>
      <origin rpy='0 0 0' xyz='0 0 0'/>
      <geometry>
        <mesh filename='../meshes/link_1.stl'/>
      </geometry>
      <material name='Orange'/>
    </visual>
    <collision name='collision_kuka_lbr_l_link_1'>
      <origin xyz='0 0 0' rpy='0 0 0'/>
      <geometry>
        <mesh filename='../meshes/link_1.stl' scale='1.0 1.0 1.0'/>
      </geometry>
    </collision>
  </link>

  <joint name='kuka_lbr_l_joint_2' type='revolute'>
    <parent link='kuka_lbr_l_link_1'/>
    <child link='kuka_lbr_l_link_2'/>
    <origin rpy='1.57079632679   0 3.14159265359' xyz='0 0 0.2025'/>
    <axis xyz='0 0 1'/>
    <limit effort='300' lower='-2.08' upper='2.08' velocity='1.48352986419'/>
    <dynamics damping='0.5'/>
  </joint>

  <link name='kuka_lbr_l_link_2'>
    <inertial>
      <origin rpy='0 0 0' xyz='0.0003 0.059 0.042'/>
      <mass value='4'/>
      <inertia ixx='0.05' ixy='0' ixz='0' iyy='0.018' iyz='0' izz='0.044'/>
    </inertial>
    <visual name='visual_kuka_lbr_l_link_2'>
      <origin rpy='0 0 0' xyz='0 0 0'/>
      <geometry>
        <mesh filename='../meshes/link_2.stl'/>
      </geometry>
      <material name='Orange'/>
    </visual>
    <collision name='collision_kuka_lbr_l_link_2'>
      <origin xyz='0 0 0' rpy='0 0 0'/>
      <geometry>
        <mesh filename='../meshes/link_2.stl' scale='1.0 1.0 1.0'/>
      </geometry>
    </collision>
  </link>

  <joint name='kuka_lbr_l_joint_3' type='revolute'>
    <parent link='kuka_lbr_l_link_2'/>
    <child link='kuka_lbr_l_link_3'/>
    <origin rpy='1.57079632679 0 3.14159265359' xyz='0 0.2045 0'/>
    <axis xyz='0 0 1'/>
    <limit effort='300' lower='-2.94' upper='2.94' velocity='1.7453292519'/>
    <dynamics damping='0.5'/>
  </joint>

  <link name='kuka_lbr_l_link_3'>
    <inertial>
      <origin rpy='0 0 0' xyz='0 0.03 0.13'/>
      <mass value='3'/>
      <inertia ixx='0.08' ixy='0' ixz='0' iyy='0.075' iyz='0' izz='0.01'/>
    </inertial>
    <visual name='visual_kuka_lbr_l_link_3'>
      <origin rpy='0 0 0' xyz='0 0 0'/>
      <geometry>
        <mesh filename='../meshes/link_3.stl'/>
      </geometry>
      <material name='Orange'/>
    </visual>
    <collision name='collision_kuka_lbr_l_link_3'>
      <origin xyz='0 0 0' rpy='0 0 0'/>
      <geometry>
        <mesh filename='../meshes/link_3.stl' scale='1.0 1.0 1.0'/>
      </geometry>
    </collision>
  </link>

  <joint name='kuka_lbr_l_joint_4' type='revolute'>
    <parent link='kuka_lbr_l_link_3'/>
    <child link='kuka_lbr_l_link_4'/>
    <origin rpy='1.57079632679 0 0' xyz='0 0 0.2155'/>
    <axis xyz='0 0 1'/>
    <limit effort='300' lower='-2.08' upper='2.08' velocity='1.3089969389'/>
    <dynamics damping='0.5'/>
  </joint>

  <link name='kuka_lbr_l_link_4'>
    <inertial>
      <origin rpy='0 0 0' xyz='0 0.067 0.034'/>
      <mass value='2.7'/>
      <inertia ixx='0.03' ixy='0' ixz='0' iyy='0.01' iyz='0' izz='0.029'/>
    </inertial>
    <visual name='visual_kuka_lbr_l_link_4'>
      <origin rpy='0 0 0' xyz='0 0 0'/>
      <geometry>
        <mesh filename='../meshes/link_4.stl'/>
      </geometry>
      <material name='Orange'/>
    </visual>
    <collision name='collision_kuka_lbr_l_link_4'>
      <origin xyz='0 0 0' rpy='0 0 0'/>
      <geometry>
        <mesh filename='../meshes/link_4.stl' scale='1.0 1.0 1.0'/>
      </geometry>
    </collision>
  </link>

  <joint name='kuka_lbr_l_joint_5' type='revolute'>
    <parent link='kuka_lbr_l_link_4'/>
    <child link='kuka_lbr_l_link_5'/>
    <origin rpy='-1.57079632679 3.14159265359 0' xyz='0 0.1845 0'/>
    <axis xyz='0 0 1'/>
    <limit effort='300' lower='-2.94' upper='2.94' velocity='2.2689280275'/>
    <dynamics damping='0.5'/>
  </joint>

  <link name='kuka_lbr_l_link_5'>
    <inertial>
      <origin rpy='0 0 0' xyz='0.0001 0.021 0.076'/>
      <mass value='1.7'/>
      <inertia ixx='0.02' ixy='0' ixz='0' iyy='0.018' iyz='0' izz='0.005'/>
    </inertial>
    <visual name='visual_kuka_lbr_l_link_5'>
      <origin rpy='0 0 0' xyz='0 0 0'/>
      <geometry>
        <mesh filename='../meshes/link_5.stl'/>
      </geometry>
      <material name='Orange'/>
    </visual>
    <collision name='collision_kuka_lbr_l_link_5'>
      <origin xyz='0 0 0' rpy='0 0 0'/>
      <geometry>
        <mesh filename='../meshes/link_5.stl' scale='1.0 1.0 1.0'/>
      </geometry>
    </collision>
  </link>

  <joint name='kuka_lbr_l_joint_6' type='revolute'>
    <parent link='kuka_lbr_l_link_5'/>
    <child link='kuka_lbr_l_link_6'/>
    <origin rpy='1.57079632679 0 0' xyz='0 0 0.2155'/>
    <axis xyz='0 0 1'/>
    <limit effort='300' lower='-2.08' upper='2.08' velocity='2.3561944901'/>
    <dynamics damping='0.5'/>
  </joint>

  <link name='kuka_lbr_l_link_6'>
    <inertial>
      <origin rpy='0 0 0' xyz='0 0.0006 0.0004'/>
      <mass value='1.8'/>
      <inertia ixx='0.005' ixy='0' ixz='0' iyy='0.0036' iyz='0' izz='0.0047'/>
    </inertial>
    <visual name='visual_kuka_lbr_l_link_6'>
      <origin rpy='0 0 0' xyz='0 0 0'/>
      <geometry>
        <mesh filename='../meshes/link_6.stl'/>
      </geometry>
      <material name='Orange'/>
    </visual>
    <collision name='collision_kuka_lbr_l_link_6'>
      <origin xyz='0 0 0' rpy='0 0 0'/>
      <geometry>
        <mesh filename='../meshes/link_6.stl' scale='1.0 1.0 1.0'/>
      </geometry>
    </collision>
  </link>

  <joint name='kuka_lbr_l_joint_7' type='revolute'>
    <parent link='kuka_lbr_l_link_6'/>
    <child link='kuka_lbr_l_link_7'/>
    <origin rpy='-1.57079632679 3.14159265359 0' xyz='0 0.081 0'/>
    <axis xyz='0 0 1'/>
    <limit effort='300' lower='-3.03' upper='3.03' velocity='2.3561944901'/>
    <dynamics damping='0.5'/>
  </joint>

  <link name='kuka_lbr_l_link_7'>
    <inertial>
      <origin rpy='0 0 0' xyz='0 0 0.02'/>
      <mass value='0.3'/>
      <inertia ixx='0.001' ixy='0' ixz='0' iyy='0.001' iyz='0' izz='0.001'/>
    </inertial>
    <visual name='visual_kuka_lbr_l_link_7'>
      <origin rpy='0 0 0' xyz='0 0 0'/>
      <geometry>
        <mesh filename='../meshes/link_7.stl'/>
      </geometry>
      <material name='LightGrey'/>
    </visual>
    <collision name='collision_kuka_lbr_l_link_7'>
      <origin xyz='0 0 0' rpy='0 0 0'/>
      <geometry>
        <mesh filename='../meshes/link_7.stl' scale='1.0 1.0 1.0'/>
      </geometry>
    </collision>
  </link>

  <joint name='kuka_lbr_l_to_tcp' type='fixed'>
    <parent link='kuka_lbr_l_link_7'/>
    <child link='kuka_lbr_l_tcp'/>
    <origin rpy='0 0 0' xyz='0 0 0.045'/>
    <axis xyz='0 0 1'/>
  </joint>

  <link name='kuka_lbr_l_tcp'/>
</robot>
