<robot name="ALElbow">
  <joint name="ALElbow" type="revolute">
    <origin xyz="0.0 0.001 0.3511" rpy="0.0 0.0 0.0"/>
    <axis xyz="1.0 0.0 0.0"/>
    <parent link="ALShoulder3_Link"/>
    <child link="ALElbow_Link"/>
    <limit effort="400.0" lower="-1.832" upper="0.0" velocity="3.1415926"/>
  </joint>
  <joint name="ALElbowAct" type="prismatic">
    <origin xyz="0.0 0.0 0.29542" rpy="0.0 0.0 0.0"/>
    <axis xyz="0.0 0.0 1.0"/>
    <parent link="ALElbowB11_Link"/>
    <child link="ALElbowAct_Link"/>
    <limit effort="400.0" lower="-1.57" upper="1.57" velocity="3.1415926"/>
  </joint>
  <link name="ALElbowAct_Link">
    <inertial>
      <origin xyz="-6.1594e-06 1.459e-10 -0.085859" rpy="0.0 0.0 0.0"/>
      <mass value="0.054652"/>
      <inertia ixx="0.00010606969013629223" ixy="3.492500000065374e-13" ixz="3.6185000000071752e-09" iyy="0.00010597469013629217" iyz="-4.3476005705310174e-14" izz="1.0000000136292127e-05"/>
    </inertial>
    <visual name="ALElbowAct_Link_Visual">
      <origin xyz="0.0 0.0 0.0" rpy="0.0 0.0 0.0"/>
      <geometry>
        <mesh filename="../meshes/lfs-stl/ALElbow_Act_Link.stl"/>
      </geometry>
      <material name="">
        <color rgba="0.75294 0.75294 0.75294 1.0"/>
      </material>
    </visual>
    <collision name="ALElbowAct_Link_Collision">
      <origin xyz="0.0 0.0 0.0" rpy="0.0 0.0 0.0"/>
      <geometry>
        <mesh filename="../meshes/lfs-stl/ALElbow_Act_Link_convexhull.stl" scale="1.0 1.0 1.0"/>
      </geometry>
    </collision>
  </link>
  <joint name="ALElbowB11" type="revolute">
    <origin xyz="0.0 -0.029 0.1391" rpy="-0.25319 0.0 0.0"/>
    <axis xyz="1.0 0.0 0.0"/>
    <parent link="ALShoulder3_Link"/>
    <child link="ALElbowB11_Link"/>
    <limit effort="400.0" lower="-1.57" upper="1.57" velocity="3.1415926"/>
  </joint>
  <link name="ALElbowB11_Link">
    <inertial>
      <origin xyz="2.5944e-05 1.8924e-05 0.10704" rpy="0.0 0.0 0.0"/>
      <mass value="0.32696"/>
      <inertia ixx="0.00011102" ixy="-1.0985e-08" ixz="-6.6288e-08" iyy="0.00011251" iyz="1.4067e-07" izz="7.0733e-05"/>
    </inertial>
    <visual name="ALElbowB11_Link_Visual">
      <origin xyz="0.0 0.0 0.0" rpy="0.0 0.0 0.0"/>
      <geometry>
        <mesh filename="../meshes/lfs-stl/ALElbow_B11_Link.stl"/>
      </geometry>
      <material name="">
        <color rgba="0.75294 0.75294 0.75294 1.0"/>
      </material>
    </visual>
    <collision name="ALElbowB11_Link_Collision">
      <origin xyz="0.0 0.0 0.0" rpy="0.0 0.0 0.0"/>
      <geometry>
        <mesh filename="../meshes/lfs-stl/ALElbow_B11_Link_convexhull.stl" scale="1.0 1.0 1.0"/>
      </geometry>
    </collision>
  </link>
  <link name="ALElbow_Link">
    <inertial>
      <origin xyz="-7.016e-05 0.001127 0.080286" rpy="0.0 0.0 0.0"/>
      <mass value="0.63578"/>
      <inertia ixx="0.00050999" ixy="2.2297e-07" ixz="4.047e-07" iyy="0.00051633" iyz="-4.4233e-05" izz="0.00046537"/>
    </inertial>
    <visual name="ALElbow_Link_Visual">
      <origin xyz="0.0 0.0 0.0" rpy="0.0 0.0 0.0"/>
      <geometry>
        <mesh filename="../meshes/lfs-stl/ALElbow_Link.stl"/>
      </geometry>
      <material name="">
        <color rgba="0.75294 0.75294 0.75294 1.0"/>
      </material>
    </visual>
    <collision name="ALElbow_Link_Collision">
      <origin xyz="0.0 0.0 0.0" rpy="0.0 0.0 0.0"/>
      <geometry>
        <mesh filename="../meshes/lfs-stl/ALElbow_Link_convexhull.stl" scale="1.0 1.0 1.0"/>
      </geometry>
    </collision>
  </link>
  <link name="ALShoulder3_Link">
    <inertial>
      <origin xyz="-3.2703e-05 0.0033688 0.14648" rpy="0.0 0.0 0.0"/>
      <mass value="0.85234"/>
      <inertia ixx="0.0028013" ixy="5.1939e-07" ixz="-7.2591e-07" iyy="0.0027401" iyz="5.4672e-05" izz="0.00078629"/>
    </inertial>
    <visual name="ALShoulder3_Link_Visual">
      <origin xyz="0.0 0.0 0.0" rpy="0.0 0.0 0.0"/>
      <geometry>
        <mesh filename="../meshes/lfs-stl/ALShoulder3_Link.stl"/>
      </geometry>
      <material name="">
        <color rgba="0.75294 0.75294 0.75294 1.0"/>
      </material>
    </visual>
    <collision name="ALShoulder3_Link_Collision">
      <origin xyz="0.0 0.0 0.0" rpy="0.0 0.0 0.0"/>
      <geometry>
        <mesh filename="../meshes/lfs-stl/ALShoulder3_Link_convexhull.stl" scale="1.0 1.0 1.0"/>
      </geometry>
    </collision>
  </link>
</robot>
