<robot name="ARElbow">
  <joint name="ARElbow" type="revolute">
    <origin xyz="0.0 0.001 -0.3511" rpy="-3.141592 0.0 -3.141592"/>
    <axis xyz="1.0 0.0 0.0"/>
    <parent link="ARShoulder3_Link"/>
    <child link="ARElbow_Link"/>
    <limit effort="400.0" lower="-1.832" upper="0.0" velocity="3.1415926"/>
  </joint>
  <joint name="ARElbowAct" type="prismatic">
    <origin xyz="0.0 0.0 0.29542" rpy="0.0 0.0 -3.141592"/>
    <axis xyz="0.0 0.0 1.0"/>
    <parent link="ARElbowB11_Link"/>
    <child link="ARElbowAct_Link"/>
    <limit effort="400.0" lower="-1.57" upper="1.57" velocity="3.1415926"/>
  </joint>
  <link name="ARElbowAct_Link">
    <inertial>
      <origin xyz="-6e-06 0.0 -0.085859" rpy="0.0 0.0 0.0"/>
      <mass value="0.05465199999999999"/>
      <inertia ixx="0.00010606969013566325" ixy="-3.794811884488628e-13" ixz="3.6268360281805788e-09" iyy="0.0001059746901362923" iyz="4.232588795943544e-14" izz="1.0000000136920807e-05"/>
    </inertial>
    <visual name="ARElbowAct_Link_Visual">
      <origin xyz="0.0 0.0 0.0" rpy="0.0 0.0 3.141593"/>
      <geometry>
        <mesh filename="../meshes/lfs-stl/ARElbow_Act_Link.stl" scale="1.0 1.0 1.0"/>
      </geometry>
      <material name="">
        <color rgba="0.75294 0.75294 0.75294 1.0"/>
      </material>
    </visual>
    <collision name="ARElbowAct_Link_Collision">
      <origin xyz="0.0 0.0 0.0" rpy="0.0 0.0 0.0"/>
      <geometry>
        <mesh filename="../meshes/lfs-stl/ARElbow_Act_Link_convexhull.stl" scale="1.0 1.0 1.0"/>
      </geometry>
    </collision>
  </link>
  <joint name="ARElbowB11" type="revolute">
    <origin xyz="0.0 -0.029 -0.1391" rpy="2.888403 0.0 -3.141592"/>
    <axis xyz="1.0 0.0 0.0"/>
    <parent link="ARShoulder3_Link"/>
    <child link="ARElbowB11_Link"/>
    <limit effort="400.0" lower="-1.57" upper="1.57" velocity="3.1415926"/>
  </joint>
  <link name="ARElbowB11_Link">
    <inertial>
      <origin xyz="-2.6e-05 1.9e-05 0.10704" rpy="0.0 0.0 0.0"/>
      <mass value="0.32695999999999986"/>
      <inertia ixx="0.00011101999998112811" ixy="1.0984488097443103e-08" ixz="6.629144855259e-08" iyy="0.00011251000000736784" iyz="1.406700231845442e-07" izz="7.073300001150397e-05"/>
    </inertial>
    <visual name="ARElbowB11_Link_Visual">
      <origin xyz="0.0 0.0 0.0" rpy="0.0 0.0 0.0"/>
      <geometry>
        <mesh filename="../meshes/lfs-stl/ARElbow_B11_Link.stl" scale="1.0 1.0 1.0"/>
      </geometry>
      <material name="">
        <color rgba="0.75294 0.75294 0.75294 1.0"/>
      </material>
    </visual>
    <collision name="ARElbowB11_Link_Collision">
      <origin xyz="0.0 0.0 0.0" rpy="0.0 0.0 0.0"/>
      <geometry>
        <mesh filename="../meshes/lfs-stl/ARElbow_B11_Link_convexhull.stl" scale="1.0 1.0 1.0"/>
      </geometry>
    </collision>
  </link>
  <link name="ARElbow_Link">
    <inertial>
      <origin xyz="7e-05 0.001127 0.080286" rpy="0.0 0.0 0.0"/>
      <mass value="0.6357799999999997"/>
      <inertia ixx="0.0005099900001544764" ixy="-2.2297207206594354e-07" ixz="-4.0468474586715554e-07" iyy="0.0005163300270204655" iyz="-4.423298448630883e-05" izz="0.00046536997282505774"/>
    </inertial>
    <visual name="ARElbow_Link_Visual">
      <origin xyz="0.0 -0.0 0.0" rpy="0.0 0.0 3.141593"/>
      <geometry>
        <mesh filename="../meshes/lfs-stl/ARElbow_Link.stl" scale="1.0 1.0 1.0"/>
      </geometry>
      <material name="">
        <color rgba="0.75294 0.75294 0.75294 1.0"/>
      </material>
    </visual>
    <collision name="ARElbow_Link_Collision">
      <origin xyz="0.0 0.0 0.0" rpy="0.0 0.0 0.0"/>
      <geometry>
        <mesh filename="../meshes/lfs-stl/ARElbow_Link_convexhull.stl" scale="1.0 1.0 1.0"/>
      </geometry>
    </collision>
  </link>
  <link name="ARShoulder3_Link">
    <inertial>
      <origin xyz="-3.3e-05 0.003369 -0.14648" rpy="0.0 0.0 0.0"/>
      <mass value="0.8525751706215601"/>
      <inertia ixx="0.0028013000003190894" ixy="5.193714519100651e-07" ixz="7.258930202151745e-07" iyy="0.002740099961802801" iyz="-5.467267704269619e-05" izz="0.000786290037878108"/>
    </inertial>
    <visual name="ARShoulder3_Link_Visual">
      <origin xyz="0.0 0.0 0.0" rpy="3.141593 0.0 0.0"/>
      <geometry>
        <mesh filename="../meshes/lfs-stl/ARShoulder3_Link.stl" scale="1.0 1.0 1.0"/>
      </geometry>
      <material name="">
        <color rgba="0.75294 0.75294 0.75294 1.0"/>
      </material>
    </visual>
    <collision name="ARShoulder3_Link_Collision">
      <origin xyz="0.0 0.0 0.0" rpy="0.0 0.0 0.0"/>
      <geometry>
        <mesh filename="../meshes/lfs-stl/ARShoulder3_Link_convexhull.stl" scale="1.0 1.0 1.0"/>
      </geometry>
    </collision>
  </link>
</robot>
