<robot name="Head">
  <joint name="HeadActC" type="revolute">
    <origin xyz="0.15925 0.0 0.0" rpy="-1.5708 0.0 0.0"/>
    <axis xyz="1.0 0.0 0.0"/>
    <parent link="HeadBase_Link"/>
    <child link="HeadActC_Link"/>
    <limit effort="400.0" lower="-3.1415926" upper="3.1415926" velocity="3.1415926"/>
  </joint>
  <link name="HeadActC_Link">
    <inertial>
      <origin xyz="-0.017674 7.2495e-17 5.4996e-17" rpy="0.0 0.0 0.0"/>
      <mass value="0.0046686"/>
      <inertia ixx="1e-05" ixy="4.873599999999988e-23" ixz="5.031600000000013e-23" iyy="1.003789e-05" iyz="-4.798999999999274e-09" izz="1.004626e-05"/>
    </inertial>
    <visual name="HeadActC_Visual">
      <origin xyz="0.0 0.0 0.0" rpy="0.0 0.0 0.0"/>
      <geometry>
        <mesh filename="../meshes/lfs-stl/Head_ActC.stl"/>
      </geometry>
      <material name="">
        <color rgba="0.89804 0.91765 0.92941 1.0"/>
      </material>
    </visual>
    <collision name="HeadActC_Collision">
      <origin xyz="0.0 0.0 0.0" rpy="0.0 0.0 0.0"/>
      <geometry>
        <mesh filename="../meshes/lfs-stl/Head_ActC_convexhull.stl" scale="1.0 1.0 1.0"/>
      </geometry>
    </collision>
  </link>
  <joint name="HeadActL" type="revolute">
    <origin xyz="0.15925 0.0 0.0" rpy="3.1416 0.0 1.5708"/>
    <axis xyz="1.0 0.0 0.0"/>
    <parent link="HeadBase_Link"/>
    <child link="HeadActL_Link"/>
    <limit effort="400.0" lower="-3.1415926" upper="3.1415926" velocity="3.1415926"/>
  </joint>
  <link name="HeadActL_Link">
    <inertial>
      <origin xyz="-0.018628 0.0 1.3747e-17" rpy="0.0 0.0 0.0"/>
      <mass value="0.049162"/>
      <inertia ixx="1.50716e-05" ixy="3.3203e-22" ixz="-3.6271000000000003e-22" iyy="1.0000000000000003e-05" iyz="-8.470329472543003e-22" izz="1.0000000000000003e-05"/>
    </inertial>
    <visual name="HeadActL_Visual">
      <origin xyz="0.0 0.0 0.0" rpy="0.0 0.0 0.0"/>
      <geometry>
        <mesh filename="../meshes/lfs-stl/Head_ActL.stl"/>
      </geometry>
      <material name="">
        <color rgba="0.69804 0.69804 0.69804 1.0"/>
      </material>
    </visual>
    <collision name="HeadActL_Collision">
      <origin xyz="0.0 0.0 0.0" rpy="0.0 0.0 0.0"/>
      <geometry>
        <mesh filename="../meshes/lfs-stl/Head_ActL_convexhull.stl" scale="1.0 1.0 1.0"/>
      </geometry>
    </collision>
  </link>
  <joint name="HeadActR" type="revolute">
    <origin xyz="0.15925 0.0 0.0" rpy="0.0 0.0 -1.5708"/>
    <axis xyz="1.0 0.0 0.0"/>
    <parent link="HeadBase_Link"/>
    <child link="HeadActR_Link"/>
    <limit effort="400.0" lower="-3.1415926" upper="3.1415926" velocity="3.1415926"/>
  </joint>
  <link name="HeadActR_Link">
    <inertial>
      <origin xyz="-0.018628 -1.3878e-17 9.5749e-18" rpy="0.0 0.0 0.0"/>
      <mass value="0.049162"/>
      <inertia ixx="1.5071600000000002e-05" ixy="2.9254000000000035e-22" ixz="-3.611699999999999e-22" iyy="1.0000000000000008e-05" iyz="-2.541098841762901e-21" izz="1e-05"/>
    </inertial>
    <visual name="HeadActR_Visual">
      <origin xyz="0.0 0.0 0.0" rpy="0.0 0.0 0.0"/>
      <geometry>
        <mesh filename="../meshes/lfs-stl/Head_ActR.stl"/>
      </geometry>
      <material name="">
        <color rgba="0.69804 0.69804 0.69804 1.0"/>
      </material>
    </visual>
    <collision name="HeadActR_Collision">
      <origin xyz="0.0 0.0 0.0" rpy="0.0 0.0 0.0"/>
      <geometry>
        <mesh filename="../meshes/lfs-stl/Head_ActR_convexhull.stl" scale="1.0 1.0 1.0"/>
      </geometry>
    </collision>
  </link>
  <link name="HeadBase_Link">
    <inertial>
      <origin xyz="0.074228 -3.6471e-05 -0.00062034" rpy="0.0 0.0 0.0"/>
      <mass value="1.339"/>
      <inertia ixx="0.0017089" ixy="4.2668e-08" ixz="5.2598e-08" iyy="0.0014476" iyz="7.0143e-07" izz="0.0013396"/>
    </inertial>
    <visual name="HeadBase_Visual">
      <origin xyz="0.0 0.0 0.0" rpy="0.0 0.0 0.0"/>
      <geometry>
        <mesh filename="../meshes/lfs-stl/Head_Base.stl"/>
      </geometry>
      <material name="">
        <color rgba="0.69804 0.69804 0.69804 1.0"/>
      </material>
    </visual>
    <collision name="HeadBase_Collision">
      <origin xyz="0.0 0.0 0.0" rpy="0.0 0.0 0.0"/>
      <geometry>
        <mesh filename="../meshes/lfs-stl/Head_Base_convexhull.stl" scale="1.0 1.0 1.0"/>
      </geometry>
    </collision>
  </link>
  <joint name="HeadPitch" type="revolute">
    <origin xyz="0.15925 0.0 0.0" rpy="0.0 0.0 -1.5708"/>
    <axis xyz="1.0 0.0 0.0"/>
    <parent link="HeadBase_Link"/>
    <child link="HeadPitch_Link"/>
    <limit effort="400.0" lower="-0.3" upper="0.35" velocity="3.1415926"/>
  </joint>
  <link name="HeadPitch_Link">
    <inertial>
      <origin xyz="3.73800046473431e-08 -4.45791975556276e-09 0.00296950883117566" rpy="0.0 0.0 0.0"/>
      <mass value="0.0135306815484183"/>
      <inertia ixx="1.0900469792997046e-05" ixy="-1.983276674419689e-12" ixz="2.9229038977620623e-12" iyy="1.1777940400612256e-05" iyz="-1.006944634337718e-13" izz="1.0000000000009494e-05"/>
    </inertial>
    <visual name="HeadPitch_Visual">
      <origin xyz="0.0 0.0 0.0" rpy="0.0 0.0 0.0"/>
      <geometry>
        <mesh filename="../meshes/lfs-stl/HeadPitch.stl"/>
      </geometry>
      <material name="">
        <color rgba="0.898039215686275 0.917647058823529 0.929411764705882 1.0"/>
      </material>
    </visual>
    <collision name="HeadPitch_Collision">
      <origin xyz="0.0 0.0 0.0" rpy="0.0 0.0 0.0"/>
      <geometry>
        <mesh filename="../meshes/lfs-stl/HeadPitch_convexhull.stl" scale="1.0 1.0 1.0"/>
      </geometry>
    </collision>
  </link>
  <joint name="HeadRoll" type="revolute">
    <origin xyz="0.0 0.0 0.0" rpy="-1.5708 -1.5708 0.0"/>
    <axis xyz="-1.0 0.0 0.0"/>
    <parent link="HeadPitch_Link"/>
    <child link="HeadRoll_Link"/>
    <limit effort="400.0" lower="-0.45" upper="0.007853981633974483" velocity="3.1415926"/>
  </joint>
  <link name="HeadRoll_Link">
    <inertial>
      <origin xyz="-0.00844253878850604 -4.18737776903302e-08 0.00884603238325907" rpy="0.0 0.0 0.0"/>
      <mass value="0.109788715391496"/>
      <inertia ixx="1.83994177455821e-05" ixy="5.13405597754959e-11" ixz="-1.07875589146075e-08" iyy="1.359548687449e-05" iyz="-9.3011670884998e-10" izz="1.39946184243742e-05"/>
    </inertial>
    <visual name="HeadRoll_Visual">
      <origin xyz="0.0 0.0 0.0" rpy="0.0 0.0 0.0"/>
      <geometry>
        <mesh filename="../meshes/lfs-stl/HeadRoll.stl"/>
      </geometry>
      <material name="">
        <color rgba="0.898039215686275 0.917647058823529 0.929411764705882 1.0"/>
      </material>
    </visual>
    <collision name="HeadRoll_Collision">
      <origin xyz="0.0 0.0 0.0" rpy="0.0 0.0 0.0"/>
      <geometry>
        <mesh filename="../meshes/lfs-stl/HeadRoll_convexhull.stl" scale="1.0 1.0 1.0"/>
      </geometry>
    </collision>
  </link>
  <joint name="HeadYaw" type="revolute">
    <origin xyz="0.0 0.0 0.0" rpy="1.5708 -1.5708 0.0"/>
    <axis xyz="1.0 0.0 0.0"/>
    <parent link="HeadRoll_Link"/>
    <child link="HeadYaw_Link"/>
    <limit effort="400.0" lower="-2.1" upper="2.1" velocity="3.1415926"/>
  </joint>
  <link name="HeadYaw_Link">
    <inertial>
      <origin xyz="0.0865202750448954 -0.0440420348532486 -0.00282280741895916" rpy="0.0 0.0 0.0"/>
      <mass value="1.46451930762968"/>
      <inertia ixx="0.00400957562211491" ixy="-0.000773636855316844" ixz="-8.24762860917018e-06" iyy="0.00399135489001388" iyz="-9.04346097850664e-06" izz="0.00411109150468807"/>
    </inertial>
    <visual name="HeadYaw_Visual">
      <origin xyz="0.0 0.0 0.0" rpy="0.0 0.0 0.0"/>
      <geometry>
        <mesh filename="../meshes/lfs-stl/HeadYaw.stl"/>
      </geometry>
      <material name="">
        <color rgba="0.498039215686275 0.498039215686275 0.498039215686275 1.0"/>
      </material>
    </visual>
    <collision name="HeadYaw_Collision">
      <origin xyz="0.0 0.0 0.0" rpy="0.0 0.0 0.0"/>
      <geometry>
        <mesh filename="../meshes/lfs-stl/HeadYaw_convexhull.stl" scale="1.0 1.0 1.0"/>
      </geometry>
    </collision>
  </link>
  <transmission name="head_joints">
    <type>MultiJointLinearTransmission</type>
    <joint name="HeadActC">
      <depends_on joint="HeadYaw" multiplier="1.0" offset="0"/>
    </joint>
    <joint name="HeadActL">
      <depends_on joint="HeadRoll" multiplier="1.0" offset="0"/>
      <depends_on joint="HeadPitch" multiplier="-1.0" offset="0"/>
    </joint>
    <joint name="HeadActR">
      <depends_on joint="HeadRoll" multiplier="-1.0" offset="0"/>
      <depends_on joint="HeadPitch" multiplier="-1.0" offset="0"/>
    </joint>
  </transmission>
</robot>
