<robot name="RH5">
  <joint name="ALElbow" type="revolute">
    <origin xyz="0.0 0.0 0.355" rpy="1.5708 -1.5708 0.0"/>
    <axis xyz="0.0 0.0 -1.0"/>
    <parent link="ALShoulder3_Link"/>
    <child link="ALElbow_Link"/>
    <limit effort="30.0" lower="-1.62" upper="0.1872" velocity="1.8326"/>
  </joint>
  <link name="ALElbow_Link">
    <inertial>
      <origin xyz="0.010641 3.9392e-07 0.0080701" rpy="0.0 0.0 0.0"/>
      <mass value="0.255"/>
      <inertia ixx="0.00028052" ixy="-4.0187e-09" ixz="2.2663e-05" iyy="0.00036848" iyz="2.9394e-09" izz="0.00038255"/>
    </inertial>
    <visual name="ALElbow_Link_visual">
      <origin xyz="0.0 0.0 0.0" rpy="0.0 0.0 0.0"/>
      <geometry>
        <mesh filename="../meshes/ALElbow_Link.STL"/>
      </geometry>
      <material name="">
        <color rgba="0.69804 0.69804 0.69804 1.0"/>
      </material>
    </visual>
  </link>
  <joint name="ALShoulder1" type="revolute">
    <origin xyz="0.012 0.313 0.386" rpy="-3.1415889803981822 3.673205103455057e-06 1.328"/>
    <axis xyz="1.0 0.0 0.0"/>
    <parent link="BodyYaw_Link"/>
    <child link="ALShoulder1_Link"/>
    <limit effort="135.0" lower="-3.0543" upper="3.0543" velocity="1.8326"/>
  </joint>
  <link name="ALShoulder1_Link">
    <inertial>
      <origin xyz="-0.053027 0.0029798 -1.6132e-07" rpy="0.0 0.0 0.0"/>
      <mass value="0.47438"/>
      <inertia ixx="0.0013753" ixy="3.4317e-05" ixz="-5.2624e-09" iyy="0.00084701" iyz="1.2533e-08" izz="0.0018205"/>
    </inertial>
    <visual name="ALShoulder1_Link_visual">
      <origin xyz="0.0 0.0 0.0" rpy="0.0 0.0 0.0"/>
      <geometry>
        <mesh filename="../meshes/ALShoulder1_Link.STL"/>
      </geometry>
      <material name="">
        <color rgba="0.69804 0.69804 0.69804 1.0"/>
      </material>
    </visual>
  </link>
  <joint name="ALShoulder2" type="revolute">
    <origin xyz="0.0 0.0 0.0" rpy="0.0 1.9722e-31 0.0"/>
    <axis xyz="0.0 1.0 0.0"/>
    <parent link="ALShoulder1_Link"/>
    <child link="ALShoulder2_Link"/>
    <limit effort="167.0" lower="-0.5236" upper="1.571" velocity="1.8326"/>
  </joint>
  <link name="ALShoulder2_Link">
    <inertial>
      <origin xyz="2.5304e-05 0.0076989 0.0023608" rpy="0.0 0.0 0.0"/>
      <mass value="0.98"/>
      <inertia ixx="0.0012245" ixy="3.9462e-07" ixz="5.5448e-07" iyy="0.0010372" iyz="3.2296e-05" izz="0.0012057"/>
    </inertial>
    <visual name="ALShoulder2_Link_visual">
      <origin xyz="0.0 0.0 0.0" rpy="0.0 0.0 0.0"/>
      <geometry>
        <mesh filename="../meshes/ALShoulder2_Link.STL"/>
      </geometry>
      <material name="">
        <color rgba="0.69804 0.69804 0.69804 1.0"/>
      </material>
    </visual>
    <collision name="ALShoulder2_Link_collision">
      <origin xyz="0.0 0.0 0.0" rpy="0.0 0.0 0.0"/>
      <geometry>
        <mesh filename="../meshes/ALShoulder2_Link.STL"/>
      </geometry>
    </collision>
  </link>
  <joint name="ALShoulder3" type="revolute">
    <origin xyz="0.0 0.0 0.0" rpy="0.0 1.9722e-31 0.0"/>
    <axis xyz="0.0 0.0 1.0"/>
    <parent link="ALShoulder2_Link"/>
    <child link="ALShoulder3_Link"/>
    <limit effort="53.0" lower="-3.0543" upper="3.0543" velocity="1.8326"/>
  </joint>
  <link name="ALShoulder3_Link">
    <inertial>
      <origin xyz="7.9284e-06 3.7845e-05 0.16439" rpy="0.0 0.0 0.0"/>
      <mass value="1.3999"/>
      <inertia ixx="0.013898" ixy="1.2682e-06" ixz="8.7833e-07" iyy="0.013686" iyz="2.7121e-06" izz="0.0019878"/>
    </inertial>
    <visual name="ALShoulder3_Link_visual">
      <origin xyz="0.0 0.0 0.0" rpy="0.0 0.0 0.0"/>
      <geometry>
        <mesh filename="../meshes/ALShoulder3_Link.STL"/>
      </geometry>
      <material name="">
        <color rgba="0.69804 0.69804 0.69804 1.0"/>
      </material>
    </visual>
    <collision name="ALShoulder3_Link_collision">
      <origin xyz="0.0 0.0 0.0" rpy="0.0 0.0 0.0"/>
      <geometry>
        <mesh filename="../meshes/ALShoulder3_Link.STL"/>
      </geometry>
    </collision>
  </link>
  <joint name="ALWristPitch" type="revolute">
    <origin xyz="0.0 0.0 0.0" rpy="-4.9304e-32 -9.5526e-32 0.0"/>
    <axis xyz="0.0 1.0 0.0"/>
    <parent link="ALWristYaw_Link"/>
    <child link="ALWristPitch_Link"/>
    <limit effort="12.5" lower="-3.1416" upper="3.1416" velocity="5.0"/>
  </joint>
  <link name="ALWristPitch_Link">
    <inertial>
      <origin xyz="3.0531e-14 -6.0923e-15 -3.3085e-14" rpy="0.0 0.0 0.0"/>
      <mass value="6.2832e-06"/>
      <inertia ixx="3.6652e-12" ixy="1.757e-26" ixz="2.9539e-41" iyy="3.1416e-12" iyz="-9.766e-28" izz="3.6652e-12"/>
    </inertial>
    <visual name="ALWristPitch_Link_visual">
      <origin xyz="0.0 0.0 0.0" rpy="0.0 0.0 0.0"/>
      <geometry>
        <mesh filename="../meshes/ALWristPitch_Link.STL"/>
      </geometry>
      <material name="">
        <color rgba="0.79216 0.81961 0.93333 1.0"/>
      </material>
    </visual>
    <collision name="ALWristPitch_Link_collision">
      <origin xyz="0.0 0.0 0.0" rpy="0.0 0.0 0.0"/>
      <geometry>
        <mesh filename="../meshes/ALWristPitch_Link.STL"/>
      </geometry>
    </collision>
  </link>
  <joint name="ALWristRoll" type="revolute">
    <origin xyz="0.386 0.0 0.0" rpy="-1.5708 3.1415926536 1.5708"/>
    <axis xyz="0.0 0.0 -1.0"/>
    <parent link="ALElbow_Link"/>
    <child link="ALWristRoll_Link"/>
    <limit effort="53.0" lower="-3.0543" upper="3.0543" velocity="1.8326"/>
  </joint>
  <link name="ALWristRoll_Link">
    <inertial>
      <origin xyz="0.025274 -4.3815e-06 0.19965" rpy="0.0 0.0 0.0"/>
      <mass value="2.3703"/>
      <inertia ixx="0.020206" ixy="1.7582e-07" ixz="0.0025932" iyy="0.020635" iyz="2.8078e-06" izz="0.0051431"/>
    </inertial>
    <visual name="ALWristRoll_Link_visual">
      <origin xyz="0.0 0.0 0.0" rpy="0.0 0.0 0.0"/>
      <geometry>
        <mesh filename="../meshes/ALWristRoll_Link.STL"/>
      </geometry>
      <material name="">
        <color rgba="0.69804 0.69804 0.69804 1.0"/>
      </material>
    </visual>
    <collision name="ALWristRoll_Link_collision">
      <origin xyz="0.0 0.0 0.0" rpy="0.0 0.0 0.0"/>
      <geometry>
        <mesh filename="../meshes/ALWristRoll_Link.STL"/>
      </geometry>
    </collision>
  </link>
  <joint name="ALWristYaw" type="revolute">
    <origin xyz="0.0 0.0 0.0" rpy="-4.9304e-32 -9.5526e-32 0.0"/>
    <axis xyz="1.0 0.0 0.0"/>
    <parent link="ALWristRoll_Link"/>
    <child link="ALWristYaw_Link"/>
    <limit effort="12.5" lower="-1.2566" upper="0.7853" velocity="5.0"/>
  </joint>
  <link name="ALWristYaw_Link">
    <inertial>
      <origin xyz="-3.8303e-15 -5.8703e-15 -1.6653e-16" rpy="0.0 0.0 0.0"/>
      <mass value="0.006976"/>
      <inertia ixx="1.0349e-06" ixy="-7.3387e-21" ixz="1.7878e-22" iyy="4.8433e-07" iyz="-5.1569e-21" izz="1.4399e-06"/>
    </inertial>
    <visual name="ALWristYaw_Link_visual">
      <origin xyz="0.0 0.0 0.0" rpy="0.0 0.0 0.0"/>
      <geometry>
        <mesh filename="../meshes/ALWristYaw_Link.STL"/>
      </geometry>
      <material name="">
        <color rgba="0.79216 0.81961 0.93333 1.0"/>
      </material>
    </visual>
    <collision name="ALWristYaw_Link_collision">
      <origin xyz="0.0 0.0 0.0" rpy="0.0 0.0 0.0"/>
      <geometry>
        <mesh filename="../meshes/ALWristYaw_Link.STL"/>
      </geometry>
    </collision>
  </link>
  <joint name="ALWrist_Act1" type="prismatic">
    <origin xyz="0.0 0.0 0.26731" rpy="0.071148 0.014965 -1.3713e-14"/>
    <axis xyz="-0.014964 0.07108 0.99736"/>
    <parent link="ALWrist_B12_Link"/>
    <child link="ALWrist_Act1_Link"/>
    <limit effort="262.0" lower="-0.02046" upper="0.04454" velocity="0.2"/>
  </joint>
  <link name="ALWrist_Act1_Link">
    <inertial>
      <origin xyz="0.0006222 -0.0029555 -0.04147" rpy="0.0 0.0 0.0"/>
      <mass value="0.02"/>
      <inertia ixx="1.3508e-05" ixy="1.3691e-08" ixz="1.9172e-07" iyy="1.3471e-05" iyz="-9.1248e-07" izz="7.3244e-07"/>
    </inertial>
    <visual name="ALWrist_Act1_Link_visual">
      <origin xyz="0.0 0.0 0.0" rpy="0.0 0.0 0.0"/>
      <geometry>
        <mesh filename="../meshes/ALWrist_Act1_Link.STL"/>
      </geometry>
      <material name="">
        <color rgba="0.69804 0.69804 0.69804 1.0"/>
      </material>
    </visual>
    <collision name="ALWrist_Act1_Link_collision">
      <origin xyz="0.0 0.0 0.0" rpy="0.0 0.0 0.0"/>
      <geometry>
        <mesh filename="../meshes/ALWrist_Act1_Link.STL"/>
      </geometry>
    </collision>
  </link>
  <joint name="ALWrist_Act2" type="prismatic">
    <origin xyz="0.00070119 0.0 0.26731" rpy="-8.743e-16 0.0026232 -2.7756e-17"/>
    <axis xyz="0.0 0.0 1.0"/>
    <parent link="ALWrist_B22_Link"/>
    <child link="ALWrist_Act2_Link"/>
    <limit effort="262.0" lower="-0.02046" upper="0.04454" velocity="0.2"/>
  </joint>
  <link name="ALWrist_Act2_Link">
    <inertial>
      <origin xyz="-1.7311e-09 1.2133e-09 -0.04158" rpy="0.0 0.0 0.0"/>
      <mass value="0.02"/>
      <inertia ixx="1.3511e-05" ixy="-2.7182e-11" ixz="1.0876e-12" iyy="1.3536e-05" iyz="-8.3798e-13" izz="6.6453e-07"/>
    </inertial>
    <visual name="ALWrist_Act2_Link_visual">
      <origin xyz="0.0 0.0 0.0" rpy="0.0 0.0 0.0"/>
      <geometry>
        <mesh filename="../meshes/ALWrist_Act2_Link.STL"/>
      </geometry>
      <material name="">
        <color rgba="0.69804 0.69804 0.69804 1.0"/>
      </material>
    </visual>
    <collision name="ALWrist_Act2_Link_collision">
      <origin xyz="0.0 0.0 0.0" rpy="0.0 0.0 0.0"/>
      <geometry>
        <mesh filename="../meshes/ALWrist_Act2_Link.STL"/>
      </geometry>
    </collision>
  </link>
  <joint name="ALWrist_B11" type="revolute">
    <origin xyz="-0.032 -0.016 0.2616" rpy="3.0704 -3.307e-15 -2.7145e-14"/>
    <axis xyz="1.0 0.0 0.0"/>
    <parent link="ALWristRoll_Link"/>
    <child link="ALWrist_B11_Link"/>
    <limit effort="0.0" lower="0" upper="0" velocity="0.0"/>
  </joint>
  <link name="ALWrist_B11_Link">
    <inertial>
      <origin xyz="-2.8647e-11 -2.8644e-11 7.6796e-15" rpy="0.0 0.0 0.0"/>
      <mass value="0.0016071"/>
      <inertia ixx="1.3441e-08" ixy="-2.7504e-23" ixz="-3.6865e-16" iyy="1.3441e-08" iyz="3.6865e-16" izz="1.2362e-08"/>
    </inertial>
    <visual name="ALWrist_B11_Link_visual">
      <origin xyz="0.0 0.0 0.0" rpy="0.0 0.0 0.0"/>
      <geometry>
        <mesh filename="../meshes/ALWrist_B11_Link.STL"/>
      </geometry>
      <material name="">
        <color rgba="0.64706 0.61961 0.58824 1.0"/>
      </material>
    </visual>
    <collision name="ALWrist_B11_Link_collision">
      <origin xyz="0.0 0.0 0.0" rpy="0.0 0.0 0.0"/>
      <geometry>
        <mesh filename="../meshes/ALWrist_B11_Link.STL"/>
      </geometry>
    </collision>
  </link>
  <joint name="ALWrist_B12" type="revolute">
    <origin xyz="0.0 0.0 0.0" rpy="4.3165e-15 -0.014965 0.0"/>
    <axis xyz="0.0 1.0 0.0"/>
    <parent link="ALWrist_B11_Link"/>
    <child link="ALWrist_B12_Link"/>
    <limit effort="0.0" lower="0" upper="0" velocity="0.0"/>
  </joint>
  <link name="ALWrist_B12_Link">
    <inertial>
      <origin xyz="-5.9648e-05 -4.9733e-09 0.09465" rpy="0.0 0.0 0.0"/>
      <mass value="0.17"/>
      <inertia ixx="0.00060078" ixy="1.3729e-11" ixz="-8.26e-07" iyy="0.00060065" iyz="5.1897e-11" izz="2.1279e-05"/>
    </inertial>
    <visual name="ALWrist_B12_Link_visual">
      <origin xyz="0.0 0.0 0.0" rpy="0.0 0.0 0.0"/>
      <geometry>
        <mesh filename="../meshes/ALWrist_B12_Link.STL"/>
      </geometry>
      <material name="">
        <color rgba="0.69804 0.69804 0.69804 1.0"/>
      </material>
    </visual>
    <collision name="ALWrist_B12_Link_collision">
      <origin xyz="0.0 0.0 0.0" rpy="0.0 0.0 0.0"/>
      <geometry>
        <mesh filename="../meshes/ALWrist_B12_Link.STL"/>
      </geometry>
    </collision>
  </link>
  <joint name="ALWrist_B21" type="revolute">
    <origin xyz="-0.032 0.016 0.2616" rpy="-3.0704 0.014927 0.0010639"/>
    <axis xyz="0.99989 0.0 -0.014964"/>
    <parent link="ALWristRoll_Link"/>
    <child link="ALWrist_B21_Link"/>
    <limit effort="0.0" lower="0" upper="0" velocity="0.0"/>
  </joint>
  <link name="ALWrist_B21_Link">
    <inertial>
      <origin xyz="-2.8641e-11 2.8645e-11 4.2873e-13" rpy="0.0 0.0 0.0"/>
      <mass value="0.0016071"/>
      <inertia ixx="1.3441e-08" ixy="5.5165e-18" ixz="-1.6142e-11" iyy="1.3441e-08" iyz="3.6861e-16" izz="1.2362e-08"/>
    </inertial>
    <visual name="ALWrist_B21_Link_visual">
      <origin xyz="0.0 0.0 0.0" rpy="0.0 0.0 0.0"/>
      <geometry>
        <mesh filename="../meshes/ALWrist_B21_Link.STL"/>
      </geometry>
      <material name="">
        <color rgba="0.64706 0.61961 0.58824 1.0"/>
      </material>
    </visual>
    <collision name="ALWrist_B21_Link_collision">
      <origin xyz="0.0 0.0 0.0" rpy="0.0 0.0 0.0"/>
      <geometry>
        <mesh filename="../meshes/ALWrist_B21_Link.STL"/>
      </geometry>
    </collision>
  </link>
  <joint name="ALWrist_B22" type="revolute">
    <origin xyz="0.0 0.0 0.0" rpy="8.8818e-16 -0.0026232 -2.7756e-17"/>
    <axis xyz="0.0 1.0 0.0"/>
    <parent link="ALWrist_B21_Link"/>
    <child link="ALWrist_B22_Link"/>
    <limit effort="0.0" lower="0" upper="0" velocity="0.0"/>
  </joint>
  <link name="ALWrist_B22_Link">
    <inertial>
      <origin xyz="0.00030793 4.2857e-09 0.094649" rpy="0.0 0.0 0.0"/>
      <mass value="0.17"/>
      <inertia ixx="0.00060078" ixy="1.3111e-11" ixz="-6.9413e-07" iyy="0.00060065" iyz="-3.467e-11" izz="2.1279e-05"/>
    </inertial>
    <visual name="ALWrist_B22_Link_visual">
      <origin xyz="0.0 0.0 0.0" rpy="0.0 0.0 0.0"/>
      <geometry>
        <mesh filename="../meshes/ALWrist_B22_Link.STL"/>
      </geometry>
      <material name="">
        <color rgba="0.69804 0.69804 0.69804 1.0"/>
      </material>
    </visual>
    <collision name="ALWrist_B22_Link_collision">
      <origin xyz="0.0 0.0 0.0" rpy="0.0 0.0 0.0"/>
      <geometry>
        <mesh filename="../meshes/ALWrist_B22_Link.STL"/>
      </geometry>
    </collision>
  </link>
  <link name="ALWrist_FT">
    <inertial>
      <origin xyz="0.0013964 -8.0618e-05 0.041768" rpy="0.0 0.0 0.0"/>
      <mass value="0.46746"/>
      <inertia ixx="0.0011813" ixy="9.7393e-07" ixz="-6.577e-05" iyy="0.00099999" iyz="3.5173e-06" izz="0.00055976"/>
    </inertial>
    <visual name="ALWrist_FT_visual">
      <origin xyz="0.0 0.0 0.0" rpy="0.0 0.0 0.0"/>
      <geometry>
        <mesh filename="../meshes/ALWrist_FT.STL"/>
      </geometry>
      <material name="">
        <color rgba="0.69804 0.69804 0.69804 1.0"/>
      </material>
    </visual>
    <collision name="ALWrist_FT_collision">
      <origin xyz="0.0 0.0 0.0" rpy="0.0 0.0 0.0"/>
      <geometry>
        <mesh filename="../meshes/ALWrist_FT.STL"/>
      </geometry>
    </collision>
  </link>
  <joint name="ALWrist_FT" type="fixed">
    <origin xyz="0.0 0.0 -0.02995" rpy="-3.1416 -2.9034e-15 1.6653e-16"/>
    <axis xyz="0.0 0.0 0.0"/>
    <parent link="ALWristPitch_Link"/>
    <child link="ALWrist_FT"/>
  </joint>
  <joint name="ARElbow" type="revolute">
    <origin xyz="0.0 0.0 0.355" rpy="1.5708 -1.5708 0.0"/>
    <axis xyz="0.0 0.0 -1.0"/>
    <parent link="ARShoulder3_Link"/>
    <child link="ARElbow_Link"/>
    <limit effort="30.0" lower="-0.1872" upper="1.62" velocity="1.8326"/>
  </joint>
  <link name="ARElbow_Link">
    <inertial>
      <origin xyz="0.010641 3.9392e-07 0.0080701" rpy="0.0 0.0 0.0"/>
      <mass value="0.255"/>
      <inertia ixx="0.00028052" ixy="-4.0187e-09" ixz="2.2663e-05" iyy="0.00036848" iyz="2.9394e-09" izz="0.00038255"/>
    </inertial>
    <visual name="ARElbow_Link_visual">
      <origin xyz="0.0 0.0 0.0" rpy="0.0 0.0 0.0"/>
      <geometry>
        <mesh filename="../meshes/ALElbow_Link.STL"/>
      </geometry>
      <material name="">
        <color rgba="0.69804 0.69804 0.69804 1.0"/>
      </material>
    </visual>
  </link>
  <joint name="ARShoulder1" type="revolute">
    <origin xyz="0.012 -0.313 0.386" rpy="-3.1415889803981822 -3.673205103510568e-06 1.8135999999999999"/>
    <axis xyz="-1.0 0.0 0.0"/>
    <parent link="BodyYaw_Link"/>
    <child link="ARShoulder1_Link"/>
    <limit effort="135.0" lower="-3.0543" upper="3.0543" velocity="1.8326"/>
  </joint>
  <link name="ARShoulder1_Link">
    <inertial>
      <origin xyz="0.053027 0.0029798 1.6135e-07" rpy="0.0 0.0 0.0"/>
      <mass value="0.47438"/>
      <inertia ixx="0.0013753" ixy="-3.4317e-05" ixz="-5.2626e-09" iyy="0.000847" iyz="-1.2533e-08" izz="0.0018205"/>
    </inertial>
    <visual name="ARShoulder1_Link_visual">
      <origin xyz="0.0 0.0 0.0" rpy="0.0 0.0 0.0"/>
      <geometry>
        <mesh filename="../meshes/ARShoulder1_Link.STL"/>
      </geometry>
      <material name="">
        <color rgba="0.69804 0.69804 0.69804 1.0"/>
      </material>
    </visual>
  </link>
  <joint name="ARShoulder2" type="revolute">
    <origin xyz="0.0 0.0 0.0" rpy="0.0 -1.9722e-31 0.0"/>
    <axis xyz="0.0 1.0 0.0"/>
    <parent link="ARShoulder1_Link"/>
    <child link="ARShoulder2_Link"/>
    <limit effort="167.0" lower="-1.571" upper="0.5236" velocity="1.8326"/>
  </joint>
  <link name="ARShoulder2_Link">
    <inertial>
      <origin xyz="2.5307e-05 0.0076989 0.0023608" rpy="0.0 0.0 0.0"/>
      <mass value="0.98"/>
      <inertia ixx="0.0012245" ixy="3.9471e-07" ixz="5.5464e-07" iyy="0.0010372" iyz="3.2296e-05" izz="0.0012057"/>
    </inertial>
    <visual name="ARShoulder2_Link_visual">
      <origin xyz="0.0 0.0 0.0" rpy="0.0 0.0 0.0"/>
      <geometry>
        <mesh filename="../meshes/ARShoulder2_Link.STL"/>
      </geometry>
      <material name="">
        <color rgba="0.69804 0.69804 0.69804 1.0"/>
      </material>
    </visual>
    <collision name="ARShoulder2_Link_collision">
      <origin xyz="0.0 0.0 0.0" rpy="0.0 0.0 0.0"/>
      <geometry>
        <mesh filename="../meshes/ARShoulder2_Link.STL"/>
      </geometry>
    </collision>
  </link>
  <joint name="ARShoulder3" type="revolute">
    <origin xyz="0.0 0.0 0.0" rpy="0.0 1.9722e-31 0.0"/>
    <axis xyz="0.0 0.0 1.0"/>
    <parent link="ARShoulder2_Link"/>
    <child link="ARShoulder3_Link"/>
    <limit effort="53.0" lower="-3.0543" upper="3.0543" velocity="1.8326"/>
  </joint>
  <link name="ARShoulder3_Link">
    <inertial>
      <origin xyz="7.9284e-06 3.7845e-05 0.16439" rpy="0.0 0.0 0.0"/>
      <mass value="1.3999"/>
      <inertia ixx="0.013898" ixy="1.2682e-06" ixz="8.7833e-07" iyy="0.013686" iyz="2.7121e-06" izz="0.0019878"/>
    </inertial>
    <visual name="ARShoulder3_Link_visual">
      <origin xyz="0.0 0.0 0.0" rpy="0.0 0.0 0.0"/>
      <geometry>
        <mesh filename="../meshes/ALShoulder3_Link.STL"/>
      </geometry>
      <material name="">
        <color rgba="0.69804 0.69804 0.69804 1.0"/>
      </material>
    </visual>
    <collision name="ARShoulder3_Link_collision">
      <origin xyz="0.0 0.0 0.0" rpy="0.0 0.0 0.0"/>
      <geometry>
        <mesh filename="../meshes/ALShoulder3_Link.STL"/>
      </geometry>
    </collision>
  </link>
  <joint name="ARWristPitch" type="revolute">
    <origin xyz="0.0 0.0 0.0" rpy="-4.9304e-32 -9.5526e-32 0.0"/>
    <axis xyz="0.0 1.0 0.0"/>
    <parent link="ARWristYaw_Link"/>
    <child link="ARWristPitch_Link"/>
    <limit effort="12.5" lower="-3.1416" upper="3.1416" velocity="5.0"/>
  </joint>
  <link name="ARWristPitch_Link">
    <inertial>
      <origin xyz="3.0531e-14 -6.0923e-15 -3.3085e-14" rpy="0.0 0.0 0.0"/>
      <mass value="6.2832e-06"/>
      <inertia ixx="3.6652e-12" ixy="1.757e-26" ixz="2.9539e-41" iyy="3.1416e-12" iyz="-9.766e-28" izz="3.6652e-12"/>
    </inertial>
    <visual name="ARWristPitch_Link_visual">
      <origin xyz="0.0 0.0 0.0" rpy="0.0 0.0 0.0"/>
      <geometry>
        <mesh filename="../meshes/ALWristPitch_Link.STL"/>
      </geometry>
      <material name="">
        <color rgba="0.79216 0.81961 0.93333 1.0"/>
      </material>
    </visual>
    <collision name="ARWristPitch_Link_collision">
      <origin xyz="0.0 0.0 0.0" rpy="0.0 0.0 0.0"/>
      <geometry>
        <mesh filename="../meshes/ALWristPitch_Link.STL"/>
      </geometry>
    </collision>
  </link>
  <joint name="ARWristRoll" type="revolute">
    <origin xyz="0.386 0.0 0.0" rpy="-1.5708 0.0 1.5708"/>
    <axis xyz="0.0 0.0 -1.0"/>
    <parent link="ARElbow_Link"/>
    <child link="ARWristRoll_Link"/>
    <limit effort="53.0" lower="-3.0543" upper="3.0543" velocity="1.8326"/>
  </joint>
  <link name="ARWristRoll_Link">
    <inertial>
      <origin xyz="0.025274 -4.3815e-06 0.19965" rpy="0.0 0.0 0.0"/>
      <mass value="2.3703"/>
      <inertia ixx="0.020206" ixy="1.7582e-07" ixz="0.0025932" iyy="0.020635" iyz="2.8078e-06" izz="0.0051431"/>
    </inertial>
    <visual name="ARWristRoll_Link_visual">
      <origin xyz="0.0 0.0 0.0" rpy="0.0 0.0 0.0"/>
      <geometry>
        <mesh filename="../meshes/ALWristRoll_Link.STL"/>
      </geometry>
      <material name="">
        <color rgba="0.69804 0.69804 0.69804 1.0"/>
      </material>
    </visual>
    <collision name="ARWristRoll_Link_collision">
      <origin xyz="0.0 0.0 0.0" rpy="0.0 0.0 0.0"/>
      <geometry>
        <mesh filename="../meshes/ALWristRoll_Link.STL"/>
      </geometry>
    </collision>
  </link>
  <joint name="ARWristYaw" type="revolute">
    <origin xyz="0.0 0.0 0.0" rpy="-4.9304e-32 -9.5526e-32 0.0"/>
    <axis xyz="1.0 0.0 0.0"/>
    <parent link="ARWristRoll_Link"/>
    <child link="ARWristYaw_Link"/>
    <limit effort="12.5" lower="-1.2566" upper="0.7853" velocity="5.0"/>
  </joint>
  <link name="ARWristYaw_Link">
    <inertial>
      <origin xyz="-3.8303e-15 -5.8703e-15 -1.6653e-16" rpy="0.0 0.0 0.0"/>
      <mass value="0.006976"/>
      <inertia ixx="1.0349e-06" ixy="-7.3387e-21" ixz="1.7878e-22" iyy="4.8433e-07" iyz="-5.1569e-21" izz="1.4399e-06"/>
    </inertial>
    <visual name="ARWristYaw_Link_visual">
      <origin xyz="0.0 0.0 0.0" rpy="0.0 0.0 0.0"/>
      <geometry>
        <mesh filename="../meshes/ALWristYaw_Link.STL"/>
      </geometry>
      <material name="">
        <color rgba="0.79216 0.81961 0.93333 1.0"/>
      </material>
    </visual>
    <collision name="ARWristYaw_Link_collision">
      <origin xyz="0.0 0.0 0.0" rpy="0.0 0.0 0.0"/>
      <geometry>
        <mesh filename="../meshes/ALWristYaw_Link.STL"/>
      </geometry>
    </collision>
  </link>
  <joint name="ARWrist_Act1" type="prismatic">
    <origin xyz="0.0 0.0 0.26731" rpy="0.071148 0.014965 -1.3713e-14"/>
    <axis xyz="-0.014964 0.07108 0.99736"/>
    <parent link="ARWrist_B12_Link"/>
    <child link="ARWrist_Act1_Link"/>
    <limit effort="262.0" lower="-0.02046" upper="0.04454" velocity="0.2"/>
  </joint>
  <link name="ARWrist_Act1_Link">
    <inertial>
      <origin xyz="0.0006222 -0.0029555 -0.04147" rpy="0.0 0.0 0.0"/>
      <mass value="0.02"/>
      <inertia ixx="1.3508e-05" ixy="1.3691e-08" ixz="1.9172e-07" iyy="1.3471e-05" iyz="-9.1248e-07" izz="7.3244e-07"/>
    </inertial>
    <visual name="ARWrist_Act1_Link_visual">
      <origin xyz="0.0 0.0 0.0" rpy="0.0 0.0 0.0"/>
      <geometry>
        <mesh filename="../meshes/ALWrist_Act1_Link.STL"/>
      </geometry>
      <material name="">
        <color rgba="0.69804 0.69804 0.69804 1.0"/>
      </material>
    </visual>
    <collision name="ARWrist_Act1_Link_collision">
      <origin xyz="0.0 0.0 0.0" rpy="0.0 0.0 0.0"/>
      <geometry>
        <mesh filename="../meshes/ALWrist_Act1_Link.STL"/>
      </geometry>
    </collision>
  </link>
  <joint name="ARWrist_Act2" type="prismatic">
    <origin xyz="0.00070119 0.0 0.26731" rpy="-8.743e-16 0.0026232 -2.7756e-17"/>
    <axis xyz="0.0 0.0 1.0"/>
    <parent link="ARWrist_B22_Link"/>
    <child link="ARWrist_Act2_Link"/>
    <limit effort="262.0" lower="-0.02046" upper="0.04454" velocity="0.2"/>
  </joint>
  <link name="ARWrist_Act2_Link">
    <inertial>
      <origin xyz="-1.7311e-09 1.2133e-09 -0.04158" rpy="0.0 0.0 0.0"/>
      <mass value="0.02"/>
      <inertia ixx="1.3511e-05" ixy="-2.7182e-11" ixz="1.0876e-12" iyy="1.3536e-05" iyz="-8.3798e-13" izz="6.6453e-07"/>
    </inertial>
    <visual name="ARWrist_Act2_Link_visual">
      <origin xyz="0.0 0.0 0.0" rpy="0.0 0.0 0.0"/>
      <geometry>
        <mesh filename="../meshes/ALWrist_Act2_Link.STL"/>
      </geometry>
      <material name="">
        <color rgba="0.69804 0.69804 0.69804 1.0"/>
      </material>
    </visual>
    <collision name="ARWrist_Act2_Link_collision">
      <origin xyz="0.0 0.0 0.0" rpy="0.0 0.0 0.0"/>
      <geometry>
        <mesh filename="../meshes/ALWrist_Act2_Link.STL"/>
      </geometry>
    </collision>
  </link>
  <joint name="ARWrist_B11" type="revolute">
    <origin xyz="-0.032 -0.016 0.2616" rpy="3.0704 -3.307e-15 -2.7145e-14"/>
    <axis xyz="1.0 0.0 0.0"/>
    <parent link="ARWristRoll_Link"/>
    <child link="ARWrist_B11_Link"/>
    <limit effort="0.0" lower="0" upper="0" velocity="0.0"/>
  </joint>
  <link name="ARWrist_B11_Link">
    <inertial>
      <origin xyz="-2.8647e-11 -2.8644e-11 7.6796e-15" rpy="0.0 0.0 0.0"/>
      <mass value="0.0016071"/>
      <inertia ixx="1.3441e-08" ixy="-2.7504e-23" ixz="-3.6865e-16" iyy="1.3441e-08" iyz="3.6865e-16" izz="1.2362e-08"/>
    </inertial>
    <visual name="ARWrist_B11_Link_visual">
      <origin xyz="0.0 0.0 0.0" rpy="0.0 0.0 0.0"/>
      <geometry>
        <mesh filename="../meshes/ALWrist_B11_Link.STL"/>
      </geometry>
      <material name="">
        <color rgba="0.64706 0.61961 0.58824 1.0"/>
      </material>
    </visual>
    <collision name="ARWrist_B11_Link_collision">
      <origin xyz="0.0 0.0 0.0" rpy="0.0 0.0 0.0"/>
      <geometry>
        <mesh filename="../meshes/ALWrist_B11_Link.STL"/>
      </geometry>
    </collision>
  </link>
  <joint name="ARWrist_B12" type="revolute">
    <origin xyz="0.0 0.0 0.0" rpy="4.3165e-15 -0.014965 0.0"/>
    <axis xyz="0.0 1.0 0.0"/>
    <parent link="ARWrist_B11_Link"/>
    <child link="ARWrist_B12_Link"/>
    <limit effort="0.0" lower="0" upper="0" velocity="0.0"/>
  </joint>
  <link name="ARWrist_B12_Link">
    <inertial>
      <origin xyz="-5.9648e-05 -4.9733e-09 0.09465" rpy="0.0 0.0 0.0"/>
      <mass value="0.17"/>
      <inertia ixx="0.00060078" ixy="1.3729e-11" ixz="-8.26e-07" iyy="0.00060065" iyz="5.1897e-11" izz="2.1279e-05"/>
    </inertial>
    <visual name="ARWrist_B12_Link_visual">
      <origin xyz="0.0 0.0 0.0" rpy="0.0 0.0 0.0"/>
      <geometry>
        <mesh filename="../meshes/ALWrist_B12_Link.STL"/>
      </geometry>
      <material name="">
        <color rgba="0.69804 0.69804 0.69804 1.0"/>
      </material>
    </visual>
    <collision name="ARWrist_B12_Link_collision">
      <origin xyz="0.0 0.0 0.0" rpy="0.0 0.0 0.0"/>
      <geometry>
        <mesh filename="../meshes/ALWrist_B12_Link.STL"/>
      </geometry>
    </collision>
  </link>
  <joint name="ARWrist_B21" type="revolute">
    <origin xyz="-0.032 0.016 0.2616" rpy="-3.0704 0.014927 0.0010639"/>
    <axis xyz="0.99989 0.0 -0.014964"/>
    <parent link="ARWristRoll_Link"/>
    <child link="ARWrist_B21_Link"/>
    <limit effort="0.0" lower="0" upper="0" velocity="0.0"/>
  </joint>
  <link name="ARWrist_B21_Link">
    <inertial>
      <origin xyz="-2.8641e-11 2.8645e-11 4.2873e-13" rpy="0.0 0.0 0.0"/>
      <mass value="0.0016071"/>
      <inertia ixx="1.3441e-08" ixy="5.5165e-18" ixz="-1.6142e-11" iyy="1.3441e-08" iyz="3.6861e-16" izz="1.2362e-08"/>
    </inertial>
    <visual name="ARWrist_B21_Link_visual">
      <origin xyz="0.0 0.0 0.0" rpy="0.0 0.0 0.0"/>
      <geometry>
        <mesh filename="../meshes/ALWrist_B21_Link.STL"/>
      </geometry>
      <material name="">
        <color rgba="0.64706 0.61961 0.58824 1.0"/>
      </material>
    </visual>
    <collision name="ARWrist_B21_Link_collision">
      <origin xyz="0.0 0.0 0.0" rpy="0.0 0.0 0.0"/>
      <geometry>
        <mesh filename="../meshes/ALWrist_B21_Link.STL"/>
      </geometry>
    </collision>
  </link>
  <joint name="ARWrist_B22" type="revolute">
    <origin xyz="0.0 0.0 0.0" rpy="8.8818e-16 -0.0026232 -2.7756e-17"/>
    <axis xyz="0.0 1.0 0.0"/>
    <parent link="ARWrist_B21_Link"/>
    <child link="ARWrist_B22_Link"/>
    <limit effort="0.0" lower="0" upper="0" velocity="0.0"/>
  </joint>
  <link name="ARWrist_B22_Link">
    <inertial>
      <origin xyz="0.00030793 4.2857e-09 0.094649" rpy="0.0 0.0 0.0"/>
      <mass value="0.17"/>
      <inertia ixx="0.00060078" ixy="1.3111e-11" ixz="-6.9413e-07" iyy="0.00060065" iyz="-3.467e-11" izz="2.1279e-05"/>
    </inertial>
    <visual name="ARWrist_B22_Link_visual">
      <origin xyz="0.0 0.0 0.0" rpy="0.0 0.0 0.0"/>
      <geometry>
        <mesh filename="../meshes/ALWrist_B22_Link.STL"/>
      </geometry>
      <material name="">
        <color rgba="0.69804 0.69804 0.69804 1.0"/>
      </material>
    </visual>
    <collision name="ARWrist_B22_Link_collision">
      <origin xyz="0.0 0.0 0.0" rpy="0.0 0.0 0.0"/>
      <geometry>
        <mesh filename="../meshes/ALWrist_B22_Link.STL"/>
      </geometry>
    </collision>
  </link>
  <link name="ARWrist_FT">
    <inertial>
      <origin xyz="0.0013964 -8.0618e-05 0.041768" rpy="0.0 0.0 0.0"/>
      <mass value="0.46746"/>
      <inertia ixx="0.0011813" ixy="9.7393e-07" ixz="-6.577e-05" iyy="0.00099999" iyz="3.5173e-06" izz="0.00055976"/>
    </inertial>
    <visual name="ARWrist_FT_visual">
      <origin xyz="0.0 0.0 0.0" rpy="0.0 0.0 0.0"/>
      <geometry>
        <mesh filename="../meshes/ALWrist_FT.STL"/>
      </geometry>
      <material name="">
        <color rgba="0.69804 0.69804 0.69804 1.0"/>
      </material>
    </visual>
    <collision name="ARWrist_FT_collision">
      <origin xyz="0.0 0.0 0.0" rpy="0.0 0.0 0.0"/>
      <geometry>
        <mesh filename="../meshes/ALWrist_FT.STL"/>
      </geometry>
    </collision>
  </link>
  <joint name="ARWrist_FT" type="fixed">
    <origin xyz="0.0 0.0 -0.02995" rpy="-3.1416 -2.9034e-15 1.6653e-16"/>
    <axis xyz="0.0 0.0 0.0"/>
    <parent link="ARWristPitch_Link"/>
    <child link="ARWrist_FT"/>
  </joint>
  <joint name="BodyBase" type="fixed">
    <origin xyz="0.048 0.0 0.217" rpy="0.0 3.14159265359 -1.57079632679"/>
    <axis xyz="0.0 0.0 1.0"/>
    <parent link="RH5_Root_Link"/>
    <child link="BodyBase_Link"/>
  </joint>
  <link name="BodyBase_Link">
    <inertial>
      <origin xyz="0.0 0.0 0.0" rpy="0.0 0.0 0.0"/>
      <mass value="0.0"/>
      <inertia ixx="0.0" ixy="0.0" ixz="0.0" iyy="0.0" iyz="0.0" izz="0.0"/>
    </inertial>
  </link>
  <joint name="BodyPitch" type="revolute">
    <origin xyz="0.0 0.0 0.0" rpy="3.14159 0.0 1.5708"/>
    <axis xyz="0.0 1.0 0.0"/>
    <parent link="BodyBase_Link"/>
    <child link="BodyPitch_Link"/>
    <limit effort="140.0" lower="-0.367" upper="0.489" velocity="2.321"/>
  </joint>
  <link name="BodyPitch_Link">
    <inertial>
      <origin xyz="-1.3464e-09 2.3289e-09 2.2552e-09" rpy="0.0 0.0 0.0"/>
      <mass value="0.085152"/>
      <inertia ixx="2.6756e-05" ixy="-2.1852e-12" ixz="-2.2958e-12" iyy="2.6756e-05" iyz="-2.6082e-13" izz="5.0206e-05"/>
    </inertial>
    <visual name="BodyPitch_Link_visual">
      <origin xyz="0.0 0.0 0.0" rpy="0.0 0.0 0.0"/>
      <geometry>
        <mesh filename="../meshes/BodyPitch_Link.STL"/>
      </geometry>
      <material name="">
        <color rgba="0.89804 0.91765 0.92941 1.0"/>
      </material>
    </visual>
    <collision name="BodyPitch_Link_collision">
      <origin xyz="0.0 0.0 0.0" rpy="0.0 0.0 0.0"/>
      <geometry>
        <mesh filename="../meshes/BodyPitch_Link.STL"/>
      </geometry>
    </collision>
  </link>
  <joint name="BodyRoll" type="revolute">
    <origin xyz="0.0 0.0 0.0" rpy="9.4311e-35 0.0 0.0"/>
    <axis xyz="1.0 0.0 0.0"/>
    <parent link="BodyPitch_Link"/>
    <child link="BodyRoll_Link"/>
    <limit effort="140.0" lower="-0.402" upper="0.402" velocity="2.321"/>
  </joint>
  <link name="BodyRoll_Link">
    <inertial>
      <origin xyz="-0.018531 1.3194e-09 0.025426" rpy="0.0 0.0 0.0"/>
      <mass value="0.31532"/>
      <inertia ixx="0.00053663" ixy="-3.6063e-10" ixz="-2.5818e-05" iyy="0.00050964" iyz="-3.7361e-11" izz="0.00097717"/>
    </inertial>
    <visual name="BodyRoll_Link_visual">
      <origin xyz="0.0 0.0 0.0" rpy="0.0 0.0 0.0"/>
      <geometry>
        <mesh filename="../meshes/BodyRoll_Link.STL"/>
      </geometry>
      <material name="">
        <color rgba="0.69804 0.69804 0.69804 1.0"/>
      </material>
    </visual>
    <collision name="BodyRoll_Link_collision">
      <origin xyz="0.0 0.0 0.0" rpy="0.0 0.0 0.0"/>
      <geometry>
        <mesh filename="../meshes/BodyRoll_Link.STL"/>
      </geometry>
    </collision>
  </link>
  <joint name="BodyYaw" type="revolute">
    <origin xyz="0.0 0.0 0.0" rpy="9.4311e-35 0.0 0.0"/>
    <axis xyz="0.0 0.0 1.0"/>
    <parent link="BodyRoll_Link"/>
    <child link="BodyYaw_Link"/>
    <limit effort="23.0" lower="-0.523567" upper="0.523567" velocity="1.8326"/>
  </joint>
  <joint name="BodyYaw_Act1" type="fixed">
    <origin xyz="-0.145 0.0 0.04741" rpy="-1.0007e-16 0.0 -3.4915e-15"/>
    <parent link="BodyYaw_Link"/>
    <child link="BodyYaw_Act1_Link"/>
  </joint>
  <link name="BodyYaw_Act1_Link">
    <inertial>
      <origin xyz="1.763e-11 -4.5241e-12 0.0012603" rpy="0.0 0.0 0.0"/>
      <mass value="0.02866"/>
      <inertia ixx="1.1831e-05" ixy="1.0449e-07" ixz="-8.9828e-16" iyy="2.0005e-06" iyz="2.305e-16" izz="1.3286e-05"/>
    </inertial>
    <visual name="BodyYaw_Act1_Link_visual">
      <origin xyz="0.0 0.0 0.0" rpy="0.0 0.0 0.0"/>
      <geometry>
        <mesh filename="../meshes/BodyYaw_Act1_Link.STL"/>
      </geometry>
      <material name="">
        <color rgba="0.69804 0.69804 0.69804 1.0"/>
      </material>
    </visual>
    <collision name="BodyYaw_Act1_Link_collision">
      <origin xyz="0.0 0.0 0.0" rpy="0.0 0.0 0.0"/>
      <geometry>
        <mesh filename="../meshes/BodyYaw_Act1_Link.STL"/>
      </geometry>
    </collision>
  </link>
  <joint name="BodyYaw_B11" type="fixed">
    <origin xyz="-0.00031836 0.029998 0.0" rpy="1.5708 0.0 0.0"/>
    <parent link="BodyYaw_Act1_Link"/>
    <child link="BodyYaw_B11_Link"/>
  </joint>
  <link name="BodyYaw_B11_Link">
    <inertial>
      <origin xyz="0.072545 -0.00291 0.073125" rpy="0.0 0.0 0.0"/>
      <mass value="0.04223"/>
      <inertia ixx="2.3177e-06" ixy="2.9846e-20" ixz="-1.2878e-05" iyy="9.5892e-05" iyz="3.8825e-21" izz="9.3687e-05"/>
    </inertial>
    <visual name="BodyYaw_B11_Link_visual">
      <origin xyz="0.0 0.0 0.0" rpy="0.0 0.0 0.0"/>
      <geometry>
        <mesh filename="../meshes/BodyYaw_B11_Link.STL"/>
      </geometry>
      <material name="">
        <color rgba="0.69804 0.69804 0.69804 1.0"/>
      </material>
    </visual>
    <collision name="BodyYaw_B11_Link_collision">
      <origin xyz="0.0 0.0 0.0" rpy="0.0 0.0 0.0"/>
      <geometry>
        <mesh filename="../meshes/BodyYaw_B11_Link.STL"/>
      </geometry>
    </collision>
  </link>
  <joint name="BodyYaw_B21" type="fixed">
    <origin xyz="0.00031836 -0.029998 0.0" rpy="1.5708 0.0 0.0"/>
    <parent link="BodyYaw_Act1_Link"/>
    <child link="BodyYaw_B21_Link"/>
  </joint>
  <link name="BodyYaw_B21_Link">
    <inertial>
      <origin xyz="0.071966 -0.00291 -0.072539" rpy="0.0 0.0 0.0"/>
      <mass value="0.04223"/>
      <inertia ixx="2.531e-06" ixy="3.9704e-20" ixz="1.3612e-05" iyy="9.5892e-05" iyz="-5.5529e-21" izz="9.3474e-05"/>
    </inertial>
    <visual name="BodyYaw_B21_Link_visual">
      <origin xyz="0.0 0.0 0.0" rpy="0.0 0.0 0.0"/>
      <geometry>
        <mesh filename="../meshes/BodyYaw_B21_Link.STL"/>
      </geometry>
      <material name="">
        <color rgba="0.69804 0.69804 0.69804 1.0"/>
      </material>
    </visual>
    <collision name="BodyYaw_B21_Link_collision">
      <origin xyz="0.0 0.0 0.0" rpy="0.0 0.0 0.0"/>
      <geometry>
        <mesh filename="../meshes/BodyYaw_B21_Link.STL"/>
      </geometry>
    </collision>
  </link>
  <link name="BodyYaw_Link">
    <inertial>
      <origin xyz="-0.015999 0.00018406 0.27483" rpy="0.0 0.0 0.0"/>
      <mass value="27.291"/>
      <inertia ixx="1.1652" ixy="-5.1088e-05" ixz="-0.027697" iyy="0.98908" iyz="-0.00057966" izz="0.60666"/>
    </inertial>
    <visual name="BodyYaw_Link_visual">
      <origin xyz="0.0 0.0 0.0" rpy="0.0 0.0 0.0"/>
      <geometry>
        <mesh filename="../meshes/BodyYaw_Link.STL"/>
      </geometry>
      <material name="">
        <color rgba="1.0 1.0 1.0 1.0"/>
      </material>
    </visual>
    <collision name="BodyYaw_Link_collision">
      <origin xyz="0.0 0.0 0.0" rpy="0.0 0.0 0.0"/>
      <geometry>
        <mesh filename="../meshes/BodyYaw_Link_Collision.STL"/>
      </geometry>
    </collision>
  </link>
  <joint name="Body_Act1" type="prismatic">
    <origin xyz="0.0 0.0 0.24008" rpy="5.9043e-18 0.0 -1.0277e-19"/>
    <axis xyz="0.0 0.0 1.0"/>
    <parent link="Body_B12_Link"/>
    <child link="Body_Act1_Link"/>
    <limit effort="874.0" lower="-0.01" upper="0.01" velocity="0.291"/>
  </joint>
  <link name="Body_Act1_Link">
    <inertial>
      <origin xyz="2.411e-13 -1.992e-13 -0.074113" rpy="0.0 0.0 0.0"/>
      <mass value="0.16486"/>
      <inertia ixx="0.00041758" ixy="-7.8776e-09" ixz="8.4801e-16" iyy="0.00041757" iyz="-7.0091e-16" izz="3.5325e-06"/>
    </inertial>
    <visual name="Body_Act1_Link_visual">
      <origin xyz="0.0 0.0 0.0" rpy="0.0 0.0 0.0"/>
      <geometry>
        <mesh filename="../meshes/Body_Act1_Link.STL"/>
      </geometry>
      <material name="">
        <color rgba="0.69804 0.69804 0.69804 1.0"/>
      </material>
    </visual>
    <collision name="Body_Act1_Link_collision">
      <origin xyz="0.0 0.0 0.0" rpy="0.0 0.0 0.0"/>
      <geometry>
        <mesh filename="../meshes/Body_Act1_Link.STL"/>
      </geometry>
    </collision>
  </link>
  <joint name="Body_Act2" type="prismatic">
    <origin xyz="0.0 0.0 0.24008" rpy="-3.8527e-17 0.0 1.2552e-18"/>
    <axis xyz="0.0 0.0 1.0"/>
    <parent link="Body_B22_Link"/>
    <child link="Body_Act2_Link"/>
    <limit effort="874.0" lower="-0.01" upper="0.01" velocity="0.291"/>
  </joint>
  <link name="Body_Act2_Link">
    <inertial>
      <origin xyz="2.4164e-13 1.9856e-13 -0.074113" rpy="0.0 0.0 0.0"/>
      <mass value="0.16486"/>
      <inertia ixx="0.00041758" ixy="7.8776e-09" ixz="8.4854e-16" iyy="0.00041757" iyz="7.0039e-16" izz="3.5325e-06"/>
    </inertial>
    <visual name="Body_Act2_Link_visual">
      <origin xyz="0.0 0.0 0.0" rpy="0.0 0.0 0.0"/>
      <geometry>
        <mesh filename="../meshes/Body_Act2_Link.STL"/>
      </geometry>
      <material name="">
        <color rgba="0.69804 0.69804 0.69804 1.0"/>
      </material>
    </visual>
    <collision name="Body_Act2_Link_collision">
      <origin xyz="0.0 0.0 0.0" rpy="0.0 0.0 0.0"/>
      <geometry>
        <mesh filename="../meshes/Body_Act2_Link.STL"/>
      </geometry>
    </collision>
  </link>
  <joint name="Body_B11" type="revolute">
    <origin xyz="-0.02 -0.08 0.21" rpy="-2.90242 0.0 1.57079632679"/>
    <axis xyz="1.0 0.0 0.0"/>
    <parent link="BodyBase_Link"/>
    <child link="Body_B11_Link"/>
    <limit effort="0.0" lower="0" upper="0" velocity="0.0"/>
  </joint>
  <link name="Body_B11_Link">
    <inertial>
      <origin xyz="0.024193 0.0 -1.3878e-17" rpy="0.0 0.0 0.0"/>
      <mass value="0.041"/>
      <inertia ixx="1.7814e-06" ixy="5.5829e-22" ixz="1.8238e-21" iyy="1.2712e-05" iyz="-6.3527e-22" izz="1.3807e-05"/>
    </inertial>
    <visual name="Body_B11_Link_visual">
      <origin xyz="0.0 0.0 0.0" rpy="0.0 0.0 0.0"/>
      <geometry>
        <mesh filename="../meshes/Body_B11_Link.STL"/>
      </geometry>
      <material name="">
        <color rgba="0.69804 0.69804 0.69804 1.0"/>
      </material>
    </visual>
    <collision name="Body_B11_Link_collision">
      <origin xyz="0.0 0.0 0.0" rpy="0.0 0.0 0.0"/>
      <geometry>
        <mesh filename="../meshes/Body_B11_Link.STL"/>
      </geometry>
    </collision>
  </link>
  <joint name="Body_B12" type="revolute">
    <origin xyz="0.0 0.0 0.0" rpy="-1.3337e-15 -0.04601 -2.9484e-18"/>
    <axis xyz="0.0 1.0 0.0"/>
    <parent link="Body_B11_Link"/>
    <child link="Body_B12_Link"/>
    <limit effort="0.0" lower="0" upper="0" velocity="0.0"/>
  </joint>
  <link name="Body_B12_Link">
    <inertial>
      <origin xyz="-2.3739e-06 1.801e-05 0.11892" rpy="0.0 0.0 0.0"/>
      <mass value="0.525"/>
      <inertia ixx="0.00091851" ixy="-2.4755e-08" ixz="5.5277e-07" iyy="0.00091807" iyz="1.2075e-06" izz="0.00039619"/>
    </inertial>
    <visual name="Body_B12_Link_visual">
      <origin xyz="0.0 0.0 0.0" rpy="0.0 0.0 0.0"/>
      <geometry>
        <mesh filename="../meshes/Body_B12_Link.STL"/>
      </geometry>
      <material name="">
        <color rgba="0.69804 0.69804 0.69804 1.0"/>
      </material>
    </visual>
    <collision name="Body_B12_Link_collision">
      <origin xyz="0.0 0.0 0.0" rpy="0.0 0.0 0.0"/>
      <geometry>
        <mesh filename="../meshes/Body_B12_Link.STL"/>
      </geometry>
    </collision>
  </link>
  <joint name="Body_B21" type="revolute">
    <origin xyz="0.02 -0.08 0.21" rpy="2.90242 0.0 1.57079632679"/>
    <axis xyz="1.0 0.0 0.0"/>
    <parent link="BodyBase_Link"/>
    <child link="Body_B21_Link"/>
    <limit effort="0.0" lower="0" upper="0" velocity="0.0"/>
  </joint>
  <link name="Body_B21_Link">
    <inertial>
      <origin xyz="0.024193 0.0 0.0" rpy="0.0 0.0 0.0"/>
      <mass value="0.041"/>
      <inertia ixx="1.7814e-06" ixy="-6.8803e-22" ixz="1.0426e-22" iyy="1.2712e-05" iyz="-1.4823e-21" izz="1.3807e-05"/>
    </inertial>
    <visual name="Body_B21_Link_visual">
      <origin xyz="0.0 0.0 0.0" rpy="0.0 0.0 0.0"/>
      <geometry>
        <mesh filename="../meshes/Body_B21_Link.STL"/>
      </geometry>
      <material name="">
        <color rgba="0.69804 0.69804 0.69804 1.0"/>
      </material>
    </visual>
    <collision name="Body_B21_Link_collision">
      <origin xyz="0.0 0.0 0.0" rpy="0.0 0.0 0.0"/>
      <geometry>
        <mesh filename="../meshes/Body_B21_Link.STL"/>
      </geometry>
    </collision>
  </link>
  <joint name="Body_B22" type="revolute">
    <origin xyz="0.0 0.0 0.0" rpy="-3.612e-16 -0.04601 -1.0723e-18"/>
    <axis xyz="0.0 1.0 0.0"/>
    <parent link="Body_B21_Link"/>
    <child link="Body_B22_Link"/>
    <limit effort="0.0" lower="0" upper="0" velocity="0.0"/>
  </joint>
  <link name="Body_B22_Link">
    <inertial>
      <origin xyz="-2.375e-06 1.8011e-05 0.11892" rpy="0.0 0.0 0.0"/>
      <mass value="0.525"/>
      <inertia ixx="0.00091851" ixy="-2.4752e-08" ixz="5.5262e-07" iyy="0.00091807" iyz="1.2073e-06" izz="0.00039619"/>
    </inertial>
    <visual name="Body_B22_Link_visual">
      <origin xyz="0.0 0.0 0.0" rpy="0.0 0.0 0.0"/>
      <geometry>
        <mesh filename="../meshes/Body_B22_Link.STL"/>
      </geometry>
      <material name="">
        <color rgba="0.69804 0.69804 0.69804 1.0"/>
      </material>
    </visual>
    <collision name="Body_B22_Link_collision">
      <origin xyz="0.0 0.0 0.0" rpy="0.0 0.0 0.0"/>
      <geometry>
        <mesh filename="../meshes/Body_B22_Link.STL"/>
      </geometry>
    </collision>
  </link>
  <joint name="Camera_Left" type="fixed">
    <origin xyz="0.12605 0.0402 0.089608" rpy="0.0 0.0 0.0"/>
    <axis xyz="0.0 0.0 0.0"/>
    <parent link="HeadYaw_Link"/>
    <child link="Camera_Left_Link"/>
  </joint>
  <link name="Camera_Left_Link"/>
  <joint name="Camera_Right" type="fixed">
    <origin xyz="0.12605 -0.0402 0.089608" rpy="0.0 0.0 0.0"/>
    <axis xyz="0.0 0.0 0.0"/>
    <parent link="HeadYaw_Link"/>
    <child link="Camera_Right_Link"/>
  </joint>
  <link name="Camera_Right_Link"/>
  <joint name="Camera_Torso" type="fixed">
    <origin xyz="0.182 0.0 0.383" rpy="0.0 0.0 0.0"/>
    <parent link="BodyYaw_Link"/>
    <child link="Camera_Torso_Link"/>
  </joint>
  <link name="Camera_Torso_Link"/>
  <joint name="FLC_FrontLeft" type="fixed">
    <origin xyz="0.13 -0.04 0.0274" rpy="3.1416 0.0 0.0"/>
    <axis xyz="0.0 0.0 0.0"/>
    <parent link="LLAnkle_FT"/>
    <child link="FLC_FrontLeft_Link"/>
  </joint>
  <link name="FLC_FrontLeft_Link">
    <collision name="FLC_FrontLeft_Collision">
      <origin xyz="0.0 0.0 0.0" rpy="0.0 0.0 0.0"/>
      <geometry>
        <sphere radius="0.017"/>
      </geometry>
    </collision>
  </link>
  <joint name="FLC_FrontRight" type="fixed">
    <origin xyz="0.13 0.04 0.0274" rpy="3.1416 0.0 0.0"/>
    <axis xyz="0.0 0.0 0.0"/>
    <parent link="LLAnkle_FT"/>
    <child link="FLC_FrontRight_Link"/>
  </joint>
  <link name="FLC_FrontRight_Link">
    <collision name="FLC_FrontRight_Collision">
      <origin xyz="0.0 0.0 0.0" rpy="0.0 0.0 0.0"/>
      <geometry>
        <sphere radius="0.017"/>
      </geometry>
    </collision>
  </link>
  <joint name="FLC_RearLeft" type="fixed">
    <origin xyz="-0.07 -0.04 0.0274" rpy="3.1416 0.0 0.0"/>
    <axis xyz="0.0 0.0 0.0"/>
    <parent link="LLAnkle_FT"/>
    <child link="FLC_RearLeft_Link"/>
  </joint>
  <link name="FLC_RearLeft_Link">
    <collision name="FLC_RearLeft_Collision">
      <origin xyz="0.0 0.0 0.0" rpy="0.0 0.0 0.0"/>
      <geometry>
        <sphere radius="0.017"/>
      </geometry>
    </collision>
  </link>
  <joint name="FLC_RearRight" type="fixed">
    <origin xyz="-0.07 0.04 0.0274" rpy="3.1416 0.0 0.0"/>
    <axis xyz="0.0 0.0 0.0"/>
    <parent link="LLAnkle_FT"/>
    <child link="FLC_RearRight_Link"/>
  </joint>
  <link name="FLC_RearRight_Link">
    <collision name="FLC_RearRight_Collision">
      <origin xyz="0.0 0.0 0.0" rpy="0.0 0.0 0.0"/>
      <geometry>
        <sphere radius="0.017"/>
      </geometry>
    </collision>
  </link>
  <link name="FL_SupportCenter"/>
  <joint name="FL_SupportCenter" type="fixed">
    <origin xyz="0.03 0.0 0.0444" rpy="3.1416 0.0 0.0"/>
    <axis xyz="0.0 0.0 0.0"/>
    <parent link="LLAnkle_FT"/>
    <child link="FL_SupportCenter"/>
  </joint>
  <joint name="FRC_FrontLeft" type="fixed">
    <origin xyz="0.13 -0.04 0.0274" rpy="3.1416 0.0 0.0"/>
    <axis xyz="0.0 0.0 0.0"/>
    <parent link="LRAnkle_FT"/>
    <child link="FRC_FrontLeft_Link"/>
  </joint>
  <link name="FRC_FrontLeft_Link">
    <collision name="FRC_FrontLeft_Collision">
      <origin xyz="0.0 0.0 0.0" rpy="0.0 0.0 0.0"/>
      <geometry>
        <sphere radius="0.017"/>
      </geometry>
    </collision>
  </link>
  <joint name="FRC_FrontRight" type="fixed">
    <origin xyz="0.13 0.04 0.0274" rpy="3.1416 0.0 0.0"/>
    <axis xyz="0.0 0.0 0.0"/>
    <parent link="LRAnkle_FT"/>
    <child link="FRC_FrontRight_Link"/>
  </joint>
  <link name="FRC_FrontRight_Link">
    <collision name="FRC_FrontRight_Collision">
      <origin xyz="0.0 0.0 0.0" rpy="0.0 0.0 0.0"/>
      <geometry>
        <sphere radius="0.017"/>
      </geometry>
    </collision>
  </link>
  <joint name="FRC_RearLeft" type="fixed">
    <origin xyz="-0.07 -0.04 0.0274" rpy="3.1416 0.0 0.0"/>
    <axis xyz="0.0 0.0 0.0"/>
    <parent link="LRAnkle_FT"/>
    <child link="FRC_RearLeft_Link"/>
  </joint>
  <link name="FRC_RearLeft_Link">
    <collision name="FRC_RearLeft_Collision">
      <origin xyz="0.0 0.0 0.0" rpy="0.0 0.0 0.0"/>
      <geometry>
        <sphere radius="0.017"/>
      </geometry>
    </collision>
  </link>
  <joint name="FRC_RearRight" type="fixed">
    <origin xyz="-0.07 0.04 0.0274" rpy="3.1416 0.0 0.0"/>
    <axis xyz="0.0 0.0 0.0"/>
    <parent link="LRAnkle_FT"/>
    <child link="FRC_RearRight_Link"/>
  </joint>
  <link name="FRC_RearRight_Link">
    <collision name="FRC_RearRight_Collision">
      <origin xyz="0.0 0.0 0.0" rpy="0.0 0.0 0.0"/>
      <geometry>
        <sphere radius="0.017"/>
      </geometry>
    </collision>
  </link>
  <link name="FR_SupportCenter"/>
  <joint name="FR_SupportCenter" type="fixed">
    <origin xyz="0.03 0.0 0.0444" rpy="3.1416 0.0 0.0"/>
    <axis xyz="0.0 0.0 0.0"/>
    <parent link="LRAnkle_FT"/>
    <child link="FR_SupportCenter"/>
  </joint>

  <link name="Head_Act1_Link" />
  <link name="Head_Act2_Link" />
  <link name="Head_Act3_Link" />
  <joint name="Head_Act1" type="revolute">
    <origin xyz="0.00395 0 0.66179" rpy="2.8216E-18 3.4225E-16 1.0489E-14" />
    <parent link="BodyYaw_Link" />
    <child link="Head_Act1_Link" />
    <limit effort="9.8" lower="-0.3490658504" upper="0.2617993878" velocity="8.0553657784"/>
  </joint>
  <joint name="Head_Act2" type="revolute">
    <origin xyz="0.00395 0 0.66179" rpy="2.8216E-18 3.4225E-16 1.0489E-14" />
    <parent link="BodyYaw_Link" />
    <child link="Head_Act2_Link" />
    <limit effort="9.8" lower="-0.3490658504" upper="0.2617993878" velocity="8.0553657784"/>
  </joint>
  <joint name="Head_Act3" type="revolute">
    <origin xyz="0.00395 0 0.66179" rpy="2.8216E-18 3.4225E-16 1.0489E-14" />
    <parent link="BodyYaw_Link" />
    <child link="Head_Act3_Link" />
    <limit effort="9.8" lower="-0.3490658504" upper="0.2617993878" velocity="8.0553657784"/>
  </joint>

  <joint name="HeadPitch" type="revolute">
    <origin xyz="0.00395 0.0 0.66179" rpy="2.8216e-18 3.4225e-16 1.0489e-14"/>
    <axis xyz="0.0 1.0 0.0"/>
    <parent link="BodyYaw_Link"/>
    <child link="HeadPitch_Link"/>
    <limit effort="9.8" lower="-0.3490658504" upper="0.2617993878" velocity="8.0553657784"/>
  </joint>
  <link name="HeadPitch_Link">
    <inertial>
      <origin xyz="0.0029695 3.7352e-08 -4.1086e-09" rpy="0.0 0.0 0.0"/>
      <mass value="0.01353"/>
      <inertia ixx="1.2693e-06" ixy="2.9253e-12" ixz="-1.323e-13" iyy="2.1697e-06" iyz="-1.983e-12" izz="3.0472e-06"/>
    </inertial>
    <visual name="HeadPitch_Link_visual">
      <origin xyz="0.0 0.0 0.0" rpy="0.0 0.0 0.0"/>
      <geometry>
        <mesh filename="../meshes/HeadPitch_Link.STL"/>
      </geometry>
      <material name="">
        <color rgba="0.69804 0.69804 0.69804 1.0"/>
      </material>
    </visual>
  </link>
  <joint name="HeadRoll" type="revolute">
    <origin xyz="0.0 0.0 0.0" rpy="1.6457e-37 0.0 0.0"/>
    <axis xyz="1.0 0.0 0.0"/>
    <parent link="HeadPitch_Link"/>
    <child link="HeadRoll_Link"/>
    <limit effort="9.8" lower="-0.436332313" upper="0.436332313" velocity="8.0553657784"/>
  </joint>
  <link name="HeadRoll_Link">
    <inertial>
      <origin xyz="-0.0040042 1.6567e-08 0.017195" rpy="0.0 0.0 0.0"/>
      <mass value="0.03223"/>
      <inertia ixx="1.2379e-05" ixy="7.9876e-12" ixz="-2.2191e-06" iyy="2.1298e-05" iyz="5.8926e-11" izz="1.355e-05"/>
    </inertial>
    <visual name="HeadRoll_Link_visual">
      <origin xyz="0.0 0.0 0.0" rpy="0.0 0.0 0.0"/>
      <geometry>
        <mesh filename="../meshes/HeadRoll_Link.STL"/>
      </geometry>
      <material name="">
        <color rgba="0.69804 0.69804 0.69804 1.0"/>
      </material>
    </visual>
  </link>
  <joint name="HeadYaw" type="revolute">
    <origin xyz="0.0 0.0 0.0" rpy="1.6457e-37 0.0 0.0"/>
    <axis xyz="0.0 0.0 1.0"/>
    <parent link="HeadRoll_Link"/>
    <child link="HeadYaw_Link"/>
    <limit effort="4.9" lower="-1.5707963268" upper="1.5707963268" velocity="8.0553657784"/>
  </joint>
  <link name="HeadYaw_Link">
    <inertial>
      <origin xyz="0.029368 -0.00017537 0.06406" rpy="0.0 0.0 0.0"/>
      <mass value="1.7003"/>
      <inertia ixx="0.01193" ixy="-2.7459e-05" ixz="0.0010678" iyy="0.01151" iyz="-4.681e-05" izz="0.012306"/>
    </inertial>
    <visual name="HeadYaw_Link_visual">
      <origin xyz="0.0 0.0 0.0" rpy="0.0 0.0 0.0"/>
      <geometry>
        <mesh filename="../meshes/HeadYaw_Link.STL"/>
      </geometry>
      <material name="">
        <color rgba="0.69804 0.69804 0.69804 1.0"/>
      </material>
    </visual>
    <collision name="HeadYaw_Link_collision">
      <origin xyz="0.0 0.0 0.0" rpy="0.0 0.0 0.0"/>
      <geometry>
        <mesh filename="../meshes/HeadYaw_Link.STL"/>
      </geometry>
    </collision>
  </link>
  <joint name="IMU" type="fixed">
    <origin xyz="0.175 0.0 0.145" rpy="0.0 -1.57079632679 3.14159265359"/>
    <axis xyz="0.0 0.0 0.0"/>
    <parent link="RH5_Root_Link"/>
    <child link="IMU_Link"/>
  </joint>
  <link name="IMU_Link"/>
  <joint name="Initial_root" type="fixed">
    <origin xyz="0.0 0.0 0.02" rpy="0.0 0.0 0.0"/>
    <axis xyz="0.0 0.0 0.0"/>
    <parent link="BodyYaw_Link"/>
    <child link="Initial_root_Link"/>
  </joint>
  <link name="Initial_root_Link"/>
  <joint name="LLAnkleBase" type="fixed">
    <origin xyz="0.42 0.0 0.0015" rpy="1.5708 0.0 -1.5708"/>
    <parent link="LLKnee_Link"/>
    <child link="LLAnkleBase_Link"/>
  </joint>
  <link name="LLAnkleBase_Link">
    <inertial>
      <origin xyz="0.0 0.0 0.0" rpy="0.0 0.0 0.0"/>
      <mass value="0.0"/>
      <inertia ixx="0.0" ixy="0.0" ixz="0.0" iyy="0.0" iyz="0.0" izz="0.0"/>
    </inertial>
  </link>
  <joint name="LLAnklePitch" type="revolute">
    <origin xyz="0.0 0.0 0.0" rpy="0.0 0.0 0.0"/>
    <axis xyz="0.0 1.0 0.0"/>
    <parent link="LLAnkleRoll_Link"/>
    <child link="LLAnklePitch_Link"/>
    <limit effort="200.0" lower="-0.698" upper="0.698" velocity="3.141"/>
  </joint>
  <link name="LLAnklePitch_Link">
    <inertial>
      <origin xyz="2.8493e-18 -1.3878e-16 0.0" rpy="0.0 0.0 0.0"/>
      <mass value="2.8252e-05"/>
      <inertia ixx="4.5912e-11" ixy="1.8118e-28" ixz="-1.4548e-27" iyy="6.6802e-11" iyz="5.3633e-27" izz="3.9725e-11"/>
    </inertial>
    <visual name="LLAnklePitch_Link_visual">
      <origin xyz="0.0 0.0 0.0" rpy="0.0 0.0 0.0"/>
      <geometry>
        <mesh filename="../meshes/AnklePitch_Link.STL"/>
      </geometry>
      <material name="">
        <color rgba="0.79216 0.81961 0.93333 1.0"/>
      </material>
    </visual>
  </link>
  <joint name="LLAnkleRoll" type="revolute">
    <origin xyz="0.0 0.0 0.0" rpy="0.0 0.0 0.0"/>
    <axis xyz="1.0 0.0 0.0"/>
    <parent link="LLAnkleBase_Link"/>
    <child link="LLAnkleRoll_Link"/>
    <limit effort="200.0" lower="-0.524" upper="0.524" velocity="3.141"/>
  </joint>
  <link name="LLAnkleRoll_Link">
    <inertial>
      <origin xyz="-4.1608e-08 7.2923e-08 -5.2997e-09" rpy="0.0 0.0 0.0"/>
      <mass value="0.02493"/>
      <inertia ixx="2.9269e-06" ixy="-7.8377e-12" ixz="-1.0382e-12" iyy="1.1591e-06" iyz="1.5876e-12" izz="3.5758e-06"/>
    </inertial>
    <visual name="LLAnkleRoll_Link_visual">
      <origin xyz="0.0 0.0 0.0" rpy="0.0 0.0 0.0"/>
      <geometry>
        <mesh filename="../meshes/AnkleRoll_Link.STL"/>
      </geometry>
      <material name="">
        <color rgba="0.64706 0.61961 0.58824 1.0"/>
      </material>
    </visual>
    <collision name="LLAnkleRoll_Link_collision">
      <origin xyz="0.0 0.0 0.0" rpy="0.0 0.0 0.0"/>
      <geometry>
        <mesh filename="../meshes/AnkleRoll_Link.STL"/>
      </geometry>
    </collision>
  </link>
  <joint name="LLAnkle_Act1" type="prismatic">
    <origin xyz="0.0 0.0 0.26597" rpy="0.0 0.0 0.0"/>
    <axis xyz="0.0 0.0 1.0"/>
    <parent link="LLAnkle_B12_Link"/>
    <child link="LLAnkle_Act1_Link"/>
    <limit effort="571.0" lower="-0.0449" upper="0.0647" velocity="0.14466"/>
  </joint>
  <link name="LLAnkle_Act1_Link">
    <inertial>
      <origin xyz="0.0 0.0 0.0" rpy="0.0 0.0 0.0"/>
      <mass value="0.07896134655058572"/>
      <inertia ixx="0.0002465399999951976" ixy="2.2218334565684636e-09" ixz="-1.2305787261017842e-09" iyy="0.00024678" iyz="-6.276200589605272e-08" izz="1.0730000048024368e-06"/>
    </inertial>
    <visual name="LLAnkle_Act1_Link_visual">
      <origin xyz="0.0 0.0 0.0" rpy="0.0 3.14159 1.57079632679"/>
      <geometry>
        <mesh filename="../meshes/Ankle_Act1_Link.STL"/>
      </geometry>
      <material name="">
        <color rgba="0.69804 0.69804 0.69804 1.0"/>
      </material>
    </visual>
    <collision name="LLAnkle_Act1_Link_collision">
      <origin xyz="0.0 0.0 0.0" rpy="0.0 3.14159 1.57079632679"/>
      <geometry>
        <mesh filename="../meshes/Ankle_Act1_Link.STL"/>
      </geometry>
    </collision>
  </link>
  <joint name="LLAnkle_Act2" type="prismatic">
    <origin xyz="0.0 0.0 0.26597" rpy="0.0 0.0 0.0"/>
    <axis xyz="0.0 0.0 1.0"/>
    <parent link="LLAnkle_B22_Link"/>
    <child link="LLAnkle_Act2_Link"/>
    <limit effort="571.0" lower="-0.0449" upper="0.0647" velocity="0.14466"/>
  </joint>
  <link name="LLAnkle_Act2_Link">
    <inertial>
      <origin xyz="0.0 0.0 0.0" rpy="0.0 -0.0 0.0"/>
      <mass value="0.07896134655058568"/>
      <inertia ixx="0.00024653999999529885" ixy="-2.1503334660041774e-09" ixz="-1.2114887257947331e-09" iyy="0.00024678" iyz="6.275800570632389e-08" izz="1.0730000047011228e-06"/>
    </inertial>
    <visual name="LLAnkle_Act2_Link_visual">
      <origin xyz="0.0 0.0 0.0" rpy="0.0 3.14159 0.0"/>
      <geometry>
        <mesh filename="../meshes/Ankle_Act2_Link.STL"/>
      </geometry>
      <material name="">
        <color rgba="0.69804 0.69804 0.69804 1.0"/>
      </material>
    </visual>
    <collision name="LLAnkle_Act2_Link_collision">
      <origin xyz="0.0 0.0 0.0" rpy="0.0 3.14159 0.0"/>
      <geometry>
        <mesh filename="../meshes/Ankle_Act2_Link.STL"/>
      </geometry>
    </collision>
  </link>
  <joint name="LLAnkle_B11" type="revolute">
    <origin xyz="-0.0223 0.025 0.29127" rpy="3.091 -0.174503 3.14159"/>
    <axis xyz="1.0 0.0 0.0"/>
    <parent link="LLAnkleBase_Link"/>
    <child link="LLAnkle_B11_Link"/>
    <limit effort="0.0" lower="0" upper="0" velocity="0.0"/>
  </joint>
  <link name="LLAnkle_B11_Link">
    <inertial>
      <origin xyz="-0.0026075 -1.6785e-12 0.0015126" rpy="0.0 0.0 0.0"/>
      <mass value="0.00654"/>
      <inertia ixx="1.5907e-06" ixy="3.9038e-14" ixz="8.7457e-09" iyy="1.8739e-06" iyz="8.1942e-15" izz="3.3241e-06"/>
    </inertial>
    <visual name="LLAnkle_B11_Link_visual">
      <origin xyz="0.0 0.0 0.0" rpy="0.0 0.0 0.0"/>
      <geometry>
        <mesh filename="../meshes/Ankle_B11_Link.STL"/>
      </geometry>
      <material name="">
        <color rgba="0.69804 0.69804 0.69804 1.0"/>
      </material>
    </visual>
    <collision name="LLAnkle_B11_Link_collision">
      <origin xyz="0.0 0.0 0.0" rpy="0.0 0.0 0.0"/>
      <geometry>
        <mesh filename="../meshes/Ankle_B11_Link.STL"/>
      </geometry>
    </collision>
  </link>
  <joint name="LLAnkle_B12" type="revolute">
    <origin xyz="0.0 0.0 0.0" rpy="0.0 -0.0060102 0.0"/>
    <axis xyz="0.0 1.0 0.0"/>
    <parent link="LLAnkle_B11_Link"/>
    <child link="LLAnkle_B12_Link"/>
    <limit effort="0.0" lower="0" upper="0" velocity="0.0"/>
  </joint>
  <link name="LLAnkle_B12_Link">
    <inertial>
      <origin xyz="0.0 0.0 0.0" rpy="0.0 -0.0 0.0"/>
      <mass value="0.626756605161674"/>
      <inertia ixx="0.0024658002179549095" ixy="-7.781387113609205e-08" ixz="4.106487105614771e-05" iyy="0.0024841" iyz="4.2541020648759203e-07" izz="0.0001561197820450909"/>
    </inertial>
    <visual name="LLAnkle_B12_Link_visual">
      <origin xyz="0.0 0.0 0.0" rpy="0.0 3.14159 0.0"/>
      <geometry>
        <mesh filename="../meshes/Ankle_B12_Link.STL"/>
      </geometry>
      <material name="">
        <color rgba="0.69804 0.69804 0.69804 1.0"/>
      </material>
    </visual>
    <collision name="LLAnkle_B12_Link_collision">
      <origin xyz="0.0 0.0 0.0" rpy="0.0 3.14159 0.0"/>
      <geometry>
        <mesh filename="../meshes/Ankle_B12_Link.STL"/>
      </geometry>
    </collision>
  </link>
  <joint name="LLAnkle_B21" type="revolute">
    <origin xyz="-0.0223 -0.025 0.29127" rpy="-3.09098 -0.174503 3.14159"/>
    <axis xyz="1.0 0.0 0.0"/>
    <parent link="LLAnkleBase_Link"/>
    <child link="LLAnkle_B21_Link"/>
    <limit effort="0.0" lower="0" upper="0" velocity="0.0"/>
  </joint>
  <link name="LLAnkle_B21_Link">
    <inertial>
      <origin xyz="-0.0026075 1.5362e-12 0.0015126" rpy="0.0 0.0 0.0"/>
      <mass value="0.00654"/>
      <inertia ixx="1.5907e-06" ixy="3.9046e-14" ixz="8.7457e-09" iyy="1.8739e-06" iyz="-5.5038e-15" izz="3.3241e-06"/>
    </inertial>
    <visual name="LLAnkle_B21_Link_visual">
      <origin xyz="0.0 0.0 0.0" rpy="0.0 0.0 0.0"/>
      <geometry>
        <mesh filename="../meshes/Ankle_B21_Link.STL"/>
      </geometry>
      <material name="">
        <color rgba="0.69804 0.69804 0.69804 1.0"/>
      </material>
    </visual>
    <collision name="LLAnkle_B21_Link_collision">
      <origin xyz="0.0 0.0 0.0" rpy="0.0 0.0 0.0"/>
      <geometry>
        <mesh filename="../meshes/Ankle_B21_Link.STL"/>
      </geometry>
    </collision>
  </link>
  <joint name="LLAnkle_B22" type="revolute">
    <origin xyz="0.0 0.0 0.0" rpy="0.0 -0.0060102 0.0"/>
    <axis xyz="0.0 1.0 0.0"/>
    <parent link="LLAnkle_B21_Link"/>
    <child link="LLAnkle_B22_Link"/>
    <limit effort="0.0" lower="0" upper="0" velocity="0.0"/>
  </joint>
  <link name="LLAnkle_B22_Link">
    <inertial>
      <origin xyz="0.0 0.0 0.0" rpy="0.0 0.0 0.0"/>
      <mass value="0.6267566051616451"/>
      <inertia ixx="0.0024658002179549095" ixy="-7.617188419175961e-08" ixz="4.106487105614771e-05" iyy="0.0024841" iyz="4.204902021304149e-07" izz="0.0001561197820450909"/>
    </inertial>
    <visual name="LLAnkle_B22_Link_visual">
      <origin xyz="0.0 0.0 0.0" rpy="0.0 3.14159 0.0"/>
      <geometry>
        <mesh filename="../meshes/Ankle_B22_Link.STL"/>
      </geometry>
      <material name="">
        <color rgba="0.69804 0.69804 0.69804 1.0"/>
      </material>
    </visual>
    <collision name="LLAnkle_B22_Link_collision">
      <origin xyz="0.0 0.0 0.0" rpy="0.0 3.14159 0.0"/>
      <geometry>
        <mesh filename="../meshes/Ankle_B22_Link.STL"/>
      </geometry>
    </collision>
  </link>
  <joint name="LLAnkle_E11" type="revolute">
    <origin xyz="-0.07 0.04 0.0" rpy="0.05066 0.0 0.0"/>
    <axis xyz="1.0 0.0 0.0"/>
    <parent link="LLAnklePitch_Link"/>
    <child link="LLAnkle_E11_Link"/>
    <limit effort="0.0" lower="0" upper="0" velocity="0.0"/>
  </joint>
  <link name="LLAnkle_E11_Link">
    <inertial>
      <origin xyz="-3.2627e-08 -0.00061479 0.011938" rpy="0.0 0.0 0.0"/>
      <mass value="0.025"/>
      <inertia ixx="5.6966e-06" ixy="2.0874e-13" ixz="-6.1394e-13" iyy="5.4356e-06" iyz="2.0391e-07" izz="1.4865e-06"/>
    </inertial>
    <visual name="LLAnkle_E11_Link_visual">
      <origin xyz="0.0 0.0 0.0" rpy="0.0 0.0 0.0"/>
      <geometry>
        <mesh filename="../meshes/Ankle_E11_Link.STL"/>
      </geometry>
      <material name="">
        <color rgba="0.69804 0.69804 0.69804 1.0"/>
      </material>
    </visual>
    <collision name="LLAnkle_E11_Link_collision">
      <origin xyz="0.0 0.0 0.0" rpy="0.0 0.0 0.0"/>
      <geometry>
        <mesh filename="../meshes/Ankle_E11_Link.STL"/>
      </geometry>
    </collision>
  </link>
  <joint name="LLAnkle_E21" type="revolute">
    <origin xyz="-0.07 -0.04 0.0" rpy="-0.05066 0.0 0.0"/>
    <axis xyz="1.0 0.0 0.0"/>
    <parent link="LLAnklePitch_Link"/>
    <child link="LLAnkle_E21_Link"/>
    <limit effort="0.0" lower="0" upper="0" velocity="0.0"/>
  </joint>
  <link name="LLAnkle_E21_Link">
    <inertial>
      <origin xyz="-3.2627e-08 0.00061479 0.011938" rpy="0.0 0.0 0.0"/>
      <mass value="0.025"/>
      <inertia ixx="5.6966e-06" ixy="-2.0874e-13" ixz="-6.1394e-13" iyy="5.4356e-06" iyz="-2.0391e-07" izz="1.4865e-06"/>
    </inertial>
    <visual name="LLAnkle_E21_Link_visual">
      <origin xyz="0.0 0.0 0.0" rpy="0.0 0.0 0.0"/>
      <geometry>
        <mesh filename="../meshes/Ankle_E21_Link.STL"/>
      </geometry>
      <material name="">
        <color rgba="0.69804 0.69804 0.69804 1.0"/>
      </material>
    </visual>
    <collision name="LLAnkle_E21_Link_collision">
      <origin xyz="0.0 0.0 0.0" rpy="0.0 0.0 0.0"/>
      <geometry>
        <mesh filename="../meshes/Ankle_E21_Link.STL"/>
      </geometry>
    </collision>
  </link>
  <link name="LLAnkle_FT">
    <inertial>
      <origin xyz="0.016102 4.5932e-05 0.0078533" rpy="0.0 0.0 0.0"/>
      <mass value="1.2348"/>
      <inertia ixx="0.0018722" ixy="1.7891e-07" ixz="-0.00077672" iyy="0.0072567" iyz="3.8393e-06" izz="0.007267"/>
    </inertial>
    <visual name="LLAnkle_FT_visual">
      <origin xyz="0.0 0.0 0.0" rpy="0.0 0.0 0.0"/>
      <geometry>
        <mesh filename="../meshes/FL_FT_Link.STL"/>
      </geometry>
      <material name="">
        <color rgba="0.69804 0.69804 0.69804 1.0"/>
      </material>
    </visual>
    <collision name="LLAnkle_FT_collision">
      <origin xyz="0.0 0.0 0.0" rpy="0.0 0.0 0.0"/>
      <geometry>
        <mesh filename="../meshes/FL_FT_Link.STL"/>
      </geometry>
    </collision>
  </link>
  <joint name="LLAnkle_FT" type="fixed">
    <origin xyz="0.0 0.0 -0.058972" rpy="-3.1416 0.0 -1.2151e-16"/>
    <axis xyz="0.0 0.0 0.0"/>
    <parent link="LLAnklePitch_Link"/>
    <child link="LLAnkle_FT"/>
  </joint>
  <joint name="LLHip1" type="revolute">
    <origin xyz="0.0735 0.11044 0.014269" rpy="8.0247e-16 0.2618 -1.5708"/>
    <axis xyz="0.0 0.0 1.0"/>
    <parent link="RH5_Root_Link"/>
    <child link="LLHip1_Link"/>
    <limit effort="135.0" lower="-0.7330" upper="0.7330" velocity="1.658"/>
  </joint>
  <link name="LLHip1_Link">
    <inertial>
      <origin xyz="-4.7812e-08 -0.0016168 0.04962" rpy="0.0 0.0 0.0"/>
      <mass value="0.5"/>
      <inertia ixx="0.0020247" ixy="7.2405e-09" ixz="3.8164e-09" iyy="0.00095765" iyz="-0.00012913" izz="0.0015078"/>
    </inertial>
    <visual name="LLHip1_Link_visual">
      <origin xyz="0.0 0.0 0.0" rpy="0.0 0.0 0.0"/>
      <geometry>
        <mesh filename="../meshes/LLHip1_Link.STL"/>
      </geometry>
      <material name="">
        <color rgba="0.69804 0.69804 0.69804 1.0"/>
      </material>
    </visual>
    <collision name="LLHip1_Link_collision">
      <origin xyz="0.0 0.0 0.0" rpy="0.0 0.0 0.0"/>
      <geometry>
        <mesh filename="../meshes/LLHip1_Link.STL"/>
      </geometry>
    </collision>
  </link>
  <joint name="LLHip2" type="revolute">
    <origin xyz="0.0 0.0 0.0" rpy="9.8608e-32 2.7756e-17 -4.9304e-32"/>
    <axis xyz="0.0 1.0 0.0"/>
    <parent link="LLHip1_Link"/>
    <child link="LLHip2_Link"/>
    <limit effort="135.0" lower="-0.3840" upper="0.8203" velocity="1.658"/>
  </joint>
  <link name="LLHip2_Link">
    <inertial>
      <origin xyz="0.0013954 0.0024309 -0.0053241" rpy="0.0 0.0 0.0"/>
      <mass value="0.969"/>
      <inertia ixx="0.0017014" ixy="7.9487e-05" ixz="4.6091e-05" iyy="0.0011578" iyz="-0.0003011" izz="0.0015428"/>
    </inertial>
    <visual name="LLHip2_Link_visual">
      <origin xyz="0.0 0.0 0.0" rpy="0.0 0.0 0.0"/>
      <geometry>
        <mesh filename="../meshes/LLHip2_Link.STL"/>
      </geometry>
      <material name="">
        <color rgba="0.69804 0.69804 0.69804 1.0"/>
      </material>
    </visual>
  </link>
  <joint name="LLHip3" type="revolute">
    <origin xyz="0.0 0.0 0.0" rpy="9.8608e-32 2.7756e-17 -4.9304e-32"/>
    <axis xyz="-0.96593 0.0 -0.25882"/>
    <parent link="LLHip2_Link"/>
    <child link="LLHip3_Link"/>
    <limit effort="378.0" lower="-1.49563127" upper="0.28858014" velocity="2.247"/>
  </joint>
  <joint name="LLHip3_Act1" type="prismatic">
    <origin xyz="0.2974 0.0 0.0" rpy="3.1416 -5.2385e-31 0.0"/>
    <axis xyz="1.0 0.0 0.0"/>
    <parent link="LLHip3_B11_Link"/>
    <child link="LLHip3_Act1_Link"/>
    <limit effort="3000.0" lower="-0.0255" upper="0.1335" velocity="0.175"/>
  </joint>
  <link name="LLHip3_Act1_Link">
    <inertial>
      <origin xyz="-0.16939 -0.00046849 4.4559e-05" rpy="0.0 0.0 0.0"/>
      <mass value="1.224"/>
      <inertia ixx="0.00077764" ixy="5.3759e-05" ixz="4.1291e-07" iyy="0.0059452" iyz="-2.966e-08" izz="0.0059569"/>
    </inertial>
    <visual name="LLHip3_Act1_Link_visual">
      <origin xyz="0.0 0.0 0.0" rpy="0.0 0.0 0.0"/>
      <geometry>
        <mesh filename="../meshes/LLHip3_Act1_Link.STL"/>
      </geometry>
      <material name="">
        <color rgba="0.69804 0.69804 0.69804 1.0"/>
      </material>
    </visual>
    <collision name="LLHip3_Act1_Link_collision">
      <origin xyz="0.0 0.0 0.0" rpy="0.0 0.0 0.0"/>
      <geometry>
        <mesh filename="../meshes/LLHip3_Act1_Link.STL"/>
      </geometry>
    </collision>
  </link>
  <joint name="LLHip3_B11" type="revolute">
    <origin xyz="0.018117 -0.09 -0.067615" rpy="-2.5686 1.2577 0.59588"/>
    <axis xyz="0.0 0.0 1.0"/>
    <parent link="LLHip2_Link"/>
    <child link="LLHip3_B11_Link"/>
    <limit effort="0.0" lower="0" upper="0" velocity="0.0"/>
  </joint>
  <link name="LLHip3_B11_Link">
    <inertial>
      <origin xyz="0.10645 -2.4289e-13 1.9568e-15" rpy="0.0 0.0 0.0"/>
      <mass value="0.16503"/>
      <inertia ixx="3.4113e-06" ixy="3.8263e-12" ixz="-7.0537e-16" iyy="0.00081967" iyz="-1.7661e-15" izz="0.00081963"/>
    </inertial>
    <visual name="LLHip3_B11_Link_visual">
      <origin xyz="0.0 0.0 0.0" rpy="0.0 0.0 0.0"/>
      <geometry>
        <mesh filename="../meshes/Hip3_B11_Link.STL"/>
      </geometry>
      <material name="">
        <color rgba="0.69804 0.69804 0.69804 1.0"/>
      </material>
    </visual>
    <collision name="LLHip3_B11_Link_collision">
      <origin xyz="0.0 0.0 0.0" rpy="0.0 0.0 0.0"/>
      <geometry>
        <mesh filename="../meshes/Hip3_B11_Link.STL"/>
      </geometry>
    </collision>
  </link>
  <link name="LLHip3_Link">
    <inertial>
      <origin xyz="0.051263 0.0072511 -0.19232" rpy="0.0 0.0 0.0"/>
      <mass value="1.0487"/>
      <inertia ixx="0.020383" ixy="3.4682e-05" ixz="0.0047264" iyy="0.022629" iyz="-0.00014075" izz="0.0042174"/>
    </inertial>
    <visual name="LLHip3_Link_visual">
      <origin xyz="0.0 0.0 0.0" rpy="0.0 0.0 0.0"/>
      <geometry>
        <mesh filename="../meshes/Hip3_Link.STL"/>
      </geometry>
      <material name="">
        <color rgba="0.69804 0.69804 0.69804 1.0"/>
      </material>
    </visual>
    <collision name="LLHip3_Link_collision">
      <origin xyz="0.0 0.0 0.0" rpy="0.0 0.0 0.0"/>
      <geometry>
        <mesh filename="../meshes/Hip3_Link.STL"/>
      </geometry>
    </collision>
  </link>
  <joint name="LLKnee" type="revolute">
    <origin xyz="0.10788 -0.0005 -0.39684" rpy="3.1416 1.309 -2.9949e-15"/>
    <axis xyz="0.0 0.0 1.0"/>
    <parent link="LLHip3_Link"/>
    <child link="LLKnee_Link"/>
    <limit effort="325.0" lower="0.0" upper="1.67012158" velocity="2.247"/>
  </joint>
  <joint name="LLKnee_Act1" type="prismatic">
    <origin xyz="0.27341 0.0 0.0" rpy="0.0 7.7037e-32 -6.9389e-18"/>
    <axis xyz="1.0 0.0 0.0"/>
    <parent link="LLKnee_B11_Link"/>
    <child link="LLKnee_Act1_Link"/>
    <limit effort="1825.0" lower="0.0" upper="0.1175" velocity="0.14"/>
  </joint>
  <link name="LLKnee_Act1_Link">
    <inertial>
      <origin xyz="-0.10645 -2.465e-13 1.5266e-16" rpy="0.0 0.0 0.0"/>
      <mass value="0.16503"/>
      <inertia ixx="3.4113e-06" ixy="-3.8263e-12" ixz="-7.1291e-16" iyy="0.00081967" iyz="1.7661e-15" izz="0.00081963"/>
    </inertial>
    <visual name="LLKnee_Act1_Link_visual">
      <origin xyz="0.0 0.0 0.0" rpy="0.0 0.0 0.0"/>
      <geometry>
        <mesh filename="../meshes/Knee_Act1_Link.STL"/>
      </geometry>
      <material name="">
        <color rgba="0.69804 0.69804 0.69804 1.0"/>
      </material>
    </visual>
    <collision name="LLKnee_Act1_Link_collision">
      <origin xyz="0.0 0.0 0.0" rpy="0.0 0.0 0.0"/>
      <geometry>
        <mesh filename="../meshes/Knee_Act1_Link.STL"/>
      </geometry>
    </collision>
  </link>
  <joint name="LLKnee_B11" type="revolute">
    <origin xyz="0.020175 0.070737 -0.075294" rpy="-0.15081 1.3059 -0.15617"/>
    <axis xyz="0.0 0.0 -1.0"/>
    <parent link="LLHip3_Link"/>
    <child link="LLKnee_B11_Link"/>
    <limit effort="0.0" lower="0" upper="0" velocity="0.0"/>
  </joint>
  <link name="LLKnee_B11_Link">
    <inertial>
      <origin xyz="0.16939 0.00046866 4.4515e-05" rpy="0.0 0.0 0.0"/>
      <mass value="1.224"/>
      <inertia ixx="0.00077764" ixy="5.3789e-05" ixz="-4.184e-07" iyy="0.0059454" iyz="3.0443e-08" izz="0.0059571"/>
    </inertial>
    <visual name="LLKnee_B11_Link_visual">
      <origin xyz="0.0 0.0 0.0" rpy="0.0 0.0 0.0"/>
      <geometry>
        <mesh filename="../meshes/Knee_B11_Link.STL"/>
      </geometry>
      <material name="">
        <color rgba="0.69804 0.69804 0.69804 1.0"/>
      </material>
    </visual>
    <collision name="LLKnee_B11_Link_collision">
      <origin xyz="0.0 0.0 0.0" rpy="0.0 0.0 0.0"/>
      <geometry>
        <mesh filename="../meshes/Knee_B11_Link.STL"/>
      </geometry>
    </collision>
  </link>
  <link name="LLKnee_Link">
    <inertial>
      <origin xyz="0.11911 -0.001888 0.00058411" rpy="0.0 0.0 0.0"/>
      <mass value="0.94401"/>
      <inertia ixx="0.0017333" ixy="-5.494e-05" ixz="-0.00010491" iyy="0.01483" iyz="2.0836e-06" izz="0.014618"/>
    </inertial>
    <visual name="LLKnee_Link_visual">
      <origin xyz="0.0 0.0 0.0" rpy="0.0 0.0 0.0"/>
      <geometry>
        <mesh filename="../meshes/Knee_Link.STL"/>
      </geometry>
      <material name="">
        <color rgba="0.69804 0.69804 0.69804 1.0"/>
      </material>
    </visual>
    <collision name="LLKnee_Link_collision">
      <origin xyz="0.0 0.0 0.0" rpy="0.0 0.0 0.0"/>
      <geometry>
        <mesh filename="../meshes/Knee_Link.STL"/>
      </geometry>
    </collision>
  </link>
  <joint name="LRAnkleBase" type="fixed">
    <origin xyz="0.42 0.0 0.0015" rpy="1.5708 -0.0 -1.5708"/>
    <axis xyz="0.0 0.0 0.0"/>
    <parent link="LRKnee_Link"/>
    <child link="LRAnkleBase_Link"/>
  </joint>
  <link name="LRAnkleBase_Link">
    <inertial>
      <origin xyz="0.0 0.0 0.0" rpy="0.0 0.0 0.0"/>
      <mass value="0.0"/>
      <inertia ixx="0.0" ixy="0.0" ixz="0.0" iyy="0.0" iyz="0.0" izz="0.0"/>
    </inertial>
  </link>
  <joint name="LRAnklePitch" type="revolute">
    <origin xyz="0.0 0.0 0.0" rpy="0.0 0.0 0.0"/>
    <axis xyz="0.0 1.0 0.0"/>
    <parent link="LRAnkleRoll_Link"/>
    <child link="LRAnklePitch_Link"/>
    <limit effort="200.0" lower="-0.698" upper="0.698" velocity="3.141"/>
  </joint>
  <link name="LRAnklePitch_Link">
    <inertial>
      <origin xyz="2.8493e-18 -1.3878e-16 0.0" rpy="0.0 0.0 0.0"/>
      <mass value="2.8252e-05"/>
      <inertia ixx="4.5912e-11" ixy="1.8118e-28" ixz="-1.4548e-27" iyy="6.6802e-11" iyz="5.3633e-27" izz="3.9725e-11"/>
    </inertial>
    <visual name="LRAnklePitch_Link_visual">
      <origin xyz="0.0 0.0 0.0" rpy="0.0 0.0 0.0"/>
      <geometry>
        <mesh filename="../meshes/AnklePitch_Link.STL"/>
      </geometry>
      <material name="">
        <color rgba="0.79216 0.81961 0.93333 1.0"/>
      </material>
    </visual>
  </link>
  <joint name="LRAnkleRoll" type="revolute">
    <origin xyz="0.0 0.0 0.0" rpy="0.0 0.0 0.0"/>
    <axis xyz="1.0 0.0 0.0"/>
    <parent link="LRAnkleBase_Link"/>
    <child link="LRAnkleRoll_Link"/>
    <limit effort="200.0" lower="-0.524" upper="0.524" velocity="3.141"/>
  </joint>
  <link name="LRAnkleRoll_Link">
    <inertial>
      <origin xyz="-4.1608e-08 7.2923e-08 -5.2997e-09" rpy="0.0 0.0 0.0"/>
      <mass value="0.02493"/>
      <inertia ixx="2.9269e-06" ixy="-7.8377e-12" ixz="-1.0382e-12" iyy="1.1591e-06" iyz="1.5876e-12" izz="3.5758e-06"/>
    </inertial>
    <visual name="LRAnkleRoll_Link_visual">
      <origin xyz="0.0 0.0 0.0" rpy="0.0 0.0 0.0"/>
      <geometry>
        <mesh filename="../meshes/AnkleRoll_Link.STL"/>
      </geometry>
      <material name="">
        <color rgba="0.64706 0.61961 0.58824 1.0"/>
      </material>
    </visual>
    <collision name="LRAnkleRoll_Link_collision">
      <origin xyz="0.0 0.0 0.0" rpy="0.0 0.0 0.0"/>
      <geometry>
        <mesh filename="../meshes/AnkleRoll_Link.STL"/>
      </geometry>
    </collision>
  </link>
  <joint name="LRAnkle_Act1" type="prismatic">
    <origin xyz="0.0 0.0 0.26597" rpy="0.0 0.0 0.0"/>
    <axis xyz="0.0 0.0 1.0"/>
    <parent link="LRAnkle_B12_Link"/>
    <child link="LRAnkle_Act1_Link"/>
    <limit effort="571.0" lower="-0.0449" upper="0.0647" velocity="0.14466"/>
  </joint>
  <link name="LRAnkle_Act1_Link">
    <inertial>
      <origin xyz="0.0 0.0 0.0" rpy="0.0 -0.0 0.0"/>
      <mass value="0.07896134655058572"/>
      <inertia ixx="0.0002465399999951976" ixy="2.2218334565684636e-09" ixz="-1.2305787261017842e-09" iyy="0.00024678" iyz="-6.276200589605272e-08" izz="1.0730000048024368e-06"/>
    </inertial>
    <visual name="LRAnkle_Act1_Link_visual">
      <origin xyz="0.0 0.0 0.0" rpy="0.0 3.14159 1.57079632679"/>
      <geometry>
        <mesh filename="../meshes/Ankle_Act1_Link.STL"/>
      </geometry>
      <material name="">
        <color rgba="0.69804 0.69804 0.69804 1.0"/>
      </material>
    </visual>
    <collision name="LRAnkle_Act1_Link_collision">
      <origin xyz="0.0 0.0 0.0" rpy="0.0 3.14159 1.57079632679"/>
      <geometry>
        <mesh filename="../meshes/Ankle_Act1_Link.STL"/>
      </geometry>
    </collision>
  </link>
  <joint name="LRAnkle_Act2" type="prismatic">
    <origin xyz="0.0 0.0 0.26597" rpy="0.0 0.0 0.0"/>
    <axis xyz="0.0 0.0 1.0"/>
    <parent link="LRAnkle_B22_Link"/>
    <child link="LRAnkle_Act2_Link"/>
    <limit effort="571.0" lower="-0.0449" upper="0.0647" velocity="0.14466"/>
  </joint>
  <link name="LRAnkle_Act2_Link">
    <inertial>
      <origin xyz="0.0 0.0 0.0" rpy="0.0 -0.0 0.0"/>
      <mass value="0.07896134655058568"/>
      <inertia ixx="0.00024653999999529885" ixy="-2.1503334660041774e-09" ixz="-1.2114887257947331e-09" iyy="0.00024678" iyz="6.275800570632389e-08" izz="1.0730000047011228e-06"/>
    </inertial>
    <visual name="LRAnkle_Act2_Link_visual">
      <origin xyz="0.0 0.0 0.0" rpy="0.0 3.14159 0.0"/>
      <geometry>
        <mesh filename="../meshes/Ankle_Act2_Link.STL"/>
      </geometry>
      <material name="">
        <color rgba="0.69804 0.69804 0.69804 1.0"/>
      </material>
    </visual>
    <collision name="LRAnkle_Act2_Link_collision">
      <origin xyz="0.0 0.0 0.0" rpy="0.0 3.14159 0.0"/>
      <geometry>
        <mesh filename="../meshes/Ankle_Act2_Link.STL"/>
      </geometry>
    </collision>
  </link>
  <joint name="LRAnkle_B11" type="revolute">
    <origin xyz="-0.0223 0.025 0.29127" rpy="3.091 -0.174503 3.14159"/>
    <axis xyz="1.0 0.0 0.0"/>
    <parent link="LRAnkleBase_Link"/>
    <child link="LRAnkle_B11_Link"/>
    <limit effort="0.0" lower="0" upper="0" velocity="0.0"/>
  </joint>
  <link name="LRAnkle_B11_Link">
    <inertial>
      <origin xyz="-0.0026075 -1.6785e-12 0.0015126" rpy="0.0 0.0 0.0"/>
      <mass value="0.00654"/>
      <inertia ixx="1.5907e-06" ixy="3.9038e-14" ixz="8.7457e-09" iyy="1.8739e-06" iyz="8.1942e-15" izz="3.3241e-06"/>
    </inertial>
    <visual name="LRAnkle_B11_Link_visual">
      <origin xyz="0.0 0.0 0.0" rpy="0.0 0.0 0.0"/>
      <geometry>
        <mesh filename="../meshes/Ankle_B11_Link.STL"/>
      </geometry>
      <material name="">
        <color rgba="0.69804 0.69804 0.69804 1.0"/>
      </material>
    </visual>
    <collision name="LRAnkle_B11_Link_collision">
      <origin xyz="0.0 0.0 0.0" rpy="0.0 0.0 0.0"/>
      <geometry>
        <mesh filename="../meshes/Ankle_B11_Link.STL"/>
      </geometry>
    </collision>
  </link>
  <joint name="LRAnkle_B12" type="revolute">
    <origin xyz="0.0 0.0 0.0" rpy="0.0 -0.0060102 0.0"/>
    <axis xyz="0.0 1.0 0.0"/>
    <parent link="LRAnkle_B11_Link"/>
    <child link="LRAnkle_B12_Link"/>
    <limit effort="0.0" lower="0" upper="0" velocity="0.0"/>
  </joint>
  <link name="LRAnkle_B12_Link">
    <inertial>
      <origin xyz="0.0 0.0 0.0" rpy="0.0 -0.0 0.0"/>
      <mass value="0.626756605161674"/>
      <inertia ixx="0.0024658002179549095" ixy="-7.781387113609205e-08" ixz="4.106487105614771e-05" iyy="0.0024841" iyz="4.2541020648759203e-07" izz="0.0001561197820450909"/>
    </inertial>
    <visual name="LRAnkle_B12_Link_visual">
      <origin xyz="0.0 0.0 0.0" rpy="0.0 3.14159 0.0"/>
      <geometry>
        <mesh filename="../meshes/Ankle_B12_Link.STL"/>
      </geometry>
      <material name="">
        <color rgba="0.69804 0.69804 0.69804 1.0"/>
      </material>
    </visual>
    <collision name="LRAnkle_B12_Link_collision">
      <origin xyz="0.0 0.0 0.0" rpy="0.0 3.14159 0.0"/>
      <geometry>
        <mesh filename="../meshes/Ankle_B12_Link.STL"/>
      </geometry>
    </collision>
  </link>
  <joint name="LRAnkle_B21" type="revolute">
    <origin xyz="-0.0223 -0.025 0.29127" rpy="-3.09098 -0.174503 3.14159"/>
    <axis xyz="1.0 0.0 0.0"/>
    <parent link="LRAnkleBase_Link"/>
    <child link="LRAnkle_B21_Link"/>
    <limit effort="0.0" lower="0" upper="0" velocity="0.0"/>
  </joint>
  <link name="LRAnkle_B21_Link">
    <inertial>
      <origin xyz="0.0 0.0 0.0" rpy="0.0 -0.0 0.0"/>
      <mass value="0.006540000004287366"/>
      <inertia ixx="1.5907000464272066e-06" ixy="-3.904598539503503e-14" ixz="8.750299732424617e-09" iyy="1.8739e-06" iyz="5.503903612047694e-15" izz="3.324099953572794e-06"/>
    </inertial>
    <visual name="LRAnkle_B21_Link_visual">
      <origin xyz="0.0 0.0 0.0" rpy="0.0 3.14159 0.0"/>
      <geometry>
        <mesh filename="../meshes/Ankle_B21_Link.STL"/>
      </geometry>
      <material name="">
        <color rgba="0.69804 0.69804 0.69804 1.0"/>
      </material>
    </visual>
    <collision name="LRAnkle_B21_Link_collision">
      <origin xyz="0.0 0.0 0.0" rpy="0.0 3.14159 0.0"/>
      <geometry>
        <mesh filename="../meshes/Ankle_B21_Link.STL"/>
      </geometry>
    </collision>
  </link>
  <joint name="LRAnkle_B22" type="revolute">
    <origin xyz="0.0 0.0 0.0" rpy="0.0 -0.0060102 0.0"/>
    <axis xyz="0.0 1.0 0.0"/>
    <parent link="LRAnkle_B21_Link"/>
    <child link="LRAnkle_B22_Link"/>
    <limit effort="0.0" lower="0" upper="0" velocity="0.0"/>
  </joint>
  <link name="LRAnkle_B22_Link">
    <inertial>
      <origin xyz="0.0 0.0 0.0" rpy="0.0 -0.0 0.0"/>
      <mass value="0.6267566051616451"/>
      <inertia ixx="0.0024658002179549095" ixy="-7.617188419175961e-08" ixz="4.106487105614771e-05" iyy="0.0024841" iyz="4.204902021304149e-07" izz="0.0001561197820450909"/>
    </inertial>
    <visual name="LRAnkle_B22_Link_visual">
      <origin xyz="0.0 0.0 0.0" rpy="0.0 3.14159 0.0"/>
      <geometry>
        <mesh filename="../meshes/Ankle_B22_Link.STL"/>
      </geometry>
      <material name="">
        <color rgba="0.69804 0.69804 0.69804 1.0"/>
      </material>
    </visual>
    <collision name="LRAnkle_B22_Link_collision">
      <origin xyz="0.0 0.0 0.0" rpy="0.0 3.14159 0.0"/>
      <geometry>
        <mesh filename="../meshes/Ankle_B22_Link.STL"/>
      </geometry>
    </collision>
  </link>
  <joint name="LRAnkle_E11" type="revolute">
    <origin xyz="-0.07 0.04 0.0" rpy="0.05066 0.0 0.0"/>
    <axis xyz="1.0 0.0 0.0"/>
    <parent link="LRAnklePitch_Link"/>
    <child link="LRAnkle_E11_Link"/>
    <limit effort="0.0" lower="0" upper="0" velocity="0.0"/>
  </joint>
  <link name="LRAnkle_E11_Link">
    <inertial>
      <origin xyz="-3.2627e-08 -0.00061479 0.011938" rpy="0.0 0.0 0.0"/>
      <mass value="0.025"/>
      <inertia ixx="5.6966e-06" ixy="2.0874e-13" ixz="-6.1394e-13" iyy="5.4356e-06" iyz="2.0391e-07" izz="1.4865e-06"/>
    </inertial>
    <visual name="LRAnkle_E11_Link_visual">
      <origin xyz="0.0 0.0 0.0" rpy="0.0 0.0 0.0"/>
      <geometry>
        <mesh filename="../meshes/Ankle_E11_Link.STL"/>
      </geometry>
      <material name="">
        <color rgba="0.69804 0.69804 0.69804 1.0"/>
      </material>
    </visual>
    <collision name="LRAnkle_E11_Link_collision">
      <origin xyz="0.0 0.0 0.0" rpy="0.0 0.0 0.0"/>
      <geometry>
        <mesh filename="../meshes/Ankle_E11_Link.STL"/>
      </geometry>
    </collision>
  </link>
  <joint name="LRAnkle_E21" type="revolute">
    <origin xyz="-0.07 -0.04 0.0" rpy="-0.05066 0.0 0.0"/>
    <axis xyz="1.0 0.0 0.0"/>
    <parent link="LRAnklePitch_Link"/>
    <child link="LRAnkle_E21_Link"/>
    <limit effort="0.0" lower="0" upper="0" velocity="0.0"/>
  </joint>
  <link name="LRAnkle_E21_Link">
    <inertial>
      <origin xyz="-3.2627e-08 0.00061479 0.011938" rpy="0.0 0.0 0.0"/>
      <mass value="0.025"/>
      <inertia ixx="5.6966e-06" ixy="-2.0874e-13" ixz="-6.1394e-13" iyy="5.4356e-06" iyz="-2.0391e-07" izz="1.4865e-06"/>
    </inertial>
    <visual name="LRAnkle_E21_Link_visual">
      <origin xyz="0.0 0.0 0.0" rpy="0.0 0.0 0.0"/>
      <geometry>
        <mesh filename="../meshes/Ankle_E21_Link.STL"/>
      </geometry>
      <material name="">
        <color rgba="0.69804 0.69804 0.69804 1.0"/>
      </material>
    </visual>
    <collision name="LRAnkle_E21_Link_collision">
      <origin xyz="0.0 0.0 0.0" rpy="0.0 0.0 0.0"/>
      <geometry>
        <mesh filename="../meshes/Ankle_E21_Link.STL"/>
      </geometry>
    </collision>
  </link>
  <link name="LRAnkle_FT">
    <inertial>
      <origin xyz="0.016102 4.5932e-05 0.0078533" rpy="0.0 0.0 0.0"/>
      <mass value="1.2348"/>
      <inertia ixx="0.0018722" ixy="1.7891e-07" ixz="-0.00077672" iyy="0.0072567" iyz="3.8393e-06" izz="0.007267"/>
    </inertial>
    <visual name="LRAnkle_FT_visual">
      <origin xyz="0.0 0.0 0.0" rpy="0.0 0.0 0.0"/>
      <geometry>
        <mesh filename="../meshes/FL_FT_Link.STL"/>
      </geometry>
      <material name="">
        <color rgba="0.69804 0.69804 0.69804 1.0"/>
      </material>
    </visual>
    <collision name="LRAnkle_FT_collision">
      <origin xyz="0.0 0.0 0.0" rpy="0.0 0.0 0.0"/>
      <geometry>
        <mesh filename="../meshes/FL_FT_Link.STL"/>
      </geometry>
    </collision>
  </link>
  <joint name="LRAnkle_FT" type="fixed">
    <origin xyz="0.0 0.0 -0.058972" rpy="-3.1416 0.0 -1.2151e-16"/>
    <axis xyz="0.0 0.0 0.0"/>
    <parent link="LRAnklePitch_Link"/>
    <child link="LRAnkle_FT"/>
  </joint>
  <joint name="LRHip1" type="revolute">
    <origin xyz="0.0735 -0.11044 0.014269" rpy="3.4781e-17 -0.2618 -1.5708"/>
    <axis xyz="0.0 0.0 1.0"/>
    <parent link="RH5_Root_Link"/>
    <child link="LRHip1_Link"/>
    <limit effort="135.0" lower="-0.7330" upper="0.7330" velocity="1.658"/>
  </joint>
  <link name="LRHip1_Link">
    <inertial>
      <origin xyz="-4.5821e-08 -0.0016166 0.04962" rpy="0.0 0.0 0.0"/>
      <mass value="0.5"/>
      <inertia ixx="0.0020247" ixy="8.3227e-09" ixz="3.6838e-09" iyy="0.00095763" iyz="-0.00012913" izz="0.0015078"/>
    </inertial>
    <visual name="LRHip1_Link_visual">
      <origin xyz="0.0 0.0 0.0" rpy="0.0 0.0 0.0"/>
      <geometry>
        <mesh filename="../meshes/LRHip1_Link.STL"/>
      </geometry>
      <material name="">
        <color rgba="0.69804 0.69804 0.69804 1.0"/>
      </material>
    </visual>
    <collision name="LRHip1_Link_collision">
      <origin xyz="0.0 0.0 0.0" rpy="0.0 0.0 0.0"/>
      <geometry>
        <mesh filename="../meshes/LRHip1_Link.STL"/>
      </geometry>
    </collision>
  </link>
  <joint name="LRHip2" type="revolute">
    <origin xyz="0.0 0.0 0.0" rpy="-4.0161e-17 0.5236 -2.0081e-17"/>
    <axis xyz="0.0 1.0 0.0"/>
    <parent link="LRHip1_Link"/>
    <child link="LRHip2_Link"/>
    <limit effort="135.0" lower="-0.8203" upper="0.3840" velocity="1.658"/>
  </joint>
  <link name="LRHip2_Link">
    <inertial>
      <origin xyz="0.0013954 0.0024309 -0.0053241" rpy="0.0 0.0 0.0"/>
      <mass value="0.969"/>
      <inertia ixx="0.0017014" ixy="7.9487e-05" ixz="4.6091e-05" iyy="0.0011578" iyz="-0.0003011" izz="0.0015428"/>
    </inertial>
    <visual name="LRHip2_Link_visual">
      <origin xyz="0.0 0.0 0.0" rpy="0.0 0.0 0.0"/>
      <geometry>
        <mesh filename="../meshes/LRHip2_Link.STL"/>
      </geometry>
      <material name="">
        <color rgba="0.69804 0.69804 0.69804 1.0"/>
      </material>
    </visual>
  </link>
  <joint name="LRHip3" type="revolute">
    <origin xyz="0.0 0.0 0.0" rpy="9.8608e-32 2.7756e-17 -4.9304e-32"/>
    <axis xyz="-0.96593 0.0 -0.25882"/>
    <parent link="LRHip2_Link"/>
    <child link="LRHip3_Link"/>
    <limit effort="378.0" lower="-1.49563127" upper="0.28858014" velocity="2.247"/>
  </joint>
  <joint name="LRHip3_Act1" type="prismatic">
    <origin xyz="0.2974 0.0 0.0" rpy="3.1416 -5.2385e-31 0.0"/>
    <axis xyz="1.0 0.0 0.0"/>
    <parent link="LRHip3_B11_Link"/>
    <child link="LRHip3_Act1_Link"/>
    <limit effort="3000.0" lower="-0.0255" upper="0.1335" velocity="0.175"/>
  </joint>
  <link name="LRHip3_Act1_Link">
    <inertial>
      <origin xyz="-0.16939 -0.00046849 4.4559e-05" rpy="0.0 0.0 0.0"/>
      <mass value="1.224"/>
      <inertia ixx="0.00077764" ixy="5.3759e-05" ixz="4.1291e-07" iyy="0.0059452" iyz="-2.966e-08" izz="0.0059569"/>
    </inertial>
    <visual name="LRHip3_Act1_Link_visual">
      <origin xyz="0.0 0.0 0.0" rpy="0.0 0.0 0.0"/>
      <geometry>
        <mesh filename="../meshes/LLHip3_Act1_Link.STL"/>
      </geometry>
      <material name="">
        <color rgba="0.69804 0.69804 0.69804 1.0"/>
      </material>
    </visual>
    <collision name="LRHip3_Act1_Link_collision">
      <origin xyz="0.0 0.0 0.0" rpy="0.0 0.0 0.0"/>
      <geometry>
        <mesh filename="../meshes/LLHip3_Act1_Link.STL"/>
      </geometry>
    </collision>
  </link>
  <joint name="LRHip3_B11" type="revolute">
    <origin xyz="0.018117 -0.09 -0.067615" rpy="-2.5686 1.2577 0.59588"/>
    <axis xyz="0.0 0.0 1.0"/>
    <parent link="LRHip2_Link"/>
    <child link="LRHip3_B11_Link"/>
    <limit effort="0.0" lower="0" upper="0" velocity="0.0"/>
  </joint>
  <link name="LRHip3_B11_Link">
    <inertial>
      <origin xyz="0.10645 -2.4289e-13 1.9568e-15" rpy="0.0 0.0 0.0"/>
      <mass value="0.16503"/>
      <inertia ixx="3.4113e-06" ixy="3.8263e-12" ixz="-7.0537e-16" iyy="0.00081967" iyz="-1.7661e-15" izz="0.00081963"/>
    </inertial>
    <visual name="LRHip3_B11_Link_visual">
      <origin xyz="0.0 0.0 0.0" rpy="0.0 0.0 0.0"/>
      <geometry>
        <mesh filename="../meshes/Hip3_B11_Link.STL"/>
      </geometry>
      <material name="">
        <color rgba="0.69804 0.69804 0.69804 1.0"/>
      </material>
    </visual>
    <collision name="LRHip3_B11_Link_collision">
      <origin xyz="0.0 0.0 0.0" rpy="0.0 0.0 0.0"/>
      <geometry>
        <mesh filename="../meshes/Hip3_B11_Link.STL"/>
      </geometry>
    </collision>
  </link>
  <link name="LRHip3_Link">
    <inertial>
      <origin xyz="0.051263 0.0072511 -0.19232" rpy="0.0 0.0 0.0"/>
      <mass value="1.0487"/>
      <inertia ixx="0.020383" ixy="3.4682e-05" ixz="0.0047264" iyy="0.022629" iyz="-0.00014075" izz="0.0042174"/>
    </inertial>
    <visual name="LRHip3_Link_visual">
      <origin xyz="0.0 0.0 0.0" rpy="0.0 0.0 0.0"/>
      <geometry>
        <mesh filename="../meshes/Hip3_Link.STL"/>
      </geometry>
      <material name="">
        <color rgba="0.69804 0.69804 0.69804 1.0"/>
      </material>
    </visual>
    <collision name="LRHip3_Link_collision">
      <origin xyz="0.0 0.0 0.0" rpy="0.0 0.0 0.0"/>
      <geometry>
        <mesh filename="../meshes/Hip3_Link.STL"/>
      </geometry>
    </collision>
  </link>
  <joint name="LRKnee" type="revolute">
    <origin xyz="0.10788 -0.0005 -0.39684" rpy="3.1416 1.309 -2.9949e-15"/>
    <axis xyz="0.0 0.0 1.0"/>
    <parent link="LRHip3_Link"/>
    <child link="LRKnee_Link"/>
    <limit effort="325.0" lower="0.0" upper="1.67012158" velocity="2.247"/>
  </joint>
  <joint name="LRKnee_Act1" type="prismatic">
    <origin xyz="0.27341 0.0 0.0" rpy="0.0 7.7037e-32 -6.9389e-18"/>
    <axis xyz="1.0 0.0 0.0"/>
    <parent link="LRKnee_B11_Link"/>
    <child link="LRKnee_Act1_Link"/>
    <limit effort="1825.0" lower="0.0" upper="0.1175" velocity="0.14"/>
  </joint>
  <link name="LRKnee_Act1_Link">
    <inertial>
      <origin xyz="-0.10645 -2.465e-13 1.5266e-16" rpy="0.0 0.0 0.0"/>
      <mass value="0.16503"/>
      <inertia ixx="3.4113e-06" ixy="-3.8263e-12" ixz="-7.1291e-16" iyy="0.00081967" iyz="1.7661e-15" izz="0.00081963"/>
    </inertial>
    <visual name="LRKnee_Act1_Link_visual">
      <origin xyz="0.0 0.0 0.0" rpy="0.0 0.0 0.0"/>
      <geometry>
        <mesh filename="../meshes/Knee_Act1_Link.STL"/>
      </geometry>
      <material name="">
        <color rgba="0.69804 0.69804 0.69804 1.0"/>
      </material>
    </visual>
    <collision name="LRKnee_Act1_Link_collision">
      <origin xyz="0.0 0.0 0.0" rpy="0.0 0.0 0.0"/>
      <geometry>
        <mesh filename="../meshes/Knee_Act1_Link.STL"/>
      </geometry>
    </collision>
  </link>
  <joint name="LRKnee_B11" type="revolute">
    <origin xyz="0.020175 0.070737 -0.075294" rpy="-0.15081 1.3059 -0.15617"/>
    <axis xyz="0.0 0.0 -1.0"/>
    <parent link="LRHip3_Link"/>
    <child link="LRKnee_B11_Link"/>
    <limit effort="0.0" lower="0" upper="0" velocity="0.0"/>
  </joint>
  <link name="LRKnee_B11_Link">
    <inertial>
      <origin xyz="0.16939 0.00046866 4.4515e-05" rpy="0.0 0.0 0.0"/>
      <mass value="1.224"/>
      <inertia ixx="0.00077764" ixy="5.3789e-05" ixz="-4.184e-07" iyy="0.0059454" iyz="3.0443e-08" izz="0.0059571"/>
    </inertial>
    <visual name="LRKnee_B11_Link_visual">
      <origin xyz="0.0 0.0 0.0" rpy="0.0 0.0 0.0"/>
      <geometry>
        <mesh filename="../meshes/Knee_B11_Link.STL"/>
      </geometry>
      <material name="">
        <color rgba="0.69804 0.69804 0.69804 1.0"/>
      </material>
    </visual>
    <collision name="LRKnee_B11_Link_collision">
      <origin xyz="0.0 0.0 0.0" rpy="0.0 0.0 0.0"/>
      <geometry>
        <mesh filename="../meshes/Knee_B11_Link.STL"/>
      </geometry>
    </collision>
  </link>
  <link name="LRKnee_Link">
    <inertial>
      <origin xyz="0.11911 -0.001888 0.00058411" rpy="0.0 0.0 0.0"/>
      <mass value="0.94401"/>
      <inertia ixx="0.0017333" ixy="-5.494e-05" ixz="-0.00010491" iyy="0.01483" iyz="2.0836e-06" izz="0.014618"/>
    </inertial>
    <visual name="LRKnee_Link_visual">
      <origin xyz="0.0 0.0 0.0" rpy="0.0 0.0 0.0"/>
      <geometry>
        <mesh filename="../meshes/Knee_Link.STL"/>
      </geometry>
      <material name="">
        <color rgba="0.69804 0.69804 0.69804 1.0"/>
      </material>
    </visual>
    <collision name="LRKnee_Link_collision">
      <origin xyz="0.0 0.0 0.0" rpy="0.0 0.0 0.0"/>
      <geometry>
        <mesh filename="../meshes/Knee_Link.STL"/>
      </geometry>
    </collision>
  </link>
  <link name="RH5_Root_Link">
    <inertial>
      <origin xyz="0.057726 2.1253e-05 0.13284" rpy="0.0 0.0 0.0"/>
      <mass value="3.341"/>
      <inertia ixx="0.030478" ixy="-3.6697e-06" ixz="-0.0019703" iyy="0.01926" iyz="-7.8077e-06" izz="0.036595"/>
    </inertial>
    <visual name="RH5_Root_Link_visual">
      <origin xyz="0.0 0.0 0.0" rpy="0.0 0.0 0.0"/>
      <geometry>
        <mesh filename="../meshes/RH5_Root_Link.STL"/>
      </geometry>
      <material name="">
        <color rgba="0.69804 0.69804 0.69804 1.0"/>
      </material>
    </visual>
    <collision name="RH5_Root_Link_collision">
      <origin xyz="0.0 0.0 0.0" rpy="0.0 0.0 0.0"/>
      <geometry>
        <mesh filename="../meshes/RH5_Root_Link.STL"/>
      </geometry>
    </collision>
  </link>
  <joint name="VLP16" type="fixed">
    <origin xyz="0.0 0.0 0.56179" rpy="0.0 0.0 0.0"/>
    <axis xyz="0.0 0.0 1.0"/>
    <parent link="BodyYaw_Link"/>
    <child link="VLP16_Link"/>
  </joint>
  <link name="VLP16_Link"/>
</robot>
