<robot name="LRKnee">
  <link name="LRHip3_Link">
    <inertial>
      <origin xyz="0.051263 0.0072511 -0.19232" rpy="0.0 0.0 0.0"/>
      <mass value="1.0487"/>
      <inertia ixx="0.020383" ixy="3.4682e-05" ixz="0.0047264" iyy="0.022629" iyz="-0.00014075" izz="0.0042174"/>
    </inertial>
    <visual name="LRHip3_Link_visual">
      <origin xyz="0.0 0.0 0.0" rpy="0.0 0.0 0.0"/>
      <geometry>
        <mesh filename="../meshes/stl/Hip3_Link.STL"/>
      </geometry>
      <material name="">
        <color rgba="0.69804 0.69804 0.69804 1.0"/>
      </material>
    </visual>
    <collision name="LRHip3_Link_collision">
      <origin xyz="0.0 0.0 0.0" rpy="0.0 0.0 0.0"/>
      <geometry>
        <mesh filename="../meshes/stl/Hip3_Link.STL"/>
      </geometry>
    </collision>
  </link>
  <joint name="LRKnee" type="revolute">
    <origin xyz="0.10788 -0.0005 -0.39684" rpy="3.1416 1.309 -2.9949e-15"/>
    <axis xyz="0.0 0.0 1.0"/>
    <parent link="LRHip3_Link"/>
    <child link="LRKnee_Link"/>
    <limit effort="325.0" lower="-0.026" upper="1.43" velocity="2.321"/>
  </joint>
  <joint name="LRKnee_Act1" type="prismatic">
    <origin xyz="0.27341 0.0 0.0" rpy="0.0 7.7037e-32 -6.9389e-18"/>
    <axis xyz="1.0 0.0 0.0"/>
    <parent link="LRKnee_B11_Link"/>
    <child link="LRKnee_Act1_Link"/>
    <limit effort="1825.0" lower="0.0" upper="0.1175" velocity="0.14"/>
  </joint>
  <link name="LRKnee_Act1_Link">
    <inertial>
      <origin xyz="-0.10645 -2.465e-13 1.5266e-16" rpy="0.0 0.0 0.0"/>
      <mass value="0.16503"/>
      <inertia ixx="3.4113e-06" ixy="-3.8263e-12" ixz="-7.1291e-16" iyy="0.00081967" iyz="1.7661e-15" izz="0.00081963"/>
    </inertial>
    <visual name="LRKnee_Act1_Link_visual">
      <origin xyz="0.0 0.0 0.0" rpy="0.0 0.0 0.0"/>
      <geometry>
        <mesh filename="../meshes/stl/Knee_Act1_Link.STL"/>
      </geometry>
      <material name="">
        <color rgba="0.69804 0.69804 0.69804 1.0"/>
      </material>
    </visual>
    <collision name="LRKnee_Act1_Link_collision">
      <origin xyz="0.0 0.0 0.0" rpy="0.0 0.0 0.0"/>
      <geometry>
        <mesh filename="../meshes/stl/Knee_Act1_Link.STL"/>
      </geometry>
    </collision>
  </link>
  <joint name="LRKnee_B11" type="revolute">
    <origin xyz="0.020175 0.070737 -0.075294" rpy="-0.15081 1.3059 -0.15617"/>
    <axis xyz="0.0 0.0 -1.0"/>
    <parent link="LRHip3_Link"/>
    <child link="LRKnee_B11_Link"/>
    <limit effort="0.0" lower="0" upper="0" velocity="0.0"/>
  </joint>
  <link name="LRKnee_B11_Link">
    <inertial>
      <origin xyz="0.16939 0.00046866 4.4515e-05" rpy="0.0 0.0 0.0"/>
      <mass value="1.224"/>
      <inertia ixx="0.00077764" ixy="5.3789e-05" ixz="-4.184e-07" iyy="0.0059454" iyz="3.0443e-08" izz="0.0059571"/>
    </inertial>
    <visual name="LRKnee_B11_Link_visual">
      <origin xyz="0.0 0.0 0.0" rpy="0.0 0.0 0.0"/>
      <geometry>
        <mesh filename="../meshes/stl/Knee_B11_Link.STL"/>
      </geometry>
      <material name="">
        <color rgba="0.69804 0.69804 0.69804 1.0"/>
      </material>
    </visual>
    <collision name="LRKnee_B11_Link_collision">
      <origin xyz="0.0 0.0 0.0" rpy="0.0 0.0 0.0"/>
      <geometry>
        <mesh filename="../meshes/stl/Knee_B11_Link.STL"/>
      </geometry>
    </collision>
  </link>
  <link name="LRKnee_Link">
    <inertial>
      <origin xyz="0.11911 -0.001888 0.00058411" rpy="0.0 0.0 0.0"/>
      <mass value="0.94401"/>
      <inertia ixx="0.0017333" ixy="-5.494e-05" ixz="-0.00010491" iyy="0.01483" iyz="2.0836e-06" izz="0.014618"/>
    </inertial>
    <visual name="LRKnee_Link_visual">
      <origin xyz="0.0 0.0 0.0" rpy="0.0 0.0 0.0"/>
      <geometry>
        <mesh filename="../meshes/stl/Knee_Link.STL"/>
      </geometry>
      <material name="">
        <color rgba="0.69804 0.69804 0.69804 1.0"/>
      </material>
    </visual>
    <collision name="LRKnee_Link_collision">
      <origin xyz="0.0 0.0 0.0" rpy="0.0 0.0 0.0"/>
      <geometry>
        <mesh filename="../meshes/stl/Knee_Link.STL"/>
      </geometry>
    </collision>
  </link>
</robot>
