<?xml version="1.0" ?>
<robot name="RH5v2" version="1.0">
    <link name="world"/>
    <joint name="base_joint" type="fixed">
       <parent link="world"/>
       <child link="RH5v2_Root_Link"/>
       <origin rpy="0 0 0" xyz="0 0 0"/>
    </joint>

	<joint name="ALBase" type="fixed">
		<origin rpy="-6.2e-05 -0.23628 1.309002" xyz="-0.025162 0.126091 0.35059"/>
		<parent link="BodyYaw_Link"/>
		<child link="ALBase_Link"/>
	</joint>
	<link name="ALBase_Link">
		<inertial>
			<origin rpy="0.0 0.0 0.0" xyz="0.0079897 0.0 0.00019625"/>
			<mass value="1.1943"/>
			<inertia ixx="0.00089755" ixy="1.4484e-08" ixz="-2.6127e-07" iyy="0.00057565" iyz="-7.8027e-07" izz="0.00056347"/>
		</inertial>
		<visual name="ALBase_Link_Visual">
			<origin rpy="0.0 0.0 0.0" xyz="0.0 0.0 0.0"/>
			<geometry>
				<mesh filename="../meshes/ALBase_Link.stl"/>
			</geometry>
			<material name="">
				<color rgba="0.75294 0.75294 0.75294 1.0"/>
			</material>
		</visual>
	</link>
	<joint name="ALElbow" type="revolute">
		<origin rpy="0.0 0.0 0.0" xyz="0.0 0.001 0.3511"/>
		<axis xyz="1.0 0.0 0.0"/>
		<parent link="ALShoulder3_Link"/>
		<child link="ALElbow_Link"/>
		<limit effort="110.13" lower="-1.78" upper="0.01" velocity="7.075"/>
	</joint>
	<link name="ALElbow_Link">
		<inertial>
			<origin rpy="0.0 0.0 0.0" xyz="0.0 0.001127 0.080286"/>
			<mass value="0.63578"/>
			<inertia ixx="0.00050999" ixy="2.2297e-07" ixz="4.047e-07" iyy="0.00051633" iyz="-4.4233e-05" izz="0.00046537"/>
		</inertial>
		<visual name="ALElbow_Link_Visual">
			<origin rpy="0.0 0.0 0.0" xyz="0.0 0.0 0.0"/>
			<geometry>
				<mesh filename="../meshes/ALElbow_Link.stl"/>
			</geometry>
			<material name="">
				<color rgba="0.75294 0.75294 0.75294 1.0"/>
			</material>
		</visual>
	</link>
	<joint name="ALShoulder1" type="revolute">
		<origin rpy="3.1416 0.0 0.0" xyz="0.1076 0.0 0.0"/>
		<axis xyz="1.0 0.0 0.0"/>
		<parent link="ALBase_Link"/>
		<child link="ALShoulder1_Link"/>
		<limit effort="157.0" lower="-3.0543" upper="3.0543" velocity="3.6"/>
	</joint>
	<link name="ALShoulder1_Link">
		<inertial>
			<origin rpy="0.0 0.0 0.0" xyz="-0.0091569 0.0036464 -0.00016872"/>
			<mass value="1.602"/>
			<inertia ixx="0.0012117" ixy="-8.0704e-05" ixz="-3.528e-06" iyy="0.0015561" iyz="-2.6511e-06" izz="0.0010024"/>
		</inertial>
		<visual name="ALShoulder1_Link_Visual">
			<origin rpy="0.0 0.0 0.0" xyz="0.0 0.0 0.0"/>
			<geometry>
				<mesh filename="../meshes/ALShoulder1_Link.stl"/>
			</geometry>
			<material name="">
				<color rgba="0.75294 0.75294 0.75294 1.0"/>
			</material>
		</visual>
		<collision name="ALShoulder1_Link_Collision">
			<origin rpy="1.570796 -1.568017 0.0" xyz="-0.005334 -0.004665 -0.002299"/>
			<geometry>
				<sphere radius="0.059044141322374344"/>
			</geometry>
		</collision>
	</link>
	<joint name="ALShoulder2" type="revolute">
		<origin rpy="0.0 0.0 0.0" xyz="0.0 0.0 0.0"/>
		<axis xyz="0.0 1.0 0.0"/>
		<parent link="ALShoulder1_Link"/>
		<child link="ALShoulder2_Link"/>
		<limit effort="157.0" lower="-0.248" upper="1.845" velocity="3.6"/>
	</joint>
	<link name="ALShoulder2_Link">
		<inertial>
			<origin rpy="0.0 0.0 0.0" xyz="0.010763 0.020477 0.0278"/>
			<mass value="0.50849"/>
			<inertia ixx="0.0010465" ixy="0.00012061" ixz="5.4855e-05" iyy="0.00092568" iyz="0.00027501" izz="0.0010393"/>
		</inertial>
		<visual name="ALShoulder2_Link_Visual">
			<origin rpy="0.0 0.0 0.0" xyz="0.0 0.0 0.0"/>
			<geometry>
				<mesh filename="../meshes/ALShoulder2_Link.stl"/>
			</geometry>
			<material name="">
				<color rgba="0.75294 0.75294 0.75294 1.0"/>
			</material>
		</visual>
	</link>
	<joint name="ALShoulder3" type="revolute">
		<origin rpy="0.0 0.0 1.5707" xyz="0.0 0.0 0.0"/>
		<axis xyz="0.0 0.0 1.0"/>
		<parent link="ALShoulder2_Link"/>
		<child link="ALShoulder3_Link"/>
		<limit effort="28.0" lower="-3.0543" upper="3.0543" velocity="5.7"/>
	</joint>
	<link name="ALShoulder3_Link">
		<inertial>
			<origin rpy="0.0 0.0 0.0" xyz="0.0 0.0023269698080689164 0.12573969350370376"/>
			<mass value="1.234064594016641"/>
			<inertia ixx="0.003018389690136292" ixy="5.244535247714018e-07" ixz="-7.893331595881071e-07" iyy="0.0029498729569298384" iyz="8.820081543697286e-05" izz="0.0008757347333427459"/>
		</inertial>
		<visual name="ALShoulder3_Link_Visual">
			<origin rpy="0.0 0.0 0.0" xyz="0.0 0.0 0.0"/>
			<geometry>
				<mesh filename="../meshes/ALShoulder3_Link.stl"/>
			</geometry>
			<material name="">
				<color rgba="0.75294 0.75294 0.75294 1.0"/>
			</material>
		</visual>
		<visual name="ALElbowB11_Link_Visual">
			<origin rpy="-0.25319 0.0 0.0" xyz="0.0 -0.029 0.1391"/>
			<geometry>
				<mesh filename="../meshes/ALElbow_B11_Link.stl"/>
			</geometry>
			<material name="">
				<color rgba="0.75294 0.75294 0.75294 1.0"/>
			</material>
		</visual>
		<visual name="ALElbowAct_Link_Visual">
			<origin rpy="-0.25319 0.0 0.0" xyz="0.0 0.045001 0.425102"/>
			<geometry>
				<mesh filename="../meshes/ALElbow_Act_Link.stl"/>
			</geometry>
			<material name="">
				<color rgba="0.75294 0.75294 0.75294 1.0"/>
			</material>
		</visual>
		<collision name="ALShoulder3_Link_Collision">
			<origin rpy="3.071603 0.037077 0.479525" xyz="0.000897 0.015259 0.247292"/>
			<geometry>
				<cylinder length="0.37510071270897083" radius="0.04989704605643945"/>
			</geometry>
		</collision>
	</link>
	<joint name="ALWristFT" type="fixed">
		<origin rpy="0.0 0.0 1.5708" xyz="0.0 0.0 0.042748"/>
		<parent link="ALWristYaw_Link"/>
		<child link="ALWristFT_Link"/>
	</joint>
	<link name="ALWristFT_Link">
		<inertial>
			<origin rpy="0.0 0.0 0.0" xyz="-0.0021257506868597852 0.0025643917283102577 0.020104290293592838"/>
			<mass value="2.323616875904794"/>
			<inertia ixx="0.0016940457940833257" ixy="5.327619969251473e-05" ixz="3.918511751113743e-06" iyy="0.0009331975295453429" iyz="-2.582742097403667e-05" izz="0.001329614684356007"/>
		</inertial>
		<visual name="ALWristFT_Link_Visual">
			<origin rpy="0.0 0.0 0.0" xyz="0.0 0.0 0.0"/>
			<geometry>
				<mesh filename="../meshes/ALWristFT_Link.stl"/>
			</geometry>
			<material name="">
				<color rgba="0.698039215686274 0.698039215686274 0.698039215686274 1.0"/>
			</material>
		</visual>
		<visual name="GLBase_Visual">
			<origin rpy="-3.141592 0.0 0.0" xyz="0.0 0.0 0.0"/>
			<geometry>
				<mesh filename="../meshes/GripperLeft_BaseFrame.stl" scale="1.0 1.0 1.0"/>
			</geometry>
			<material name="">
				<color rgba="0.94118 0.67451 0.11765 1.0"/>
			</material>
		</visual>
		<visual name="GLF1Base_Visual">
			<origin rpy="1.7921 0.1664 -1.533593" xyz="-0.013458 -0.038971 0.065211"/>
			<geometry>
				<mesh filename="../meshes/Finger_Base_Frame.stl"/>
			</geometry>
			<material name="">
				<color rgba="0.79216 0.81961 0.93333 1.0"/>
			</material>
		</visual>
		<visual name="GLF1ProximalBar_Visual">
			<origin rpy="0.6783 0.1664 -1.533593" xyz="-0.053439 -0.029588 0.079319"/>
			<geometry>
				<mesh filename="../meshes/F_ProximalBar_Frame.stl"/>
			</geometry>
			<material name="">
				<color rgba="0.94118 0.67451 0.11765 1.0"/>
			</material>
		</visual>
		<visual name="GLF2Base_Visual">
			<origin rpy="1.7907 -0.12478 -1.598593" xyz="-0.014454 0.012122 0.06971"/>
			<geometry>
				<mesh filename="../meshes/Finger_Base_Frame.stl"/>
			</geometry>
			<material name="">
				<color rgba="0.79216 0.81961 0.93333 1.0"/>
			</material>
		</visual>
		<visual name="GLF2ProximalBar_Visual">
			<origin rpy="0.6769 -0.12478 -1.598593" xyz="-0.053624 0.02768 0.080161"/>
			<geometry>
				<mesh filename="../meshes/F_ProximalBar_Frame.stl"/>
			</geometry>
			<material name="">
				<color rgba="0.94118 0.67451 0.11765 1.0"/>
			</material>
		</visual>
		<visual name="GLF3Base_Visual">
			<origin rpy="1.7907 -0.124785 -1.598609" xyz="-0.013488 0.046837 0.065354"/>
			<geometry>
				<mesh filename="../meshes/Finger_Base_Frame.stl"/>
			</geometry>
			<material name="">
				<color rgba="0.79216 0.81961 0.93333 1.0"/>
			</material>
		</visual>
		<visual name="GLF3ProximalBar_Visual">
			<origin rpy="0.6769 -0.124785 -1.598609" xyz="-0.052657 0.062395 0.075805"/>
			<geometry>
				<mesh filename="../meshes/F_ProximalBar_Frame.stl"/>
			</geometry>
			<material name="">
				<color rgba="0.94118 0.67451 0.11765 1.0"/>
			</material>
		</visual>
	</link>
	<joint name="ALWristPitch" type="revolute">
		<origin rpy="-3.141592 -1.5707 0.0" xyz="0.173 0.0 0.0"/>
		<axis xyz="1.0 0.0 0.0"/>
		<parent link="ALWristRoll_Link"/>
		<child link="ALWristPitch_Link"/>
		<limit effort="43.135" lower="-0.7" upper="1.57" velocity="9.255"/>
	</joint>
	<link name="ALWristPitch_Link">
		<inertial>
			<origin rpy="0.0 0.0 0.0" xyz="0.0 0.0 0.0"/>
			<mass value="0.0303458029555441"/>
			<inertia ixx="1.0000000011242503e-05" ixy="0.0" ixz="1.3686128944734017e-10" iyy="1.0143779057796202e-05" iyz="1.3756897885334319e-10" izz="1.1666089364158581e-05"/>
		</inertial>
		<visual name="ALWristPitch_Link_Visual">
			<origin rpy="0.0 0.0 0.0" xyz="0.0 0.0 0.0"/>
			<geometry>
				<mesh filename="../meshes/ALWristPitch_Link.stl"/>
			</geometry>
			<material name="">
				<color rgba="0.647058823529412 0.619607843137255 0.588235294117647 1.0"/>
			</material>
		</visual>
	</link>
	<joint name="ALWristRoll" type="revolute">
		<origin rpy="3.1416 -1.5708 0.0" xyz="0.0 0.0 0.122"/>
		<axis xyz="1.0 0.0 0.0"/>
		<parent link="ALElbow_Link"/>
		<child link="ALWristRoll_Link"/>
		<limit effort="28.0" lower="-3.0543" upper="3.0543" velocity="5.7"/>
	</joint>
	<link name="ALWristRoll_Link">
		<inertial>
			<origin rpy="0.0 0.0 0.0" xyz="0.021100858801034905 0.020750070314189212 -0.022279202338594394"/>
			<mass value="0.7033703261930893"/>
			<inertia ixx="0.0005821306127387027" ixy="-2.1540995274711544e-05" ixz="8.844208549962065e-08" iyy="0.0014430712704364768" iyz="-3.4237658176659823e-07" izz="0.0014292089005863153"/>
		</inertial>
		<visual name="ALWristRoot_Link_Visual">
			<origin rpy="-3.141592 -1.5707 0.0" xyz="0.173 0.0 0.0"/>
			<geometry>
				<mesh filename="../meshes/ALWrist_Root_Link.stl"/>
			</geometry>
			<material name="">
				<color rgba="0.64706 0.61961 0.58824 1.0"/>
			</material>
		</visual>
		<visual name="ALWristBL1_Link_Visual">
			<origin rpy="0.259193 -1.5707 0.0" xyz="0.141001 -0.011 0.015503"/>
			<geometry>
				<mesh filename="../meshes/ALWrist_BL1_Link.stl"/>
			</geometry>
			<material name="">
				<color rgba="0.89804 0.91765 0.92941 1.0"/>
			</material>
		</visual>
		<visual name="ALWristBR1_Link_Visual">
			<origin rpy="0.259193 -1.5707 0.0" xyz="0.140999 -0.011 -0.015497"/>
			<geometry>
				<mesh filename="../meshes/ALWrist_BR1_Link.stl"/>
			</geometry>
			<material name="">
				<color rgba="0.89804 0.91765 0.92941 1.0"/>
			</material>
		</visual>
		<visual name="ALWristAL1_Link_Visual">
			<origin rpy="-1.553092 -1.5707 0.0" xyz="-0.004999 0.034 0.015517"/>
			<geometry>
				<mesh filename="../meshes/ALWrist_AL1_Link.stl"/>
			</geometry>
			<material name="">
				<color rgba="0.898039215686275 0.917647058823529 0.929411764705882 1.0"/>
			</material>
		</visual>
		<visual name="ALWristAR1_Link_Visual">
			<origin rpy="-1.553092 -1.5707 0.0" xyz="-0.005002 0.034 -0.015483"/>
			<geometry>
				<mesh filename="../meshes/ALWrist_AR1_Link.stl"/>
			</geometry>
			<material name="">
				<color rgba="0.89804 0.91765 0.92941 1.0"/>
			</material>
		</visual>
		<visual name="ALWristActL_Link_Visual">
			<origin rpy="-3.123892 -1.5707 0.0" xyz="0.12844 0.036363 0.015504"/>
			<geometry>
				<mesh filename="../meshes/ALWrist_ActL_Link.stl"/>
			</geometry>
			<material name="">
				<color rgba="0.77647 0.75686 0.73725 1.0"/>
			</material>
		</visual>
		<visual name="ALWristActR_Link_Visual">
			<origin rpy="-3.123892 -1.5707 0.0" xyz="0.128437 0.036363 -0.015496"/>
			<geometry>
				<mesh filename="../meshes/ALWrist_ActR_Link.stl"/>
			</geometry>
			<material name="">
				<color rgba="0.776470588235294 0.756862745098039 0.737254901960784 1.0"/>
			</material>
		</visual>
		<visual name="ALWristBase_Link_Visual">
			<origin rpy="3.141592 0.0001 0.0" xyz="0.005 0.0 0.0"/>
			<geometry>
				<mesh filename="../meshes/ALWrist_Base_Link.stl"/>
			</geometry>
			<material name="">
				<color rgba="0.898039215686275 0.917647058823529 0.929411764705882 1.0"/>
			</material>
		</visual>
		<collision name="ALWristRoll_Link_Collision">
			<origin rpy="1.529155 1.46726 -1.538407" xyz="0.081951 0.005319 -0.000273"/>
			<geometry>
				<cylinder length="0.19892359808020985" radius="0.051451062143852824"/>
			</geometry>
		</collision>
	</link>
	<joint name="ALWristYaw" type="revolute">
		<origin rpy="0.0 0.0 0.0" xyz="0.0 0.0 0.0"/>
		<axis xyz="0.0 1.0 0.0"/>
		<parent link="ALWristPitch_Link"/>
		<child link="ALWristYaw_Link"/>
		<limit effort="44.635" lower="-0.475" upper="0.585" velocity="7.725"/>
	</joint>
	<link name="ALWristYaw_Link">
		<inertial>
			<origin rpy="0.0 0.0 0.0" xyz="-0.0006783379600145488 -0.004595821715438101 0.013428986627659206"/>
			<mass value="0.10750158088268805"/>
			<inertia ixx="9.569999289025244e-05" ixy="3.991373626540703e-09" ixz="8.851013257069966e-10" iyy="9.189962271073085e-05" iyz="-1.4768282982305257e-06" izz="9.710214057827659e-05"/>
		</inertial>
		<visual name="ALWristYaw_Link_Visual">
			<origin rpy="0.0 0.0 0.0" xyz="0.0 0.0 0.0"/>
			<geometry>
				<mesh filename="../meshes/ALWristYaw_Link.stl"/>
			</geometry>
			<material name="">
				<color rgba="0.898039215686275 0.917647058823529 0.929411764705882 1.0"/>
			</material>
		</visual>
		<visual name="ALWristBL4_Link_Visual">
			<origin rpy="2.9998 0.0 0.0" xyz="0.027 -0.03 0.0"/>
			<geometry>
				<mesh filename="../meshes/ALWrist_BL4_Link.stl"/>
			</geometry>
			<material name="">
				<color rgba="0.776470588235294 0.756862745098039 0.737254901960784 1.0"/>
			</material>
		</visual>
		<visual name="ALWristBR4_Link_Visual">
			<origin rpy="-2.9998 0.0 3.141585" xyz="-0.027 -0.03 0.0"/>
			<geometry>
				<mesh filename="../meshes/ALWrist_BR4_Link.stl"/>
			</geometry>
			<material name="">
				<color rgba="0.647058823529412 0.619607843137255 0.588235294117647 1.0"/>
			</material>
		</visual>
		<visual name="ALWristBL3_Link_Visual">
			<origin rpy="2.999779 0.017082 -0.002439" xyz="0.027 -0.03 0.0"/>
			<geometry>
				<mesh filename="../meshes/ALWrist_BL3_Link.stl"/>
			</geometry>
			<material name="">
				<color rgba="0.898039215686275 0.917647058823529 0.929411764705882 1.0"/>
			</material>
		</visual>
		<visual name="ALWristBR3_Link_Visual">
			<origin rpy="-2.999779 0.017082 -3.139161" xyz="-0.027 -0.03 0.0"/>
			<geometry>
				<mesh filename="../meshes/ALWrist_BR3_Link.stl"/>
			</geometry>
			<material name="">
				<color rgba="0.529411764705882 0.549019607843137 0.549019607843137 1.0"/>
			</material>
		</visual>
		<visual name="ALWristBL2_Link_Visual">
			<origin rpy="2.999779 0.017082 -0.002439" xyz="0.026223 -0.036361 -0.04456"/>
			<geometry>
				<mesh filename="../meshes/ALWrist_BL2_Link.stl"/>
			</geometry>
			<material name="">
				<color rgba="0.647058823529412 0.619607843137255 0.588235294117647 1.0"/>
			</material>
		</visual>
		<visual name="ALWristBR2_Link_Visual">
			<origin rpy="-2.999779 0.017082 -3.139161" xyz="-0.026223 -0.036361 -0.04456"/>
			<geometry>
				<mesh filename="../meshes/ALWrist_BR2_Link.stl"/>
			</geometry>
			<material name="">
				<color rgba="0.647058823529412 0.619607843137255 0.588235294117647 1.0"/>
			</material>
		</visual>
	</link>
	<joint name="ARBase" type="fixed">
		<origin rpy="6e-05 -0.236287 -1.308995" xyz="-0.025162 -0.126089 0.35059"/>
		<parent link="BodyYaw_Link"/>
		<child link="ARBase_Link"/>
	</joint>
	<link name="ARBase_Link">
		<inertial>
			<origin rpy="0.0 0.0 0.0" xyz="0.00799 0.0 0.000196"/>
			<mass value="1.194300000000001"/>
			<inertia ixx="0.00089755" ixy="-1.4484e-08" ixz="-2.6127e-07" iyy="0.00057565" iyz="7.8027e-07" izz="0.00056347"/>
		</inertial>
		<visual name="ARBase_Link_Visual">
			<origin rpy="3.141593 0.0 0.0" xyz="0.0 0.0 0.0"/>
			<geometry>
				<mesh filename="../meshes/ARBase_Link.stl" scale="1.0 1.0 1.0"/>
			</geometry>
			<material name="">
				<color rgba="0.75294 0.75294 0.75294 1.0"/>
			</material>
		</visual>
	</link>
	<joint name="ARElbow" type="revolute">
		<origin rpy="-3.141592 0.0 -3.141592" xyz="0.0 0.001 -0.3511"/>
		<axis xyz="1.0 0.0 0.0"/>
		<parent link="ARShoulder3_Link"/>
		<child link="ARElbow_Link"/>
		<limit effort="110.13" lower="-1.78" upper="0.01" velocity="7.075"/>
	</joint>
	<link name="ARElbow_Link">
		<inertial>
			<origin rpy="0.0 0.0 0.0" xyz="0.0 0.001127 0.080286"/>
			<mass value="0.6357799999999997"/>
			<inertia ixx="0.0005099900001544764" ixy="-2.2297207206594354e-07" ixz="-4.0468474586715554e-07" iyy="0.0005163300270204655" iyz="-4.423298448630883e-05" izz="0.00046536997282505774"/>
		</inertial>
		<visual name="ARElbow_Link_Visual">
			<origin rpy="0.0 0.0 3.141593" xyz="0.0 0.0 0.0"/>
			<geometry>
				<mesh filename="../meshes/ARElbow_Link.stl" scale="1.0 1.0 1.0"/>
			</geometry>
			<material name="">
				<color rgba="0.75294 0.75294 0.75294 1.0"/>
			</material>
		</visual>
	</link>
	<joint name="ARShoulder1" type="revolute">
		<origin rpy="-3.141585 0.0 3.141593" xyz="0.1076 0.0 0.0"/>
		<axis xyz="1.0 0.0 0.0"/>
		<parent link="ARBase_Link"/>
		<child link="ARShoulder1_Link"/>
		<limit effort="157.0" lower="-3.0543" upper="3.0543" velocity="3.6"/>
	</joint>
	<link name="ARShoulder1_Link">
		<inertial>
			<origin rpy="0.0 0.0 0.0" xyz="0.009157 0.003646 -0.000169"/>
			<mass value="1.6019999999999996"/>
			<inertia ixx="0.0012116999440866811" ixy="8.070387961256474e-05" ixz="3.5280257083975037e-06" iyy="0.001556100057542011" iyz="-2.650928692723903e-06" izz="0.0010023999983713062"/>
		</inertial>
		<visual name="ARShoulder1_Link_Visual">
			<origin rpy="0.0 0.0 3.141593" xyz="0.0 0.0 0.0"/>
			<geometry>
				<mesh filename="../meshes/ARShoulder1_Link.stl" scale="1.0 1.0 1.0"/>
			</geometry>
			<material name="">
				<color rgba="0.75294 0.75294 0.75294 1.0"/>
			</material>
		</visual>
		<collision name="ARShoulder1_Link_Collision">
			<origin rpy="1.570864 -1.568017 3.141524" xyz="0.005334 -0.004665 -0.002299"/>
			<geometry>
				<sphere radius="0.059044145081229044"/>
			</geometry>
		</collision>
	</link>
	<joint name="ARShoulder2" type="revolute">
		<origin rpy="0.0 0.0 -3.141592" xyz="0.0 0.0 0.0"/>
		<axis xyz="0.0 1.0 0.0"/>
		<parent link="ARShoulder1_Link"/>
		<child link="ARShoulder2_Link"/>
		<limit effort="157.0" lower="-0.248" upper="1.845" velocity="3.6"/>
	</joint>
	<link name="ARShoulder2_Link">
		<inertial>
			<origin rpy="0.0 0.0 0.0" xyz="0.010763 -0.020477 0.0278"/>
			<mass value="0.5084917431461261"/>
			<inertia ixx="0.0010464999259024192" ixy="-0.00012061005396444852" ixz="5.485487847357631e-05" iyy="0.0009256802430528081" iyz="-0.0002750100517516733" izz="0.0010392998310447714"/>
		</inertial>
		<visual name="ARShoulder2_Link_Visual">
			<origin rpy="0.0 0.0 0.0" xyz="0.0 0.0 0.0"/>
			<geometry>
				<mesh filename="../meshes/ARShoulder2_Link.stl" scale="1.0 1.0 1.0"/>
			</geometry>
			<material name="">
				<color rgba="0.75294 0.75294 0.75294 1.0"/>
			</material>
		</visual>
	</link>
	<joint name="ARShoulder3" type="revolute">
		<origin rpy="-3.141593 1e-06 -1.5707" xyz="0.0 0.0 0.0"/>
		<axis xyz="0.0 0.0 1.0"/>
		<parent link="ARShoulder2_Link"/>
		<child link="ARShoulder3_Link"/>
		<limit effort="28.0" lower="-3.0543" upper="3.0543" velocity="5.7"/>
	</joint>
	<link name="ARShoulder3_Link">
		<inertial>
			<origin rpy="0.0 0.0 0.0" xyz="0.0 0.002327302974746533 -0.07663324824532092"/>
			<mass value="1.2342237960002198"/>
			<inertia ixx="0.00301838969045024" ixy="4.912221472850882e-07" ixz="7.838080878027623e-07" iyy="0.0029500093958173892" iyz="-6.7939016136265e-05" izz="0.0008755982941412455"/>
		</inertial>
		<visual name="ARShoulder3_Link_Visual">
			<origin rpy="3.141593 0.0 0.0" xyz="0.0 0.0 0.0"/>
			<geometry>
				<mesh filename="../meshes/ARShoulder3_Link.stl" scale="1.0 1.0 1.0"/>
			</geometry>
			<material name="">
				<color rgba="0.75294 0.75294 0.75294 1.0"/>
			</material>
		</visual>
		<visual name="ARElbowB11_Link_Visual">
			<origin rpy="2.888403 0.0 -3.141592" xyz="0.0 -0.029 -0.1391"/>
			<geometry>
				<mesh filename="../meshes/ARElbow_B11_Link.stl" scale="1.0 1.0 1.0"/>
			</geometry>
			<material name="">
				<color rgba="0.75294 0.75294 0.75294 1.0"/>
			</material>
		</visual>
		<visual name="ARElbowAct_Link_Visual">
			<origin rpy="2.888403 0.0 3.141592" xyz="0.0 0.045001 -0.425102"/>
			<geometry>
				<mesh filename="../meshes/ARElbow_Act_Link.stl" scale="1.0 1.0 1.0"/>
			</geometry>
			<material name="">
				<color rgba="0.75294 0.75294 0.75294 1.0"/>
			</material>
		</visual>
		<collision name="ARShoulder3_Link_Collision">
			<origin rpy="0.06999 -0.037077 0.479526" xyz="0.000897 0.015259 -0.247292"/>
			<geometry>
				<cylinder length="0.37510067633392874" radius="0.04989704634130358"/>
			</geometry>
		</collision>
	</link>
	<joint name="ARWristFT" type="fixed">
		<origin rpy="0.0 0.0 -1.5708" xyz="0.0 0.0 0.042748"/>
		<parent link="ARWristYaw_Link"/>
		<child link="ARWristFT_Link"/>
	</joint>
	<link name="ARWristFT_Link">
		<inertial>
			<origin rpy="0.0 0.0 0.0" xyz="-0.007384643000911799 -0.007810180244104391 0.022625684875546382"/>
			<mass value="0.6716364094742334"/>
			<inertia ixx="0.0002471607631168521" ixy="-1.2947206607771007e-07" ixz="-7.211116735608899e-07" iyy="0.0004114610354509037" iyz="-3.1627128739890997e-06" izz="0.0003044465748229154"/>
		</inertial>
		<visual name="ARWristFT_Link_Visual">
			<origin rpy="0.0 0.0 3.141593" xyz="0.0 0.0 0.0"/>
			<geometry>
				<mesh filename="../meshes/ARWristFT_Link.stl" scale="1.0 1.0 1.0"/>
			</geometry>
			<material name="">
				<color rgba="0.698039215686274 0.698039215686274 0.698039215686274 1.0"/>
			</material>
		</visual>
		<visual name="GRBase_Visual">
			<origin rpy="0.0 0.0 3.141593" xyz="0.0 0.0 0.0"/>
			<geometry>
				<mesh filename="../meshes/2FGripper_BaseFrame.stl"/>
			</geometry>
			<material name="">
				<color rgba="0.77647 0.75686 0.73725 1.0"/>
			</material>
		</visual>
		<visual name="GRF1Base_Visual">
			<origin rpy="1.789 0.0 1.570793" xyz="0.021725 0.013001 0.064903"/>
			<geometry>
				<mesh filename="../meshes/Finger_Base_Frame.stl"/>
			</geometry>
			<material name="">
				<color rgba="0.79216 0.81961 0.93333 1.0"/>
			</material>
		</visual>
		<visual name="GRF1ProximalBar_Visual">
			<origin rpy="0.6752 0.0 1.570793" xyz="0.061291 0.0 0.07714"/>
			<geometry>
				<mesh filename="../meshes/F_ProximalBar_Frame.stl"/>
			</geometry>
			<material name="">
				<color rgba="0.94118 0.67451 0.11765 1.0"/>
			</material>
		</visual>
		<visual name="GRF2Base_Visual">
			<origin rpy="1.789 0.0 -1.570793" xyz="-0.02175 -0.012996 0.064903"/>
			<geometry>
				<mesh filename="../meshes/Finger_Base_Frame.stl"/>
			</geometry>
			<material name="">
				<color rgba="0.79216 0.81961 0.93333 1.0"/>
			</material>
		</visual>
		<visual name="GRF2ProximalBar_Visual">
			<origin rpy="0.6752 0.0 -1.570793" xyz="-0.061316 0.0 0.07714"/>
			<geometry>
				<mesh filename="../meshes/F_ProximalBar_Frame.stl"/>
			</geometry>
			<material name="">
				<color rgba="0.94118 0.67451 0.11765 1.0"/>
			</material>
		</visual>
	</link>
	<joint name="ARWristPitch" type="revolute">
		<origin rpy="-3.141592 -1.5707 3.141592" xyz="-0.173 0.0 0.0"/>
		<axis xyz="1.0 0.0 0.0"/>
		<parent link="ARWristRoll_Link"/>
		<child link="ARWristPitch_Link"/>
		<limit effort="43.135" lower="-0.7" upper="1.57" velocity="9.255"/>
	</joint>
	<link name="ARWristPitch_Link">
		<inertial>
			<origin rpy="0.0 0.0 0.0" xyz="0.0 0.0 0.0"/>
			<mass value="0.030345802955544107"/>
			<inertia ixx="1.0000000011242505e-05" ixy="0.0" ixz="1.3686128944732079e-10" iyy="1.0143779057796206e-05" iyz="-1.3756897885220354e-10" izz="1.1666089364158585e-05"/>
		</inertial>
		<visual name="ARWristPitch_Link_Visual">
			<origin rpy="0.0 0.0 0.0" xyz="0.0 0.0 0.0"/>
			<geometry>
				<mesh filename="../meshes/ARWristPitch_Link.stl" scale="1.0 1.0 1.0"/>
			</geometry>
			<material name="">
				<color rgba="0.647058823529412 0.619607843137255 0.588235294117647 1.0"/>
			</material>
		</visual>
	</link>
	<joint name="ARWristRoll" type="revolute">
		<origin rpy="0.08344 1.570793 -3.058159" xyz="0.0 0.0 0.122"/>
		<axis xyz="1.0 0.0 0.0"/>
		<parent link="ARElbow_Link"/>
		<child link="ARWristRoll_Link"/>
		<limit effort="28.0" lower="-3.0543" upper="3.0543" velocity="5.7"/>
	</joint>
	<link name="ARWristRoll_Link">
		<inertial>
			<origin rpy="0.0 0.0 0.0" xyz="0.021101834391639287 0.01863898496767983 -0.022279585222716346"/>
			<mass value="0.7033939349158417"/>
			<inertia ixx="0.000591630305461663" ixy="1.7607232597827022e-05" ixz="4.3997628888334523e-07" iyy="0.0014425181855461675" iyz="1.2878607337505122e-06" izz="0.0014202622927536614"/>
		</inertial>
		<visual name="ARWristRoot_Link_Visual">
			<origin rpy="-0.01038 -1.5707 -3.131212" xyz="-0.173 0.0 0.0"/>
			<geometry>
				<mesh filename="../meshes/ARWrist_Root_Link.stl" scale="1.0 1.0 1.0"/>
			</geometry>
			<material name="">
				<color rgba="0.64706 0.61961 0.58824 1.0"/>
			</material>
		</visual>
		<visual name="ARWristBase_Link_Visual">
			<origin rpy="1e-06 0.0001 -3.141592" xyz="-0.005 0.0 0.0"/>
			<geometry>
				<mesh filename="../meshes/ARWrist_Base_Link.stl" scale="1.0 1.0 1.0"/>
			</geometry>
			<material name="">
				<color rgba="0.898039215686275 0.917647058823529 0.929411764705882 1.0"/>
			</material>
		</visual>
		<visual name="ARWristBL1_Link_Visual">
			<origin rpy="0.262788 1.5707 0.003596" xyz="-0.140999 -0.011 -0.015497"/>
			<geometry>
				<mesh filename="../meshes/ARWrist_BR1_Link.stl" scale="1.0 1.0 1.0"/>
			</geometry>
			<material name="">
				<color rgba="0.89804 0.91765 0.92941 1.0"/>
			</material>
		</visual>
		<visual name="ARWristBR1_Link_Visual">
			<origin rpy="0.262788 1.5707 0.003596" xyz="-0.141001 -0.011 0.015503"/>
			<geometry>
				<mesh filename="../meshes/ARWrist_BL1_Link.stl" scale="1.0 1.0 1.0"/>
			</geometry>
			<material name="">
				<color rgba="0.89804 0.91765 0.92941 1.0"/>
			</material>
		</visual>
		<visual name="ARWristAL1_Link_Visual">
			<origin rpy="-1.59202 -1.5707 -3.138073" xyz="0.005001 0.034 -0.015483"/>
			<geometry>
				<mesh filename="../meshes/ARWrist_AR1_Link.stl" scale="1.0 1.0 1.0"/>
			</geometry>
			<material name="">
				<color rgba="0.89804 0.91765 0.92941 1.0"/>
			</material>
		</visual>
		<visual name="ARWristAR1_Link_Visual">
			<origin rpy="-1.59202 -1.5707 -3.138073" xyz="0.004999 0.034 0.015517"/>
			<geometry>
				<mesh filename="../meshes/ARWrist_AL1_Link.stl" scale="1.0 1.0 1.0"/>
			</geometry>
			<material name="">
				<color rgba="0.898039215686275 0.917647058823529 0.929411764705882 1.0"/>
			</material>
		</visual>
		<visual name="ARWristActL_Link_Visual">
			<origin rpy="-3.116778 1.5707 0.007115" xyz="-0.128438 0.036363 -0.015496"/>
			<geometry>
				<mesh filename="../meshes/ARWrist_ActR_Link.stl" scale="1.0 1.0 1.0"/>
			</geometry>
			<material name="">
				<color rgba="0.776470588235294 0.756862745098039 0.737254901960784 1.0"/>
			</material>
		</visual>
		<visual name="ARWristActR_Link_Visual">
			<origin rpy="-3.116778 1.5707 0.007115" xyz="-0.12844 0.036363 0.015504"/>
			<geometry>
				<mesh filename="../meshes/ARWrist_ActL_Link.stl" scale="1.0 1.0 1.0"/>
			</geometry>
			<material name="">
				<color rgba="0.77647 0.75686 0.73725 1.0"/>
			</material>
		</visual>
		<collision name="ARWristRoll_Link_Collision">
			<origin rpy="1.57398 -1.456133 1.499218" xyz="-0.082074 0.004997 0.0"/>
			<geometry>
				<cylinder length="0.19860603208685698" radius="0.05148203817753268"/>
			</geometry>
		</collision>
	</link>
	<joint name="ARWristYaw" type="revolute">
		<origin rpy="0.0 0.0 -1e-06" xyz="0.0 0.0 0.0"/>
		<axis xyz="0.0 1.0 0.0"/>
		<parent link="ARWristPitch_Link"/>
		<child link="ARWristYaw_Link"/>
		<limit effort="44.635" lower="-0.475" upper="0.585" velocity="7.725"/>
	</joint>
	<link name="ARWristYaw_Link">
		<inertial>
			<origin rpy="0.0 0.0 0.0" xyz="0.0002815627050320236 0.004595921950291922 0.013428870722144314"/>
			<mass value="0.10750158918767636"/>
			<inertia ixx="9.569999289069512e-05" ixy="-3.990355623077085e-09" ixz="8.851741228806157e-10" iyy="9.189962270706206e-05" iyz="1.4768283027416586e-06" izz="9.710214058150272e-05"/>
		</inertial>
		<visual name="ARWristYaw_Link_Visual">
			<origin rpy="0.0 0.0 -3.141592" xyz="0.0 0.0 0.0"/>
			<geometry>
				<mesh filename="../meshes/ARWristYaw_Link.stl" scale="1.0 1.0 1.0"/>
			</geometry>
			<material name="">
				<color rgba="0.898039215686275 0.917647058823529 0.929411764705882 1.0"/>
			</material>
		</visual>
		<visual name="ARWristBL4_Link_Visual">
			<origin rpy="-2.9998 0.0 8e-06" xyz="-0.027 0.03 0.0"/>
			<geometry>
				<mesh filename="../meshes/ARWrist_BR4_Link.stl" scale="1.0 1.0 1.0"/>
			</geometry>
			<material name="">
				<color rgba="0.647058823529412 0.619607843137255 0.588235294117647 1.0"/>
			</material>
		</visual>
		<visual name="ARWristBR4_Link_Visual">
			<origin rpy="2.9998 0.0 -3.141592" xyz="0.027 0.03 0.0"/>
			<geometry>
				<mesh filename="../meshes/ARWrist_BL4_Link.stl" scale="1.0 1.0 1.0"/>
			</geometry>
			<material name="">
				<color rgba="0.776470588235294 0.756862745098039 0.737254901960784 1.0"/>
			</material>
		</visual>
		<visual name="ARWristBL3_Link_Visual">
			<origin rpy="-2.999779 -0.017082 -0.002432" xyz="-0.027 0.03 0.0"/>
			<geometry>
				<mesh filename="../meshes/ARWrist_BR3_Link.stl" scale="1.0 1.0 1.0"/>
			</geometry>
			<material name="">
				<color rgba="0.529411764705882 0.549019607843137 0.549019607843137 1.0"/>
			</material>
		</visual>
		<visual name="ARWristBR3_Link_Visual">
			<origin rpy="2.999779 -0.017082 -3.139153" xyz="0.027 0.03 0.0"/>
			<geometry>
				<mesh filename="../meshes/ARWrist_BL3_Link.stl" scale="1.0 1.0 1.0"/>
			</geometry>
			<material name="">
				<color rgba="0.898039215686275 0.917647058823529 0.929411764705882 1.0"/>
			</material>
		</visual>
		<visual name="ARWristBL2_Link_Visual">
			<origin rpy="-2.999779 -0.017082 -0.002432" xyz="-0.026223 0.036361 -0.04456"/>
			<geometry>
				<mesh filename="../meshes/ARWrist_BR2_Link.stl" scale="1.0 1.0 1.0"/>
			</geometry>
			<material name="">
				<color rgba="0.647058823529412 0.619607843137255 0.588235294117647 1.0"/>
			</material>
		</visual>
		<visual name="ARWristBR2_Link_Visual">
			<origin rpy="2.999779 -0.017082 -3.139153" xyz="0.026223 0.036361 -0.04456"/>
			<geometry>
				<mesh filename="../meshes/ARWrist_BL2_Link.stl" scale="1.0 1.0 1.0"/>
			</geometry>
			<material name="">
				<color rgba="0.647058823529412 0.619607843137255 0.588235294117647 1.0"/>
			</material>
		</visual>
	</link>
	<joint name="BodyPitch" type="revolute">
		<origin rpy="0.0 0.0 -4e-06" xyz="0.0 0.0 0.016"/>
		<axis xyz="0.0 1.0 0.0"/>
		<parent link="RH5v2_Root_Link"/>
		<child link="BodyPitch_Link"/>
		<limit effort="400.0" lower="-0.34" upper="0.52" velocity="3.1415926"/>
	</joint>
	<link name="BodyPitch_Link">
		<inertial>
			<origin rpy="0.0 0.0 0.0" xyz="0.0 0.0 0.0"/>
			<mass value="0.076413"/>
			<inertia ixx="1.3771000000001387e-05" ixy="2.1212999999995475e-12" ixz="2.1080999098829268e-12" iyy="1.3770999999998615e-05" iyz="0.0" izz="2.4637e-05"/>
		</inertial>
		<visual name="BodyPitch_Visual">
			<origin rpy="0.0 0.0 -1.570796" xyz="0.0 0.0 0.0"/>
			<geometry>
				<mesh filename="../meshes/BodyPitch.stl"/>
			</geometry>
			<material name="">
				<color rgba="0.89804 0.91765 0.92941 1.0"/>
			</material>
		</visual>
	</link>
	<joint name="BodyRoll" type="revolute">
		<origin rpy="0.0 0.0 0.0" xyz="0.0 0.0 0.0"/>
		<axis xyz="1.0 0.0 0.0"/>
		<parent link="BodyPitch_Link"/>
		<child link="BodyRoll_Link"/>
		<limit effort="400.0" lower="-0.44" upper="0.44" velocity="3.1415926"/>
	</joint>
	<link name="BodyRoll_Link">
		<inertial>
			<origin rpy="0.0 0.0 0.0" xyz="-0.009734 0.0 0.052947"/>
			<mass value="1.4553"/>
			<inertia ixx="0.001065799999518147" ixy="-7.372513070271073e-07" ixz="-6.32019993920274e-06" iyy="0.001000600000481853" iyz="1.8604206540909618e-07" izz="0.0017602"/>
		</inertial>
		<visual name="BodyRoll_Visual">
			<origin rpy="0.0 0.0 -1.570796" xyz="0.0 0.0 0.0"/>
			<geometry>
				<mesh filename="../meshes/BodyRoll.stl"/>
			</geometry>
			<material name="">
				<color rgba="0.89804 0.91765 0.92941 1.0"/>
			</material>
		</visual>
	</link>
	<joint name="BodyYaw" type="revolute">
		<origin rpy="0.0 0.0 0.0" xyz="0.0 0.0 0.0"/>
		<axis xyz="0.0 0.0 1.0"/>
		<parent link="BodyRoll_Link"/>
		<child link="BodyYaw_Link"/>
		<limit effort="157.0" lower="-3.0543" upper="3.0543" velocity="3.6"/>
	</joint>
	<link name="BodyYaw_Link">
		<inertial>
			<origin rpy="0.0 0.0 0.0" xyz="0.17761476789572922 0.004321655486563976 -0.008277657539023625"/>
			<mass value="9.624353096261528"/>
			<inertia ixx="0.23093456009646005" ixy="-4.4100097288588015e-05" ixz="0.0055615026589329155" iyy="0.16174159908651825" iyz="-0.0001812479769965654" izz="0.13955083529859266"/>
		</inertial>
		<visual name="BodyYaw_Visual">
			<origin rpy="0.0 0.0 -1.570796" xyz="0.0 0.0 0.0"/>
			<geometry>
				<mesh filename="../meshes/BodyYaw.stl"/>
			</geometry>
			<material name="">
				<color rgba="0.89804 0.91765 0.92941 1.0"/>
			</material>
		</visual>
		<visual name="base_link_torso_Visual">
			<origin rpy="1.5708 -1.570793 1.570796" xyz="0.0 0.0 0.0525"/>
			<geometry>
				<mesh filename="../meshes/base_link_torso.stl"/>
			</geometry>
			<material name="">
				<color rgba="0.698039215686274 0.698039215686274 0.698039215686274 1.0"/>
			</material>
		</visual>
		<visual name="Connector_Torso/Head_Visual">
			<origin rpy="1.5708 -1.570793 1.570796" xyz="0.0 0.0 0.401"/>
			<geometry>
				<mesh filename="../meshes/Connector_Torso_Head.stl"/>
			</geometry>
			<material name="">
				<color rgba="0.69804 0.69804 0.69804 1.0"/>
			</material>
		</visual>
		<visual name="Connector_Torso/ArmRight_Visual">
			<origin rpy="6e-05 -0.236287 -1.308995" xyz="-0.025162 -0.126089 0.35059"/>
			<geometry>
				<mesh filename="../meshes/Connector_Torso_ArmRight.stl"/>
			</geometry>
			<material name="">
				<color rgba="0.69804 0.69804 0.69804 1.0"/>
			</material>
		</visual>
		<visual name="Connector_Torso/ArmLeft_Visual">
			<origin rpy="-6.2e-05 -0.23628 1.309002" xyz="-0.025162 0.126091 0.35059"/>
			<geometry>
				<mesh filename="../meshes/Connector_Torso_ArmLeft.stl"/>
			</geometry>
			<material name="">
				<color rgba="0.69804 0.69804 0.69804 1.0"/>
			</material>
		</visual>
		<visual name="Connector_Torso/Backpack_Visual">
			<origin rpy="3e-06 3e-06 -3.14159" xyz="-0.139 0.135001 0.354"/>
			<geometry>
				<mesh filename="../meshes/Connector_Torso_Backpack.stl"/>
			</geometry>
			<material name="">
				<color rgba="0.20784 0.30196 0.45098 1.0"/>
			</material>
		</visual>
		<collision name="BodyYaw_Link_Collision">
			<origin rpy="0.0 0.0 0.0" xyz="0.0 0.0 0.0"/>
			<geometry>
				<mesh filename="../meshes/BodyYaw_Link_abstract-urdf_joined_convexhull.obj" scale="1.0 1.0 1.0"/>
			</geometry>
		</collision>
	</link>
	<joint name="CameraHeadLeftEye" type="fixed">
		<origin rpy="0.0 0.0 0.0" xyz="0.02 0.0 0.0"/>
		<parent link="Stereo_Camera_Head_Link"/>
		<child link="CameraHeadLeftEye_Link"/>
	</joint>
	<link name="CameraHeadLeftEye_Link"/>
	<joint name="CameraTorso" type="fixed">
		<origin rpy="0.0 0.0 0.0" xyz="0.0 0.0 0.0"/>
		<parent link="Structure_Sensor_Link"/>
		<child link="CameraTorso_Link"/>
	</joint>
	<link name="CameraTorso_Link"/>
	<joint name="GLF1Gear" type="fixed">
		<origin rpy="1.2885 0.0 0.0" xyz="0.0 0.0 0.053"/>
		<axis xyz="-1.0 0.0 0.0"/>
		<parent link="GLF1ProximalSegment_Link"/>
		<child link="GLF1Gear_Link"/>
		<limit effort="400.0" lower="-3.1415926" upper="3.1415926" velocity="3.1415926"/>
		<mimic joint="GLF1ProximalSegment" multiplier="-1.0" offset="0.0"/>
	</joint>
	<link name="GLF1Gear_Link">
		<inertial>
			<origin rpy="0.0 0.0 0.0" xyz="0.00042134 0.00032509 0.0086803"/>
			<mass value="0.024785"/>
			<inertia ixx="1.1031768852531896e-05" ixy="-3.314199999999995e-09" ixz="-1.3220000000000009e-08" iyy="1.04518688525319e-05" iyz="-1.0513000000000047e-07" izz="1.0024648852531899e-05"/>
		</inertial>
		<visual name="GLF1Gear_Visual">
			<origin rpy="0.0 0.0 0.0" xyz="0.0 0.0 0.0"/>
			<geometry>
				<mesh filename="../meshes/F_Gear_Frame.stl"/>
			</geometry>
			<material name="">
				<color rgba="0.94118 0.67451 0.11765 1.0"/>
			</material>
		</visual>
	</link>
	<joint name="GLF1ProximalSegment" type="fixed">
		<origin rpy="0.6664 0.1664 -1.533593" xyz="-0.031453 -0.028781 0.079387"/>
		<axis xyz="-1.0 0.0 0.0"/>
		<parent link="ALWristFT_Link"/>
		<child link="GLF1ProximalSegment_Link"/>
		<limit effort="400.0" lower="-0.03490658503988659" upper="2.844886680750757" velocity="3.1415926"/>
	</joint>
	<link name="GLF1ProximalSegment_Link">
		<inertial>
			<origin rpy="0.0 0.0 0.0" xyz="-0.0020799169088264002 0.0003869287332191591 0.021596022319208884"/>
			<mass value="0.054303017004370104"/>
			<inertia ixx="3.088548027794202e-05" ixy="-1.4302000000000137e-08" ixz="-2.683200000000028e-07" iyy="3.374948027794203e-05" iyz="6.182299999999967e-07" izz="2.0034380277942035e-05"/>
		</inertial>
		<visual name="GLF1ProximalSegment_Visual">
			<origin rpy="0.0 0.0 0.0" xyz="0.0 0.0 0.0"/>
			<geometry>
				<mesh filename="../meshes/F_ProximalSegment_Frame.stl"/>
			</geometry>
			<material name="">
				<color rgba="0.94118 0.67451 0.11765 1.0"/>
			</material>
		</visual>
		<collision name="GLF1ProximalSegment_Collision">
			<origin rpy="0.000111 0.075418 -1.569794" xyz="0.00013 -0.002054 0.02649"/>
			<geometry>
				<box size="0.030218173173127905 0.034882865322953094 0.0747403673565936"/>
			</geometry>
		</collision>
	</link>
	<joint name="GLF1TopSegment" type="fixed">
		<origin rpy="0.0 0.0 0.0" xyz="0.0 0.0 0.0"/>
		<axis xyz="-1.0 0.0 0.0"/>
		<parent link="GLF1Gear_Link"/>
		<child link="GLF1TopSegment_Link"/>
		<limit effort="400.0" lower="-3.1415926" upper="3.1415926" velocity="3.1415926"/>
	</joint>
	<link name="GLF1TopSegment_Link">
		<inertial>
			<origin rpy="0.0 0.0 0.0" xyz="0.0009346754545048612 0.02600300827216842 -0.013271286346101328"/>
			<mass value="0.04958915985083422"/>
			<inertia ixx="5.1651277429850974e-05" ixy="4.4296000000000057e-07" ixz="-6.034000000000103e-08" iyy="5.0300577429850974e-05" iyz="7.458099999999999e-07" izz="5.3196877429850975e-05"/>
		</inertial>
		<visual name="GLF1TopSegment_Visual">
			<origin rpy="0.0 0.0 0.0" xyz="0.0 0.0 0.0"/>
			<geometry>
				<mesh filename="../meshes/F_TopSegment_Frame.stl"/>
			</geometry>
			<material name="">
				<color rgba="0.94118 0.67451 0.11765 1.0"/>
			</material>
		</visual>
		<collision name="GLF1TopSegment_Collision">
			<origin rpy="3.025162 1.145167 -1.622776" xyz="0.0 0.02387 -0.012657"/>
			<geometry>
				<box size="0.026310870976772916 0.02858935493300371 0.07745781389552309"/>
			</geometry>
		</collision>
	</link>
	<joint name="GLF2Gear" type="fixed">
		<origin rpy="1.2885 0.0 0.0" xyz="0.0 0.0 0.053"/>
		<axis xyz="-1.0 0.0 0.0"/>
		<parent link="GLF2ProximalSegment_Link"/>
		<child link="GLF2Gear_Link"/>
		<limit effort="400.0" lower="-3.1415926" upper="3.1415926" velocity="3.1415926"/>
		<mimic joint="GLF2ProximalSegment" multiplier="-1.0" offset="0.0"/>
	</joint>
	<link name="GLF2Gear_Link">
		<inertial>
			<origin rpy="0.0 0.0 0.0" xyz="0.00042134 0.00032509 0.0086803"/>
			<mass value="0.024785"/>
			<inertia ixx="1.1031768852531896e-05" ixy="-3.314199999999995e-09" ixz="-1.3220000000000009e-08" iyy="1.04518688525319e-05" iyz="-1.0513000000000047e-07" izz="1.0024648852531899e-05"/>
		</inertial>
		<visual name="GLF2Gear_Visual">
			<origin rpy="0.0 0.0 0.0" xyz="0.0 0.0 0.0"/>
			<geometry>
				<mesh filename="../meshes/F_Gear_Frame.stl"/>
			</geometry>
			<material name="">
				<color rgba="0.94118 0.67451 0.11765 1.0"/>
			</material>
		</visual>
	</link>
	<joint name="GLF2ProximalSegment" type="fixed">
		<origin rpy="0.665 -0.12478 -1.598593" xyz="-0.031632 0.027073 0.080199"/>
		<axis xyz="-1.0 0.0 0.0"/>
		<parent link="ALWristFT_Link"/>
		<child link="GLF2ProximalSegment_Link"/>
		<limit effort="400.0" lower="-0.03490658503988659" upper="2.844886680750757" velocity="3.1415926"/>
	</joint>
	<link name="GLF2ProximalSegment_Link">
		<inertial>
			<origin rpy="0.0 0.0 0.0" xyz="-0.0020799169088264002 0.0003869287332191591 0.021596022319208884"/>
			<mass value="0.054303017004370104"/>
			<inertia ixx="3.088548027794202e-05" ixy="-1.4302000000000137e-08" ixz="-2.683200000000028e-07" iyy="3.374948027794203e-05" iyz="6.182299999999967e-07" izz="2.0034380277942035e-05"/>
		</inertial>
		<visual name="GLF2ProximalSegment_Visual">
			<origin rpy="0.0 0.0 0.0" xyz="0.0 0.0 0.0"/>
			<geometry>
				<mesh filename="../meshes/F_ProximalSegment_Frame.stl"/>
			</geometry>
			<material name="">
				<color rgba="0.94118 0.67451 0.11765 1.0"/>
			</material>
		</visual>
		<collision name="GLF2ProximalSegment_Collision">
			<origin rpy="0.000111 0.075418 -1.569794" xyz="0.00013 -0.002054 0.02649"/>
			<geometry>
				<box size="0.030218173173127905 0.034882865322953094 0.0747403673565936"/>
			</geometry>
		</collision>
	</link>
	<joint name="GLF2TopSegment" type="fixed">
		<origin rpy="0.0 0.0 0.0" xyz="0.0 0.0 0.0"/>
		<axis xyz="-1.0 0.0 0.0"/>
		<parent link="GLF2Gear_Link"/>
		<child link="GLF2TopSegment_Link"/>
		<limit effort="400.0" lower="-3.1415926" upper="3.1415926" velocity="3.1415926"/>
	</joint>
	<link name="GLF2TopSegment_Link">
		<inertial>
			<origin rpy="0.0 0.0 0.0" xyz="0.0009346754545048612 0.02600300827216842 -0.013271286346101328"/>
			<mass value="0.04958915985083422"/>
			<inertia ixx="5.1651277429850974e-05" ixy="4.4296000000000057e-07" ixz="-6.034000000000103e-08" iyy="5.0300577429850974e-05" iyz="7.458099999999999e-07" izz="5.3196877429850975e-05"/>
		</inertial>
		<visual name="GLF2TopSegment_Visual">
			<origin rpy="0.0 0.0 0.0" xyz="0.0 0.0 0.0"/>
			<geometry>
				<mesh filename="../meshes/F_TopSegment_Frame.stl"/>
			</geometry>
			<material name="">
				<color rgba="0.94118 0.67451 0.11765 1.0"/>
			</material>
		</visual>
		<collision name="GLF2TopSegment_Collision">
			<origin rpy="3.025162 1.145167 -1.622776" xyz="0.0 0.02387 -0.012657"/>
			<geometry>
				<box size="0.026310870976772916 0.02858935493300371 0.07745781389552309"/>
			</geometry>
		</collision>
	</link>
	<joint name="GLF3Gear" type="fixed">
		<origin rpy="1.2885 0.0 0.0" xyz="0.0 0.0 0.053"/>
		<axis xyz="-1.0 0.0 0.0"/>
		<parent link="GLF3ProximalSegment_Link"/>
		<child link="GLF3Gear_Link"/>
		<limit effort="400.0" lower="-3.1415926" upper="3.1415926" velocity="3.1415926"/>
		<mimic joint="GLF3ProximalSegment" multiplier="-1.0" offset="0.0"/>
	</joint>
	<link name="GLF3Gear_Link">
		<inertial>
			<origin rpy="0.0 0.0 0.0" xyz="0.00042134 0.00032509 0.0086803"/>
			<mass value="0.024785"/>
			<inertia ixx="1.1031768852531896e-05" ixy="-3.314199999999995e-09" ixz="-1.3220000000000009e-08" iyy="1.04518688525319e-05" iyz="-1.0513000000000047e-07" izz="1.0024648852531899e-05"/>
		</inertial>
		<visual name="GLF3Gear_Visual">
			<origin rpy="0.0 0.0 0.0" xyz="0.0 0.0 0.0"/>
			<geometry>
				<mesh filename="../meshes/F_Gear_Frame.stl"/>
			</geometry>
			<material name="">
				<color rgba="0.94118 0.67451 0.11765 1.0"/>
			</material>
		</visual>
	</link>
	<joint name="GLF3ProximalSegment" type="fixed">
		<origin rpy="0.665 -0.124785 -1.598609" xyz="-0.030665 0.061788 0.075843"/>
		<axis xyz="-1.0 0.0 0.0"/>
		<parent link="ALWristFT_Link"/>
		<child link="GLF3ProximalSegment_Link"/>
		<limit effort="400.0" lower="-0.03490658503988659" upper="2.844886680750757" velocity="3.1415926"/>
	</joint>
	<link name="GLF3ProximalSegment_Link">
		<inertial>
			<origin rpy="0.0 0.0 0.0" xyz="-0.0020799169088264002 0.0003869287332191591 0.021596022319208884"/>
			<mass value="0.054303017004370104"/>
			<inertia ixx="3.088548027794202e-05" ixy="-1.4302000000000137e-08" ixz="-2.683200000000028e-07" iyy="3.374948027794203e-05" iyz="6.182299999999967e-07" izz="2.0034380277942035e-05"/>
		</inertial>
		<visual name="GLF3ProximalSegment_Visual">
			<origin rpy="0.0 0.0 0.0" xyz="0.0 0.0 0.0"/>
			<geometry>
				<mesh filename="../meshes/F_ProximalSegment_Frame.stl"/>
			</geometry>
			<material name="">
				<color rgba="0.94118 0.67451 0.11765 1.0"/>
			</material>
		</visual>
		<collision name="GLF3ProximalSegment_Collision">
			<origin rpy="0.000111 0.075418 -1.569794" xyz="0.00013 -0.002054 0.02649"/>
			<geometry>
				<box size="0.030218173173127905 0.034882865322953094 0.0747403673565936"/>
			</geometry>
		</collision>
	</link>
	<joint name="GLF3TopSegment" type="fixed">
		<origin rpy="0.0 0.0 0.0" xyz="0.0 0.0 0.0"/>
		<axis xyz="-1.0 0.0 0.0"/>
		<parent link="GLF3Gear_Link"/>
		<child link="GLF3TopSegment_Link"/>
		<limit effort="400.0" lower="-3.1415926" upper="3.1415926" velocity="3.1415926"/>
	</joint>
	<link name="GLF3TopSegment_Link">
		<inertial>
			<origin rpy="0.0 0.0 0.0" xyz="0.0009346754545048612 0.02600300827216842 -0.013271286346101328"/>
			<mass value="0.04958915985083422"/>
			<inertia ixx="5.1651277429850974e-05" ixy="4.4296000000000057e-07" ixz="-6.034000000000103e-08" iyy="5.0300577429850974e-05" iyz="7.458099999999999e-07" izz="5.3196877429850975e-05"/>
		</inertial>
		<visual name="GLF3TopSegment_Visual">
			<origin rpy="0.0 0.0 0.0" xyz="0.0 0.0 0.0"/>
			<geometry>
				<mesh filename="../meshes/F_TopSegment_Frame.stl"/>
			</geometry>
			<material name="">
				<color rgba="0.94118 0.67451 0.11765 1.0"/>
			</material>
		</visual>
		<collision name="GLF3TopSegment_Collision">
			<origin rpy="3.025162 1.145167 -1.622776" xyz="0.0 0.02387 -0.012657"/>
			<geometry>
				<box size="0.026310870976772916 0.02858935493300371 0.07745781389552309"/>
			</geometry>
		</collision>
	</link>
	<joint name="GLF4Gear" type="fixed">
		<origin rpy="1.2885 0.0 0.0" xyz="0.0 0.0 0.053"/>
		<axis xyz="-1.0 0.0 0.0"/>
		<parent link="GLF4ProximalSegment_Link"/>
		<child link="GLF4Gear_Link"/>
		<limit effort="400.0" lower="-3.1415926" upper="3.1415926" velocity="3.1415926"/>
		<mimic joint="GLF4ProximalSegment" multiplier="-1.0" offset="0.0"/>
	</joint>
	<link name="GLF4Gear_Link">
		<inertial>
			<origin rpy="0.0 0.0 0.0" xyz="0.00042134 0.00032509 0.0086803"/>
			<mass value="0.024785"/>
			<inertia ixx="1.1031768852531896e-05" ixy="-3.314199999999995e-09" ixz="-1.3220000000000009e-08" iyy="1.04518688525319e-05" iyz="-1.0513000000000047e-07" izz="1.0024648852531899e-05"/>
		</inertial>
		<visual name="GLF4Gear_Visual">
			<origin rpy="0.0 0.0 0.0" xyz="0.0 0.0 0.0"/>
			<geometry>
				<mesh filename="../meshes/F_Gear_Frame.stl"/>
			</geometry>
			<material name="">
				<color rgba="0.94118 0.67451 0.11765 1.0"/>
			</material>
		</visual>
	</link>
	<joint name="GLF4ProximalSegment" type="fixed">
		<origin rpy="0.6633 0.0 -1.570801" xyz="-0.029562 0.0 0.04035"/>
		<axis xyz="-1.0 0.0 0.0"/>
		<parent link="GLThumb_Link"/>
		<child link="GLF4ProximalSegment_Link"/>
		<limit effort="400.0" lower="-0.03490658503988659" upper="2.844886680750757" velocity="3.1415926"/>
	</joint>
	<link name="GLF4ProximalSegment_Link">
		<inertial>
			<origin rpy="0.0 0.0 0.0" xyz="-0.0020799169088264002 0.0003869287332191591 0.021596022319208884"/>
			<mass value="0.054303017004370104"/>
			<inertia ixx="3.088548027794202e-05" ixy="-1.4302000000000137e-08" ixz="-2.683200000000028e-07" iyy="3.374948027794203e-05" iyz="6.182299999999967e-07" izz="2.0034380277942035e-05"/>
		</inertial>
		<visual name="GLF4ProximalSegment_Visual">
			<origin rpy="0.0 0.0 0.0" xyz="0.0 0.0 0.0"/>
			<geometry>
				<mesh filename="../meshes/F_ProximalSegment_Frame.stl"/>
			</geometry>
			<material name="">
				<color rgba="0.94118 0.67451 0.11765 1.0"/>
			</material>
		</visual>
		<collision name="GLF4ProximalSegment_Collision">
			<origin rpy="0.000111 0.075418 -1.569794" xyz="0.00013 -0.002054 0.02649"/>
			<geometry>
				<box size="0.030218173173127905 0.034882865322953094 0.0747403673565936"/>
			</geometry>
		</collision>
	</link>
	<joint name="GLF4TopSegment" type="fixed">
		<origin rpy="0.0 0.0 0.0" xyz="0.0 0.0 0.0"/>
		<axis xyz="-1.0 0.0 0.0"/>
		<parent link="GLF4Gear_Link"/>
		<child link="GLF4TopSegment_Link"/>
		<limit effort="400.0" lower="-3.1415926" upper="3.1415926" velocity="3.1415926"/>
	</joint>
	<link name="GLF4TopSegment_Link">
		<inertial>
			<origin rpy="0.0 0.0 0.0" xyz="0.0009346754545048612 0.02600300827216842 -0.013271286346101328"/>
			<mass value="0.04958915985083422"/>
			<inertia ixx="5.1651277429850974e-05" ixy="4.4296000000000057e-07" ixz="-6.034000000000103e-08" iyy="5.0300577429850974e-05" iyz="7.458099999999999e-07" izz="5.3196877429850975e-05"/>
		</inertial>
		<visual name="GLF4TopSegment_Visual">
			<origin rpy="0.0 0.0 0.0" xyz="0.0 0.0 0.0"/>
			<geometry>
				<mesh filename="../meshes/F_TopSegment_Frame.stl"/>
			</geometry>
			<material name="">
				<color rgba="0.94118 0.67451 0.11765 1.0"/>
			</material>
		</visual>
		<collision name="GLF4TopSegment_Collision">
			<origin rpy="3.025162 1.145167 -1.622776" xyz="0.0 0.02387 -0.012657"/>
			<geometry>
				<box size="0.026310870976772916 0.02858935493300371 0.07745781389552309"/>
			</geometry>
		</collision>
	</link>
	<joint name="GLIMU" type="fixed">
		<origin rpy="0.0 1.3526 0.0" xyz="-0.003256 0.00202 0.053849"/>
		<parent link="ALWristFT_Link"/>
		<child link="GLIMU_Link"/>
	</joint>
	<link name="GLIMU_Link">
		<inertial>
			<origin rpy="0.0 0.0 0.0" xyz="0.0 0.0 0.0"/>
			<mass value="0.0"/>
			<inertia ixx="1e-05" ixy="0.0" ixz="0.0" iyy="1e-05" iyz="0.0" izz="1e-05"/>
		</inertial>
	</link>
	<joint name="GLThumb" type="fixed">
		<origin rpy="0.0 0.0 -3.141592" xyz="0.019161 -0.002327 0.042"/>
		<axis xyz="-1.0 0.0 0.0"/>
		<parent link="ALWristFT_Link"/>
		<child link="GLThumb_Link"/>
		<limit effort="400.0" lower="-0.2617993877991494" upper="1.064650843716541" velocity="3.1415926"/>
	</joint>
	<link name="GLThumb_Link">
		<inertial>
			<origin rpy="0.0 0.0 0.0" xyz="-0.012646064590810985 -0.008105798415063866 0.014724299589204017"/>
			<mass value="0.3647561825882988"/>
			<inertia ixx="0.00017196947154162604" ixy="-1.2849830058509908e-06" ixz="-6.455817419732357e-07" iyy="0.00015617393364816254" iyz="-1.2623201197509347e-06" izz="0.000152835229404215"/>
		</inertial>
		<visual name="GLThumb_Visual">
			<origin rpy="0.0 0.0 3.141593" xyz="0.0 0.0 0.0"/>
			<geometry>
				<mesh filename="../meshes/GL_Thumb.stl" scale="1.0 1.0 1.0"/>
			</geometry>
			<material name="">
				<color rgba="0.94118 0.67451 0.11765 1.0"/>
			</material>
		</visual>
		<visual name="GLF4Base_Visual">
			<origin rpy="1.789 0.0 -1.570801" xyz="-0.011996 -0.013 0.028112"/>
			<geometry>
				<mesh filename="../meshes/Finger_Base_Frame.stl"/>
			</geometry>
			<material name="">
				<color rgba="0.79216 0.81961 0.93333 1.0"/>
			</material>
		</visual>
		<visual name="GLF4ProximalBar_Visual">
			<origin rpy="0.6752 0.0 -1.570801" xyz="-0.051562 0.0 0.040349"/>
			<geometry>
				<mesh filename="../meshes/F_ProximalBar_Frame.stl"/>
			</geometry>
			<material name="">
				<color rgba="0.94118 0.67451 0.11765 1.0"/>
			</material>
		</visual>
	</link>
	<joint name="GRF1Gear" type="fixed">
		<origin rpy="1.2885 0.0 0.0" xyz="0.0 0.0 0.053"/>
		<axis xyz="-1.0 0.0 0.0"/>
		<parent link="GRF1ProximalSegment_Link"/>
		<child link="GRF1Gear_Link"/>
		<limit effort="400.0" lower="-3.1415926" upper="3.1415926" velocity="3.1415926"/>
		<mimic joint="GRF1ProximalSegment" multiplier="-1.0" offset="0.0"/>
	</joint>
	<link name="GRF1Gear_Link">
		<inertial>
			<origin rpy="0.0 0.0 0.0" xyz="0.00042134 0.00032509 0.0086803"/>
			<mass value="0.024785"/>
			<inertia ixx="1.1031768852531896e-05" ixy="-3.314199999999995e-09" ixz="-1.3220000000000009e-08" iyy="1.04518688525319e-05" iyz="-1.0513000000000047e-07" izz="1.0024648852531899e-05"/>
		</inertial>
		<visual name="GRF1Gear_Visual">
			<origin rpy="0.0 0.0 0.0" xyz="0.0 0.0 0.0"/>
			<geometry>
				<mesh filename="../meshes/F_Gear_Frame.stl"/>
			</geometry>
			<material name="">
				<color rgba="0.94118 0.67451 0.11765 1.0"/>
			</material>
		</visual>
	</link>
	<joint name="GRF1ProximalSegment" type="fixed">
		<origin rpy="0.6633 0.0 1.570793" xyz="0.039291 0.0 0.077141"/>
		<axis xyz="-1.0 0.0 0.0"/>
		<parent link="ARWristFT_Link"/>
		<child link="GRF1ProximalSegment_Link"/>
		<limit effort="400.0" lower="-0.05235987755982988" upper="0.7330382858376184" velocity="3.1415926"/>
	</joint>
	<link name="GRF1ProximalSegment_Link">
		<inertial>
			<origin rpy="0.0 0.0 0.0" xyz="-0.0020799169088264002 0.0003869287332191591 0.021596022319208884"/>
			<mass value="0.054303017004370104"/>
			<inertia ixx="3.088548027794202e-05" ixy="-1.4302000000000137e-08" ixz="-2.683200000000028e-07" iyy="3.374948027794203e-05" iyz="6.182299999999967e-07" izz="2.0034380277942035e-05"/>
		</inertial>
		<visual name="GRF1ProximalSegment_Visual">
			<origin rpy="0.0 0.0 0.0" xyz="0.0 0.0 0.0"/>
			<geometry>
				<mesh filename="../meshes/F_ProximalSegment_Frame.stl"/>
			</geometry>
			<material name="">
				<color rgba="0.94118 0.67451 0.11765 1.0"/>
			</material>
		</visual>
		<collision name="GRF1ProximalSegment_Collision">
			<origin rpy="0.000111 0.075418 -1.569794" xyz="0.00013 -0.002054 0.02649"/>
			<geometry>
				<box size="0.030218173173127905 0.034882865322953094 0.0747403673565936"/>
			</geometry>
		</collision>
	</link>
	<joint name="GRF1TopSegment" type="fixed">
		<origin rpy="0.0 0.0 0.0" xyz="0.0 0.0 0.0"/>
		<axis xyz="-1.0 0.0 0.0"/>
		<parent link="GRF1Gear_Link"/>
		<child link="GRF1TopSegment_Link"/>
		<limit effort="400.0" lower="-3.1415926" upper="3.1415926" velocity="3.1415926"/>
	</joint>
	<link name="GRF1TopSegment_Link">
		<inertial>
			<origin rpy="0.0 0.0 0.0" xyz="0.0009346754545048612 0.02600300827216842 -0.013271286346101328"/>
			<mass value="0.04958915985083422"/>
			<inertia ixx="5.1651277429850974e-05" ixy="4.4296000000000057e-07" ixz="-6.034000000000103e-08" iyy="5.0300577429850974e-05" iyz="7.458099999999999e-07" izz="5.3196877429850975e-05"/>
		</inertial>
		<visual name="GRF1TopSegment_Visual">
			<origin rpy="0.0 0.0 0.0" xyz="0.0 0.0 0.0"/>
			<geometry>
				<mesh filename="../meshes/F_TopSegment_Frame.stl"/>
			</geometry>
			<material name="">
				<color rgba="0.94118 0.67451 0.11765 1.0"/>
			</material>
		</visual>
		<collision name="GRF1TopSegment_Collision">
			<origin rpy="3.025162 1.145167 -1.622776" xyz="0.0 0.02387 -0.012657"/>
			<geometry>
				<box size="0.026310870976772916 0.02858935493300371 0.07745781389552309"/>
			</geometry>
		</collision>
	</link>
	<joint name="GRF2Gear" type="fixed">
		<origin rpy="1.2885 0.0 0.0" xyz="0.0 0.0 0.053"/>
		<axis xyz="-1.0 0.0 0.0"/>
		<parent link="GRF2ProximalSegment_Link"/>
		<child link="GRF2Gear_Link"/>
		<limit effort="400.0" lower="-3.1415926" upper="3.1415926" velocity="3.1415926"/>
		<mimic joint="GRF2ProximalSegment" multiplier="-1.0" offset="0.0"/>
	</joint>
	<link name="GRF2Gear_Link">
		<inertial>
			<origin rpy="0.0 0.0 0.0" xyz="0.00042134 0.00032509 0.0086803"/>
			<mass value="0.024785"/>
			<inertia ixx="1.1031768852531896e-05" ixy="-3.314199999999995e-09" ixz="-1.3220000000000009e-08" iyy="1.04518688525319e-05" iyz="-1.0513000000000047e-07" izz="1.0024648852531899e-05"/>
		</inertial>
		<visual name="GRF2Gear_Visual">
			<origin rpy="0.0 0.0 0.0" xyz="0.0 0.0 0.0"/>
			<geometry>
				<mesh filename="../meshes/F_Gear_Frame.stl"/>
			</geometry>
			<material name="">
				<color rgba="0.94118 0.67451 0.11765 1.0"/>
			</material>
		</visual>
	</link>
	<joint name="GRF2ProximalSegment" type="fixed">
		<origin rpy="0.6633 0.0 -1.570793" xyz="-0.039316 0.0 0.077141"/>
		<axis xyz="-1.0 0.0 0.0"/>
		<parent link="ARWristFT_Link"/>
		<child link="GRF2ProximalSegment_Link"/>
		<limit effort="400.0" lower="-0.05235987755982988" upper="0.7330382858376184" velocity="3.1415926"/>
	</joint>
	<link name="GRF2ProximalSegment_Link">
		<inertial>
			<origin rpy="0.0 0.0 0.0" xyz="-0.0020799169088264002 0.0003869287332191591 0.021596022319208884"/>
			<mass value="0.054303017004370104"/>
			<inertia ixx="3.088548027794202e-05" ixy="-1.4302000000000137e-08" ixz="-2.683200000000028e-07" iyy="3.374948027794203e-05" iyz="6.182299999999967e-07" izz="2.0034380277942035e-05"/>
		</inertial>
		<visual name="GRF2ProximalSegment_Visual">
			<origin rpy="0.0 0.0 0.0" xyz="0.0 0.0 0.0"/>
			<geometry>
				<mesh filename="../meshes/F_ProximalSegment_Frame.stl"/>
			</geometry>
			<material name="">
				<color rgba="0.94118 0.67451 0.11765 1.0"/>
			</material>
		</visual>
		<collision name="GRF2ProximalSegment_Collision">
			<origin rpy="0.000111 0.075418 -1.569794" xyz="0.00013 -0.002054 0.02649"/>
			<geometry>
				<box size="0.030218173173127905 0.034882865322953094 0.0747403673565936"/>
			</geometry>
		</collision>
	</link>
	<joint name="GRF2TopSegment" type="fixed">
		<origin rpy="0.0 0.0 0.0" xyz="0.0 0.0 0.0"/>
		<axis xyz="-1.0 0.0 0.0"/>
		<parent link="GRF2Gear_Link"/>
		<child link="GRF2TopSegment_Link"/>
		<limit effort="400.0" lower="-3.1415926" upper="3.1415926" velocity="3.1415926"/>
	</joint>
	<link name="GRF2TopSegment_Link">
		<inertial>
			<origin rpy="0.0 0.0 0.0" xyz="0.0009346754545048612 0.02600300827216842 -0.013271286346101328"/>
			<mass value="0.04958915985083422"/>
			<inertia ixx="5.1651277429850974e-05" ixy="4.4296000000000057e-07" ixz="-6.034000000000103e-08" iyy="5.0300577429850974e-05" iyz="7.458099999999999e-07" izz="5.3196877429850975e-05"/>
		</inertial>
		<visual name="GRF2TopSegment_Visual">
			<origin rpy="0.0 0.0 0.0" xyz="0.0 0.0 0.0"/>
			<geometry>
				<mesh filename="../meshes/F_TopSegment_Frame.stl"/>
			</geometry>
			<material name="">
				<color rgba="0.94118 0.67451 0.11765 1.0"/>
			</material>
		</visual>
		<collision name="GRF2TopSegment_Collision">
			<origin rpy="3.025162 1.145167 -1.622776" xyz="0.0 0.02387 -0.012657"/>
			<geometry>
				<box size="0.026310870976772916 0.02858935493300371 0.07745781389552309"/>
			</geometry>
		</collision>
	</link>
	<joint name="GRIMU" type="fixed">
		<origin rpy="-1.5708 -0.009708 3.141593" xyz="0.001862 -0.026119 0.056625"/>
		<parent link="ARWristFT_Link"/>
		<child link="GRIMU_Link"/>
	</joint>
	<link name="GRIMU_Link">
		<inertial>
			<origin rpy="0.0 0.0 0.0" xyz="0.0 0.0 0.0"/>
			<mass value="0.0"/>
			<inertia ixx="1e-05" ixy="0.0" ixz="0.0" iyy="1e-05" iyz="0.0" izz="1e-05"/>
		</inertial>
	</link>
	<joint name="HeadBase" type="fixed">
		<origin rpy="1.5708 -1.570793 1.570796" xyz="0.0 0.0 0.401"/>
		<parent link="BodyYaw_Link"/>
		<child link="HeadBase_Link"/>
	</joint>
	<link name="HeadBase_Link">
		<inertial>
			<origin rpy="0.0 0.0 0.0" xyz="0.06759895988262875 0.0 -0.0005760329571146471"/>
			<mass value="1.44199275293458"/>
			<inertia ixx="0.0017389000000001366" ixy="4.263074194599638e-08" ixz="5.2598000136856475e-08" iyy="0.001487789459964334" iyz="7.061917726905939e-07" izz="0.0013696378900355294"/>
		</inertial>
		<visual name="HeadBase_Visual">
			<origin rpy="0.0 0.0 0.0" xyz="0.0 0.0 0.0"/>
			<geometry>
				<mesh filename="../meshes/Head_Base.stl"/>
			</geometry>
			<material name="">
				<color rgba="0.69804 0.69804 0.69804 1.0"/>
			</material>
		</visual>
		<visual name="HeadActC_Visual">
			<origin rpy="-1.5708 0.0 0.0" xyz="0.15925 0.0 0.0"/>
			<geometry>
				<mesh filename="../meshes/Head_ActC.stl"/>
			</geometry>
			<material name="">
				<color rgba="0.89804 0.91765 0.92941 1.0"/>
			</material>
		</visual>
		<visual name="HeadActL_Visual">
			<origin rpy="-3.141585 0.0 1.5708" xyz="0.15925 0.0 0.0"/>
			<geometry>
				<mesh filename="../meshes/Head_ActL.stl"/>
			</geometry>
			<material name="">
				<color rgba="0.69804 0.69804 0.69804 1.0"/>
			</material>
		</visual>
		<visual name="HeadActR_Visual">
			<origin rpy="0.0 0.0 -1.5708" xyz="0.15925 0.0 0.0"/>
			<geometry>
				<mesh filename="../meshes/Head_ActR.stl"/>
			</geometry>
			<material name="">
				<color rgba="0.69804 0.69804 0.69804 1.0"/>
			</material>
		</visual>
		<collision name="HeadBase_Link_Collision">
			<origin rpy="1.489582 -0.057445 1.569603" xyz="0.089282 0.003564 -0.023422"/>
			<geometry>
				<box size="0.15116204744210632 0.15949007075757243 0.18968096600451853"/>
			</geometry>
		</collision>
	</link>
	<joint name="HeadPitch" type="revolute">
		<origin rpy="0.0 0.0 -1.5708" xyz="0.15925 0.0 0.0"/>
		<axis xyz="1.0 0.0 0.0"/>
		<parent link="HeadBase_Link"/>
		<child link="HeadPitch_Link"/>
		<limit effort="8.2" lower="-0.3" upper="0.35" velocity="4.8"/>
	</joint>
	<link name="HeadPitch_Link">
		<inertial>
			<origin rpy="0.0 0.0 0.0" xyz="0.0 0.0 0.00296950883117566"/>
			<mass value="0.0135306815484183"/>
			<inertia ixx="1.0900469792997046e-05" ixy="-1.983276674419689e-12" ixz="2.9229038977620623e-12" iyy="1.1777940400612256e-05" iyz="0.0" izz="1.0000000000009494e-05"/>
		</inertial>
		<visual name="HeadPitch_Visual">
			<origin rpy="0.0 0.0 0.0" xyz="0.0 0.0 0.0"/>
			<geometry>
				<mesh filename="../meshes/HeadPitch.stl"/>
			</geometry>
			<material name="">
				<color rgba="0.898039215686275 0.917647058823529 0.929411764705882 1.0"/>
			</material>
		</visual>
	</link>
	<joint name="HeadRoll" type="revolute">
		<origin rpy="-1.5708 -1.5708 0.0" xyz="0.0 0.0 0.0"/>
		<axis xyz="-1.0 0.0 0.0"/>
		<parent link="HeadPitch_Link"/>
		<child link="HeadRoll_Link"/>
		<limit effort="8.2" lower="-0.45" upper="0.45" velocity="4.8"/>
	</joint>
	<link name="HeadRoll_Link">
		<inertial>
			<origin rpy="0.0 0.0 0.0" xyz="-0.00844253878850604 0.0 0.00884603238325907"/>
			<mass value="0.109788715391496"/>
			<inertia ixx="1.83994177455821e-05" ixy="5.13405597754959e-11" ixz="-1.07875589146075e-08" iyy="1.359548687449e-05" iyz="-9.3011670884998e-10" izz="1.39946184243742e-05"/>
		</inertial>
		<visual name="HeadRoll_Visual">
			<origin rpy="0.0 0.0 0.0" xyz="0.0 0.0 0.0"/>
			<geometry>
				<mesh filename="../meshes/HeadRoll.stl"/>
			</geometry>
			<material name="">
				<color rgba="0.898039215686275 0.917647058823529 0.929411764705882 1.0"/>
			</material>
		</visual>
	</link>
	<joint name="HeadYaw" type="revolute">
		<origin rpy="1.5708 -1.5708 0.0" xyz="0.0 0.0 0.0"/>
		<axis xyz="1.0 0.0 0.0"/>
		<parent link="HeadRoll_Link"/>
		<child link="HeadYaw_Link"/>
		<limit effort="4.1" lower="-2.1" upper="2.1" velocity="4.8"/>
	</joint>
	<link name="HeadYaw_Link">
		<inertial>
			<origin rpy="0.0 0.0 0.0" xyz="0.0865202750448954 -0.0440420348532486 -0.00282280741895916"/>
			<mass value="1.46451930762968"/>
			<inertia ixx="0.00400957562211491" ixy="-0.000773636855316844" ixz="-8.24762860917018e-06" iyy="0.00399135489001388" iyz="-9.04346097850664e-06" izz="0.00411109150468807"/>
		</inertial>
		<visual name="HeadYaw_Visual">
			<origin rpy="0.0 0.0 0.0" xyz="0.0 0.0 0.0"/>
			<geometry>
				<mesh filename="../meshes/HeadYaw.stl"/>
			</geometry>
			<material name="">
				<color rgba="0.498039215686275 0.498039215686275 0.498039215686275 1.0"/>
			</material>
		</visual>
		<collision name="HeadYaw_Collision">
			<origin rpy="1.570773 -5.3e-05 2.757791" xyz="0.071982 -0.056676 0.0"/>
			<geometry>
				<box size="0.20200141506883382 0.2099636317811051 0.2599446678014104"/>
			</geometry>
		</collision>
	</link>
	<joint name="IMU_Body" type="fixed">
		<origin rpy="0.0 0.0 0.0" xyz="-0.005 -0.01745 -0.09195"/>
		<parent link="RH5v2_Root_Link"/>
		<child link="IMU_Body_Link"/>
	</joint>
	<link name="IMU_Body_Link">
		<inertial>
			<origin rpy="0.0 0.0 0.0" xyz="0.020181 0.018941 0.0015699"/>
			<mass value="0.093167"/>
			<inertia ixx="1.4618e-05" ixy="-6.5521e-08" ixz="-5.6588e-08" iyy="2.4402e-05" iyz="6.4435e-09" izz="3.4276e-05"/>
		</inertial>
		<visual name="IMU_Body_Visual">
			<origin rpy="0.0 0.0 0.0" xyz="0.0 0.0 0.0"/>
			<geometry>
				<mesh filename="../meshes/IMU_Body.stl"/>
			</geometry>
			<material name="">
				<color rgba="0.69804 0.69804 0.69804 1.0"/>
			</material>
		</visual>
	</link>
	<joint name="IMU_Torso" type="fixed">
		<origin rpy="3e-06 3e-06 -3.14159" xyz="-0.0075 -0.10255 0.19985"/>
		<parent link="BodyYaw_Link"/>
		<child link="IMU_Torso_Link"/>
	</joint>
	<link name="IMU_Torso_Link">
		<inertial>
			<origin rpy="0.0 0.0 0.0" xyz="0.020181 0.018941 0.0015699"/>
			<mass value="0.093167"/>
			<inertia ixx="1.4618e-05" ixy="-6.5519e-08" ixz="-5.6587e-08" iyy="2.4402e-05" iyz="6.4433e-09" izz="3.4276e-05"/>
		</inertial>
		<visual name="IMU_Torso_Visual">
			<origin rpy="0.0 0.0 0.0" xyz="0.0 0.0 0.0"/>
			<geometry>
				<mesh filename="../meshes/IMU_Torso.stl"/>
			</geometry>
			<material name="">
				<color rgba="0.69804 0.69804 0.69804 1.0"/>
			</material>
		</visual>
	</link>
	<link name="RH5v2_Root_Link">
		<inertial>
			<origin rpy="0.0 0.0 0.0" xyz="0.0024605808943312085 0.0005436720090129546 0.013657225497719604"/>
			<mass value="3.8294651011734016"/>
			<inertia ixx="0.017563188359104042" ixy="-4.438195543371645e-07" ixz="-0.001338106333674375" iyy="0.011878434065959306" iyz="-5.316260446147072e-07" izz="0.01783032477493666"/>
		</inertial>
		<visual name="RH5v2_Root_Link_Visual">
			<origin rpy="0.0 0.0 0.0" xyz="0.0 0.0 0.0"/>
			<geometry>
				<mesh filename="../meshes/RH5v2_Root_Link.stl"/>
			</geometry>
			<material name="">
				<color rgba="0.89804 0.91765 0.92941 1.0"/>
			</material>
		</visual>
		<collision name="RH5v2_Root_Link_Collision">
			<origin rpy="0.0 0.0 0.0" xyz="0.0 0.0 0.0"/>
			<geometry>
				<mesh filename="../meshes/RH5v2_Root_Link_convexhull.obj" scale="1.0 1.0 1.0"/>
			</geometry>
		</collision>
		<visual name="BodyRoot_Link_Visual">
			<origin rpy="0.0 0.0 -1.5708" xyz="0.0 0.0 0.016"/>
			<geometry>
				<mesh filename="../meshes/Body_Root_Link.stl"/>
			</geometry>
			<material name="">
				<color rgba="1.0 1.0 1.0 1.0"/>
			</material>
		</visual>
		<visual name="BodyBL1_Visual">
			<origin rpy="0.24177 0.0 3.141585" xyz="-0.089827 0.02 -0.194"/>
			<geometry>
				<mesh filename="../meshes/Body_BL1.stl"/>
			</geometry>
			<material name="">
				<color rgba="0.64706 0.61961 0.58824 1.0"/>
			</material>
		</visual>
		<visual name="BodyBL2_Visual">
			<origin rpy="0.241782 0.010038 -3.139125" xyz="-0.089827 0.02 -0.194"/>
			<geometry>
				<mesh filename="../meshes/Body_BL2.stl"/>
			</geometry>
			<material name="">
				<color rgba="0.61961 0.40784 0.2 1.0"/>
			</material>
		</visual>
		<visual name="BodyActL_Visual">
			<origin rpy="0.241782 0.010038 -3.139125" xyz="-0.092308 0.077456 0.038998"/>
			<geometry>
				<mesh filename="../meshes/Body_ActL.stl"/>
			</geometry>
			<material name="">
				<color rgba="0.69804 0.69804 0.69804 1.0"/>
			</material>
		</visual>
		<visual name="BodyBR1_Visual">
			<origin rpy="-0.24177 0.0 3.141585" xyz="-0.089827 -0.02 -0.194"/>
			<geometry>
				<mesh filename="../meshes/Body_BR1.stl"/>
			</geometry>
			<material name="">
				<color rgba="0.64706 0.61961 0.58824 1.0"/>
			</material>
		</visual>
		<visual name="BodyBR2_Visual">
			<origin rpy="-0.241782 0.010038 3.13911" xyz="-0.089827 -0.02 -0.194"/>
			<geometry>
				<mesh filename="../meshes/Body_BR2.stl"/>
			</geometry>
			<material name="">
				<color rgba="0.64706 0.61961 0.58824 1.0"/>
			</material>
		</visual>
		<visual name="BodyActR_Visual">
			<origin rpy="-0.241782 0.010038 3.13911" xyz="-0.092309 -0.077456 0.038998"/>
			<geometry>
				<mesh filename="../meshes/Body_ActR.stl"/>
			</geometry>
			<material name="">
				<color rgba="0.69804 0.69804 0.69804 1.0"/>
			</material>
		</visual>
	</link>
	<joint name="Stereo_Camera_Head" type="fixed">
		<origin rpy="-3.141496 -1.5707 -1.570796" xyz="0.069 -0.1035 -0.031499"/>
		<parent link="HeadYaw_Link"/>
		<child link="Stereo_Camera_Head_Link"/>
	</joint>
	<link name="Stereo_Camera_Head_Link">
		<inertial>
			<origin rpy="0.0 0.0 0.0" xyz="0.02429 0.0 0.009299"/>
			<mass value="0.16394274956965307"/>
			<inertia ixx="0.00021315559509522546" ixy="8.028068239105281e-10" ixz="1.8189970232574128e-08" iyy="0.00021456968378314532" iyz="2.481963350513344e-06" izz="1.5494393629639505e-05"/>
		</inertial>
		<visual name="Stereo_Camera_Head_Visual">
			<origin rpy="0.785398 -1.57066 0.785398" xyz="0.0 0.0 0.0"/>
			<geometry>
				<mesh filename="../meshes/Stereo_Camera_Head.stl"/>
			</geometry>
			<material name="">
				<color rgba="0.698039215686274 0.698039215686274 0.698039215686274 1.0"/>
			</material>
		</visual>
	</link>
	<joint name="Structure_Sensor" type="fixed">
		<origin rpy="-1.919866 9.2e-05 -1.570833" xyz="0.120411 0.038251 0.36839"/>
		<parent link="BodyYaw_Link"/>
		<child link="Structure_Sensor_Link"/>
	</joint>
	<link name="Structure_Sensor_Link">
		<inertial>
			<origin rpy="0.0 0.0 0.0" xyz="0.038622 0.0 -0.005631"/>
			<mass value="0.35771000000000003"/>
			<inertia ixx="3.9054002146696363e-05" ixy="2.7546331115970395e-08" ixz="6.539800799468631e-07" iyy="0.0003796399978528181" iyz="7.024737852269282e-10" izz="0.0003707500000004858"/>
		</inertial>
		<visual name="Structure_Sensor_Visual">
			<origin rpy="-3.141593 0.0 1.5707" xyz="0.0765 0.0 0.0"/>
			<geometry>
				<mesh filename="../meshes/Structure_Sensor_Torso.stl"/>
			</geometry>
			<material name="">
				<color rgba="0.69804 0.69804 0.69804 1.0"/>
			</material>
		</visual>
		<collision name="Structure_Sensor_Collision">
			<origin rpy="1.570797 0.0 -1.570893" xyz="0.038262 0.0 -0.004648"/>
			<geometry>
				<box size="0.028000000898483875 0.029504660516651193 0.11954025808869992"/>
			</geometry>
		</collision>
	</link>
	<joint name="platform" type="fixed">
		<origin rpy="-1.570801 1.309 -1.5708" xyz="0.025 -0.085744 -0.09458"/>
		<parent link="RH5v2_Root_Link"/>
		<child link="platform_Link"/>
	</joint>
	<link name="platform_Link">
		<inertial>
			<origin rpy="0.0 0.0 0.0" xyz="0.60163 0.24997 -0.2825"/>
			<mass value="98.726"/>
			<inertia ixx="1.4402" ixy="0.1287" ixz="0.044177" iyy="0.99436" iyz="0.011837" izz="0.83359"/>
		</inertial>
		<visual name="platform_Visual">
			<origin rpy="0.0 0.0 0.0" xyz="0.0 0.0 0.0"/>
			<geometry>
				<mesh filename="../meshes/base_link.stl"/>
			</geometry>
			<material name="">
				<color rgba="0.75294 0.75294 0.75294 1.0"/>
			</material>
		</visual>
		<collision name="platform_Collision">
			<origin rpy="0.0 0.0 0.0" xyz="0.0 0.0 0.0"/>
			<geometry>
				<mesh filename="../meshes/base_link_convexhull.obj" scale="1.0 1.0 1.0"/>
			</geometry>
		</collision>
	</link>
</robot>
