<robot name="floating_base">
  <link name='world'/>
  <link name='link_floating_base_trans_x'/>
  <link name='link_floating_base_trans_y'/>
  <link name='link_floating_base_trans_z'/>
  <link name='link_floating_base_rot_x'/>
  <link name='link_floating_base_rot_y'/>
  <link name='link_floating_base_rot_z'/>

  <joint name='floating_base_trans_x' type='prismatic'>
    <parent link='world'/>
    <child link='link_floating_base_trans_x'/>
    <origin rpy='0 0 0' xyz='0 0 0'/>
    <axis xyz='1 0 0'/>
    <limit effort='1000' lower='-1000' upper='1000' velocity='1000'/>
  </joint>

  <joint name='floating_base_trans_y' type='prismatic'>
    <parent link='link_floating_base_trans_x'/>
    <child link='link_floating_base_trans_y'/>
    <origin rpy='0 0 0' xyz='0 0 0'/>
    <axis xyz='0 1 0'/>
    <limit effort='1000' lower='-1000' upper='1000' velocity='1000'/>
  </joint>

  <joint name='floating_base_trans_z' type='prismatic'>
    <parent link='link_floating_base_trans_y'/>
    <child link='link_floating_base_trans_z'/>
    <origin rpy='0 0 0' xyz='0 0 0'/>
    <axis xyz='0 0 1'/>
    <limit effort='1000' lower='-1000' upper='1000' velocity='1000'/>
  </joint>

  <joint name='floating_base_rot_x' type='revolute'>
    <parent link='link_floating_base_trans_z'/>
    <child link='link_floating_base_rot_x'/>
    <origin rpy='0 0 0' xyz='0 0 0'/>
    <axis xyz='1 0 0'/>
    <limit effort='1000' lower='-1000' upper='1000' velocity='1000'/>
  </joint>

  <joint name='floating_base_rot_y' type='revolute'>
    <parent link='link_floating_base_rot_x'/>
    <child link='link_floating_base_rot_y'/>
    <origin rpy='0 0 0' xyz='0 0 0'/>
    <axis xyz='0 1 0'/>
    <limit effort='1000' lower='-1000' upper='1000' velocity='1000'/>
  </joint>

  <joint name='floating_base_rot_z' type='revolute'>
    <parent link='link_floating_base_rot_y'/>
    <child link='link_floating_base_rot_z'/>
    <origin rpy='0 0 0' xyz='0 0 0'/>
    <axis xyz='0 0 1'/>
    <limit effort='1000' lower='-1000' upper='1000' velocity='1000'/>
  </joint>

</robot>
